[2024-04-16T04:14:31.586+0000] {processor.py:154} INFO - Started process (PID=23754) to work on /opt/airflow/dags/group_dag.py
[2024-04-16T04:14:31.589+0000] {processor.py:756} INFO - Processing file /opt/airflow/dags/group_dag.py for tasks to queue
[2024-04-16T04:14:31.608+0000] {logging_mixin.py:120} INFO - [2024-04-16T04:14:31.608+0000] {dagbag.py:537} INFO - Filling up the DagBag from /opt/airflow/dags/group_dag.py
[2024-04-16T04:14:31.896+0000] {logging_mixin.py:120} INFO - [2024-04-16T04:14:31.875+0000] {dagbag.py:342} ERROR - Failed to import: /opt/airflow/dags/group_dag.py
Traceback (most recent call last):
  File "/home/airflow/.local/lib/python3.7/site-packages/airflow/models/dagbag.py", line 338, in parse
    loader.exec_module(new_module)
  File "<frozen importlib._bootstrap_external>", line 728, in exec_module
  File "<frozen importlib._bootstrap>", line 219, in _call_with_frames_removed
  File "/opt/airflow/dags/group_dag.py", line 27, in <module>
    subdag=subdag_downloads(dag.dag_id, 'downloads', args)
  File "/opt/airflow/dags/subdags/subdags_downloads.py", line 9, in subdag_downloads
    catch = args['catchup']) as dag:
TypeError: __init__() got an unexpected keyword argument 'catch'
[2024-04-16T04:14:31.897+0000] {processor.py:768} WARNING - No viable dags retrieved from /opt/airflow/dags/group_dag.py
[2024-04-16T04:14:32.071+0000] {processor.py:176} INFO - Processing /opt/airflow/dags/group_dag.py took 0.507 seconds
[2024-04-16T10:10:30.777+0000] {processor.py:154} INFO - Started process (PID=23923) to work on /opt/airflow/dags/group_dag.py
[2024-04-16T10:10:30.828+0000] {processor.py:756} INFO - Processing file /opt/airflow/dags/group_dag.py for tasks to queue
[2024-04-16T10:10:30.918+0000] {logging_mixin.py:120} INFO - [2024-04-16T10:10:30.916+0000] {dagbag.py:537} INFO - Filling up the DagBag from /opt/airflow/dags/group_dag.py
[2024-04-16T10:10:33.264+0000] {logging_mixin.py:120} INFO - [2024-04-16T10:10:33.145+0000] {dagbag.py:342} ERROR - Failed to import: /opt/airflow/dags/group_dag.py
Traceback (most recent call last):
  File "/home/airflow/.local/lib/python3.7/site-packages/airflow/models/dagbag.py", line 338, in parse
    loader.exec_module(new_module)
  File "<frozen importlib._bootstrap_external>", line 728, in exec_module
  File "<frozen importlib._bootstrap>", line 219, in _call_with_frames_removed
  File "/opt/airflow/dags/group_dag.py", line 27, in <module>
    subdag=subdag_downloads(dag.dag_id, 'downloads', args)
  File "/opt/airflow/dags/subdags/subdags_downloads.py", line 9, in subdag_downloads
    catch = args['catchup']) as dag:
TypeError: __init__() got an unexpected keyword argument 'catch'
[2024-04-16T10:10:33.347+0000] {processor.py:768} WARNING - No viable dags retrieved from /opt/airflow/dags/group_dag.py
[2024-04-16T10:10:34.848+0000] {processor.py:176} INFO - Processing /opt/airflow/dags/group_dag.py took 4.367 seconds
[2024-04-16T10:22:57.022+0000] {processor.py:154} INFO - Started process (PID=45) to work on /opt/airflow/dags/group_dag.py
[2024-04-16T10:22:57.038+0000] {processor.py:756} INFO - Processing file /opt/airflow/dags/group_dag.py for tasks to queue
[2024-04-16T10:22:57.040+0000] {logging_mixin.py:120} INFO - [2024-04-16T10:22:57.040+0000] {dagbag.py:537} INFO - Filling up the DagBag from /opt/airflow/dags/group_dag.py
[2024-04-16T10:22:57.211+0000] {logging_mixin.py:120} INFO - [2024-04-16T10:22:57.203+0000] {dagbag.py:342} ERROR - Failed to import: /opt/airflow/dags/group_dag.py
Traceback (most recent call last):
  File "/home/airflow/.local/lib/python3.7/site-packages/airflow/models/dagbag.py", line 338, in parse
    loader.exec_module(new_module)
  File "<frozen importlib._bootstrap_external>", line 728, in exec_module
  File "<frozen importlib._bootstrap>", line 219, in _call_with_frames_removed
  File "/opt/airflow/dags/group_dag.py", line 27, in <module>
    subdag=subdag_downloads(dag.dag_id, 'downloads', args)
  File "/opt/airflow/dags/subdags/subdags_downloads.py", line 9, in subdag_downloads
    catch = args['catchup']) as dag:
TypeError: __init__() got an unexpected keyword argument 'catch'
[2024-04-16T10:22:57.216+0000] {processor.py:768} WARNING - No viable dags retrieved from /opt/airflow/dags/group_dag.py
[2024-04-16T10:22:57.310+0000] {processor.py:176} INFO - Processing /opt/airflow/dags/group_dag.py took 0.300 seconds
[2024-04-16T10:23:30.022+0000] {processor.py:154} INFO - Started process (PID=113) to work on /opt/airflow/dags/group_dag.py
[2024-04-16T10:23:30.025+0000] {processor.py:756} INFO - Processing file /opt/airflow/dags/group_dag.py for tasks to queue
[2024-04-16T10:23:30.027+0000] {logging_mixin.py:120} INFO - [2024-04-16T10:23:30.027+0000] {dagbag.py:537} INFO - Filling up the DagBag from /opt/airflow/dags/group_dag.py
[2024-04-16T10:23:30.213+0000] {logging_mixin.py:120} INFO - [2024-04-16T10:23:30.192+0000] {dagbag.py:342} ERROR - Failed to import: /opt/airflow/dags/group_dag.py
Traceback (most recent call last):
  File "/home/airflow/.local/lib/python3.7/site-packages/airflow/models/dagbag.py", line 338, in parse
    loader.exec_module(new_module)
  File "<frozen importlib._bootstrap_external>", line 728, in exec_module
  File "<frozen importlib._bootstrap>", line 219, in _call_with_frames_removed
  File "/opt/airflow/dags/group_dag.py", line 27, in <module>
    subdag=subdag_downloads(dag.dag_id, 'downloads', args)
  File "/opt/airflow/dags/subdags/subdags_downloads.py", line 9, in subdag_downloads
    catch = args['catchup']) as dag:
TypeError: __init__() got an unexpected keyword argument 'catch'
[2024-04-16T10:23:30.216+0000] {processor.py:768} WARNING - No viable dags retrieved from /opt/airflow/dags/group_dag.py
[2024-04-16T10:23:30.307+0000] {processor.py:176} INFO - Processing /opt/airflow/dags/group_dag.py took 0.305 seconds
[2024-04-16T10:24:04.757+0000] {processor.py:154} INFO - Started process (PID=171) to work on /opt/airflow/dags/group_dag.py
[2024-04-16T10:24:04.760+0000] {processor.py:756} INFO - Processing file /opt/airflow/dags/group_dag.py for tasks to queue
[2024-04-16T10:24:04.761+0000] {logging_mixin.py:120} INFO - [2024-04-16T10:24:04.761+0000] {dagbag.py:537} INFO - Filling up the DagBag from /opt/airflow/dags/group_dag.py
[2024-04-16T10:24:04.802+0000] {logging_mixin.py:120} INFO - [2024-04-16T10:24:04.798+0000] {dagbag.py:342} ERROR - Failed to import: /opt/airflow/dags/group_dag.py
Traceback (most recent call last):
  File "/home/airflow/.local/lib/python3.7/site-packages/airflow/models/dagbag.py", line 338, in parse
    loader.exec_module(new_module)
  File "<frozen importlib._bootstrap_external>", line 728, in exec_module
  File "<frozen importlib._bootstrap>", line 219, in _call_with_frames_removed
  File "/opt/airflow/dags/group_dag.py", line 27, in <module>
    subdag=subdag_downloads(dag.dag_id, 'downloads', args)
  File "/opt/airflow/dags/subdags/subdags_downloads.py", line 9, in subdag_downloads
    catch = args['catchup']) as dag:
TypeError: __init__() got an unexpected keyword argument 'catch'
[2024-04-16T10:24:04.803+0000] {processor.py:768} WARNING - No viable dags retrieved from /opt/airflow/dags/group_dag.py
[2024-04-16T10:24:04.834+0000] {processor.py:176} INFO - Processing /opt/airflow/dags/group_dag.py took 0.083 seconds
[2024-04-16T10:24:54.943+0000] {processor.py:154} INFO - Started process (PID=248) to work on /opt/airflow/dags/group_dag.py
[2024-04-16T10:24:54.946+0000] {processor.py:756} INFO - Processing file /opt/airflow/dags/group_dag.py for tasks to queue
[2024-04-16T10:24:54.948+0000] {logging_mixin.py:120} INFO - [2024-04-16T10:24:54.947+0000] {dagbag.py:537} INFO - Filling up the DagBag from /opt/airflow/dags/group_dag.py
[2024-04-16T10:24:54.991+0000] {logging_mixin.py:120} INFO - [2024-04-16T10:24:54.986+0000] {dagbag.py:342} ERROR - Failed to import: /opt/airflow/dags/group_dag.py
Traceback (most recent call last):
  File "/home/airflow/.local/lib/python3.7/site-packages/airflow/models/dagbag.py", line 338, in parse
    loader.exec_module(new_module)
  File "<frozen importlib._bootstrap_external>", line 728, in exec_module
  File "<frozen importlib._bootstrap>", line 219, in _call_with_frames_removed
  File "/opt/airflow/dags/group_dag.py", line 27, in <module>
    subdag=subdag_downloads(dag.dag_id, 'downloads', args)
  File "/opt/airflow/dags/subdags/subdags_downloads.py", line 9, in subdag_downloads
    catch = args['catchup']) as dag:
TypeError: __init__() got an unexpected keyword argument 'catch'
[2024-04-16T10:24:54.993+0000] {processor.py:768} WARNING - No viable dags retrieved from /opt/airflow/dags/group_dag.py
[2024-04-16T10:24:55.027+0000] {processor.py:176} INFO - Processing /opt/airflow/dags/group_dag.py took 0.090 seconds
[2024-04-16T10:25:25.710+0000] {processor.py:154} INFO - Started process (PID=323) to work on /opt/airflow/dags/group_dag.py
[2024-04-16T10:25:25.712+0000] {processor.py:756} INFO - Processing file /opt/airflow/dags/group_dag.py for tasks to queue
[2024-04-16T10:25:25.713+0000] {logging_mixin.py:120} INFO - [2024-04-16T10:25:25.713+0000] {dagbag.py:537} INFO - Filling up the DagBag from /opt/airflow/dags/group_dag.py
[2024-04-16T10:25:25.760+0000] {logging_mixin.py:120} INFO - [2024-04-16T10:25:25.757+0000] {dagbag.py:342} ERROR - Failed to import: /opt/airflow/dags/group_dag.py
Traceback (most recent call last):
  File "/home/airflow/.local/lib/python3.7/site-packages/airflow/models/dagbag.py", line 338, in parse
    loader.exec_module(new_module)
  File "<frozen importlib._bootstrap_external>", line 728, in exec_module
  File "<frozen importlib._bootstrap>", line 219, in _call_with_frames_removed
  File "/opt/airflow/dags/group_dag.py", line 27, in <module>
    subdag=subdag_downloads(dag.dag_id, 'downloads', args)
  File "/opt/airflow/dags/subdags/subdags_downloads.py", line 9, in subdag_downloads
    catch = args['catchup']) as dag:
TypeError: __init__() got an unexpected keyword argument 'catch'
[2024-04-16T10:25:25.761+0000] {processor.py:768} WARNING - No viable dags retrieved from /opt/airflow/dags/group_dag.py
[2024-04-16T10:25:25.790+0000] {processor.py:176} INFO - Processing /opt/airflow/dags/group_dag.py took 0.086 seconds
[2024-04-16T10:26:00.944+0000] {processor.py:154} INFO - Started process (PID=398) to work on /opt/airflow/dags/group_dag.py
[2024-04-16T10:26:00.955+0000] {processor.py:756} INFO - Processing file /opt/airflow/dags/group_dag.py for tasks to queue
[2024-04-16T10:26:00.966+0000] {logging_mixin.py:120} INFO - [2024-04-16T10:26:00.964+0000] {dagbag.py:537} INFO - Filling up the DagBag from /opt/airflow/dags/group_dag.py
[2024-04-16T10:26:01.167+0000] {logging_mixin.py:120} INFO - [2024-04-16T10:26:01.149+0000] {dagbag.py:342} ERROR - Failed to import: /opt/airflow/dags/group_dag.py
Traceback (most recent call last):
  File "/home/airflow/.local/lib/python3.7/site-packages/airflow/models/dagbag.py", line 338, in parse
    loader.exec_module(new_module)
  File "<frozen importlib._bootstrap_external>", line 728, in exec_module
  File "<frozen importlib._bootstrap>", line 219, in _call_with_frames_removed
  File "/opt/airflow/dags/group_dag.py", line 27, in <module>
    subdag=subdag_downloads(dag.dag_id, 'downloads', args)
  File "/opt/airflow/dags/subdags/subdags_downloads.py", line 9, in subdag_downloads
    catch = args['catchup']) as dag:
TypeError: __init__() got an unexpected keyword argument 'catch'
[2024-04-16T10:26:01.174+0000] {processor.py:768} WARNING - No viable dags retrieved from /opt/airflow/dags/group_dag.py
[2024-04-16T10:26:01.399+0000] {processor.py:176} INFO - Processing /opt/airflow/dags/group_dag.py took 0.489 seconds
[2024-04-16T10:26:32.019+0000] {processor.py:154} INFO - Started process (PID=458) to work on /opt/airflow/dags/group_dag.py
[2024-04-16T10:26:32.023+0000] {processor.py:756} INFO - Processing file /opt/airflow/dags/group_dag.py for tasks to queue
[2024-04-16T10:26:32.026+0000] {logging_mixin.py:120} INFO - [2024-04-16T10:26:32.026+0000] {dagbag.py:537} INFO - Filling up the DagBag from /opt/airflow/dags/group_dag.py
[2024-04-16T10:26:32.082+0000] {logging_mixin.py:120} INFO - [2024-04-16T10:26:32.078+0000] {dagbag.py:342} ERROR - Failed to import: /opt/airflow/dags/group_dag.py
Traceback (most recent call last):
  File "/home/airflow/.local/lib/python3.7/site-packages/airflow/models/dagbag.py", line 338, in parse
    loader.exec_module(new_module)
  File "<frozen importlib._bootstrap_external>", line 728, in exec_module
  File "<frozen importlib._bootstrap>", line 219, in _call_with_frames_removed
  File "/opt/airflow/dags/group_dag.py", line 27, in <module>
    subdag=subdag_downloads(dag.dag_id, 'downloads', args)
  File "/opt/airflow/dags/subdags/subdags_downloads.py", line 9, in subdag_downloads
    catch = args['catchup']) as dag:
TypeError: __init__() got an unexpected keyword argument 'catch'
[2024-04-16T10:26:32.085+0000] {processor.py:768} WARNING - No viable dags retrieved from /opt/airflow/dags/group_dag.py
[2024-04-16T10:26:32.125+0000] {processor.py:176} INFO - Processing /opt/airflow/dags/group_dag.py took 0.115 seconds
[2024-04-16T10:27:04.687+0000] {processor.py:154} INFO - Started process (PID=523) to work on /opt/airflow/dags/group_dag.py
[2024-04-16T10:27:04.689+0000] {processor.py:756} INFO - Processing file /opt/airflow/dags/group_dag.py for tasks to queue
[2024-04-16T10:27:04.692+0000] {logging_mixin.py:120} INFO - [2024-04-16T10:27:04.692+0000] {dagbag.py:537} INFO - Filling up the DagBag from /opt/airflow/dags/group_dag.py
[2024-04-16T10:27:04.732+0000] {logging_mixin.py:120} INFO - [2024-04-16T10:27:04.728+0000] {dagbag.py:342} ERROR - Failed to import: /opt/airflow/dags/group_dag.py
Traceback (most recent call last):
  File "/home/airflow/.local/lib/python3.7/site-packages/airflow/models/dagbag.py", line 338, in parse
    loader.exec_module(new_module)
  File "<frozen importlib._bootstrap_external>", line 728, in exec_module
  File "<frozen importlib._bootstrap>", line 219, in _call_with_frames_removed
  File "/opt/airflow/dags/group_dag.py", line 27, in <module>
    subdag=subdag_downloads(dag.dag_id, 'downloads', args)
  File "/opt/airflow/dags/subdags/subdags_downloads.py", line 9, in subdag_downloads
    catch = args['catchup']) as dag:
TypeError: __init__() got an unexpected keyword argument 'catch'
[2024-04-16T10:27:04.733+0000] {processor.py:768} WARNING - No viable dags retrieved from /opt/airflow/dags/group_dag.py
[2024-04-16T10:27:04.769+0000] {processor.py:176} INFO - Processing /opt/airflow/dags/group_dag.py took 0.088 seconds
[2024-04-16T10:27:35.386+0000] {processor.py:154} INFO - Started process (PID=597) to work on /opt/airflow/dags/group_dag.py
[2024-04-16T10:27:35.388+0000] {processor.py:756} INFO - Processing file /opt/airflow/dags/group_dag.py for tasks to queue
[2024-04-16T10:27:35.391+0000] {logging_mixin.py:120} INFO - [2024-04-16T10:27:35.390+0000] {dagbag.py:537} INFO - Filling up the DagBag from /opt/airflow/dags/group_dag.py
[2024-04-16T10:27:35.434+0000] {logging_mixin.py:120} INFO - [2024-04-16T10:27:35.430+0000] {dagbag.py:342} ERROR - Failed to import: /opt/airflow/dags/group_dag.py
Traceback (most recent call last):
  File "/home/airflow/.local/lib/python3.7/site-packages/airflow/models/dagbag.py", line 338, in parse
    loader.exec_module(new_module)
  File "<frozen importlib._bootstrap_external>", line 728, in exec_module
  File "<frozen importlib._bootstrap>", line 219, in _call_with_frames_removed
  File "/opt/airflow/dags/group_dag.py", line 27, in <module>
    subdag=subdag_downloads(dag.dag_id, 'downloads', args)
  File "/opt/airflow/dags/subdags/subdags_downloads.py", line 9, in subdag_downloads
    catch = args['catchup']) as dag:
TypeError: __init__() got an unexpected keyword argument 'catch'
[2024-04-16T10:27:35.436+0000] {processor.py:768} WARNING - No viable dags retrieved from /opt/airflow/dags/group_dag.py
[2024-04-16T10:27:35.466+0000] {processor.py:176} INFO - Processing /opt/airflow/dags/group_dag.py took 0.086 seconds
[2024-04-16T10:28:06.039+0000] {processor.py:154} INFO - Started process (PID=660) to work on /opt/airflow/dags/group_dag.py
[2024-04-16T10:28:06.042+0000] {processor.py:756} INFO - Processing file /opt/airflow/dags/group_dag.py for tasks to queue
[2024-04-16T10:28:06.044+0000] {logging_mixin.py:120} INFO - [2024-04-16T10:28:06.044+0000] {dagbag.py:537} INFO - Filling up the DagBag from /opt/airflow/dags/group_dag.py
[2024-04-16T10:28:06.116+0000] {logging_mixin.py:120} INFO - [2024-04-16T10:28:06.108+0000] {dagbag.py:342} ERROR - Failed to import: /opt/airflow/dags/group_dag.py
Traceback (most recent call last):
  File "/home/airflow/.local/lib/python3.7/site-packages/airflow/models/dagbag.py", line 338, in parse
    loader.exec_module(new_module)
  File "<frozen importlib._bootstrap_external>", line 728, in exec_module
  File "<frozen importlib._bootstrap>", line 219, in _call_with_frames_removed
  File "/opt/airflow/dags/group_dag.py", line 27, in <module>
    subdag=subdag_downloads(dag.dag_id, 'downloads', args)
  File "/opt/airflow/dags/subdags/subdags_downloads.py", line 9, in subdag_downloads
    catch = args['catchup']) as dag:
TypeError: __init__() got an unexpected keyword argument 'catch'
[2024-04-16T10:28:06.117+0000] {processor.py:768} WARNING - No viable dags retrieved from /opt/airflow/dags/group_dag.py
[2024-04-16T10:28:07.150+0000] {processor.py:176} INFO - Processing /opt/airflow/dags/group_dag.py took 1.117 seconds
[2024-04-16T13:04:11.408+0000] {processor.py:154} INFO - Started process (PID=710) to work on /opt/airflow/dags/group_dag.py
[2024-04-16T13:04:11.412+0000] {processor.py:756} INFO - Processing file /opt/airflow/dags/group_dag.py for tasks to queue
[2024-04-16T13:04:11.424+0000] {logging_mixin.py:120} INFO - [2024-04-16T13:04:11.423+0000] {dagbag.py:537} INFO - Filling up the DagBag from /opt/airflow/dags/group_dag.py
[2024-04-16T13:04:11.491+0000] {logging_mixin.py:120} INFO - [2024-04-16T13:04:11.484+0000] {dagbag.py:342} ERROR - Failed to import: /opt/airflow/dags/group_dag.py
Traceback (most recent call last):
  File "/home/airflow/.local/lib/python3.7/site-packages/airflow/models/dagbag.py", line 338, in parse
    loader.exec_module(new_module)
  File "<frozen importlib._bootstrap_external>", line 728, in exec_module
  File "<frozen importlib._bootstrap>", line 219, in _call_with_frames_removed
  File "/opt/airflow/dags/group_dag.py", line 27, in <module>
    subdag=subdag_downloads(dag.dag_id, 'downloads', args)
  File "/opt/airflow/dags/subdags/subdags_downloads.py", line 9, in subdag_downloads
    catch = args['catchup']) as dag:
TypeError: __init__() got an unexpected keyword argument 'catch'
[2024-04-16T13:04:11.493+0000] {processor.py:768} WARNING - No viable dags retrieved from /opt/airflow/dags/group_dag.py
[2024-04-16T13:04:11.540+0000] {processor.py:176} INFO - Processing /opt/airflow/dags/group_dag.py took 0.151 seconds
[2024-04-16T13:04:42.118+0000] {processor.py:154} INFO - Started process (PID=773) to work on /opt/airflow/dags/group_dag.py
[2024-04-16T13:04:42.121+0000] {processor.py:756} INFO - Processing file /opt/airflow/dags/group_dag.py for tasks to queue
[2024-04-16T13:04:42.124+0000] {logging_mixin.py:120} INFO - [2024-04-16T13:04:42.123+0000] {dagbag.py:537} INFO - Filling up the DagBag from /opt/airflow/dags/group_dag.py
[2024-04-16T13:04:42.188+0000] {logging_mixin.py:120} INFO - [2024-04-16T13:04:42.182+0000] {dagbag.py:342} ERROR - Failed to import: /opt/airflow/dags/group_dag.py
Traceback (most recent call last):
  File "/home/airflow/.local/lib/python3.7/site-packages/airflow/models/dagbag.py", line 338, in parse
    loader.exec_module(new_module)
  File "<frozen importlib._bootstrap_external>", line 728, in exec_module
  File "<frozen importlib._bootstrap>", line 219, in _call_with_frames_removed
  File "/opt/airflow/dags/group_dag.py", line 27, in <module>
    subdag=subdag_downloads(dag.dag_id, 'downloads', args)
  File "/opt/airflow/dags/subdags/subdags_downloads.py", line 9, in subdag_downloads
    catch = args['catchup']) as dag:
TypeError: __init__() got an unexpected keyword argument 'catch'
[2024-04-16T13:04:42.190+0000] {processor.py:768} WARNING - No viable dags retrieved from /opt/airflow/dags/group_dag.py
[2024-04-16T13:04:42.249+0000] {processor.py:176} INFO - Processing /opt/airflow/dags/group_dag.py took 0.143 seconds
[2024-04-16T13:05:12.517+0000] {processor.py:154} INFO - Started process (PID=851) to work on /opt/airflow/dags/group_dag.py
[2024-04-16T13:05:12.521+0000] {processor.py:756} INFO - Processing file /opt/airflow/dags/group_dag.py for tasks to queue
[2024-04-16T13:05:12.524+0000] {logging_mixin.py:120} INFO - [2024-04-16T13:05:12.524+0000] {dagbag.py:537} INFO - Filling up the DagBag from /opt/airflow/dags/group_dag.py
[2024-04-16T13:05:12.576+0000] {logging_mixin.py:120} INFO - [2024-04-16T13:05:12.572+0000] {dagbag.py:342} ERROR - Failed to import: /opt/airflow/dags/group_dag.py
Traceback (most recent call last):
  File "/home/airflow/.local/lib/python3.7/site-packages/airflow/models/dagbag.py", line 338, in parse
    loader.exec_module(new_module)
  File "<frozen importlib._bootstrap_external>", line 728, in exec_module
  File "<frozen importlib._bootstrap>", line 219, in _call_with_frames_removed
  File "/opt/airflow/dags/group_dag.py", line 27, in <module>
    subdag=subdag_downloads(dag.dag_id, 'downloads', args)
  File "/opt/airflow/dags/subdags/subdags_downloads.py", line 9, in subdag_downloads
    catch = args['catchup']) as dag:
TypeError: __init__() got an unexpected keyword argument 'catch'
[2024-04-16T13:05:12.580+0000] {processor.py:768} WARNING - No viable dags retrieved from /opt/airflow/dags/group_dag.py
[2024-04-16T13:05:12.616+0000] {processor.py:176} INFO - Processing /opt/airflow/dags/group_dag.py took 0.108 seconds
[2024-04-16T13:05:42.948+0000] {processor.py:154} INFO - Started process (PID=920) to work on /opt/airflow/dags/group_dag.py
[2024-04-16T13:05:42.950+0000] {processor.py:756} INFO - Processing file /opt/airflow/dags/group_dag.py for tasks to queue
[2024-04-16T13:05:42.953+0000] {logging_mixin.py:120} INFO - [2024-04-16T13:05:42.952+0000] {dagbag.py:537} INFO - Filling up the DagBag from /opt/airflow/dags/group_dag.py
[2024-04-16T13:05:43.020+0000] {logging_mixin.py:120} INFO - [2024-04-16T13:05:43.015+0000] {dagbag.py:342} ERROR - Failed to import: /opt/airflow/dags/group_dag.py
Traceback (most recent call last):
  File "/home/airflow/.local/lib/python3.7/site-packages/airflow/models/dagbag.py", line 338, in parse
    loader.exec_module(new_module)
  File "<frozen importlib._bootstrap_external>", line 728, in exec_module
  File "<frozen importlib._bootstrap>", line 219, in _call_with_frames_removed
  File "/opt/airflow/dags/group_dag.py", line 27, in <module>
    subdag=subdag_downloads(dag.dag_id, 'downloads', args)
  File "/opt/airflow/dags/subdags/subdags_downloads.py", line 9, in subdag_downloads
    catch = args['catchup']) as dag:
TypeError: __init__() got an unexpected keyword argument 'catch'
[2024-04-16T13:05:43.021+0000] {processor.py:768} WARNING - No viable dags retrieved from /opt/airflow/dags/group_dag.py
[2024-04-16T13:05:43.072+0000] {processor.py:176} INFO - Processing /opt/airflow/dags/group_dag.py took 0.132 seconds
[2024-04-16T13:06:13.516+0000] {processor.py:154} INFO - Started process (PID=999) to work on /opt/airflow/dags/group_dag.py
[2024-04-16T13:06:13.519+0000] {processor.py:756} INFO - Processing file /opt/airflow/dags/group_dag.py for tasks to queue
[2024-04-16T13:06:13.521+0000] {logging_mixin.py:120} INFO - [2024-04-16T13:06:13.520+0000] {dagbag.py:537} INFO - Filling up the DagBag from /opt/airflow/dags/group_dag.py
[2024-04-16T13:06:13.567+0000] {logging_mixin.py:120} INFO - [2024-04-16T13:06:13.562+0000] {dagbag.py:342} ERROR - Failed to import: /opt/airflow/dags/group_dag.py
Traceback (most recent call last):
  File "/home/airflow/.local/lib/python3.7/site-packages/airflow/models/dagbag.py", line 338, in parse
    loader.exec_module(new_module)
  File "<frozen importlib._bootstrap_external>", line 728, in exec_module
  File "<frozen importlib._bootstrap>", line 219, in _call_with_frames_removed
  File "/opt/airflow/dags/group_dag.py", line 27, in <module>
    subdag=subdag_downloads(dag.dag_id, 'downloads', args)
  File "/opt/airflow/dags/subdags/subdags_downloads.py", line 9, in subdag_downloads
    catch = args['catchup']) as dag:
TypeError: __init__() got an unexpected keyword argument 'catch'
[2024-04-16T13:06:13.569+0000] {processor.py:768} WARNING - No viable dags retrieved from /opt/airflow/dags/group_dag.py
[2024-04-16T13:06:13.602+0000] {processor.py:176} INFO - Processing /opt/airflow/dags/group_dag.py took 0.096 seconds
[2024-04-16T13:06:43.951+0000] {processor.py:154} INFO - Started process (PID=1067) to work on /opt/airflow/dags/group_dag.py
[2024-04-16T13:06:43.957+0000] {processor.py:756} INFO - Processing file /opt/airflow/dags/group_dag.py for tasks to queue
[2024-04-16T13:06:43.959+0000] {logging_mixin.py:120} INFO - [2024-04-16T13:06:43.959+0000] {dagbag.py:537} INFO - Filling up the DagBag from /opt/airflow/dags/group_dag.py
[2024-04-16T13:06:44.045+0000] {logging_mixin.py:120} INFO - [2024-04-16T13:06:44.026+0000] {dagbag.py:342} ERROR - Failed to import: /opt/airflow/dags/group_dag.py
Traceback (most recent call last):
  File "/home/airflow/.local/lib/python3.7/site-packages/airflow/models/dagbag.py", line 338, in parse
    loader.exec_module(new_module)
  File "<frozen importlib._bootstrap_external>", line 728, in exec_module
  File "<frozen importlib._bootstrap>", line 219, in _call_with_frames_removed
  File "/opt/airflow/dags/group_dag.py", line 27, in <module>
    subdag=subdag_downloads(dag.dag_id, 'downloads', args)
  File "/opt/airflow/dags/subdags/subdags_downloads.py", line 9, in subdag_downloads
    catch = args['catchup']) as dag:
TypeError: __init__() got an unexpected keyword argument 'catch'
[2024-04-16T13:06:44.048+0000] {processor.py:768} WARNING - No viable dags retrieved from /opt/airflow/dags/group_dag.py
[2024-04-16T13:06:44.126+0000] {processor.py:176} INFO - Processing /opt/airflow/dags/group_dag.py took 0.181 seconds
[2024-04-16T13:07:14.373+0000] {processor.py:154} INFO - Started process (PID=1135) to work on /opt/airflow/dags/group_dag.py
[2024-04-16T13:07:14.376+0000] {processor.py:756} INFO - Processing file /opt/airflow/dags/group_dag.py for tasks to queue
[2024-04-16T13:07:14.378+0000] {logging_mixin.py:120} INFO - [2024-04-16T13:07:14.378+0000] {dagbag.py:537} INFO - Filling up the DagBag from /opt/airflow/dags/group_dag.py
[2024-04-16T13:07:14.417+0000] {logging_mixin.py:120} INFO - [2024-04-16T13:07:14.413+0000] {dagbag.py:342} ERROR - Failed to import: /opt/airflow/dags/group_dag.py
Traceback (most recent call last):
  File "/home/airflow/.local/lib/python3.7/site-packages/airflow/models/dagbag.py", line 338, in parse
    loader.exec_module(new_module)
  File "<frozen importlib._bootstrap_external>", line 728, in exec_module
  File "<frozen importlib._bootstrap>", line 219, in _call_with_frames_removed
  File "/opt/airflow/dags/group_dag.py", line 27, in <module>
    subdag=subdag_downloads(dag.dag_id, 'downloads', args)
  File "/opt/airflow/dags/subdags/subdags_downloads.py", line 9, in subdag_downloads
    catch = args['catchup']) as dag:
TypeError: __init__() got an unexpected keyword argument 'catch'
[2024-04-16T13:07:14.418+0000] {processor.py:768} WARNING - No viable dags retrieved from /opt/airflow/dags/group_dag.py
[2024-04-16T13:07:14.456+0000] {processor.py:176} INFO - Processing /opt/airflow/dags/group_dag.py took 0.094 seconds
[2024-04-16T13:07:45.119+0000] {processor.py:154} INFO - Started process (PID=1213) to work on /opt/airflow/dags/group_dag.py
[2024-04-16T13:07:45.122+0000] {processor.py:756} INFO - Processing file /opt/airflow/dags/group_dag.py for tasks to queue
[2024-04-16T13:07:45.125+0000] {logging_mixin.py:120} INFO - [2024-04-16T13:07:45.124+0000] {dagbag.py:537} INFO - Filling up the DagBag from /opt/airflow/dags/group_dag.py
[2024-04-16T13:07:45.219+0000] {logging_mixin.py:120} INFO - [2024-04-16T13:07:45.212+0000] {dagbag.py:342} ERROR - Failed to import: /opt/airflow/dags/group_dag.py
Traceback (most recent call last):
  File "/home/airflow/.local/lib/python3.7/site-packages/airflow/models/dagbag.py", line 338, in parse
    loader.exec_module(new_module)
  File "<frozen importlib._bootstrap_external>", line 728, in exec_module
  File "<frozen importlib._bootstrap>", line 219, in _call_with_frames_removed
  File "/opt/airflow/dags/group_dag.py", line 27, in <module>
    subdag=subdag_downloads(dag.dag_id, 'downloads', args)
  File "/opt/airflow/dags/subdags/subdags_downloads.py", line 9, in subdag_downloads
    catch = args['catchup']) as dag:
TypeError: __init__() got an unexpected keyword argument 'catch'
[2024-04-16T13:07:45.221+0000] {processor.py:768} WARNING - No viable dags retrieved from /opt/airflow/dags/group_dag.py
[2024-04-16T13:07:45.272+0000] {processor.py:176} INFO - Processing /opt/airflow/dags/group_dag.py took 0.171 seconds
[2024-04-16T13:08:16.317+0000] {processor.py:154} INFO - Started process (PID=1282) to work on /opt/airflow/dags/group_dag.py
[2024-04-16T13:08:16.319+0000] {processor.py:756} INFO - Processing file /opt/airflow/dags/group_dag.py for tasks to queue
[2024-04-16T13:08:16.320+0000] {logging_mixin.py:120} INFO - [2024-04-16T13:08:16.320+0000] {dagbag.py:537} INFO - Filling up the DagBag from /opt/airflow/dags/group_dag.py
[2024-04-16T13:08:16.358+0000] {logging_mixin.py:120} INFO - [2024-04-16T13:08:16.355+0000] {dagbag.py:342} ERROR - Failed to import: /opt/airflow/dags/group_dag.py
Traceback (most recent call last):
  File "/home/airflow/.local/lib/python3.7/site-packages/airflow/models/dagbag.py", line 338, in parse
    loader.exec_module(new_module)
  File "<frozen importlib._bootstrap_external>", line 728, in exec_module
  File "<frozen importlib._bootstrap>", line 219, in _call_with_frames_removed
  File "/opt/airflow/dags/group_dag.py", line 27, in <module>
    subdag=subdag_downloads(dag.dag_id, 'downloads', args)
  File "/opt/airflow/dags/subdags/subdags_downloads.py", line 9, in subdag_downloads
    catch = args['catchup']) as dag:
TypeError: __init__() got an unexpected keyword argument 'catch'
[2024-04-16T13:08:16.359+0000] {processor.py:768} WARNING - No viable dags retrieved from /opt/airflow/dags/group_dag.py
[2024-04-16T13:08:16.399+0000] {processor.py:176} INFO - Processing /opt/airflow/dags/group_dag.py took 0.088 seconds
[2024-04-16T13:08:46.635+0000] {processor.py:154} INFO - Started process (PID=1359) to work on /opt/airflow/dags/group_dag.py
[2024-04-16T13:08:46.639+0000] {processor.py:756} INFO - Processing file /opt/airflow/dags/group_dag.py for tasks to queue
[2024-04-16T13:08:46.644+0000] {logging_mixin.py:120} INFO - [2024-04-16T13:08:46.644+0000] {dagbag.py:537} INFO - Filling up the DagBag from /opt/airflow/dags/group_dag.py
[2024-04-16T13:08:46.718+0000] {logging_mixin.py:120} INFO - [2024-04-16T13:08:46.715+0000] {dagbag.py:342} ERROR - Failed to import: /opt/airflow/dags/group_dag.py
Traceback (most recent call last):
  File "/home/airflow/.local/lib/python3.7/site-packages/airflow/models/dagbag.py", line 338, in parse
    loader.exec_module(new_module)
  File "<frozen importlib._bootstrap_external>", line 728, in exec_module
  File "<frozen importlib._bootstrap>", line 219, in _call_with_frames_removed
  File "/opt/airflow/dags/group_dag.py", line 27, in <module>
    subdag=subdag_downloads(dag.dag_id, 'downloads', args)
  File "/opt/airflow/dags/subdags/subdags_downloads.py", line 9, in subdag_downloads
    catch = args['catchup']) as dag:
TypeError: __init__() got an unexpected keyword argument 'catch'
[2024-04-16T13:08:46.719+0000] {processor.py:768} WARNING - No viable dags retrieved from /opt/airflow/dags/group_dag.py
[2024-04-16T13:08:46.754+0000] {processor.py:176} INFO - Processing /opt/airflow/dags/group_dag.py took 0.127 seconds
[2024-04-16T13:09:16.954+0000] {processor.py:154} INFO - Started process (PID=1429) to work on /opt/airflow/dags/group_dag.py
[2024-04-16T13:09:16.957+0000] {processor.py:756} INFO - Processing file /opt/airflow/dags/group_dag.py for tasks to queue
[2024-04-16T13:09:16.959+0000] {logging_mixin.py:120} INFO - [2024-04-16T13:09:16.959+0000] {dagbag.py:537} INFO - Filling up the DagBag from /opt/airflow/dags/group_dag.py
[2024-04-16T13:09:17.008+0000] {logging_mixin.py:120} INFO - [2024-04-16T13:09:17.003+0000] {dagbag.py:342} ERROR - Failed to import: /opt/airflow/dags/group_dag.py
Traceback (most recent call last):
  File "/home/airflow/.local/lib/python3.7/site-packages/airflow/models/dagbag.py", line 338, in parse
    loader.exec_module(new_module)
  File "<frozen importlib._bootstrap_external>", line 728, in exec_module
  File "<frozen importlib._bootstrap>", line 219, in _call_with_frames_removed
  File "/opt/airflow/dags/group_dag.py", line 27, in <module>
    subdag=subdag_downloads(dag.dag_id, 'downloads', args)
  File "/opt/airflow/dags/subdags/subdags_downloads.py", line 9, in subdag_downloads
    catch = args['catchup']) as dag:
TypeError: __init__() got an unexpected keyword argument 'catch'
[2024-04-16T13:09:17.011+0000] {processor.py:768} WARNING - No viable dags retrieved from /opt/airflow/dags/group_dag.py
[2024-04-16T13:09:17.050+0000] {processor.py:176} INFO - Processing /opt/airflow/dags/group_dag.py took 0.107 seconds
[2024-04-16T13:09:48.065+0000] {processor.py:154} INFO - Started process (PID=1501) to work on /opt/airflow/dags/group_dag.py
[2024-04-16T13:09:48.067+0000] {processor.py:756} INFO - Processing file /opt/airflow/dags/group_dag.py for tasks to queue
[2024-04-16T13:09:48.069+0000] {logging_mixin.py:120} INFO - [2024-04-16T13:09:48.069+0000] {dagbag.py:537} INFO - Filling up the DagBag from /opt/airflow/dags/group_dag.py
[2024-04-16T13:09:48.111+0000] {logging_mixin.py:120} INFO - [2024-04-16T13:09:48.106+0000] {dagbag.py:342} ERROR - Failed to import: /opt/airflow/dags/group_dag.py
Traceback (most recent call last):
  File "/home/airflow/.local/lib/python3.7/site-packages/airflow/models/dagbag.py", line 338, in parse
    loader.exec_module(new_module)
  File "<frozen importlib._bootstrap_external>", line 728, in exec_module
  File "<frozen importlib._bootstrap>", line 219, in _call_with_frames_removed
  File "/opt/airflow/dags/group_dag.py", line 27, in <module>
    subdag=subdag_downloads(dag.dag_id, 'downloads', args)
  File "/opt/airflow/dags/subdags/subdags_downloads.py", line 9, in subdag_downloads
    catch = args['catchup']) as dag:
TypeError: __init__() got an unexpected keyword argument 'catch'
[2024-04-16T13:09:48.112+0000] {processor.py:768} WARNING - No viable dags retrieved from /opt/airflow/dags/group_dag.py
[2024-04-16T13:09:48.154+0000] {processor.py:176} INFO - Processing /opt/airflow/dags/group_dag.py took 0.096 seconds
[2024-04-16T13:10:18.436+0000] {processor.py:154} INFO - Started process (PID=1579) to work on /opt/airflow/dags/group_dag.py
[2024-04-16T13:10:18.441+0000] {processor.py:756} INFO - Processing file /opt/airflow/dags/group_dag.py for tasks to queue
[2024-04-16T13:10:18.443+0000] {logging_mixin.py:120} INFO - [2024-04-16T13:10:18.443+0000] {dagbag.py:537} INFO - Filling up the DagBag from /opt/airflow/dags/group_dag.py
[2024-04-16T13:10:18.485+0000] {logging_mixin.py:120} INFO - [2024-04-16T13:10:18.482+0000] {dagbag.py:342} ERROR - Failed to import: /opt/airflow/dags/group_dag.py
Traceback (most recent call last):
  File "/home/airflow/.local/lib/python3.7/site-packages/airflow/models/dagbag.py", line 338, in parse
    loader.exec_module(new_module)
  File "<frozen importlib._bootstrap_external>", line 728, in exec_module
  File "<frozen importlib._bootstrap>", line 219, in _call_with_frames_removed
  File "/opt/airflow/dags/group_dag.py", line 27, in <module>
    subdag=subdag_downloads(dag.dag_id, 'downloads', args)
  File "/opt/airflow/dags/subdags/subdags_downloads.py", line 9, in subdag_downloads
    catch = args['catchup']) as dag:
TypeError: __init__() got an unexpected keyword argument 'catch'
[2024-04-16T13:10:18.487+0000] {processor.py:768} WARNING - No viable dags retrieved from /opt/airflow/dags/group_dag.py
[2024-04-16T13:10:18.520+0000] {processor.py:176} INFO - Processing /opt/airflow/dags/group_dag.py took 0.094 seconds
[2024-04-16T13:10:48.774+0000] {processor.py:154} INFO - Started process (PID=1648) to work on /opt/airflow/dags/group_dag.py
[2024-04-16T13:10:48.776+0000] {processor.py:756} INFO - Processing file /opt/airflow/dags/group_dag.py for tasks to queue
[2024-04-16T13:10:48.779+0000] {logging_mixin.py:120} INFO - [2024-04-16T13:10:48.778+0000] {dagbag.py:537} INFO - Filling up the DagBag from /opt/airflow/dags/group_dag.py
[2024-04-16T13:10:48.826+0000] {logging_mixin.py:120} INFO - [2024-04-16T13:10:48.822+0000] {dagbag.py:342} ERROR - Failed to import: /opt/airflow/dags/group_dag.py
Traceback (most recent call last):
  File "/home/airflow/.local/lib/python3.7/site-packages/airflow/models/dagbag.py", line 338, in parse
    loader.exec_module(new_module)
  File "<frozen importlib._bootstrap_external>", line 728, in exec_module
  File "<frozen importlib._bootstrap>", line 219, in _call_with_frames_removed
  File "/opt/airflow/dags/group_dag.py", line 27, in <module>
    subdag=subdag_downloads(dag.dag_id, 'downloads', args)
  File "/opt/airflow/dags/subdags/subdags_downloads.py", line 9, in subdag_downloads
    catch = args['catchup']) as dag:
TypeError: __init__() got an unexpected keyword argument 'catch'
[2024-04-16T13:10:48.828+0000] {processor.py:768} WARNING - No viable dags retrieved from /opt/airflow/dags/group_dag.py
[2024-04-16T13:10:48.864+0000] {processor.py:176} INFO - Processing /opt/airflow/dags/group_dag.py took 0.100 seconds
[2024-04-16T13:11:19.843+0000] {processor.py:154} INFO - Started process (PID=1725) to work on /opt/airflow/dags/group_dag.py
[2024-04-16T13:11:19.846+0000] {processor.py:756} INFO - Processing file /opt/airflow/dags/group_dag.py for tasks to queue
[2024-04-16T13:11:19.852+0000] {logging_mixin.py:120} INFO - [2024-04-16T13:11:19.852+0000] {dagbag.py:537} INFO - Filling up the DagBag from /opt/airflow/dags/group_dag.py
[2024-04-16T13:11:19.900+0000] {logging_mixin.py:120} INFO - [2024-04-16T13:11:19.895+0000] {dagbag.py:342} ERROR - Failed to import: /opt/airflow/dags/group_dag.py
Traceback (most recent call last):
  File "/home/airflow/.local/lib/python3.7/site-packages/airflow/models/dagbag.py", line 338, in parse
    loader.exec_module(new_module)
  File "<frozen importlib._bootstrap_external>", line 728, in exec_module
  File "<frozen importlib._bootstrap>", line 219, in _call_with_frames_removed
  File "/opt/airflow/dags/group_dag.py", line 27, in <module>
    subdag=subdag_downloads(dag.dag_id, 'downloads', args)
  File "/opt/airflow/dags/subdags/subdags_downloads.py", line 9, in subdag_downloads
    catch = args['catchup']) as dag:
TypeError: __init__() got an unexpected keyword argument 'catch'
[2024-04-16T13:11:19.901+0000] {processor.py:768} WARNING - No viable dags retrieved from /opt/airflow/dags/group_dag.py
[2024-04-16T13:11:19.930+0000] {processor.py:176} INFO - Processing /opt/airflow/dags/group_dag.py took 0.094 seconds
[2024-04-16T13:11:50.018+0000] {processor.py:154} INFO - Started process (PID=1793) to work on /opt/airflow/dags/group_dag.py
[2024-04-16T13:11:50.020+0000] {processor.py:756} INFO - Processing file /opt/airflow/dags/group_dag.py for tasks to queue
[2024-04-16T13:11:50.023+0000] {logging_mixin.py:120} INFO - [2024-04-16T13:11:50.023+0000] {dagbag.py:537} INFO - Filling up the DagBag from /opt/airflow/dags/group_dag.py
[2024-04-16T13:11:50.078+0000] {logging_mixin.py:120} INFO - [2024-04-16T13:11:50.072+0000] {dagbag.py:342} ERROR - Failed to import: /opt/airflow/dags/group_dag.py
Traceback (most recent call last):
  File "/home/airflow/.local/lib/python3.7/site-packages/airflow/models/dagbag.py", line 338, in parse
    loader.exec_module(new_module)
  File "<frozen importlib._bootstrap_external>", line 728, in exec_module
  File "<frozen importlib._bootstrap>", line 219, in _call_with_frames_removed
  File "/opt/airflow/dags/group_dag.py", line 27, in <module>
    subdag=subdag_downloads(dag.dag_id, 'downloads', args)
  File "/opt/airflow/dags/subdags/subdags_downloads.py", line 9, in subdag_downloads
    catch = args['catchup']) as dag:
TypeError: __init__() got an unexpected keyword argument 'catch'
[2024-04-16T13:11:50.081+0000] {processor.py:768} WARNING - No viable dags retrieved from /opt/airflow/dags/group_dag.py
[2024-04-16T13:11:50.125+0000] {processor.py:176} INFO - Processing /opt/airflow/dags/group_dag.py took 0.116 seconds
[2024-04-16T13:12:20.529+0000] {processor.py:154} INFO - Started process (PID=1861) to work on /opt/airflow/dags/group_dag.py
[2024-04-16T13:12:20.537+0000] {processor.py:756} INFO - Processing file /opt/airflow/dags/group_dag.py for tasks to queue
[2024-04-16T13:12:20.542+0000] {logging_mixin.py:120} INFO - [2024-04-16T13:12:20.541+0000] {dagbag.py:537} INFO - Filling up the DagBag from /opt/airflow/dags/group_dag.py
[2024-04-16T13:12:20.617+0000] {logging_mixin.py:120} INFO - [2024-04-16T13:12:20.613+0000] {dagbag.py:342} ERROR - Failed to import: /opt/airflow/dags/group_dag.py
Traceback (most recent call last):
  File "/home/airflow/.local/lib/python3.7/site-packages/airflow/models/dagbag.py", line 338, in parse
    loader.exec_module(new_module)
  File "<frozen importlib._bootstrap_external>", line 728, in exec_module
  File "<frozen importlib._bootstrap>", line 219, in _call_with_frames_removed
  File "/opt/airflow/dags/group_dag.py", line 27, in <module>
    subdag=subdag_downloads(dag.dag_id, 'downloads', args)
  File "/opt/airflow/dags/subdags/subdags_downloads.py", line 9, in subdag_downloads
    catch = args['catchup']) as dag:
TypeError: __init__() got an unexpected keyword argument 'catch'
[2024-04-16T13:12:20.619+0000] {processor.py:768} WARNING - No viable dags retrieved from /opt/airflow/dags/group_dag.py
[2024-04-16T13:12:20.732+0000] {processor.py:176} INFO - Processing /opt/airflow/dags/group_dag.py took 0.211 seconds
[2024-04-16T13:12:51.730+0000] {processor.py:154} INFO - Started process (PID=1939) to work on /opt/airflow/dags/group_dag.py
[2024-04-16T13:12:51.732+0000] {processor.py:756} INFO - Processing file /opt/airflow/dags/group_dag.py for tasks to queue
[2024-04-16T13:12:51.735+0000] {logging_mixin.py:120} INFO - [2024-04-16T13:12:51.734+0000] {dagbag.py:537} INFO - Filling up the DagBag from /opt/airflow/dags/group_dag.py
[2024-04-16T13:12:51.778+0000] {logging_mixin.py:120} INFO - [2024-04-16T13:12:51.775+0000] {dagbag.py:342} ERROR - Failed to import: /opt/airflow/dags/group_dag.py
Traceback (most recent call last):
  File "/home/airflow/.local/lib/python3.7/site-packages/airflow/models/dagbag.py", line 338, in parse
    loader.exec_module(new_module)
  File "<frozen importlib._bootstrap_external>", line 728, in exec_module
  File "<frozen importlib._bootstrap>", line 219, in _call_with_frames_removed
  File "/opt/airflow/dags/group_dag.py", line 27, in <module>
    subdag=subdag_downloads(dag.dag_id, 'downloads', args)
  File "/opt/airflow/dags/subdags/subdags_downloads.py", line 9, in subdag_downloads
    catch = args['catchup']) as dag:
TypeError: __init__() got an unexpected keyword argument 'catch'
[2024-04-16T13:12:51.779+0000] {processor.py:768} WARNING - No viable dags retrieved from /opt/airflow/dags/group_dag.py
[2024-04-16T13:12:51.813+0000] {processor.py:176} INFO - Processing /opt/airflow/dags/group_dag.py took 0.091 seconds
[2024-04-16T13:13:22.684+0000] {processor.py:154} INFO - Started process (PID=2008) to work on /opt/airflow/dags/group_dag.py
[2024-04-16T13:13:22.686+0000] {processor.py:756} INFO - Processing file /opt/airflow/dags/group_dag.py for tasks to queue
[2024-04-16T13:13:22.688+0000] {logging_mixin.py:120} INFO - [2024-04-16T13:13:22.688+0000] {dagbag.py:537} INFO - Filling up the DagBag from /opt/airflow/dags/group_dag.py
[2024-04-16T13:13:22.731+0000] {logging_mixin.py:120} INFO - [2024-04-16T13:13:22.727+0000] {dagbag.py:342} ERROR - Failed to import: /opt/airflow/dags/group_dag.py
Traceback (most recent call last):
  File "/home/airflow/.local/lib/python3.7/site-packages/airflow/models/dagbag.py", line 338, in parse
    loader.exec_module(new_module)
  File "<frozen importlib._bootstrap_external>", line 728, in exec_module
  File "<frozen importlib._bootstrap>", line 219, in _call_with_frames_removed
  File "/opt/airflow/dags/group_dag.py", line 27, in <module>
    subdag=subdag_downloads(dag.dag_id, 'downloads', args)
  File "/opt/airflow/dags/subdags/subdags_downloads.py", line 9, in subdag_downloads
    catch = args['catchup']) as dag:
TypeError: __init__() got an unexpected keyword argument 'catch'
[2024-04-16T13:13:22.732+0000] {processor.py:768} WARNING - No viable dags retrieved from /opt/airflow/dags/group_dag.py
[2024-04-16T13:13:22.776+0000] {processor.py:176} INFO - Processing /opt/airflow/dags/group_dag.py took 0.103 seconds
[2024-04-16T13:13:53.414+0000] {processor.py:154} INFO - Started process (PID=2085) to work on /opt/airflow/dags/group_dag.py
[2024-04-16T13:13:53.416+0000] {processor.py:756} INFO - Processing file /opt/airflow/dags/group_dag.py for tasks to queue
[2024-04-16T13:13:53.418+0000] {logging_mixin.py:120} INFO - [2024-04-16T13:13:53.418+0000] {dagbag.py:537} INFO - Filling up the DagBag from /opt/airflow/dags/group_dag.py
[2024-04-16T13:13:53.479+0000] {logging_mixin.py:120} INFO - [2024-04-16T13:13:53.474+0000] {dagbag.py:342} ERROR - Failed to import: /opt/airflow/dags/group_dag.py
Traceback (most recent call last):
  File "/home/airflow/.local/lib/python3.7/site-packages/airflow/models/dagbag.py", line 338, in parse
    loader.exec_module(new_module)
  File "<frozen importlib._bootstrap_external>", line 728, in exec_module
  File "<frozen importlib._bootstrap>", line 219, in _call_with_frames_removed
  File "/opt/airflow/dags/group_dag.py", line 27, in <module>
    subdag=subdag_downloads(dag.dag_id, 'downloads', args)
  File "/opt/airflow/dags/subdags/subdags_downloads.py", line 9, in subdag_downloads
    catch = args['catchup']) as dag:
TypeError: __init__() got an unexpected keyword argument 'catch'
[2024-04-16T13:13:53.480+0000] {processor.py:768} WARNING - No viable dags retrieved from /opt/airflow/dags/group_dag.py
[2024-04-16T13:13:53.514+0000] {processor.py:176} INFO - Processing /opt/airflow/dags/group_dag.py took 0.109 seconds
[2024-04-16T13:14:24.347+0000] {processor.py:154} INFO - Started process (PID=2153) to work on /opt/airflow/dags/group_dag.py
[2024-04-16T13:14:24.349+0000] {processor.py:756} INFO - Processing file /opt/airflow/dags/group_dag.py for tasks to queue
[2024-04-16T13:14:24.352+0000] {logging_mixin.py:120} INFO - [2024-04-16T13:14:24.352+0000] {dagbag.py:537} INFO - Filling up the DagBag from /opt/airflow/dags/group_dag.py
[2024-04-16T13:14:24.396+0000] {logging_mixin.py:120} INFO - [2024-04-16T13:14:24.392+0000] {dagbag.py:342} ERROR - Failed to import: /opt/airflow/dags/group_dag.py
Traceback (most recent call last):
  File "/home/airflow/.local/lib/python3.7/site-packages/airflow/models/dagbag.py", line 338, in parse
    loader.exec_module(new_module)
  File "<frozen importlib._bootstrap_external>", line 728, in exec_module
  File "<frozen importlib._bootstrap>", line 219, in _call_with_frames_removed
  File "/opt/airflow/dags/group_dag.py", line 27, in <module>
    subdag=subdag_downloads(dag.dag_id, 'downloads', args)
  File "/opt/airflow/dags/subdags/subdags_downloads.py", line 9, in subdag_downloads
    catch = args['catchup']) as dag:
TypeError: __init__() got an unexpected keyword argument 'catch'
[2024-04-16T13:14:24.397+0000] {processor.py:768} WARNING - No viable dags retrieved from /opt/airflow/dags/group_dag.py
[2024-04-16T13:14:24.441+0000] {processor.py:176} INFO - Processing /opt/airflow/dags/group_dag.py took 0.104 seconds
[2024-04-16T13:14:54.580+0000] {processor.py:154} INFO - Started process (PID=2227) to work on /opt/airflow/dags/group_dag.py
[2024-04-16T13:14:54.582+0000] {processor.py:756} INFO - Processing file /opt/airflow/dags/group_dag.py for tasks to queue
[2024-04-16T13:14:54.584+0000] {logging_mixin.py:120} INFO - [2024-04-16T13:14:54.584+0000] {dagbag.py:537} INFO - Filling up the DagBag from /opt/airflow/dags/group_dag.py
[2024-04-16T13:14:54.629+0000] {logging_mixin.py:120} INFO - [2024-04-16T13:14:54.625+0000] {dagbag.py:342} ERROR - Failed to import: /opt/airflow/dags/group_dag.py
Traceback (most recent call last):
  File "/home/airflow/.local/lib/python3.7/site-packages/airflow/models/dagbag.py", line 338, in parse
    loader.exec_module(new_module)
  File "<frozen importlib._bootstrap_external>", line 728, in exec_module
  File "<frozen importlib._bootstrap>", line 219, in _call_with_frames_removed
  File "/opt/airflow/dags/group_dag.py", line 27, in <module>
    subdag=subdag_downloads(dag.dag_id, 'downloads', args)
  File "/opt/airflow/dags/subdags/subdags_downloads.py", line 9, in subdag_downloads
    catch = args['catchup']) as dag:
TypeError: __init__() got an unexpected keyword argument 'catch'
[2024-04-16T13:14:54.631+0000] {processor.py:768} WARNING - No viable dags retrieved from /opt/airflow/dags/group_dag.py
[2024-04-16T13:14:54.674+0000] {processor.py:176} INFO - Processing /opt/airflow/dags/group_dag.py took 0.099 seconds
[2024-04-16T13:15:24.843+0000] {processor.py:154} INFO - Started process (PID=2305) to work on /opt/airflow/dags/group_dag.py
[2024-04-16T13:15:24.846+0000] {processor.py:756} INFO - Processing file /opt/airflow/dags/group_dag.py for tasks to queue
[2024-04-16T13:15:24.848+0000] {logging_mixin.py:120} INFO - [2024-04-16T13:15:24.847+0000] {dagbag.py:537} INFO - Filling up the DagBag from /opt/airflow/dags/group_dag.py
[2024-04-16T13:15:24.886+0000] {logging_mixin.py:120} INFO - [2024-04-16T13:15:24.882+0000] {dagbag.py:342} ERROR - Failed to import: /opt/airflow/dags/group_dag.py
Traceback (most recent call last):
  File "/home/airflow/.local/lib/python3.7/site-packages/airflow/models/dagbag.py", line 338, in parse
    loader.exec_module(new_module)
  File "<frozen importlib._bootstrap_external>", line 728, in exec_module
  File "<frozen importlib._bootstrap>", line 219, in _call_with_frames_removed
  File "/opt/airflow/dags/group_dag.py", line 27, in <module>
    subdag=subdag_downloads(dag.dag_id, 'downloads', args)
  File "/opt/airflow/dags/subdags/subdags_downloads.py", line 9, in subdag_downloads
    catch = args['catchup']) as dag:
TypeError: __init__() got an unexpected keyword argument 'catch'
[2024-04-16T13:15:24.887+0000] {processor.py:768} WARNING - No viable dags retrieved from /opt/airflow/dags/group_dag.py
[2024-04-16T13:15:24.920+0000] {processor.py:176} INFO - Processing /opt/airflow/dags/group_dag.py took 0.084 seconds
[2024-04-16T13:15:55.133+0000] {processor.py:154} INFO - Started process (PID=2372) to work on /opt/airflow/dags/group_dag.py
[2024-04-16T13:15:55.136+0000] {processor.py:756} INFO - Processing file /opt/airflow/dags/group_dag.py for tasks to queue
[2024-04-16T13:15:55.138+0000] {logging_mixin.py:120} INFO - [2024-04-16T13:15:55.138+0000] {dagbag.py:537} INFO - Filling up the DagBag from /opt/airflow/dags/group_dag.py
[2024-04-16T13:15:55.194+0000] {logging_mixin.py:120} INFO - [2024-04-16T13:15:55.190+0000] {dagbag.py:342} ERROR - Failed to import: /opt/airflow/dags/group_dag.py
Traceback (most recent call last):
  File "/home/airflow/.local/lib/python3.7/site-packages/airflow/models/dagbag.py", line 338, in parse
    loader.exec_module(new_module)
  File "<frozen importlib._bootstrap_external>", line 728, in exec_module
  File "<frozen importlib._bootstrap>", line 219, in _call_with_frames_removed
  File "/opt/airflow/dags/group_dag.py", line 27, in <module>
    subdag=subdag_downloads(dag.dag_id, 'downloads', args)
  File "/opt/airflow/dags/subdags/subdags_downloads.py", line 9, in subdag_downloads
    catch = args['catchup']) as dag:
TypeError: __init__() got an unexpected keyword argument 'catch'
[2024-04-16T13:15:55.195+0000] {processor.py:768} WARNING - No viable dags retrieved from /opt/airflow/dags/group_dag.py
[2024-04-16T13:15:55.243+0000] {processor.py:176} INFO - Processing /opt/airflow/dags/group_dag.py took 0.119 seconds
[2024-04-16T13:16:25.507+0000] {processor.py:154} INFO - Started process (PID=2450) to work on /opt/airflow/dags/group_dag.py
[2024-04-16T13:16:25.509+0000] {processor.py:756} INFO - Processing file /opt/airflow/dags/group_dag.py for tasks to queue
[2024-04-16T13:16:25.511+0000] {logging_mixin.py:120} INFO - [2024-04-16T13:16:25.511+0000] {dagbag.py:537} INFO - Filling up the DagBag from /opt/airflow/dags/group_dag.py
[2024-04-16T13:16:25.547+0000] {logging_mixin.py:120} INFO - [2024-04-16T13:16:25.544+0000] {dagbag.py:342} ERROR - Failed to import: /opt/airflow/dags/group_dag.py
Traceback (most recent call last):
  File "/home/airflow/.local/lib/python3.7/site-packages/airflow/models/dagbag.py", line 338, in parse
    loader.exec_module(new_module)
  File "<frozen importlib._bootstrap_external>", line 728, in exec_module
  File "<frozen importlib._bootstrap>", line 219, in _call_with_frames_removed
  File "/opt/airflow/dags/group_dag.py", line 27, in <module>
    subdag=subdag_downloads(dag.dag_id, 'downloads', args)
  File "/opt/airflow/dags/subdags/subdags_downloads.py", line 9, in subdag_downloads
    catch = args['catchup']) as dag:
TypeError: __init__() got an unexpected keyword argument 'catch'
[2024-04-16T13:16:25.549+0000] {processor.py:768} WARNING - No viable dags retrieved from /opt/airflow/dags/group_dag.py
[2024-04-16T13:16:25.581+0000] {processor.py:176} INFO - Processing /opt/airflow/dags/group_dag.py took 0.079 seconds
[2024-04-16T13:16:56.378+0000] {processor.py:154} INFO - Started process (PID=2518) to work on /opt/airflow/dags/group_dag.py
[2024-04-16T13:16:56.394+0000] {processor.py:756} INFO - Processing file /opt/airflow/dags/group_dag.py for tasks to queue
[2024-04-16T13:16:56.396+0000] {logging_mixin.py:120} INFO - [2024-04-16T13:16:56.396+0000] {dagbag.py:537} INFO - Filling up the DagBag from /opt/airflow/dags/group_dag.py
[2024-04-16T13:16:56.511+0000] {logging_mixin.py:120} INFO - [2024-04-16T13:16:56.498+0000] {dagbag.py:342} ERROR - Failed to import: /opt/airflow/dags/group_dag.py
Traceback (most recent call last):
  File "/home/airflow/.local/lib/python3.7/site-packages/airflow/models/dagbag.py", line 338, in parse
    loader.exec_module(new_module)
  File "<frozen importlib._bootstrap_external>", line 728, in exec_module
  File "<frozen importlib._bootstrap>", line 219, in _call_with_frames_removed
  File "/opt/airflow/dags/group_dag.py", line 27, in <module>
    subdag=subdag_downloads(dag.dag_id, 'downloads', args)
  File "/opt/airflow/dags/subdags/subdags_downloads.py", line 9, in subdag_downloads
    catch = args['catchup']) as dag:
TypeError: __init__() got an unexpected keyword argument 'catch'
[2024-04-16T13:16:56.513+0000] {processor.py:768} WARNING - No viable dags retrieved from /opt/airflow/dags/group_dag.py
[2024-04-16T13:16:56.595+0000] {processor.py:176} INFO - Processing /opt/airflow/dags/group_dag.py took 0.239 seconds
[2024-04-16T13:17:27.532+0000] {processor.py:154} INFO - Started process (PID=2596) to work on /opt/airflow/dags/group_dag.py
[2024-04-16T13:17:27.533+0000] {processor.py:756} INFO - Processing file /opt/airflow/dags/group_dag.py for tasks to queue
[2024-04-16T13:17:27.535+0000] {logging_mixin.py:120} INFO - [2024-04-16T13:17:27.535+0000] {dagbag.py:537} INFO - Filling up the DagBag from /opt/airflow/dags/group_dag.py
[2024-04-16T13:17:27.571+0000] {logging_mixin.py:120} INFO - [2024-04-16T13:17:27.568+0000] {dagbag.py:342} ERROR - Failed to import: /opt/airflow/dags/group_dag.py
Traceback (most recent call last):
  File "/home/airflow/.local/lib/python3.7/site-packages/airflow/models/dagbag.py", line 338, in parse
    loader.exec_module(new_module)
  File "<frozen importlib._bootstrap_external>", line 728, in exec_module
  File "<frozen importlib._bootstrap>", line 219, in _call_with_frames_removed
  File "/opt/airflow/dags/group_dag.py", line 27, in <module>
    subdag=subdag_downloads(dag.dag_id, 'downloads', args)
  File "/opt/airflow/dags/subdags/subdags_downloads.py", line 9, in subdag_downloads
    catch = args['catchup']) as dag:
TypeError: __init__() got an unexpected keyword argument 'catch'
[2024-04-16T13:17:27.573+0000] {processor.py:768} WARNING - No viable dags retrieved from /opt/airflow/dags/group_dag.py
[2024-04-16T13:17:27.603+0000] {processor.py:176} INFO - Processing /opt/airflow/dags/group_dag.py took 0.079 seconds
[2024-04-16T13:17:57.932+0000] {processor.py:154} INFO - Started process (PID=2665) to work on /opt/airflow/dags/group_dag.py
[2024-04-16T13:17:57.934+0000] {processor.py:756} INFO - Processing file /opt/airflow/dags/group_dag.py for tasks to queue
[2024-04-16T13:17:57.936+0000] {logging_mixin.py:120} INFO - [2024-04-16T13:17:57.936+0000] {dagbag.py:537} INFO - Filling up the DagBag from /opt/airflow/dags/group_dag.py
[2024-04-16T13:17:58.014+0000] {logging_mixin.py:120} INFO - [2024-04-16T13:17:58.008+0000] {dagbag.py:342} ERROR - Failed to import: /opt/airflow/dags/group_dag.py
Traceback (most recent call last):
  File "/home/airflow/.local/lib/python3.7/site-packages/airflow/models/dagbag.py", line 338, in parse
    loader.exec_module(new_module)
  File "<frozen importlib._bootstrap_external>", line 728, in exec_module
  File "<frozen importlib._bootstrap>", line 219, in _call_with_frames_removed
  File "/opt/airflow/dags/group_dag.py", line 27, in <module>
    subdag=subdag_downloads(dag.dag_id, 'downloads', args)
  File "/opt/airflow/dags/subdags/subdags_downloads.py", line 9, in subdag_downloads
    catch = args['catchup']) as dag:
TypeError: __init__() got an unexpected keyword argument 'catch'
[2024-04-16T13:17:58.017+0000] {processor.py:768} WARNING - No viable dags retrieved from /opt/airflow/dags/group_dag.py
[2024-04-16T13:17:58.066+0000] {processor.py:176} INFO - Processing /opt/airflow/dags/group_dag.py took 0.156 seconds
[2024-04-16T13:18:28.214+0000] {processor.py:154} INFO - Started process (PID=2742) to work on /opt/airflow/dags/group_dag.py
[2024-04-16T13:18:28.217+0000] {processor.py:756} INFO - Processing file /opt/airflow/dags/group_dag.py for tasks to queue
[2024-04-16T13:18:28.219+0000] {logging_mixin.py:120} INFO - [2024-04-16T13:18:28.219+0000] {dagbag.py:537} INFO - Filling up the DagBag from /opt/airflow/dags/group_dag.py
[2024-04-16T13:18:28.260+0000] {logging_mixin.py:120} INFO - [2024-04-16T13:18:28.254+0000] {dagbag.py:342} ERROR - Failed to import: /opt/airflow/dags/group_dag.py
Traceback (most recent call last):
  File "/home/airflow/.local/lib/python3.7/site-packages/airflow/models/dagbag.py", line 338, in parse
    loader.exec_module(new_module)
  File "<frozen importlib._bootstrap_external>", line 728, in exec_module
  File "<frozen importlib._bootstrap>", line 219, in _call_with_frames_removed
  File "/opt/airflow/dags/group_dag.py", line 27, in <module>
    subdag=subdag_downloads(dag.dag_id, 'downloads', args)
  File "/opt/airflow/dags/subdags/subdags_downloads.py", line 9, in subdag_downloads
    catch = args['catchup']) as dag:
TypeError: __init__() got an unexpected keyword argument 'catch'
[2024-04-16T13:18:28.262+0000] {processor.py:768} WARNING - No viable dags retrieved from /opt/airflow/dags/group_dag.py
[2024-04-16T13:18:28.297+0000] {processor.py:176} INFO - Processing /opt/airflow/dags/group_dag.py took 0.090 seconds
[2024-04-16T13:18:59.045+0000] {processor.py:154} INFO - Started process (PID=2813) to work on /opt/airflow/dags/group_dag.py
[2024-04-16T13:18:59.048+0000] {processor.py:756} INFO - Processing file /opt/airflow/dags/group_dag.py for tasks to queue
[2024-04-16T13:18:59.051+0000] {logging_mixin.py:120} INFO - [2024-04-16T13:18:59.050+0000] {dagbag.py:537} INFO - Filling up the DagBag from /opt/airflow/dags/group_dag.py
[2024-04-16T13:18:59.111+0000] {logging_mixin.py:120} INFO - [2024-04-16T13:18:59.105+0000] {dagbag.py:342} ERROR - Failed to import: /opt/airflow/dags/group_dag.py
Traceback (most recent call last):
  File "/home/airflow/.local/lib/python3.7/site-packages/airflow/models/dagbag.py", line 338, in parse
    loader.exec_module(new_module)
  File "<frozen importlib._bootstrap_external>", line 728, in exec_module
  File "<frozen importlib._bootstrap>", line 219, in _call_with_frames_removed
  File "/opt/airflow/dags/group_dag.py", line 27, in <module>
    subdag=subdag_downloads(dag.dag_id, 'downloads', args)
  File "/opt/airflow/dags/subdags/subdags_downloads.py", line 9, in subdag_downloads
    catch = args['catchup']) as dag:
TypeError: __init__() got an unexpected keyword argument 'catch'
[2024-04-16T13:18:59.112+0000] {processor.py:768} WARNING - No viable dags retrieved from /opt/airflow/dags/group_dag.py
[2024-04-16T13:18:59.154+0000] {processor.py:176} INFO - Processing /opt/airflow/dags/group_dag.py took 0.122 seconds
[2024-04-16T13:19:29.484+0000] {processor.py:154} INFO - Started process (PID=2890) to work on /opt/airflow/dags/group_dag.py
[2024-04-16T13:19:29.486+0000] {processor.py:756} INFO - Processing file /opt/airflow/dags/group_dag.py for tasks to queue
[2024-04-16T13:19:29.488+0000] {logging_mixin.py:120} INFO - [2024-04-16T13:19:29.488+0000] {dagbag.py:537} INFO - Filling up the DagBag from /opt/airflow/dags/group_dag.py
[2024-04-16T13:19:29.526+0000] {logging_mixin.py:120} INFO - [2024-04-16T13:19:29.523+0000] {dagbag.py:342} ERROR - Failed to import: /opt/airflow/dags/group_dag.py
Traceback (most recent call last):
  File "/home/airflow/.local/lib/python3.7/site-packages/airflow/models/dagbag.py", line 338, in parse
    loader.exec_module(new_module)
  File "<frozen importlib._bootstrap_external>", line 728, in exec_module
  File "<frozen importlib._bootstrap>", line 219, in _call_with_frames_removed
  File "/opt/airflow/dags/group_dag.py", line 27, in <module>
    subdag=subdag_downloads(dag.dag_id, 'downloads', args)
  File "/opt/airflow/dags/subdags/subdags_downloads.py", line 9, in subdag_downloads
    catch = args['catchup']) as dag:
TypeError: __init__() got an unexpected keyword argument 'catch'
[2024-04-16T13:19:29.528+0000] {processor.py:768} WARNING - No viable dags retrieved from /opt/airflow/dags/group_dag.py
[2024-04-16T13:19:29.561+0000] {processor.py:176} INFO - Processing /opt/airflow/dags/group_dag.py took 0.086 seconds
[2024-04-16T13:19:59.753+0000] {processor.py:154} INFO - Started process (PID=2959) to work on /opt/airflow/dags/group_dag.py
[2024-04-16T13:19:59.755+0000] {processor.py:756} INFO - Processing file /opt/airflow/dags/group_dag.py for tasks to queue
[2024-04-16T13:19:59.757+0000] {logging_mixin.py:120} INFO - [2024-04-16T13:19:59.757+0000] {dagbag.py:537} INFO - Filling up the DagBag from /opt/airflow/dags/group_dag.py
[2024-04-16T13:19:59.794+0000] {logging_mixin.py:120} INFO - [2024-04-16T13:19:59.790+0000] {dagbag.py:342} ERROR - Failed to import: /opt/airflow/dags/group_dag.py
Traceback (most recent call last):
  File "/home/airflow/.local/lib/python3.7/site-packages/airflow/models/dagbag.py", line 338, in parse
    loader.exec_module(new_module)
  File "<frozen importlib._bootstrap_external>", line 728, in exec_module
  File "<frozen importlib._bootstrap>", line 219, in _call_with_frames_removed
  File "/opt/airflow/dags/group_dag.py", line 27, in <module>
    subdag=subdag_downloads(dag.dag_id, 'downloads', args)
  File "/opt/airflow/dags/subdags/subdags_downloads.py", line 9, in subdag_downloads
    catch = args['catchup']) as dag:
TypeError: __init__() got an unexpected keyword argument 'catch'
[2024-04-16T13:19:59.795+0000] {processor.py:768} WARNING - No viable dags retrieved from /opt/airflow/dags/group_dag.py
[2024-04-16T13:19:59.829+0000] {processor.py:176} INFO - Processing /opt/airflow/dags/group_dag.py took 0.083 seconds
[2024-04-16T13:20:30.033+0000] {processor.py:154} INFO - Started process (PID=3037) to work on /opt/airflow/dags/group_dag.py
[2024-04-16T13:20:30.035+0000] {processor.py:756} INFO - Processing file /opt/airflow/dags/group_dag.py for tasks to queue
[2024-04-16T13:20:30.038+0000] {logging_mixin.py:120} INFO - [2024-04-16T13:20:30.038+0000] {dagbag.py:537} INFO - Filling up the DagBag from /opt/airflow/dags/group_dag.py
[2024-04-16T13:20:30.091+0000] {logging_mixin.py:120} INFO - [2024-04-16T13:20:30.086+0000] {dagbag.py:342} ERROR - Failed to import: /opt/airflow/dags/group_dag.py
Traceback (most recent call last):
  File "/home/airflow/.local/lib/python3.7/site-packages/airflow/models/dagbag.py", line 338, in parse
    loader.exec_module(new_module)
  File "<frozen importlib._bootstrap_external>", line 728, in exec_module
  File "<frozen importlib._bootstrap>", line 219, in _call_with_frames_removed
  File "/opt/airflow/dags/group_dag.py", line 27, in <module>
    subdag=subdag_downloads(dag.dag_id, 'downloads', args)
  File "/opt/airflow/dags/subdags/subdags_downloads.py", line 9, in subdag_downloads
    catch = args['catchup']) as dag:
TypeError: __init__() got an unexpected keyword argument 'catch'
[2024-04-16T13:20:30.093+0000] {processor.py:768} WARNING - No viable dags retrieved from /opt/airflow/dags/group_dag.py
[2024-04-16T13:20:30.130+0000] {processor.py:176} INFO - Processing /opt/airflow/dags/group_dag.py took 0.109 seconds
[2024-04-16T13:21:00.313+0000] {processor.py:154} INFO - Started process (PID=3105) to work on /opt/airflow/dags/group_dag.py
[2024-04-16T13:21:00.315+0000] {processor.py:756} INFO - Processing file /opt/airflow/dags/group_dag.py for tasks to queue
[2024-04-16T13:21:00.317+0000] {logging_mixin.py:120} INFO - [2024-04-16T13:21:00.317+0000] {dagbag.py:537} INFO - Filling up the DagBag from /opt/airflow/dags/group_dag.py
[2024-04-16T13:21:00.356+0000] {logging_mixin.py:120} INFO - [2024-04-16T13:21:00.352+0000] {dagbag.py:342} ERROR - Failed to import: /opt/airflow/dags/group_dag.py
Traceback (most recent call last):
  File "/home/airflow/.local/lib/python3.7/site-packages/airflow/models/dagbag.py", line 338, in parse
    loader.exec_module(new_module)
  File "<frozen importlib._bootstrap_external>", line 728, in exec_module
  File "<frozen importlib._bootstrap>", line 219, in _call_with_frames_removed
  File "/opt/airflow/dags/group_dag.py", line 27, in <module>
    subdag=subdag_downloads(dag.dag_id, 'downloads', args)
  File "/opt/airflow/dags/subdags/subdags_downloads.py", line 9, in subdag_downloads
    catch = args['catchup']) as dag:
TypeError: __init__() got an unexpected keyword argument 'catch'
[2024-04-16T13:21:00.357+0000] {processor.py:768} WARNING - No viable dags retrieved from /opt/airflow/dags/group_dag.py
[2024-04-16T13:21:00.389+0000] {processor.py:176} INFO - Processing /opt/airflow/dags/group_dag.py took 0.083 seconds
[2024-04-16T13:21:32.281+0000] {processor.py:154} INFO - Started process (PID=3184) to work on /opt/airflow/dags/group_dag.py
[2024-04-16T13:21:32.284+0000] {processor.py:756} INFO - Processing file /opt/airflow/dags/group_dag.py for tasks to queue
[2024-04-16T13:21:32.287+0000] {logging_mixin.py:120} INFO - [2024-04-16T13:21:32.287+0000] {dagbag.py:537} INFO - Filling up the DagBag from /opt/airflow/dags/group_dag.py
[2024-04-16T13:21:32.340+0000] {logging_mixin.py:120} INFO - [2024-04-16T13:21:32.335+0000] {dagbag.py:342} ERROR - Failed to import: /opt/airflow/dags/group_dag.py
Traceback (most recent call last):
  File "/home/airflow/.local/lib/python3.7/site-packages/airflow/models/dagbag.py", line 338, in parse
    loader.exec_module(new_module)
  File "<frozen importlib._bootstrap_external>", line 728, in exec_module
  File "<frozen importlib._bootstrap>", line 219, in _call_with_frames_removed
  File "/opt/airflow/dags/group_dag.py", line 27, in <module>
    subdag=subdag_downloads(dag.dag_id, 'downloads', args)
  File "/opt/airflow/dags/subdags/subdags_downloads.py", line 9, in subdag_downloads
    catch = args['catchup']) as dag:
TypeError: __init__() got an unexpected keyword argument 'catch'
[2024-04-16T13:21:32.342+0000] {processor.py:768} WARNING - No viable dags retrieved from /opt/airflow/dags/group_dag.py
[2024-04-16T13:21:32.385+0000] {processor.py:176} INFO - Processing /opt/airflow/dags/group_dag.py took 0.112 seconds
[2024-04-16T13:22:02.514+0000] {processor.py:154} INFO - Started process (PID=3247) to work on /opt/airflow/dags/group_dag.py
[2024-04-16T13:22:02.517+0000] {processor.py:756} INFO - Processing file /opt/airflow/dags/group_dag.py for tasks to queue
[2024-04-16T13:22:02.518+0000] {logging_mixin.py:120} INFO - [2024-04-16T13:22:02.518+0000] {dagbag.py:537} INFO - Filling up the DagBag from /opt/airflow/dags/group_dag.py
[2024-04-16T13:22:02.557+0000] {logging_mixin.py:120} INFO - [2024-04-16T13:22:02.553+0000] {dagbag.py:342} ERROR - Failed to import: /opt/airflow/dags/group_dag.py
Traceback (most recent call last):
  File "/home/airflow/.local/lib/python3.7/site-packages/airflow/models/dagbag.py", line 338, in parse
    loader.exec_module(new_module)
  File "<frozen importlib._bootstrap_external>", line 728, in exec_module
  File "<frozen importlib._bootstrap>", line 219, in _call_with_frames_removed
  File "/opt/airflow/dags/group_dag.py", line 27, in <module>
    subdag=subdag_downloads(dag.dag_id, 'downloads', args)
  File "/opt/airflow/dags/subdags/subdags_downloads.py", line 9, in subdag_downloads
    catch = args['catchup']) as dag:
TypeError: __init__() got an unexpected keyword argument 'catch'
[2024-04-16T13:22:02.559+0000] {processor.py:768} WARNING - No viable dags retrieved from /opt/airflow/dags/group_dag.py
[2024-04-16T13:22:02.590+0000] {processor.py:176} INFO - Processing /opt/airflow/dags/group_dag.py took 0.082 seconds
[2024-04-16T13:22:32.851+0000] {processor.py:154} INFO - Started process (PID=3322) to work on /opt/airflow/dags/group_dag.py
[2024-04-16T13:22:32.855+0000] {processor.py:756} INFO - Processing file /opt/airflow/dags/group_dag.py for tasks to queue
[2024-04-16T13:22:32.858+0000] {logging_mixin.py:120} INFO - [2024-04-16T13:22:32.858+0000] {dagbag.py:537} INFO - Filling up the DagBag from /opt/airflow/dags/group_dag.py
[2024-04-16T13:22:32.941+0000] {logging_mixin.py:120} INFO - [2024-04-16T13:22:32.937+0000] {dagbag.py:342} ERROR - Failed to import: /opt/airflow/dags/group_dag.py
Traceback (most recent call last):
  File "/home/airflow/.local/lib/python3.7/site-packages/airflow/models/dagbag.py", line 338, in parse
    loader.exec_module(new_module)
  File "<frozen importlib._bootstrap_external>", line 728, in exec_module
  File "<frozen importlib._bootstrap>", line 219, in _call_with_frames_removed
  File "/opt/airflow/dags/group_dag.py", line 27, in <module>
    subdag=subdag_downloads(dag.dag_id, 'downloads', args)
  File "/opt/airflow/dags/subdags/subdags_downloads.py", line 9, in subdag_downloads
    catch = args['catchup']) as dag:
TypeError: __init__() got an unexpected keyword argument 'catch'
[2024-04-16T13:22:32.943+0000] {processor.py:768} WARNING - No viable dags retrieved from /opt/airflow/dags/group_dag.py
[2024-04-16T13:22:32.977+0000] {processor.py:176} INFO - Processing /opt/airflow/dags/group_dag.py took 0.141 seconds
[2024-04-16T13:23:03.859+0000] {processor.py:154} INFO - Started process (PID=3391) to work on /opt/airflow/dags/group_dag.py
[2024-04-16T13:23:03.861+0000] {processor.py:756} INFO - Processing file /opt/airflow/dags/group_dag.py for tasks to queue
[2024-04-16T13:23:03.863+0000] {logging_mixin.py:120} INFO - [2024-04-16T13:23:03.862+0000] {dagbag.py:537} INFO - Filling up the DagBag from /opt/airflow/dags/group_dag.py
[2024-04-16T13:23:03.903+0000] {logging_mixin.py:120} INFO - [2024-04-16T13:23:03.898+0000] {dagbag.py:342} ERROR - Failed to import: /opt/airflow/dags/group_dag.py
Traceback (most recent call last):
  File "/home/airflow/.local/lib/python3.7/site-packages/airflow/models/dagbag.py", line 338, in parse
    loader.exec_module(new_module)
  File "<frozen importlib._bootstrap_external>", line 728, in exec_module
  File "<frozen importlib._bootstrap>", line 219, in _call_with_frames_removed
  File "/opt/airflow/dags/group_dag.py", line 27, in <module>
    subdag=subdag_downloads(dag.dag_id, 'downloads', args)
  File "/opt/airflow/dags/subdags/subdags_downloads.py", line 9, in subdag_downloads
    catch = args['catchup']) as dag:
TypeError: __init__() got an unexpected keyword argument 'catch'
[2024-04-16T13:23:03.905+0000] {processor.py:768} WARNING - No viable dags retrieved from /opt/airflow/dags/group_dag.py
[2024-04-16T13:23:03.950+0000] {processor.py:176} INFO - Processing /opt/airflow/dags/group_dag.py took 0.097 seconds
[2024-04-16T13:23:34.670+0000] {processor.py:154} INFO - Started process (PID=3460) to work on /opt/airflow/dags/group_dag.py
[2024-04-16T13:23:34.689+0000] {processor.py:756} INFO - Processing file /opt/airflow/dags/group_dag.py for tasks to queue
[2024-04-16T13:23:34.696+0000] {logging_mixin.py:120} INFO - [2024-04-16T13:23:34.696+0000] {dagbag.py:537} INFO - Filling up the DagBag from /opt/airflow/dags/group_dag.py
[2024-04-16T13:23:34.861+0000] {logging_mixin.py:120} INFO - [2024-04-16T13:23:34.847+0000] {dagbag.py:342} ERROR - Failed to import: /opt/airflow/dags/group_dag.py
Traceback (most recent call last):
  File "/home/airflow/.local/lib/python3.7/site-packages/airflow/models/dagbag.py", line 338, in parse
    loader.exec_module(new_module)
  File "<frozen importlib._bootstrap_external>", line 728, in exec_module
  File "<frozen importlib._bootstrap>", line 219, in _call_with_frames_removed
  File "/opt/airflow/dags/group_dag.py", line 27, in <module>
    subdag=subdag_downloads(dag.dag_id, 'downloads', args)
  File "/opt/airflow/dags/subdags/subdags_downloads.py", line 9, in subdag_downloads
    catch = args['catchup']) as dag:
TypeError: __init__() got an unexpected keyword argument 'catch'
[2024-04-16T13:23:34.874+0000] {processor.py:768} WARNING - No viable dags retrieved from /opt/airflow/dags/group_dag.py
[2024-04-16T13:23:35.071+0000] {processor.py:176} INFO - Processing /opt/airflow/dags/group_dag.py took 0.423 seconds
[2024-04-16T13:24:05.262+0000] {processor.py:154} INFO - Started process (PID=3538) to work on /opt/airflow/dags/group_dag.py
[2024-04-16T13:24:05.264+0000] {processor.py:756} INFO - Processing file /opt/airflow/dags/group_dag.py for tasks to queue
[2024-04-16T13:24:05.266+0000] {logging_mixin.py:120} INFO - [2024-04-16T13:24:05.266+0000] {dagbag.py:537} INFO - Filling up the DagBag from /opt/airflow/dags/group_dag.py
[2024-04-16T13:24:05.305+0000] {logging_mixin.py:120} INFO - [2024-04-16T13:24:05.301+0000] {dagbag.py:342} ERROR - Failed to import: /opt/airflow/dags/group_dag.py
Traceback (most recent call last):
  File "/home/airflow/.local/lib/python3.7/site-packages/airflow/models/dagbag.py", line 338, in parse
    loader.exec_module(new_module)
  File "<frozen importlib._bootstrap_external>", line 728, in exec_module
  File "<frozen importlib._bootstrap>", line 219, in _call_with_frames_removed
  File "/opt/airflow/dags/group_dag.py", line 27, in <module>
    subdag=subdag_downloads(dag.dag_id, 'downloads', args)
  File "/opt/airflow/dags/subdags/subdags_downloads.py", line 9, in subdag_downloads
    catch = args['catchup']) as dag:
TypeError: __init__() got an unexpected keyword argument 'catch'
[2024-04-16T13:24:05.306+0000] {processor.py:768} WARNING - No viable dags retrieved from /opt/airflow/dags/group_dag.py
[2024-04-16T13:24:05.340+0000] {processor.py:176} INFO - Processing /opt/airflow/dags/group_dag.py took 0.087 seconds
[2024-04-16T13:24:35.590+0000] {processor.py:154} INFO - Started process (PID=3608) to work on /opt/airflow/dags/group_dag.py
[2024-04-16T13:24:35.639+0000] {processor.py:756} INFO - Processing file /opt/airflow/dags/group_dag.py for tasks to queue
[2024-04-16T13:24:35.654+0000] {logging_mixin.py:120} INFO - [2024-04-16T13:24:35.653+0000] {dagbag.py:537} INFO - Filling up the DagBag from /opt/airflow/dags/group_dag.py
[2024-04-16T13:24:35.730+0000] {logging_mixin.py:120} INFO - [2024-04-16T13:24:35.723+0000] {dagbag.py:342} ERROR - Failed to import: /opt/airflow/dags/group_dag.py
Traceback (most recent call last):
  File "/home/airflow/.local/lib/python3.7/site-packages/airflow/models/dagbag.py", line 338, in parse
    loader.exec_module(new_module)
  File "<frozen importlib._bootstrap_external>", line 728, in exec_module
  File "<frozen importlib._bootstrap>", line 219, in _call_with_frames_removed
  File "/opt/airflow/dags/group_dag.py", line 27, in <module>
    subdag=subdag_downloads(dag.dag_id, 'downloads', args)
  File "/opt/airflow/dags/subdags/subdags_downloads.py", line 9, in subdag_downloads
    catch = args['catchup']) as dag:
TypeError: __init__() got an unexpected keyword argument 'catch'
[2024-04-16T13:24:35.732+0000] {processor.py:768} WARNING - No viable dags retrieved from /opt/airflow/dags/group_dag.py
[2024-04-16T13:24:35.777+0000] {processor.py:176} INFO - Processing /opt/airflow/dags/group_dag.py took 0.204 seconds
[2024-04-16T13:25:05.833+0000] {processor.py:154} INFO - Started process (PID=3684) to work on /opt/airflow/dags/group_dag.py
[2024-04-16T13:25:05.835+0000] {processor.py:756} INFO - Processing file /opt/airflow/dags/group_dag.py for tasks to queue
[2024-04-16T13:25:05.837+0000] {logging_mixin.py:120} INFO - [2024-04-16T13:25:05.836+0000] {dagbag.py:537} INFO - Filling up the DagBag from /opt/airflow/dags/group_dag.py
[2024-04-16T13:25:05.872+0000] {logging_mixin.py:120} INFO - [2024-04-16T13:25:05.869+0000] {dagbag.py:342} ERROR - Failed to import: /opt/airflow/dags/group_dag.py
Traceback (most recent call last):
  File "/home/airflow/.local/lib/python3.7/site-packages/airflow/models/dagbag.py", line 338, in parse
    loader.exec_module(new_module)
  File "<frozen importlib._bootstrap_external>", line 728, in exec_module
  File "<frozen importlib._bootstrap>", line 219, in _call_with_frames_removed
  File "/opt/airflow/dags/group_dag.py", line 27, in <module>
    subdag=subdag_downloads(dag.dag_id, 'downloads', args)
  File "/opt/airflow/dags/subdags/subdags_downloads.py", line 9, in subdag_downloads
    catch = args['catchup']) as dag:
TypeError: __init__() got an unexpected keyword argument 'catch'
[2024-04-16T13:25:05.874+0000] {processor.py:768} WARNING - No viable dags retrieved from /opt/airflow/dags/group_dag.py
[2024-04-16T13:25:05.905+0000] {processor.py:176} INFO - Processing /opt/airflow/dags/group_dag.py took 0.078 seconds
[2024-04-16T13:25:36.167+0000] {processor.py:154} INFO - Started process (PID=3754) to work on /opt/airflow/dags/group_dag.py
[2024-04-16T13:25:36.169+0000] {processor.py:756} INFO - Processing file /opt/airflow/dags/group_dag.py for tasks to queue
[2024-04-16T13:25:36.172+0000] {logging_mixin.py:120} INFO - [2024-04-16T13:25:36.171+0000] {dagbag.py:537} INFO - Filling up the DagBag from /opt/airflow/dags/group_dag.py
[2024-04-16T13:25:36.207+0000] {logging_mixin.py:120} INFO - [2024-04-16T13:25:36.203+0000] {dagbag.py:342} ERROR - Failed to import: /opt/airflow/dags/group_dag.py
Traceback (most recent call last):
  File "/home/airflow/.local/lib/python3.7/site-packages/airflow/models/dagbag.py", line 338, in parse
    loader.exec_module(new_module)
  File "<frozen importlib._bootstrap_external>", line 728, in exec_module
  File "<frozen importlib._bootstrap>", line 219, in _call_with_frames_removed
  File "/opt/airflow/dags/group_dag.py", line 27, in <module>
    subdag=subdag_downloads(dag.dag_id, 'downloads', args)
  File "/opt/airflow/dags/subdags/subdags_downloads.py", line 9, in subdag_downloads
    catch = args['catchup']) as dag:
TypeError: __init__() got an unexpected keyword argument 'catch'
[2024-04-16T13:25:36.208+0000] {processor.py:768} WARNING - No viable dags retrieved from /opt/airflow/dags/group_dag.py
[2024-04-16T13:25:36.239+0000] {processor.py:176} INFO - Processing /opt/airflow/dags/group_dag.py took 0.078 seconds
[2024-04-16T13:26:06.422+0000] {processor.py:154} INFO - Started process (PID=3832) to work on /opt/airflow/dags/group_dag.py
[2024-04-16T13:26:06.427+0000] {processor.py:756} INFO - Processing file /opt/airflow/dags/group_dag.py for tasks to queue
[2024-04-16T13:26:06.429+0000] {logging_mixin.py:120} INFO - [2024-04-16T13:26:06.429+0000] {dagbag.py:537} INFO - Filling up the DagBag from /opt/airflow/dags/group_dag.py
[2024-04-16T13:26:06.465+0000] {logging_mixin.py:120} INFO - [2024-04-16T13:26:06.461+0000] {dagbag.py:342} ERROR - Failed to import: /opt/airflow/dags/group_dag.py
Traceback (most recent call last):
  File "/home/airflow/.local/lib/python3.7/site-packages/airflow/models/dagbag.py", line 338, in parse
    loader.exec_module(new_module)
  File "<frozen importlib._bootstrap_external>", line 728, in exec_module
  File "<frozen importlib._bootstrap>", line 219, in _call_with_frames_removed
  File "/opt/airflow/dags/group_dag.py", line 27, in <module>
    subdag=subdag_downloads(dag.dag_id, 'downloads', args)
  File "/opt/airflow/dags/subdags/subdags_downloads.py", line 9, in subdag_downloads
    catch = args['catchup']) as dag:
TypeError: __init__() got an unexpected keyword argument 'catch'
[2024-04-16T13:26:06.466+0000] {processor.py:768} WARNING - No viable dags retrieved from /opt/airflow/dags/group_dag.py
[2024-04-16T13:26:06.497+0000] {processor.py:176} INFO - Processing /opt/airflow/dags/group_dag.py took 0.080 seconds
[2024-04-16T13:26:36.604+0000] {processor.py:154} INFO - Started process (PID=3902) to work on /opt/airflow/dags/group_dag.py
[2024-04-16T13:26:36.606+0000] {processor.py:756} INFO - Processing file /opt/airflow/dags/group_dag.py for tasks to queue
[2024-04-16T13:26:36.609+0000] {logging_mixin.py:120} INFO - [2024-04-16T13:26:36.608+0000] {dagbag.py:537} INFO - Filling up the DagBag from /opt/airflow/dags/group_dag.py
[2024-04-16T13:26:36.648+0000] {logging_mixin.py:120} INFO - [2024-04-16T13:26:36.644+0000] {dagbag.py:342} ERROR - Failed to import: /opt/airflow/dags/group_dag.py
Traceback (most recent call last):
  File "/home/airflow/.local/lib/python3.7/site-packages/airflow/models/dagbag.py", line 338, in parse
    loader.exec_module(new_module)
  File "<frozen importlib._bootstrap_external>", line 728, in exec_module
  File "<frozen importlib._bootstrap>", line 219, in _call_with_frames_removed
  File "/opt/airflow/dags/group_dag.py", line 27, in <module>
    subdag=subdag_downloads(dag.dag_id, 'downloads', args)
  File "/opt/airflow/dags/subdags/subdags_downloads.py", line 9, in subdag_downloads
    catch = args['catchup']) as dag:
TypeError: __init__() got an unexpected keyword argument 'catch'
[2024-04-16T13:26:36.650+0000] {processor.py:768} WARNING - No viable dags retrieved from /opt/airflow/dags/group_dag.py
[2024-04-16T13:26:36.676+0000] {processor.py:176} INFO - Processing /opt/airflow/dags/group_dag.py took 0.080 seconds
[2024-04-16T13:27:07.038+0000] {processor.py:154} INFO - Started process (PID=3980) to work on /opt/airflow/dags/group_dag.py
[2024-04-16T13:27:07.040+0000] {processor.py:756} INFO - Processing file /opt/airflow/dags/group_dag.py for tasks to queue
[2024-04-16T13:27:07.042+0000] {logging_mixin.py:120} INFO - [2024-04-16T13:27:07.042+0000] {dagbag.py:537} INFO - Filling up the DagBag from /opt/airflow/dags/group_dag.py
[2024-04-16T13:27:07.082+0000] {logging_mixin.py:120} INFO - [2024-04-16T13:27:07.074+0000] {dagbag.py:342} ERROR - Failed to import: /opt/airflow/dags/group_dag.py
Traceback (most recent call last):
  File "/home/airflow/.local/lib/python3.7/site-packages/airflow/models/dagbag.py", line 338, in parse
    loader.exec_module(new_module)
  File "<frozen importlib._bootstrap_external>", line 728, in exec_module
  File "<frozen importlib._bootstrap>", line 219, in _call_with_frames_removed
  File "/opt/airflow/dags/group_dag.py", line 27, in <module>
    subdag=subdag_downloads(dag.dag_id, 'downloads', args)
  File "/opt/airflow/dags/subdags/subdags_downloads.py", line 9, in subdag_downloads
    catch = args['catchup']) as dag:
TypeError: __init__() got an unexpected keyword argument 'catch'
[2024-04-16T13:27:07.084+0000] {processor.py:768} WARNING - No viable dags retrieved from /opt/airflow/dags/group_dag.py
[2024-04-16T13:27:07.131+0000] {processor.py:176} INFO - Processing /opt/airflow/dags/group_dag.py took 0.098 seconds
[2024-04-16T13:27:37.791+0000] {processor.py:154} INFO - Started process (PID=4049) to work on /opt/airflow/dags/group_dag.py
[2024-04-16T13:27:37.796+0000] {processor.py:756} INFO - Processing file /opt/airflow/dags/group_dag.py for tasks to queue
[2024-04-16T13:27:37.797+0000] {logging_mixin.py:120} INFO - [2024-04-16T13:27:37.797+0000] {dagbag.py:537} INFO - Filling up the DagBag from /opt/airflow/dags/group_dag.py
[2024-04-16T13:27:37.836+0000] {logging_mixin.py:120} INFO - [2024-04-16T13:27:37.833+0000] {dagbag.py:342} ERROR - Failed to import: /opt/airflow/dags/group_dag.py
Traceback (most recent call last):
  File "/home/airflow/.local/lib/python3.7/site-packages/airflow/models/dagbag.py", line 338, in parse
    loader.exec_module(new_module)
  File "<frozen importlib._bootstrap_external>", line 728, in exec_module
  File "<frozen importlib._bootstrap>", line 219, in _call_with_frames_removed
  File "/opt/airflow/dags/group_dag.py", line 27, in <module>
    subdag=subdag_downloads(dag.dag_id, 'downloads', args)
  File "/opt/airflow/dags/subdags/subdags_downloads.py", line 9, in subdag_downloads
    catch = args['catchup']) as dag:
TypeError: __init__() got an unexpected keyword argument 'catch'
[2024-04-16T13:27:37.837+0000] {processor.py:768} WARNING - No viable dags retrieved from /opt/airflow/dags/group_dag.py
[2024-04-16T13:27:37.871+0000] {processor.py:176} INFO - Processing /opt/airflow/dags/group_dag.py took 0.088 seconds
[2024-04-16T13:28:08.183+0000] {processor.py:154} INFO - Started process (PID=4127) to work on /opt/airflow/dags/group_dag.py
[2024-04-16T13:28:08.186+0000] {processor.py:756} INFO - Processing file /opt/airflow/dags/group_dag.py for tasks to queue
[2024-04-16T13:28:08.187+0000] {logging_mixin.py:120} INFO - [2024-04-16T13:28:08.187+0000] {dagbag.py:537} INFO - Filling up the DagBag from /opt/airflow/dags/group_dag.py
[2024-04-16T13:28:08.231+0000] {logging_mixin.py:120} INFO - [2024-04-16T13:28:08.228+0000] {dagbag.py:342} ERROR - Failed to import: /opt/airflow/dags/group_dag.py
Traceback (most recent call last):
  File "/home/airflow/.local/lib/python3.7/site-packages/airflow/models/dagbag.py", line 338, in parse
    loader.exec_module(new_module)
  File "<frozen importlib._bootstrap_external>", line 728, in exec_module
  File "<frozen importlib._bootstrap>", line 219, in _call_with_frames_removed
  File "/opt/airflow/dags/group_dag.py", line 27, in <module>
    subdag=subdag_downloads(dag.dag_id, 'downloads', args)
  File "/opt/airflow/dags/subdags/subdags_downloads.py", line 9, in subdag_downloads
    catch = args['catchup']) as dag:
TypeError: __init__() got an unexpected keyword argument 'catch'
[2024-04-16T13:28:08.233+0000] {processor.py:768} WARNING - No viable dags retrieved from /opt/airflow/dags/group_dag.py
[2024-04-16T13:28:08.271+0000] {processor.py:176} INFO - Processing /opt/airflow/dags/group_dag.py took 0.096 seconds
[2024-04-16T13:28:39.023+0000] {processor.py:154} INFO - Started process (PID=4196) to work on /opt/airflow/dags/group_dag.py
[2024-04-16T13:28:39.027+0000] {processor.py:756} INFO - Processing file /opt/airflow/dags/group_dag.py for tasks to queue
[2024-04-16T13:28:39.029+0000] {logging_mixin.py:120} INFO - [2024-04-16T13:28:39.028+0000] {dagbag.py:537} INFO - Filling up the DagBag from /opt/airflow/dags/group_dag.py
[2024-04-16T13:28:39.068+0000] {logging_mixin.py:120} INFO - [2024-04-16T13:28:39.063+0000] {dagbag.py:342} ERROR - Failed to import: /opt/airflow/dags/group_dag.py
Traceback (most recent call last):
  File "/home/airflow/.local/lib/python3.7/site-packages/airflow/models/dagbag.py", line 338, in parse
    loader.exec_module(new_module)
  File "<frozen importlib._bootstrap_external>", line 728, in exec_module
  File "<frozen importlib._bootstrap>", line 219, in _call_with_frames_removed
  File "/opt/airflow/dags/group_dag.py", line 27, in <module>
    subdag=subdag_downloads(dag.dag_id, 'downloads', args)
  File "/opt/airflow/dags/subdags/subdags_downloads.py", line 9, in subdag_downloads
    catch = args['catchup']) as dag:
TypeError: __init__() got an unexpected keyword argument 'catch'
[2024-04-16T13:28:39.069+0000] {processor.py:768} WARNING - No viable dags retrieved from /opt/airflow/dags/group_dag.py
[2024-04-16T13:28:39.098+0000] {processor.py:176} INFO - Processing /opt/airflow/dags/group_dag.py took 0.081 seconds
[2024-04-16T13:29:09.780+0000] {processor.py:154} INFO - Started process (PID=4276) to work on /opt/airflow/dags/group_dag.py
[2024-04-16T13:29:09.782+0000] {processor.py:756} INFO - Processing file /opt/airflow/dags/group_dag.py for tasks to queue
[2024-04-16T13:29:09.784+0000] {logging_mixin.py:120} INFO - [2024-04-16T13:29:09.784+0000] {dagbag.py:537} INFO - Filling up the DagBag from /opt/airflow/dags/group_dag.py
[2024-04-16T13:29:09.825+0000] {logging_mixin.py:120} INFO - [2024-04-16T13:29:09.822+0000] {dagbag.py:342} ERROR - Failed to import: /opt/airflow/dags/group_dag.py
Traceback (most recent call last):
  File "/home/airflow/.local/lib/python3.7/site-packages/airflow/models/dagbag.py", line 338, in parse
    loader.exec_module(new_module)
  File "<frozen importlib._bootstrap_external>", line 728, in exec_module
  File "<frozen importlib._bootstrap>", line 219, in _call_with_frames_removed
  File "/opt/airflow/dags/group_dag.py", line 27, in <module>
    subdag=subdag_downloads(dag.dag_id, 'downloads', args)
  File "/opt/airflow/dags/subdags/subdags_downloads.py", line 9, in subdag_downloads
    catch = args['catchup']) as dag:
TypeError: __init__() got an unexpected keyword argument 'catch'
[2024-04-16T13:29:09.830+0000] {processor.py:768} WARNING - No viable dags retrieved from /opt/airflow/dags/group_dag.py
[2024-04-16T13:29:09.863+0000] {processor.py:176} INFO - Processing /opt/airflow/dags/group_dag.py took 0.090 seconds
[2024-04-16T13:29:40.564+0000] {processor.py:154} INFO - Started process (PID=4342) to work on /opt/airflow/dags/group_dag.py
[2024-04-16T13:29:40.566+0000] {processor.py:756} INFO - Processing file /opt/airflow/dags/group_dag.py for tasks to queue
[2024-04-16T13:29:40.568+0000] {logging_mixin.py:120} INFO - [2024-04-16T13:29:40.567+0000] {dagbag.py:537} INFO - Filling up the DagBag from /opt/airflow/dags/group_dag.py
[2024-04-16T13:29:40.612+0000] {logging_mixin.py:120} INFO - [2024-04-16T13:29:40.608+0000] {dagbag.py:342} ERROR - Failed to import: /opt/airflow/dags/group_dag.py
Traceback (most recent call last):
  File "/home/airflow/.local/lib/python3.7/site-packages/airflow/models/dagbag.py", line 338, in parse
    loader.exec_module(new_module)
  File "<frozen importlib._bootstrap_external>", line 728, in exec_module
  File "<frozen importlib._bootstrap>", line 219, in _call_with_frames_removed
  File "/opt/airflow/dags/group_dag.py", line 27, in <module>
    subdag=subdag_downloads(dag.dag_id, 'downloads', args)
  File "/opt/airflow/dags/subdags/subdags_downloads.py", line 9, in subdag_downloads
    catch = args['catchup']) as dag:
TypeError: __init__() got an unexpected keyword argument 'catch'
[2024-04-16T13:29:40.613+0000] {processor.py:768} WARNING - No viable dags retrieved from /opt/airflow/dags/group_dag.py
[2024-04-16T13:29:40.642+0000] {processor.py:176} INFO - Processing /opt/airflow/dags/group_dag.py took 0.084 seconds
[2024-04-16T13:30:11.612+0000] {processor.py:154} INFO - Started process (PID=4421) to work on /opt/airflow/dags/group_dag.py
[2024-04-16T13:30:11.614+0000] {processor.py:756} INFO - Processing file /opt/airflow/dags/group_dag.py for tasks to queue
[2024-04-16T13:30:11.615+0000] {logging_mixin.py:120} INFO - [2024-04-16T13:30:11.615+0000] {dagbag.py:537} INFO - Filling up the DagBag from /opt/airflow/dags/group_dag.py
[2024-04-16T13:30:11.653+0000] {logging_mixin.py:120} INFO - [2024-04-16T13:30:11.649+0000] {dagbag.py:342} ERROR - Failed to import: /opt/airflow/dags/group_dag.py
Traceback (most recent call last):
  File "/home/airflow/.local/lib/python3.7/site-packages/airflow/models/dagbag.py", line 338, in parse
    loader.exec_module(new_module)
  File "<frozen importlib._bootstrap_external>", line 728, in exec_module
  File "<frozen importlib._bootstrap>", line 219, in _call_with_frames_removed
  File "/opt/airflow/dags/group_dag.py", line 27, in <module>
    subdag=subdag_downloads(dag.dag_id, 'downloads', args)
  File "/opt/airflow/dags/subdags/subdags_downloads.py", line 9, in subdag_downloads
    catch = args['catchup']) as dag:
TypeError: __init__() got an unexpected keyword argument 'catch'
[2024-04-16T13:30:11.654+0000] {processor.py:768} WARNING - No viable dags retrieved from /opt/airflow/dags/group_dag.py
[2024-04-16T13:30:11.683+0000] {processor.py:176} INFO - Processing /opt/airflow/dags/group_dag.py took 0.077 seconds
[2024-04-16T13:30:41.830+0000] {processor.py:154} INFO - Started process (PID=4497) to work on /opt/airflow/dags/group_dag.py
[2024-04-16T13:30:41.832+0000] {processor.py:756} INFO - Processing file /opt/airflow/dags/group_dag.py for tasks to queue
[2024-04-16T13:30:41.834+0000] {logging_mixin.py:120} INFO - [2024-04-16T13:30:41.834+0000] {dagbag.py:537} INFO - Filling up the DagBag from /opt/airflow/dags/group_dag.py
[2024-04-16T13:30:41.872+0000] {logging_mixin.py:120} INFO - [2024-04-16T13:30:41.868+0000] {dagbag.py:342} ERROR - Failed to import: /opt/airflow/dags/group_dag.py
Traceback (most recent call last):
  File "/home/airflow/.local/lib/python3.7/site-packages/airflow/models/dagbag.py", line 338, in parse
    loader.exec_module(new_module)
  File "<frozen importlib._bootstrap_external>", line 728, in exec_module
  File "<frozen importlib._bootstrap>", line 219, in _call_with_frames_removed
  File "/opt/airflow/dags/group_dag.py", line 27, in <module>
    subdag=subdag_downloads(dag.dag_id, 'downloads', args)
  File "/opt/airflow/dags/subdags/subdags_downloads.py", line 9, in subdag_downloads
    catch = args['catchup']) as dag:
TypeError: __init__() got an unexpected keyword argument 'catch'
[2024-04-16T13:30:41.874+0000] {processor.py:768} WARNING - No viable dags retrieved from /opt/airflow/dags/group_dag.py
[2024-04-16T13:30:41.908+0000] {processor.py:176} INFO - Processing /opt/airflow/dags/group_dag.py took 0.083 seconds
[2024-04-16T13:31:12.328+0000] {processor.py:154} INFO - Started process (PID=4566) to work on /opt/airflow/dags/group_dag.py
[2024-04-16T13:31:12.333+0000] {processor.py:756} INFO - Processing file /opt/airflow/dags/group_dag.py for tasks to queue
[2024-04-16T13:31:12.336+0000] {logging_mixin.py:120} INFO - [2024-04-16T13:31:12.336+0000] {dagbag.py:537} INFO - Filling up the DagBag from /opt/airflow/dags/group_dag.py
[2024-04-16T13:31:12.376+0000] {logging_mixin.py:120} INFO - [2024-04-16T13:31:12.372+0000] {dagbag.py:342} ERROR - Failed to import: /opt/airflow/dags/group_dag.py
Traceback (most recent call last):
  File "/home/airflow/.local/lib/python3.7/site-packages/airflow/models/dagbag.py", line 338, in parse
    loader.exec_module(new_module)
  File "<frozen importlib._bootstrap_external>", line 728, in exec_module
  File "<frozen importlib._bootstrap>", line 219, in _call_with_frames_removed
  File "/opt/airflow/dags/group_dag.py", line 27, in <module>
    subdag=subdag_downloads(dag.dag_id, 'downloads', args)
  File "/opt/airflow/dags/subdags/subdags_downloads.py", line 9, in subdag_downloads
    catch = args['catchup']) as dag:
TypeError: __init__() got an unexpected keyword argument 'catch'
[2024-04-16T13:31:12.377+0000] {processor.py:768} WARNING - No viable dags retrieved from /opt/airflow/dags/group_dag.py
[2024-04-16T13:31:12.410+0000] {processor.py:176} INFO - Processing /opt/airflow/dags/group_dag.py took 0.088 seconds
