[2024-04-05T16:09:19.386+0000] {taskinstance.py:1165} INFO - Dependencies all met for <TaskInstance: user_processing.is_api_available scheduled__2024-04-03T00:00:00+00:00 [queued]>
[2024-04-05T16:09:19.409+0000] {taskinstance.py:1165} INFO - Dependencies all met for <TaskInstance: user_processing.is_api_available scheduled__2024-04-03T00:00:00+00:00 [queued]>
[2024-04-05T16:09:19.410+0000] {taskinstance.py:1362} INFO - 
--------------------------------------------------------------------------------
[2024-04-05T16:09:19.411+0000] {taskinstance.py:1363} INFO - Starting attempt 1 of 1
[2024-04-05T16:09:19.412+0000] {taskinstance.py:1364} INFO - 
--------------------------------------------------------------------------------
[2024-04-05T16:09:19.515+0000] {taskinstance.py:1383} INFO - Executing <Task(HttpSensor): is_api_available> on 2024-04-03 00:00:00+00:00
[2024-04-05T16:09:19.542+0000] {standard_task_runner.py:55} INFO - Started process 3254 to run task
[2024-04-05T16:09:19.586+0000] {standard_task_runner.py:82} INFO - Running: ['***', 'tasks', 'run', 'user_processing', 'is_api_available', 'scheduled__2024-04-03T00:00:00+00:00', '--job-id', '114', '--raw', '--subdir', 'DAGS_FOLDER/user_processing.py', '--cfg-path', '/tmp/tmp9ilmhclh']
[2024-04-05T16:09:19.594+0000] {standard_task_runner.py:83} INFO - Job 114: Subtask is_api_available
[2024-04-05T16:09:20.498+0000] {task_command.py:376} INFO - Running <TaskInstance: user_processing.is_api_available scheduled__2024-04-03T00:00:00+00:00 [running]> on host a868c0c748e3
[2024-04-05T16:09:22.263+0000] {taskinstance.py:1592} INFO - Exporting the following env vars:
AIRFLOW_CTX_DAG_OWNER=***
AIRFLOW_CTX_DAG_ID=user_processing
AIRFLOW_CTX_TASK_ID=is_api_available
AIRFLOW_CTX_EXECUTION_DATE=2024-04-03T00:00:00+00:00
AIRFLOW_CTX_TRY_NUMBER=1
AIRFLOW_CTX_DAG_RUN_ID=scheduled__2024-04-03T00:00:00+00:00
[2024-04-05T16:09:22.283+0000] {http.py:120} INFO - Poking: api/
[2024-04-05T16:09:22.488+0000] {taskinstance.py:1851} ERROR - Task failed with exception
Traceback (most recent call last):
  File "/home/airflow/.local/lib/python3.7/site-packages/airflow/sensors/base.py", line 189, in execute
    poke_return = self.poke(context)
  File "/home/airflow/.local/lib/python3.7/site-packages/airflow/providers/http/sensors/http.py", line 135, in poke
    raise exc
  File "/home/airflow/.local/lib/python3.7/site-packages/airflow/providers/http/sensors/http.py", line 126, in poke
    extra_options=self.extra_options,
  File "/home/airflow/.local/lib/python3.7/site-packages/airflow/providers/http/hooks/http.py", line 128, in run
    session = self.get_conn(headers)
  File "/home/airflow/.local/lib/python3.7/site-packages/airflow/providers/http/hooks/http.py", line 82, in get_conn
    conn = self.get_connection(self.http_conn_id)
  File "/home/airflow/.local/lib/python3.7/site-packages/airflow/hooks/base.py", line 70, in get_connection
    conn = Connection.get_connection_from_secrets(conn_id)
  File "/home/airflow/.local/lib/python3.7/site-packages/airflow/models/connection.py", line 432, in get_connection_from_secrets
    raise AirflowNotFoundException(f"The conn_id `{conn_id}` isn't defined")
airflow.exceptions.AirflowNotFoundException: The conn_id `user_api` isn't defined
[2024-04-05T16:09:22.570+0000] {taskinstance.py:1406} INFO - Marking task as FAILED. dag_id=user_processing, task_id=is_api_available, execution_date=20240403T000000, start_date=20240405T160919, end_date=20240405T160922
[2024-04-05T16:09:22.661+0000] {standard_task_runner.py:105} ERROR - Failed to execute job 114 for task is_api_available (The conn_id `user_api` isn't defined; 3254)
[2024-04-05T16:09:22.780+0000] {local_task_job.py:164} INFO - Task exited with return code 1
[2024-04-05T16:09:23.138+0000] {local_task_job.py:273} INFO - 0 downstream tasks scheduled from follow-on schedule check
