[2024-03-29T05:56:49.588+0000] {taskinstance.py:1165} INFO - Dependencies all met for <TaskInstance: user_processing.create_table manual__2024-03-29T05:56:48.225789+00:00 [queued]>
[2024-03-29T05:56:49.603+0000] {taskinstance.py:1165} INFO - Dependencies all met for <TaskInstance: user_processing.create_table manual__2024-03-29T05:56:48.225789+00:00 [queued]>
[2024-03-29T05:56:49.604+0000] {taskinstance.py:1362} INFO - 
--------------------------------------------------------------------------------
[2024-03-29T05:56:49.605+0000] {taskinstance.py:1363} INFO - Starting attempt 1 of 1
[2024-03-29T05:56:49.606+0000] {taskinstance.py:1364} INFO - 
--------------------------------------------------------------------------------
[2024-03-29T05:56:49.634+0000] {taskinstance.py:1383} INFO - Executing <Task(PostgresOperator): create_table> on 2024-03-29 05:56:48.225789+00:00
[2024-03-29T05:56:49.641+0000] {standard_task_runner.py:55} INFO - Started process 7636 to run task
[2024-03-29T05:56:49.647+0000] {standard_task_runner.py:82} INFO - Running: ['***', 'tasks', 'run', 'user_processing', 'create_table', 'manual__2024-03-29T05:56:48.225789+00:00', '--job-id', '48', '--raw', '--subdir', 'DAGS_FOLDER/user_processing.py', '--cfg-path', '/tmp/tmph7eqcqz_']
[2024-03-29T05:56:49.648+0000] {standard_task_runner.py:83} INFO - Job 48: Subtask create_table
[2024-03-29T05:56:49.747+0000] {task_command.py:376} INFO - Running <TaskInstance: user_processing.create_table manual__2024-03-29T05:56:48.225789+00:00 [running]> on host 0245ea477832
[2024-03-29T05:56:49.845+0000] {taskinstance.py:1592} INFO - Exporting the following env vars:
AIRFLOW_CTX_DAG_OWNER=***
AIRFLOW_CTX_DAG_ID=user_processing
AIRFLOW_CTX_TASK_ID=create_table
AIRFLOW_CTX_EXECUTION_DATE=2024-03-29T05:56:48.225789+00:00
AIRFLOW_CTX_TRY_NUMBER=1
AIRFLOW_CTX_DAG_RUN_ID=manual__2024-03-29T05:56:48.225789+00:00
[2024-03-29T05:56:49.875+0000] {taskinstance.py:1851} ERROR - Task failed with exception
Traceback (most recent call last):
  File "/home/airflow/.local/lib/python3.7/site-packages/airflow/providers/postgres/operators/postgres.py", line 94, in execute
    self.hook.run(self.sql, self.autocommit, parameters=self.parameters)
  File "/home/airflow/.local/lib/python3.7/site-packages/airflow/providers/common/sql/hooks/sql.py", line 288, in run
    with closing(self.get_conn()) as conn:
  File "/home/airflow/.local/lib/python3.7/site-packages/airflow/providers/postgres/hooks/postgres.py", line 88, in get_conn
    conn = deepcopy(self.connection or self.get_connection(conn_id))
  File "/home/airflow/.local/lib/python3.7/site-packages/airflow/hooks/base.py", line 70, in get_connection
    conn = Connection.get_connection_from_secrets(conn_id)
  File "/home/airflow/.local/lib/python3.7/site-packages/airflow/models/connection.py", line 432, in get_connection_from_secrets
    raise AirflowNotFoundException(f"The conn_id `{conn_id}` isn't defined")
airflow.exceptions.AirflowNotFoundException: The conn_id `postgres` isn't defined
[2024-03-29T05:56:49.882+0000] {taskinstance.py:1406} INFO - Marking task as FAILED. dag_id=user_processing, task_id=create_table, execution_date=20240329T055648, start_date=20240329T055649, end_date=20240329T055649
[2024-03-29T05:56:49.886+0000] {standard_task_runner.py:105} ERROR - Failed to execute job 48 for task create_table (The conn_id `postgres` isn't defined; 7636)
[2024-03-29T05:56:49.919+0000] {local_task_job.py:164} INFO - Task exited with return code 1
[2024-03-29T05:56:49.974+0000] {local_task_job.py:273} INFO - 0 downstream tasks scheduled from follow-on schedule check
