[2024-04-17T12:00:17.409+0000] {processor.py:154} INFO - Started process (PID=4637) to work on /opt/airflow/dags/group_dag.py
[2024-04-17T12:00:17.425+0000] {processor.py:756} INFO - Processing file /opt/airflow/dags/group_dag.py for tasks to queue
[2024-04-17T12:00:17.428+0000] {logging_mixin.py:120} INFO - [2024-04-17T12:00:17.428+0000] {dagbag.py:537} INFO - Filling up the DagBag from /opt/airflow/dags/group_dag.py
[2024-04-17T12:00:19.187+0000] {logging_mixin.py:120} INFO - [2024-04-17T12:00:19.157+0000] {dagbag.py:342} ERROR - Failed to import: /opt/airflow/dags/group_dag.py
Traceback (most recent call last):
  File "/home/airflow/.local/lib/python3.7/site-packages/airflow/models/dagbag.py", line 338, in parse
    loader.exec_module(new_module)
  File "<frozen importlib._bootstrap_external>", line 728, in exec_module
  File "<frozen importlib._bootstrap>", line 219, in _call_with_frames_removed
  File "/opt/airflow/dags/group_dag.py", line 27, in <module>
    subdag=subdag_downloads(dag.dag_id, 'downloads', args)
  File "/opt/airflow/dags/subdags/subdags_downloads.py", line 9, in subdag_downloads
    catch = args['catchup']) as dag:
TypeError: __init__() got an unexpected keyword argument 'catch'
[2024-04-17T12:00:19.195+0000] {processor.py:768} WARNING - No viable dags retrieved from /opt/airflow/dags/group_dag.py
[2024-04-17T12:00:19.528+0000] {processor.py:176} INFO - Processing /opt/airflow/dags/group_dag.py took 2.156 seconds
[2024-04-17T12:00:50.394+0000] {processor.py:154} INFO - Started process (PID=4709) to work on /opt/airflow/dags/group_dag.py
[2024-04-17T12:00:50.529+0000] {processor.py:756} INFO - Processing file /opt/airflow/dags/group_dag.py for tasks to queue
[2024-04-17T12:00:50.645+0000] {logging_mixin.py:120} INFO - [2024-04-17T12:00:50.645+0000] {dagbag.py:537} INFO - Filling up the DagBag from /opt/airflow/dags/group_dag.py
[2024-04-17T12:00:50.780+0000] {logging_mixin.py:120} INFO - [2024-04-17T12:00:50.772+0000] {dagbag.py:342} ERROR - Failed to import: /opt/airflow/dags/group_dag.py
Traceback (most recent call last):
  File "/home/airflow/.local/lib/python3.7/site-packages/airflow/models/dagbag.py", line 338, in parse
    loader.exec_module(new_module)
  File "<frozen importlib._bootstrap_external>", line 728, in exec_module
  File "<frozen importlib._bootstrap>", line 219, in _call_with_frames_removed
  File "/opt/airflow/dags/group_dag.py", line 27, in <module>
    subdag=subdag_downloads(dag.dag_id, 'downloads', args)
  File "/opt/airflow/dags/subdags/subdags_downloads.py", line 9, in subdag_downloads
    catch = args['catchup']) as dag:
TypeError: __init__() got an unexpected keyword argument 'catch'
[2024-04-17T12:00:50.783+0000] {processor.py:768} WARNING - No viable dags retrieved from /opt/airflow/dags/group_dag.py
[2024-04-17T12:00:50.835+0000] {processor.py:176} INFO - Processing /opt/airflow/dags/group_dag.py took 0.448 seconds
[2024-04-17T12:01:21.638+0000] {processor.py:154} INFO - Started process (PID=4787) to work on /opt/airflow/dags/group_dag.py
[2024-04-17T12:01:21.640+0000] {processor.py:756} INFO - Processing file /opt/airflow/dags/group_dag.py for tasks to queue
[2024-04-17T12:01:21.643+0000] {logging_mixin.py:120} INFO - [2024-04-17T12:01:21.643+0000] {dagbag.py:537} INFO - Filling up the DagBag from /opt/airflow/dags/group_dag.py
[2024-04-17T12:01:21.723+0000] {logging_mixin.py:120} INFO - [2024-04-17T12:01:21.716+0000] {dagbag.py:342} ERROR - Failed to import: /opt/airflow/dags/group_dag.py
Traceback (most recent call last):
  File "/home/airflow/.local/lib/python3.7/site-packages/airflow/models/dagbag.py", line 338, in parse
    loader.exec_module(new_module)
  File "<frozen importlib._bootstrap_external>", line 728, in exec_module
  File "<frozen importlib._bootstrap>", line 219, in _call_with_frames_removed
  File "/opt/airflow/dags/group_dag.py", line 27, in <module>
    subdag=subdag_downloads(dag.dag_id, 'downloads', args)
  File "/opt/airflow/dags/subdags/subdags_downloads.py", line 9, in subdag_downloads
    catch = args['catchup']) as dag:
TypeError: __init__() got an unexpected keyword argument 'catch'
[2024-04-17T12:01:21.726+0000] {processor.py:768} WARNING - No viable dags retrieved from /opt/airflow/dags/group_dag.py
[2024-04-17T12:01:21.763+0000] {processor.py:176} INFO - Processing /opt/airflow/dags/group_dag.py took 0.134 seconds
[2024-04-17T12:01:52.149+0000] {processor.py:154} INFO - Started process (PID=4856) to work on /opt/airflow/dags/group_dag.py
[2024-04-17T12:01:52.151+0000] {processor.py:756} INFO - Processing file /opt/airflow/dags/group_dag.py for tasks to queue
[2024-04-17T12:01:52.154+0000] {logging_mixin.py:120} INFO - [2024-04-17T12:01:52.153+0000] {dagbag.py:537} INFO - Filling up the DagBag from /opt/airflow/dags/group_dag.py
[2024-04-17T12:01:52.205+0000] {logging_mixin.py:120} INFO - [2024-04-17T12:01:52.200+0000] {dagbag.py:342} ERROR - Failed to import: /opt/airflow/dags/group_dag.py
Traceback (most recent call last):
  File "/home/airflow/.local/lib/python3.7/site-packages/airflow/models/dagbag.py", line 338, in parse
    loader.exec_module(new_module)
  File "<frozen importlib._bootstrap_external>", line 728, in exec_module
  File "<frozen importlib._bootstrap>", line 219, in _call_with_frames_removed
  File "/opt/airflow/dags/group_dag.py", line 27, in <module>
    subdag=subdag_downloads(dag.dag_id, 'downloads', args)
  File "/opt/airflow/dags/subdags/subdags_downloads.py", line 9, in subdag_downloads
    catch = args['catchup']) as dag:
TypeError: __init__() got an unexpected keyword argument 'catch'
[2024-04-17T12:01:52.212+0000] {processor.py:768} WARNING - No viable dags retrieved from /opt/airflow/dags/group_dag.py
[2024-04-17T12:01:52.261+0000] {processor.py:176} INFO - Processing /opt/airflow/dags/group_dag.py took 0.123 seconds
[2024-04-17T12:02:23.309+0000] {processor.py:154} INFO - Started process (PID=4928) to work on /opt/airflow/dags/group_dag.py
[2024-04-17T12:02:23.311+0000] {processor.py:756} INFO - Processing file /opt/airflow/dags/group_dag.py for tasks to queue
[2024-04-17T12:02:23.313+0000] {logging_mixin.py:120} INFO - [2024-04-17T12:02:23.313+0000] {dagbag.py:537} INFO - Filling up the DagBag from /opt/airflow/dags/group_dag.py
[2024-04-17T12:02:23.366+0000] {logging_mixin.py:120} INFO - [2024-04-17T12:02:23.361+0000] {dagbag.py:342} ERROR - Failed to import: /opt/airflow/dags/group_dag.py
Traceback (most recent call last):
  File "/home/airflow/.local/lib/python3.7/site-packages/airflow/models/dagbag.py", line 338, in parse
    loader.exec_module(new_module)
  File "<frozen importlib._bootstrap_external>", line 728, in exec_module
  File "<frozen importlib._bootstrap>", line 219, in _call_with_frames_removed
  File "/opt/airflow/dags/group_dag.py", line 27, in <module>
    subdag=subdag_downloads(dag.dag_id, 'downloads', args)
  File "/opt/airflow/dags/subdags/subdags_downloads.py", line 9, in subdag_downloads
    catch = args['catchup']) as dag:
TypeError: __init__() got an unexpected keyword argument 'catch'
[2024-04-17T12:02:23.369+0000] {processor.py:768} WARNING - No viable dags retrieved from /opt/airflow/dags/group_dag.py
[2024-04-17T12:02:23.405+0000] {processor.py:176} INFO - Processing /opt/airflow/dags/group_dag.py took 0.102 seconds
[2024-04-17T12:02:53.528+0000] {processor.py:154} INFO - Started process (PID=4990) to work on /opt/airflow/dags/group_dag.py
[2024-04-17T12:02:53.530+0000] {processor.py:756} INFO - Processing file /opt/airflow/dags/group_dag.py for tasks to queue
[2024-04-17T12:02:53.532+0000] {logging_mixin.py:120} INFO - [2024-04-17T12:02:53.532+0000] {dagbag.py:537} INFO - Filling up the DagBag from /opt/airflow/dags/group_dag.py
[2024-04-17T12:02:53.577+0000] {logging_mixin.py:120} INFO - [2024-04-17T12:02:53.574+0000] {dagbag.py:342} ERROR - Failed to import: /opt/airflow/dags/group_dag.py
Traceback (most recent call last):
  File "/home/airflow/.local/lib/python3.7/site-packages/airflow/models/dagbag.py", line 338, in parse
    loader.exec_module(new_module)
  File "<frozen importlib._bootstrap_external>", line 728, in exec_module
  File "<frozen importlib._bootstrap>", line 219, in _call_with_frames_removed
  File "/opt/airflow/dags/group_dag.py", line 27, in <module>
    subdag=subdag_downloads(dag.dag_id, 'downloads', args)
  File "/opt/airflow/dags/subdags/subdags_downloads.py", line 9, in subdag_downloads
    catch = args['catchup']) as dag:
TypeError: __init__() got an unexpected keyword argument 'catch'
[2024-04-17T12:02:53.579+0000] {processor.py:768} WARNING - No viable dags retrieved from /opt/airflow/dags/group_dag.py
[2024-04-17T12:02:53.616+0000] {processor.py:176} INFO - Processing /opt/airflow/dags/group_dag.py took 0.096 seconds
[2024-04-17T12:03:24.336+0000] {processor.py:154} INFO - Started process (PID=5067) to work on /opt/airflow/dags/group_dag.py
[2024-04-17T12:03:24.340+0000] {processor.py:756} INFO - Processing file /opt/airflow/dags/group_dag.py for tasks to queue
[2024-04-17T12:03:24.345+0000] {logging_mixin.py:120} INFO - [2024-04-17T12:03:24.344+0000] {dagbag.py:537} INFO - Filling up the DagBag from /opt/airflow/dags/group_dag.py
[2024-04-17T12:03:24.407+0000] {logging_mixin.py:120} INFO - [2024-04-17T12:03:24.401+0000] {dagbag.py:342} ERROR - Failed to import: /opt/airflow/dags/group_dag.py
Traceback (most recent call last):
  File "/home/airflow/.local/lib/python3.7/site-packages/airflow/models/dagbag.py", line 338, in parse
    loader.exec_module(new_module)
  File "<frozen importlib._bootstrap_external>", line 728, in exec_module
  File "<frozen importlib._bootstrap>", line 219, in _call_with_frames_removed
  File "/opt/airflow/dags/group_dag.py", line 27, in <module>
    subdag=subdag_downloads(dag.dag_id, 'downloads', args)
  File "/opt/airflow/dags/subdags/subdags_downloads.py", line 9, in subdag_downloads
    catch = args['catchup']) as dag:
TypeError: __init__() got an unexpected keyword argument 'catch'
[2024-04-17T12:03:24.409+0000] {processor.py:768} WARNING - No viable dags retrieved from /opt/airflow/dags/group_dag.py
[2024-04-17T12:03:24.460+0000] {processor.py:176} INFO - Processing /opt/airflow/dags/group_dag.py took 0.136 seconds
[2024-04-17T12:03:54.845+0000] {processor.py:154} INFO - Started process (PID=5137) to work on /opt/airflow/dags/group_dag.py
[2024-04-17T12:03:54.847+0000] {processor.py:756} INFO - Processing file /opt/airflow/dags/group_dag.py for tasks to queue
[2024-04-17T12:03:54.850+0000] {logging_mixin.py:120} INFO - [2024-04-17T12:03:54.849+0000] {dagbag.py:537} INFO - Filling up the DagBag from /opt/airflow/dags/group_dag.py
[2024-04-17T12:03:54.898+0000] {logging_mixin.py:120} INFO - [2024-04-17T12:03:54.892+0000] {dagbag.py:342} ERROR - Failed to import: /opt/airflow/dags/group_dag.py
Traceback (most recent call last):
  File "/home/airflow/.local/lib/python3.7/site-packages/airflow/models/dagbag.py", line 338, in parse
    loader.exec_module(new_module)
  File "<frozen importlib._bootstrap_external>", line 728, in exec_module
  File "<frozen importlib._bootstrap>", line 219, in _call_with_frames_removed
  File "/opt/airflow/dags/group_dag.py", line 27, in <module>
    subdag=subdag_downloads(dag.dag_id, 'downloads', args)
  File "/opt/airflow/dags/subdags/subdags_downloads.py", line 9, in subdag_downloads
    catch = args['catchup']) as dag:
TypeError: __init__() got an unexpected keyword argument 'catch'
[2024-04-17T12:03:54.899+0000] {processor.py:768} WARNING - No viable dags retrieved from /opt/airflow/dags/group_dag.py
[2024-04-17T12:03:54.938+0000] {processor.py:176} INFO - Processing /opt/airflow/dags/group_dag.py took 0.099 seconds
[2024-04-17T12:04:25.072+0000] {processor.py:154} INFO - Started process (PID=5206) to work on /opt/airflow/dags/group_dag.py
[2024-04-17T12:04:25.076+0000] {processor.py:756} INFO - Processing file /opt/airflow/dags/group_dag.py for tasks to queue
[2024-04-17T12:04:25.079+0000] {logging_mixin.py:120} INFO - [2024-04-17T12:04:25.079+0000] {dagbag.py:537} INFO - Filling up the DagBag from /opt/airflow/dags/group_dag.py
[2024-04-17T12:04:25.137+0000] {logging_mixin.py:120} INFO - [2024-04-17T12:04:25.134+0000] {dagbag.py:342} ERROR - Failed to import: /opt/airflow/dags/group_dag.py
Traceback (most recent call last):
  File "/home/airflow/.local/lib/python3.7/site-packages/airflow/models/dagbag.py", line 338, in parse
    loader.exec_module(new_module)
  File "<frozen importlib._bootstrap_external>", line 728, in exec_module
  File "<frozen importlib._bootstrap>", line 219, in _call_with_frames_removed
  File "/opt/airflow/dags/group_dag.py", line 27, in <module>
    subdag=subdag_downloads(dag.dag_id, 'downloads', args)
  File "/opt/airflow/dags/subdags/subdags_downloads.py", line 9, in subdag_downloads
    catch = args['catchup']) as dag:
TypeError: __init__() got an unexpected keyword argument 'catch'
[2024-04-17T12:04:25.139+0000] {processor.py:768} WARNING - No viable dags retrieved from /opt/airflow/dags/group_dag.py
[2024-04-17T12:04:25.192+0000] {processor.py:176} INFO - Processing /opt/airflow/dags/group_dag.py took 0.132 seconds
[2024-04-17T12:04:55.362+0000] {processor.py:154} INFO - Started process (PID=5284) to work on /opt/airflow/dags/group_dag.py
[2024-04-17T12:04:55.366+0000] {processor.py:756} INFO - Processing file /opt/airflow/dags/group_dag.py for tasks to queue
[2024-04-17T12:04:55.369+0000] {logging_mixin.py:120} INFO - [2024-04-17T12:04:55.368+0000] {dagbag.py:537} INFO - Filling up the DagBag from /opt/airflow/dags/group_dag.py
[2024-04-17T12:04:55.465+0000] {logging_mixin.py:120} INFO - [2024-04-17T12:04:55.453+0000] {dagbag.py:342} ERROR - Failed to import: /opt/airflow/dags/group_dag.py
Traceback (most recent call last):
  File "/home/airflow/.local/lib/python3.7/site-packages/airflow/models/dagbag.py", line 338, in parse
    loader.exec_module(new_module)
  File "<frozen importlib._bootstrap_external>", line 728, in exec_module
  File "<frozen importlib._bootstrap>", line 219, in _call_with_frames_removed
  File "/opt/airflow/dags/group_dag.py", line 27, in <module>
    subdag=subdag_downloads(dag.dag_id, 'downloads', args)
  File "/opt/airflow/dags/subdags/subdags_downloads.py", line 9, in subdag_downloads
    catch = args['catchup']) as dag:
TypeError: __init__() got an unexpected keyword argument 'catch'
[2024-04-17T12:04:55.470+0000] {processor.py:768} WARNING - No viable dags retrieved from /opt/airflow/dags/group_dag.py
[2024-04-17T12:04:55.540+0000] {processor.py:176} INFO - Processing /opt/airflow/dags/group_dag.py took 0.189 seconds
[2024-04-17T12:05:25.627+0000] {processor.py:154} INFO - Started process (PID=5353) to work on /opt/airflow/dags/group_dag.py
[2024-04-17T12:05:25.630+0000] {processor.py:756} INFO - Processing file /opt/airflow/dags/group_dag.py for tasks to queue
[2024-04-17T12:05:25.632+0000] {logging_mixin.py:120} INFO - [2024-04-17T12:05:25.632+0000] {dagbag.py:537} INFO - Filling up the DagBag from /opt/airflow/dags/group_dag.py
[2024-04-17T12:05:25.683+0000] {logging_mixin.py:120} INFO - [2024-04-17T12:05:25.679+0000] {dagbag.py:342} ERROR - Failed to import: /opt/airflow/dags/group_dag.py
Traceback (most recent call last):
  File "/home/airflow/.local/lib/python3.7/site-packages/airflow/models/dagbag.py", line 338, in parse
    loader.exec_module(new_module)
  File "<frozen importlib._bootstrap_external>", line 728, in exec_module
  File "<frozen importlib._bootstrap>", line 219, in _call_with_frames_removed
  File "/opt/airflow/dags/group_dag.py", line 27, in <module>
    subdag=subdag_downloads(dag.dag_id, 'downloads', args)
  File "/opt/airflow/dags/subdags/subdags_downloads.py", line 9, in subdag_downloads
    catch = args['catchup']) as dag:
TypeError: __init__() got an unexpected keyword argument 'catch'
[2024-04-17T12:05:25.684+0000] {processor.py:768} WARNING - No viable dags retrieved from /opt/airflow/dags/group_dag.py
[2024-04-17T12:05:25.731+0000] {processor.py:176} INFO - Processing /opt/airflow/dags/group_dag.py took 0.110 seconds
[2024-04-17T12:05:55.794+0000] {processor.py:154} INFO - Started process (PID=5432) to work on /opt/airflow/dags/group_dag.py
[2024-04-17T12:05:55.797+0000] {processor.py:756} INFO - Processing file /opt/airflow/dags/group_dag.py for tasks to queue
[2024-04-17T12:05:55.803+0000] {logging_mixin.py:120} INFO - [2024-04-17T12:05:55.800+0000] {dagbag.py:537} INFO - Filling up the DagBag from /opt/airflow/dags/group_dag.py
[2024-04-17T12:05:55.845+0000] {logging_mixin.py:120} INFO - [2024-04-17T12:05:55.841+0000] {dagbag.py:342} ERROR - Failed to import: /opt/airflow/dags/group_dag.py
Traceback (most recent call last):
  File "/home/airflow/.local/lib/python3.7/site-packages/airflow/models/dagbag.py", line 338, in parse
    loader.exec_module(new_module)
  File "<frozen importlib._bootstrap_external>", line 728, in exec_module
  File "<frozen importlib._bootstrap>", line 219, in _call_with_frames_removed
  File "/opt/airflow/dags/group_dag.py", line 27, in <module>
    subdag=subdag_downloads(dag.dag_id, 'downloads', args)
  File "/opt/airflow/dags/subdags/subdags_downloads.py", line 9, in subdag_downloads
    catch = args['catchup']) as dag:
TypeError: __init__() got an unexpected keyword argument 'catch'
[2024-04-17T12:05:55.846+0000] {processor.py:768} WARNING - No viable dags retrieved from /opt/airflow/dags/group_dag.py
[2024-04-17T12:05:55.880+0000] {processor.py:176} INFO - Processing /opt/airflow/dags/group_dag.py took 0.095 seconds
[2024-04-17T12:06:26.107+0000] {processor.py:154} INFO - Started process (PID=5501) to work on /opt/airflow/dags/group_dag.py
[2024-04-17T12:06:26.110+0000] {processor.py:756} INFO - Processing file /opt/airflow/dags/group_dag.py for tasks to queue
[2024-04-17T12:06:26.112+0000] {logging_mixin.py:120} INFO - [2024-04-17T12:06:26.112+0000] {dagbag.py:537} INFO - Filling up the DagBag from /opt/airflow/dags/group_dag.py
[2024-04-17T12:06:26.157+0000] {logging_mixin.py:120} INFO - [2024-04-17T12:06:26.154+0000] {dagbag.py:342} ERROR - Failed to import: /opt/airflow/dags/group_dag.py
Traceback (most recent call last):
  File "/home/airflow/.local/lib/python3.7/site-packages/airflow/models/dagbag.py", line 338, in parse
    loader.exec_module(new_module)
  File "<frozen importlib._bootstrap_external>", line 728, in exec_module
  File "<frozen importlib._bootstrap>", line 219, in _call_with_frames_removed
  File "/opt/airflow/dags/group_dag.py", line 27, in <module>
    subdag=subdag_downloads(dag.dag_id, 'downloads', args)
  File "/opt/airflow/dags/subdags/subdags_downloads.py", line 9, in subdag_downloads
    catch = args['catchup']) as dag:
TypeError: __init__() got an unexpected keyword argument 'catch'
[2024-04-17T12:06:26.158+0000] {processor.py:768} WARNING - No viable dags retrieved from /opt/airflow/dags/group_dag.py
[2024-04-17T12:06:26.197+0000] {processor.py:176} INFO - Processing /opt/airflow/dags/group_dag.py took 0.099 seconds
[2024-04-17T12:06:57.055+0000] {processor.py:154} INFO - Started process (PID=5579) to work on /opt/airflow/dags/group_dag.py
[2024-04-17T12:06:57.060+0000] {processor.py:756} INFO - Processing file /opt/airflow/dags/group_dag.py for tasks to queue
[2024-04-17T12:06:57.064+0000] {logging_mixin.py:120} INFO - [2024-04-17T12:06:57.064+0000] {dagbag.py:537} INFO - Filling up the DagBag from /opt/airflow/dags/group_dag.py
[2024-04-17T12:06:57.143+0000] {logging_mixin.py:120} INFO - [2024-04-17T12:06:57.137+0000] {dagbag.py:342} ERROR - Failed to import: /opt/airflow/dags/group_dag.py
Traceback (most recent call last):
  File "/home/airflow/.local/lib/python3.7/site-packages/airflow/models/dagbag.py", line 338, in parse
    loader.exec_module(new_module)
  File "<frozen importlib._bootstrap_external>", line 728, in exec_module
  File "<frozen importlib._bootstrap>", line 219, in _call_with_frames_removed
  File "/opt/airflow/dags/group_dag.py", line 27, in <module>
    subdag=subdag_downloads(dag.dag_id, 'downloads', args)
  File "/opt/airflow/dags/subdags/subdags_downloads.py", line 9, in subdag_downloads
    catch = args['catchup']) as dag:
TypeError: __init__() got an unexpected keyword argument 'catch'
[2024-04-17T12:06:57.145+0000] {processor.py:768} WARNING - No viable dags retrieved from /opt/airflow/dags/group_dag.py
[2024-04-17T12:06:57.189+0000] {processor.py:176} INFO - Processing /opt/airflow/dags/group_dag.py took 0.145 seconds
[2024-04-17T12:07:27.531+0000] {processor.py:154} INFO - Started process (PID=5648) to work on /opt/airflow/dags/group_dag.py
[2024-04-17T12:07:27.534+0000] {processor.py:756} INFO - Processing file /opt/airflow/dags/group_dag.py for tasks to queue
[2024-04-17T12:07:27.537+0000] {logging_mixin.py:120} INFO - [2024-04-17T12:07:27.536+0000] {dagbag.py:537} INFO - Filling up the DagBag from /opt/airflow/dags/group_dag.py
[2024-04-17T12:07:27.599+0000] {logging_mixin.py:120} INFO - [2024-04-17T12:07:27.594+0000] {dagbag.py:342} ERROR - Failed to import: /opt/airflow/dags/group_dag.py
Traceback (most recent call last):
  File "/home/airflow/.local/lib/python3.7/site-packages/airflow/models/dagbag.py", line 338, in parse
    loader.exec_module(new_module)
  File "<frozen importlib._bootstrap_external>", line 728, in exec_module
  File "<frozen importlib._bootstrap>", line 219, in _call_with_frames_removed
  File "/opt/airflow/dags/group_dag.py", line 27, in <module>
    subdag=subdag_downloads(dag.dag_id, 'downloads', args)
  File "/opt/airflow/dags/subdags/subdags_downloads.py", line 9, in subdag_downloads
    catch = args['catchup']) as dag:
TypeError: __init__() got an unexpected keyword argument 'catch'
[2024-04-17T12:07:27.601+0000] {processor.py:768} WARNING - No viable dags retrieved from /opt/airflow/dags/group_dag.py
[2024-04-17T12:07:27.650+0000] {processor.py:176} INFO - Processing /opt/airflow/dags/group_dag.py took 0.127 seconds
[2024-04-17T12:07:58.298+0000] {processor.py:154} INFO - Started process (PID=5726) to work on /opt/airflow/dags/group_dag.py
[2024-04-17T12:07:58.302+0000] {processor.py:756} INFO - Processing file /opt/airflow/dags/group_dag.py for tasks to queue
[2024-04-17T12:07:58.304+0000] {logging_mixin.py:120} INFO - [2024-04-17T12:07:58.304+0000] {dagbag.py:537} INFO - Filling up the DagBag from /opt/airflow/dags/group_dag.py
[2024-04-17T12:07:58.352+0000] {logging_mixin.py:120} INFO - [2024-04-17T12:07:58.347+0000] {dagbag.py:342} ERROR - Failed to import: /opt/airflow/dags/group_dag.py
Traceback (most recent call last):
  File "/home/airflow/.local/lib/python3.7/site-packages/airflow/models/dagbag.py", line 338, in parse
    loader.exec_module(new_module)
  File "<frozen importlib._bootstrap_external>", line 728, in exec_module
  File "<frozen importlib._bootstrap>", line 219, in _call_with_frames_removed
  File "/opt/airflow/dags/group_dag.py", line 27, in <module>
    subdag=subdag_downloads(dag.dag_id, 'downloads', args)
  File "/opt/airflow/dags/subdags/subdags_downloads.py", line 9, in subdag_downloads
    catch = args['catchup']) as dag:
TypeError: __init__() got an unexpected keyword argument 'catch'
[2024-04-17T12:07:58.354+0000] {processor.py:768} WARNING - No viable dags retrieved from /opt/airflow/dags/group_dag.py
[2024-04-17T12:07:58.401+0000] {processor.py:176} INFO - Processing /opt/airflow/dags/group_dag.py took 0.110 seconds
[2024-04-17T12:08:28.618+0000] {processor.py:154} INFO - Started process (PID=5793) to work on /opt/airflow/dags/group_dag.py
[2024-04-17T12:08:28.623+0000] {processor.py:756} INFO - Processing file /opt/airflow/dags/group_dag.py for tasks to queue
[2024-04-17T12:08:28.627+0000] {logging_mixin.py:120} INFO - [2024-04-17T12:08:28.626+0000] {dagbag.py:537} INFO - Filling up the DagBag from /opt/airflow/dags/group_dag.py
[2024-04-17T12:08:28.682+0000] {logging_mixin.py:120} INFO - [2024-04-17T12:08:28.677+0000] {dagbag.py:342} ERROR - Failed to import: /opt/airflow/dags/group_dag.py
Traceback (most recent call last):
  File "/home/airflow/.local/lib/python3.7/site-packages/airflow/models/dagbag.py", line 338, in parse
    loader.exec_module(new_module)
  File "<frozen importlib._bootstrap_external>", line 728, in exec_module
  File "<frozen importlib._bootstrap>", line 219, in _call_with_frames_removed
  File "/opt/airflow/dags/group_dag.py", line 27, in <module>
    subdag=subdag_downloads(dag.dag_id, 'downloads', args)
  File "/opt/airflow/dags/subdags/subdags_downloads.py", line 9, in subdag_downloads
    catch = args['catchup']) as dag:
TypeError: __init__() got an unexpected keyword argument 'catch'
[2024-04-17T12:08:28.685+0000] {processor.py:768} WARNING - No viable dags retrieved from /opt/airflow/dags/group_dag.py
[2024-04-17T12:08:28.740+0000] {processor.py:176} INFO - Processing /opt/airflow/dags/group_dag.py took 0.131 seconds
[2024-04-17T12:08:59.047+0000] {processor.py:154} INFO - Started process (PID=5873) to work on /opt/airflow/dags/group_dag.py
[2024-04-17T12:08:59.051+0000] {processor.py:756} INFO - Processing file /opt/airflow/dags/group_dag.py for tasks to queue
[2024-04-17T12:08:59.054+0000] {logging_mixin.py:120} INFO - [2024-04-17T12:08:59.054+0000] {dagbag.py:537} INFO - Filling up the DagBag from /opt/airflow/dags/group_dag.py
[2024-04-17T12:08:59.123+0000] {logging_mixin.py:120} INFO - [2024-04-17T12:08:59.117+0000] {dagbag.py:342} ERROR - Failed to import: /opt/airflow/dags/group_dag.py
Traceback (most recent call last):
  File "/home/airflow/.local/lib/python3.7/site-packages/airflow/models/dagbag.py", line 338, in parse
    loader.exec_module(new_module)
  File "<frozen importlib._bootstrap_external>", line 728, in exec_module
  File "<frozen importlib._bootstrap>", line 219, in _call_with_frames_removed
  File "/opt/airflow/dags/group_dag.py", line 27, in <module>
    subdag=subdag_downloads(dag.dag_id, 'downloads', args)
  File "/opt/airflow/dags/subdags/subdags_downloads.py", line 9, in subdag_downloads
    catch = args['catchup']) as dag:
TypeError: __init__() got an unexpected keyword argument 'catch'
[2024-04-17T12:08:59.125+0000] {processor.py:768} WARNING - No viable dags retrieved from /opt/airflow/dags/group_dag.py
[2024-04-17T12:08:59.168+0000] {processor.py:176} INFO - Processing /opt/airflow/dags/group_dag.py took 0.132 seconds
[2024-04-17T12:09:29.302+0000] {processor.py:154} INFO - Started process (PID=5938) to work on /opt/airflow/dags/group_dag.py
[2024-04-17T12:09:29.304+0000] {processor.py:756} INFO - Processing file /opt/airflow/dags/group_dag.py for tasks to queue
[2024-04-17T12:09:29.306+0000] {logging_mixin.py:120} INFO - [2024-04-17T12:09:29.306+0000] {dagbag.py:537} INFO - Filling up the DagBag from /opt/airflow/dags/group_dag.py
[2024-04-17T12:09:29.362+0000] {logging_mixin.py:120} INFO - [2024-04-17T12:09:29.357+0000] {dagbag.py:342} ERROR - Failed to import: /opt/airflow/dags/group_dag.py
Traceback (most recent call last):
  File "/home/airflow/.local/lib/python3.7/site-packages/airflow/models/dagbag.py", line 338, in parse
    loader.exec_module(new_module)
  File "<frozen importlib._bootstrap_external>", line 728, in exec_module
  File "<frozen importlib._bootstrap>", line 219, in _call_with_frames_removed
  File "/opt/airflow/dags/group_dag.py", line 27, in <module>
    subdag=subdag_downloads(dag.dag_id, 'downloads', args)
  File "/opt/airflow/dags/subdags/subdags_downloads.py", line 9, in subdag_downloads
    catch = args['catchup']) as dag:
TypeError: __init__() got an unexpected keyword argument 'catch'
[2024-04-17T12:09:29.364+0000] {processor.py:768} WARNING - No viable dags retrieved from /opt/airflow/dags/group_dag.py
[2024-04-17T12:09:29.421+0000] {processor.py:176} INFO - Processing /opt/airflow/dags/group_dag.py took 0.129 seconds
[2024-04-17T12:09:59.700+0000] {processor.py:154} INFO - Started process (PID=6007) to work on /opt/airflow/dags/group_dag.py
[2024-04-17T12:09:59.704+0000] {processor.py:756} INFO - Processing file /opt/airflow/dags/group_dag.py for tasks to queue
[2024-04-17T12:09:59.706+0000] {logging_mixin.py:120} INFO - [2024-04-17T12:09:59.705+0000] {dagbag.py:537} INFO - Filling up the DagBag from /opt/airflow/dags/group_dag.py
[2024-04-17T12:09:59.753+0000] {logging_mixin.py:120} INFO - [2024-04-17T12:09:59.745+0000] {dagbag.py:342} ERROR - Failed to import: /opt/airflow/dags/group_dag.py
Traceback (most recent call last):
  File "/home/airflow/.local/lib/python3.7/site-packages/airflow/models/dagbag.py", line 338, in parse
    loader.exec_module(new_module)
  File "<frozen importlib._bootstrap_external>", line 728, in exec_module
  File "<frozen importlib._bootstrap>", line 219, in _call_with_frames_removed
  File "/opt/airflow/dags/group_dag.py", line 27, in <module>
    subdag=subdag_downloads(dag.dag_id, 'downloads', args)
  File "/opt/airflow/dags/subdags/subdags_downloads.py", line 9, in subdag_downloads
    catch = args['catchup']) as dag:
TypeError: __init__() got an unexpected keyword argument 'catch'
[2024-04-17T12:09:59.755+0000] {processor.py:768} WARNING - No viable dags retrieved from /opt/airflow/dags/group_dag.py
[2024-04-17T12:09:59.798+0000] {processor.py:176} INFO - Processing /opt/airflow/dags/group_dag.py took 0.106 seconds
[2024-04-17T12:10:29.957+0000] {processor.py:154} INFO - Started process (PID=6086) to work on /opt/airflow/dags/group_dag.py
[2024-04-17T12:10:29.960+0000] {processor.py:756} INFO - Processing file /opt/airflow/dags/group_dag.py for tasks to queue
[2024-04-17T12:10:29.963+0000] {logging_mixin.py:120} INFO - [2024-04-17T12:10:29.963+0000] {dagbag.py:537} INFO - Filling up the DagBag from /opt/airflow/dags/group_dag.py
[2024-04-17T12:10:30.028+0000] {logging_mixin.py:120} INFO - [2024-04-17T12:10:30.021+0000] {dagbag.py:342} ERROR - Failed to import: /opt/airflow/dags/group_dag.py
Traceback (most recent call last):
  File "/home/airflow/.local/lib/python3.7/site-packages/airflow/models/dagbag.py", line 338, in parse
    loader.exec_module(new_module)
  File "<frozen importlib._bootstrap_external>", line 728, in exec_module
  File "<frozen importlib._bootstrap>", line 219, in _call_with_frames_removed
  File "/opt/airflow/dags/group_dag.py", line 27, in <module>
    subdag=subdag_downloads(dag.dag_id, 'downloads', args)
  File "/opt/airflow/dags/subdags/subdags_downloads.py", line 9, in subdag_downloads
    catch = args['catchup']) as dag:
TypeError: __init__() got an unexpected keyword argument 'catch'
[2024-04-17T12:10:30.030+0000] {processor.py:768} WARNING - No viable dags retrieved from /opt/airflow/dags/group_dag.py
[2024-04-17T12:10:30.094+0000] {processor.py:176} INFO - Processing /opt/airflow/dags/group_dag.py took 0.147 seconds
[2024-04-17T12:11:00.649+0000] {processor.py:154} INFO - Started process (PID=6153) to work on /opt/airflow/dags/group_dag.py
[2024-04-17T12:11:00.652+0000] {processor.py:756} INFO - Processing file /opt/airflow/dags/group_dag.py for tasks to queue
[2024-04-17T12:11:00.655+0000] {logging_mixin.py:120} INFO - [2024-04-17T12:11:00.655+0000] {dagbag.py:537} INFO - Filling up the DagBag from /opt/airflow/dags/group_dag.py
[2024-04-17T12:11:00.708+0000] {logging_mixin.py:120} INFO - [2024-04-17T12:11:00.703+0000] {dagbag.py:342} ERROR - Failed to import: /opt/airflow/dags/group_dag.py
Traceback (most recent call last):
  File "/home/airflow/.local/lib/python3.7/site-packages/airflow/models/dagbag.py", line 338, in parse
    loader.exec_module(new_module)
  File "<frozen importlib._bootstrap_external>", line 728, in exec_module
  File "<frozen importlib._bootstrap>", line 219, in _call_with_frames_removed
  File "/opt/airflow/dags/group_dag.py", line 27, in <module>
    subdag=subdag_downloads(dag.dag_id, 'downloads', args)
  File "/opt/airflow/dags/subdags/subdags_downloads.py", line 9, in subdag_downloads
    catch = args['catchup']) as dag:
TypeError: __init__() got an unexpected keyword argument 'catch'
[2024-04-17T12:11:00.710+0000] {processor.py:768} WARNING - No viable dags retrieved from /opt/airflow/dags/group_dag.py
[2024-04-17T12:11:00.740+0000] {processor.py:176} INFO - Processing /opt/airflow/dags/group_dag.py took 0.097 seconds
[2024-04-17T12:11:31.155+0000] {processor.py:154} INFO - Started process (PID=6230) to work on /opt/airflow/dags/group_dag.py
[2024-04-17T12:11:31.158+0000] {processor.py:756} INFO - Processing file /opt/airflow/dags/group_dag.py for tasks to queue
[2024-04-17T12:11:31.160+0000] {logging_mixin.py:120} INFO - [2024-04-17T12:11:31.160+0000] {dagbag.py:537} INFO - Filling up the DagBag from /opt/airflow/dags/group_dag.py
[2024-04-17T12:11:31.210+0000] {logging_mixin.py:120} INFO - [2024-04-17T12:11:31.206+0000] {dagbag.py:342} ERROR - Failed to import: /opt/airflow/dags/group_dag.py
Traceback (most recent call last):
  File "/home/airflow/.local/lib/python3.7/site-packages/airflow/models/dagbag.py", line 338, in parse
    loader.exec_module(new_module)
  File "<frozen importlib._bootstrap_external>", line 728, in exec_module
  File "<frozen importlib._bootstrap>", line 219, in _call_with_frames_removed
  File "/opt/airflow/dags/group_dag.py", line 27, in <module>
    subdag=subdag_downloads(dag.dag_id, 'downloads', args)
  File "/opt/airflow/dags/subdags/subdags_downloads.py", line 9, in subdag_downloads
    catch = args['catchup']) as dag:
TypeError: __init__() got an unexpected keyword argument 'catch'
[2024-04-17T12:11:31.213+0000] {processor.py:768} WARNING - No viable dags retrieved from /opt/airflow/dags/group_dag.py
[2024-04-17T12:11:31.272+0000] {processor.py:176} INFO - Processing /opt/airflow/dags/group_dag.py took 0.124 seconds
[2024-04-17T12:12:01.618+0000] {processor.py:154} INFO - Started process (PID=6299) to work on /opt/airflow/dags/group_dag.py
[2024-04-17T12:12:01.623+0000] {processor.py:756} INFO - Processing file /opt/airflow/dags/group_dag.py for tasks to queue
[2024-04-17T12:12:01.626+0000] {logging_mixin.py:120} INFO - [2024-04-17T12:12:01.626+0000] {dagbag.py:537} INFO - Filling up the DagBag from /opt/airflow/dags/group_dag.py
[2024-04-17T12:12:01.701+0000] {logging_mixin.py:120} INFO - [2024-04-17T12:12:01.693+0000] {dagbag.py:342} ERROR - Failed to import: /opt/airflow/dags/group_dag.py
Traceback (most recent call last):
  File "/home/airflow/.local/lib/python3.7/site-packages/airflow/models/dagbag.py", line 338, in parse
    loader.exec_module(new_module)
  File "<frozen importlib._bootstrap_external>", line 728, in exec_module
  File "<frozen importlib._bootstrap>", line 219, in _call_with_frames_removed
  File "/opt/airflow/dags/group_dag.py", line 27, in <module>
    subdag=subdag_downloads(dag.dag_id, 'downloads', args)
  File "/opt/airflow/dags/subdags/subdags_downloads.py", line 9, in subdag_downloads
    catch = args['catchup']) as dag:
TypeError: __init__() got an unexpected keyword argument 'catch'
[2024-04-17T12:12:01.703+0000] {processor.py:768} WARNING - No viable dags retrieved from /opt/airflow/dags/group_dag.py
[2024-04-17T12:12:01.773+0000] {processor.py:176} INFO - Processing /opt/airflow/dags/group_dag.py took 0.165 seconds
[2024-04-17T12:12:32.532+0000] {processor.py:154} INFO - Started process (PID=6378) to work on /opt/airflow/dags/group_dag.py
[2024-04-17T12:12:32.535+0000] {processor.py:756} INFO - Processing file /opt/airflow/dags/group_dag.py for tasks to queue
[2024-04-17T12:12:32.539+0000] {logging_mixin.py:120} INFO - [2024-04-17T12:12:32.538+0000] {dagbag.py:537} INFO - Filling up the DagBag from /opt/airflow/dags/group_dag.py
[2024-04-17T12:12:32.593+0000] {logging_mixin.py:120} INFO - [2024-04-17T12:12:32.588+0000] {dagbag.py:342} ERROR - Failed to import: /opt/airflow/dags/group_dag.py
Traceback (most recent call last):
  File "/home/airflow/.local/lib/python3.7/site-packages/airflow/models/dagbag.py", line 338, in parse
    loader.exec_module(new_module)
  File "<frozen importlib._bootstrap_external>", line 728, in exec_module
  File "<frozen importlib._bootstrap>", line 219, in _call_with_frames_removed
  File "/opt/airflow/dags/group_dag.py", line 27, in <module>
    subdag=subdag_downloads(dag.dag_id, 'downloads', args)
  File "/opt/airflow/dags/subdags/subdags_downloads.py", line 9, in subdag_downloads
    catch = args['catchup']) as dag:
TypeError: __init__() got an unexpected keyword argument 'catch'
[2024-04-17T12:12:32.594+0000] {processor.py:768} WARNING - No viable dags retrieved from /opt/airflow/dags/group_dag.py
[2024-04-17T12:12:32.642+0000] {processor.py:176} INFO - Processing /opt/airflow/dags/group_dag.py took 0.116 seconds
[2024-04-17T12:13:02.979+0000] {processor.py:154} INFO - Started process (PID=6447) to work on /opt/airflow/dags/group_dag.py
[2024-04-17T12:13:02.982+0000] {processor.py:756} INFO - Processing file /opt/airflow/dags/group_dag.py for tasks to queue
[2024-04-17T12:13:03.003+0000] {logging_mixin.py:120} INFO - [2024-04-17T12:13:03.002+0000] {dagbag.py:537} INFO - Filling up the DagBag from /opt/airflow/dags/group_dag.py
[2024-04-17T12:13:03.099+0000] {logging_mixin.py:120} INFO - [2024-04-17T12:13:03.095+0000] {dagbag.py:342} ERROR - Failed to import: /opt/airflow/dags/group_dag.py
Traceback (most recent call last):
  File "/home/airflow/.local/lib/python3.7/site-packages/airflow/models/dagbag.py", line 338, in parse
    loader.exec_module(new_module)
  File "<frozen importlib._bootstrap_external>", line 728, in exec_module
  File "<frozen importlib._bootstrap>", line 219, in _call_with_frames_removed
  File "/opt/airflow/dags/group_dag.py", line 27, in <module>
    subdag=subdag_downloads(dag.dag_id, 'downloads', args)
  File "/opt/airflow/dags/subdags/subdags_downloads.py", line 9, in subdag_downloads
    catch = args['catchup']) as dag:
TypeError: __init__() got an unexpected keyword argument 'catch'
[2024-04-17T12:13:03.100+0000] {processor.py:768} WARNING - No viable dags retrieved from /opt/airflow/dags/group_dag.py
[2024-04-17T12:13:03.140+0000] {processor.py:176} INFO - Processing /opt/airflow/dags/group_dag.py took 0.174 seconds
[2024-04-17T12:13:33.333+0000] {processor.py:154} INFO - Started process (PID=6527) to work on /opt/airflow/dags/group_dag.py
[2024-04-17T12:13:33.337+0000] {processor.py:756} INFO - Processing file /opt/airflow/dags/group_dag.py for tasks to queue
[2024-04-17T12:13:33.339+0000] {logging_mixin.py:120} INFO - [2024-04-17T12:13:33.339+0000] {dagbag.py:537} INFO - Filling up the DagBag from /opt/airflow/dags/group_dag.py
[2024-04-17T12:13:33.407+0000] {logging_mixin.py:120} INFO - [2024-04-17T12:13:33.403+0000] {dagbag.py:342} ERROR - Failed to import: /opt/airflow/dags/group_dag.py
Traceback (most recent call last):
  File "/home/airflow/.local/lib/python3.7/site-packages/airflow/models/dagbag.py", line 338, in parse
    loader.exec_module(new_module)
  File "<frozen importlib._bootstrap_external>", line 728, in exec_module
  File "<frozen importlib._bootstrap>", line 219, in _call_with_frames_removed
  File "/opt/airflow/dags/group_dag.py", line 27, in <module>
    subdag=subdag_downloads(dag.dag_id, 'downloads', args)
  File "/opt/airflow/dags/subdags/subdags_downloads.py", line 9, in subdag_downloads
    catch = args['catchup']) as dag:
TypeError: __init__() got an unexpected keyword argument 'catch'
[2024-04-17T12:13:33.409+0000] {processor.py:768} WARNING - No viable dags retrieved from /opt/airflow/dags/group_dag.py
[2024-04-17T12:13:33.449+0000] {processor.py:176} INFO - Processing /opt/airflow/dags/group_dag.py took 0.128 seconds
[2024-04-17T12:14:05.004+0000] {processor.py:154} INFO - Started process (PID=6595) to work on /opt/airflow/dags/group_dag.py
[2024-04-17T12:14:05.007+0000] {processor.py:756} INFO - Processing file /opt/airflow/dags/group_dag.py for tasks to queue
[2024-04-17T12:14:05.010+0000] {logging_mixin.py:120} INFO - [2024-04-17T12:14:05.010+0000] {dagbag.py:537} INFO - Filling up the DagBag from /opt/airflow/dags/group_dag.py
[2024-04-17T12:14:05.073+0000] {logging_mixin.py:120} INFO - [2024-04-17T12:14:05.069+0000] {dagbag.py:342} ERROR - Failed to import: /opt/airflow/dags/group_dag.py
Traceback (most recent call last):
  File "/home/airflow/.local/lib/python3.7/site-packages/airflow/models/dagbag.py", line 338, in parse
    loader.exec_module(new_module)
  File "<frozen importlib._bootstrap_external>", line 728, in exec_module
  File "<frozen importlib._bootstrap>", line 219, in _call_with_frames_removed
  File "/opt/airflow/dags/group_dag.py", line 27, in <module>
    subdag=subdag_downloads(dag.dag_id, 'downloads', args)
  File "/opt/airflow/dags/subdags/subdags_downloads.py", line 9, in subdag_downloads
    catch = args['catchup']) as dag:
TypeError: __init__() got an unexpected keyword argument 'catch'
[2024-04-17T12:14:05.074+0000] {processor.py:768} WARNING - No viable dags retrieved from /opt/airflow/dags/group_dag.py
[2024-04-17T12:14:05.135+0000] {processor.py:176} INFO - Processing /opt/airflow/dags/group_dag.py took 0.162 seconds
[2024-04-17T12:14:35.213+0000] {processor.py:154} INFO - Started process (PID=6673) to work on /opt/airflow/dags/group_dag.py
[2024-04-17T12:14:35.219+0000] {processor.py:756} INFO - Processing file /opt/airflow/dags/group_dag.py for tasks to queue
[2024-04-17T12:14:35.223+0000] {logging_mixin.py:120} INFO - [2024-04-17T12:14:35.223+0000] {dagbag.py:537} INFO - Filling up the DagBag from /opt/airflow/dags/group_dag.py
[2024-04-17T12:14:35.284+0000] {logging_mixin.py:120} INFO - [2024-04-17T12:14:35.279+0000] {dagbag.py:342} ERROR - Failed to import: /opt/airflow/dags/group_dag.py
Traceback (most recent call last):
  File "/home/airflow/.local/lib/python3.7/site-packages/airflow/models/dagbag.py", line 338, in parse
    loader.exec_module(new_module)
  File "<frozen importlib._bootstrap_external>", line 728, in exec_module
  File "<frozen importlib._bootstrap>", line 219, in _call_with_frames_removed
  File "/opt/airflow/dags/group_dag.py", line 27, in <module>
    subdag=subdag_downloads(dag.dag_id, 'downloads', args)
  File "/opt/airflow/dags/subdags/subdags_downloads.py", line 9, in subdag_downloads
    catch = args['catchup']) as dag:
TypeError: __init__() got an unexpected keyword argument 'catch'
[2024-04-17T12:14:35.286+0000] {processor.py:768} WARNING - No viable dags retrieved from /opt/airflow/dags/group_dag.py
[2024-04-17T12:14:35.338+0000] {processor.py:176} INFO - Processing /opt/airflow/dags/group_dag.py took 0.134 seconds
[2024-04-17T12:15:06.074+0000] {processor.py:154} INFO - Started process (PID=6742) to work on /opt/airflow/dags/group_dag.py
[2024-04-17T12:15:06.078+0000] {processor.py:756} INFO - Processing file /opt/airflow/dags/group_dag.py for tasks to queue
[2024-04-17T12:15:06.086+0000] {logging_mixin.py:120} INFO - [2024-04-17T12:15:06.086+0000] {dagbag.py:537} INFO - Filling up the DagBag from /opt/airflow/dags/group_dag.py
[2024-04-17T12:15:06.149+0000] {logging_mixin.py:120} INFO - [2024-04-17T12:15:06.145+0000] {dagbag.py:342} ERROR - Failed to import: /opt/airflow/dags/group_dag.py
Traceback (most recent call last):
  File "/home/airflow/.local/lib/python3.7/site-packages/airflow/models/dagbag.py", line 338, in parse
    loader.exec_module(new_module)
  File "<frozen importlib._bootstrap_external>", line 728, in exec_module
  File "<frozen importlib._bootstrap>", line 219, in _call_with_frames_removed
  File "/opt/airflow/dags/group_dag.py", line 27, in <module>
    subdag=subdag_downloads(dag.dag_id, 'downloads', args)
  File "/opt/airflow/dags/subdags/subdags_downloads.py", line 9, in subdag_downloads
    catch = args['catchup']) as dag:
TypeError: __init__() got an unexpected keyword argument 'catch'
[2024-04-17T12:15:06.151+0000] {processor.py:768} WARNING - No viable dags retrieved from /opt/airflow/dags/group_dag.py
[2024-04-17T12:15:06.205+0000] {processor.py:176} INFO - Processing /opt/airflow/dags/group_dag.py took 0.142 seconds
[2024-04-17T12:15:36.971+0000] {processor.py:154} INFO - Started process (PID=6817) to work on /opt/airflow/dags/group_dag.py
[2024-04-17T12:15:36.978+0000] {processor.py:756} INFO - Processing file /opt/airflow/dags/group_dag.py for tasks to queue
[2024-04-17T12:15:36.982+0000] {logging_mixin.py:120} INFO - [2024-04-17T12:15:36.981+0000] {dagbag.py:537} INFO - Filling up the DagBag from /opt/airflow/dags/group_dag.py
[2024-04-17T12:15:37.095+0000] {logging_mixin.py:120} INFO - [2024-04-17T12:15:37.081+0000] {dagbag.py:342} ERROR - Failed to import: /opt/airflow/dags/group_dag.py
Traceback (most recent call last):
  File "/home/airflow/.local/lib/python3.7/site-packages/airflow/models/dagbag.py", line 338, in parse
    loader.exec_module(new_module)
  File "<frozen importlib._bootstrap_external>", line 728, in exec_module
  File "<frozen importlib._bootstrap>", line 219, in _call_with_frames_removed
  File "/opt/airflow/dags/group_dag.py", line 27, in <module>
    subdag=subdag_downloads(dag.dag_id, 'downloads', args)
  File "/opt/airflow/dags/subdags/subdags_downloads.py", line 9, in subdag_downloads
    catch = args['catchup']) as dag:
TypeError: __init__() got an unexpected keyword argument 'catch'
[2024-04-17T12:15:37.101+0000] {processor.py:768} WARNING - No viable dags retrieved from /opt/airflow/dags/group_dag.py
[2024-04-17T12:15:37.187+0000] {processor.py:176} INFO - Processing /opt/airflow/dags/group_dag.py took 0.234 seconds
[2024-04-17T12:16:07.602+0000] {processor.py:154} INFO - Started process (PID=6884) to work on /opt/airflow/dags/group_dag.py
[2024-04-17T12:16:07.606+0000] {processor.py:756} INFO - Processing file /opt/airflow/dags/group_dag.py for tasks to queue
[2024-04-17T12:16:07.608+0000] {logging_mixin.py:120} INFO - [2024-04-17T12:16:07.608+0000] {dagbag.py:537} INFO - Filling up the DagBag from /opt/airflow/dags/group_dag.py
[2024-04-17T12:16:07.654+0000] {logging_mixin.py:120} INFO - [2024-04-17T12:16:07.651+0000] {dagbag.py:342} ERROR - Failed to import: /opt/airflow/dags/group_dag.py
Traceback (most recent call last):
  File "/home/airflow/.local/lib/python3.7/site-packages/airflow/models/dagbag.py", line 338, in parse
    loader.exec_module(new_module)
  File "<frozen importlib._bootstrap_external>", line 728, in exec_module
  File "<frozen importlib._bootstrap>", line 219, in _call_with_frames_removed
  File "/opt/airflow/dags/group_dag.py", line 27, in <module>
    subdag=subdag_downloads(dag.dag_id, 'downloads', args)
  File "/opt/airflow/dags/subdags/subdags_downloads.py", line 9, in subdag_downloads
    catch = args['catchup']) as dag:
TypeError: __init__() got an unexpected keyword argument 'catch'
[2024-04-17T12:16:07.656+0000] {processor.py:768} WARNING - No viable dags retrieved from /opt/airflow/dags/group_dag.py
[2024-04-17T12:16:07.697+0000] {processor.py:176} INFO - Processing /opt/airflow/dags/group_dag.py took 0.101 seconds
[2024-04-17T12:16:38.211+0000] {processor.py:154} INFO - Started process (PID=6960) to work on /opt/airflow/dags/group_dag.py
[2024-04-17T12:16:38.214+0000] {processor.py:756} INFO - Processing file /opt/airflow/dags/group_dag.py for tasks to queue
[2024-04-17T12:16:38.219+0000] {logging_mixin.py:120} INFO - [2024-04-17T12:16:38.219+0000] {dagbag.py:537} INFO - Filling up the DagBag from /opt/airflow/dags/group_dag.py
[2024-04-17T12:16:38.332+0000] {logging_mixin.py:120} INFO - [2024-04-17T12:16:38.324+0000] {dagbag.py:342} ERROR - Failed to import: /opt/airflow/dags/group_dag.py
Traceback (most recent call last):
  File "/home/airflow/.local/lib/python3.7/site-packages/airflow/models/dagbag.py", line 338, in parse
    loader.exec_module(new_module)
  File "<frozen importlib._bootstrap_external>", line 728, in exec_module
  File "<frozen importlib._bootstrap>", line 219, in _call_with_frames_removed
  File "/opt/airflow/dags/group_dag.py", line 27, in <module>
    subdag=subdag_downloads(dag.dag_id, 'downloads', args)
  File "/opt/airflow/dags/subdags/subdags_downloads.py", line 9, in subdag_downloads
    catch = args['catchup']) as dag:
TypeError: __init__() got an unexpected keyword argument 'catch'
[2024-04-17T12:16:38.338+0000] {processor.py:768} WARNING - No viable dags retrieved from /opt/airflow/dags/group_dag.py
[2024-04-17T12:16:38.411+0000] {processor.py:176} INFO - Processing /opt/airflow/dags/group_dag.py took 0.230 seconds
[2024-04-17T12:17:08.908+0000] {processor.py:154} INFO - Started process (PID=7030) to work on /opt/airflow/dags/group_dag.py
[2024-04-17T12:17:08.912+0000] {processor.py:756} INFO - Processing file /opt/airflow/dags/group_dag.py for tasks to queue
[2024-04-17T12:17:08.915+0000] {logging_mixin.py:120} INFO - [2024-04-17T12:17:08.914+0000] {dagbag.py:537} INFO - Filling up the DagBag from /opt/airflow/dags/group_dag.py
[2024-04-17T12:17:08.963+0000] {logging_mixin.py:120} INFO - [2024-04-17T12:17:08.960+0000] {dagbag.py:342} ERROR - Failed to import: /opt/airflow/dags/group_dag.py
Traceback (most recent call last):
  File "/home/airflow/.local/lib/python3.7/site-packages/airflow/models/dagbag.py", line 338, in parse
    loader.exec_module(new_module)
  File "<frozen importlib._bootstrap_external>", line 728, in exec_module
  File "<frozen importlib._bootstrap>", line 219, in _call_with_frames_removed
  File "/opt/airflow/dags/group_dag.py", line 27, in <module>
    subdag=subdag_downloads(dag.dag_id, 'downloads', args)
  File "/opt/airflow/dags/subdags/subdags_downloads.py", line 9, in subdag_downloads
    catch = args['catchup']) as dag:
TypeError: __init__() got an unexpected keyword argument 'catch'
[2024-04-17T12:17:08.965+0000] {processor.py:768} WARNING - No viable dags retrieved from /opt/airflow/dags/group_dag.py
[2024-04-17T12:17:09.007+0000] {processor.py:176} INFO - Processing /opt/airflow/dags/group_dag.py took 0.107 seconds
[2024-04-17T12:17:39.254+0000] {processor.py:154} INFO - Started process (PID=7108) to work on /opt/airflow/dags/group_dag.py
[2024-04-17T12:17:39.260+0000] {processor.py:756} INFO - Processing file /opt/airflow/dags/group_dag.py for tasks to queue
[2024-04-17T12:17:39.262+0000] {logging_mixin.py:120} INFO - [2024-04-17T12:17:39.262+0000] {dagbag.py:537} INFO - Filling up the DagBag from /opt/airflow/dags/group_dag.py
[2024-04-17T12:17:39.360+0000] {logging_mixin.py:120} INFO - [2024-04-17T12:17:39.343+0000] {dagbag.py:342} ERROR - Failed to import: /opt/airflow/dags/group_dag.py
Traceback (most recent call last):
  File "/home/airflow/.local/lib/python3.7/site-packages/airflow/models/dagbag.py", line 338, in parse
    loader.exec_module(new_module)
  File "<frozen importlib._bootstrap_external>", line 728, in exec_module
  File "<frozen importlib._bootstrap>", line 219, in _call_with_frames_removed
  File "/opt/airflow/dags/group_dag.py", line 27, in <module>
    subdag=subdag_downloads(dag.dag_id, 'downloads', args)
  File "/opt/airflow/dags/subdags/subdags_downloads.py", line 9, in subdag_downloads
    catch = args['catchup']) as dag:
TypeError: __init__() got an unexpected keyword argument 'catch'
[2024-04-17T12:17:39.361+0000] {processor.py:768} WARNING - No viable dags retrieved from /opt/airflow/dags/group_dag.py
[2024-04-17T12:17:39.447+0000] {processor.py:176} INFO - Processing /opt/airflow/dags/group_dag.py took 0.202 seconds
[2024-04-17T12:18:10.079+0000] {processor.py:154} INFO - Started process (PID=7177) to work on /opt/airflow/dags/group_dag.py
[2024-04-17T12:18:10.082+0000] {processor.py:756} INFO - Processing file /opt/airflow/dags/group_dag.py for tasks to queue
[2024-04-17T12:18:10.086+0000] {logging_mixin.py:120} INFO - [2024-04-17T12:18:10.085+0000] {dagbag.py:537} INFO - Filling up the DagBag from /opt/airflow/dags/group_dag.py
[2024-04-17T12:18:10.173+0000] {logging_mixin.py:120} INFO - [2024-04-17T12:18:10.161+0000] {dagbag.py:342} ERROR - Failed to import: /opt/airflow/dags/group_dag.py
Traceback (most recent call last):
  File "/home/airflow/.local/lib/python3.7/site-packages/airflow/models/dagbag.py", line 338, in parse
    loader.exec_module(new_module)
  File "<frozen importlib._bootstrap_external>", line 728, in exec_module
  File "<frozen importlib._bootstrap>", line 219, in _call_with_frames_removed
  File "/opt/airflow/dags/group_dag.py", line 27, in <module>
    subdag=subdag_downloads(dag.dag_id, 'downloads', args)
  File "/opt/airflow/dags/subdags/subdags_downloads.py", line 9, in subdag_downloads
    catch = args['catchup']) as dag:
TypeError: __init__() got an unexpected keyword argument 'catch'
[2024-04-17T12:18:10.174+0000] {processor.py:768} WARNING - No viable dags retrieved from /opt/airflow/dags/group_dag.py
[2024-04-17T12:18:10.229+0000] {processor.py:176} INFO - Processing /opt/airflow/dags/group_dag.py took 0.171 seconds
[2024-04-17T12:18:40.852+0000] {processor.py:154} INFO - Started process (PID=7245) to work on /opt/airflow/dags/group_dag.py
[2024-04-17T12:18:40.856+0000] {processor.py:756} INFO - Processing file /opt/airflow/dags/group_dag.py for tasks to queue
[2024-04-17T12:18:40.859+0000] {logging_mixin.py:120} INFO - [2024-04-17T12:18:40.858+0000] {dagbag.py:537} INFO - Filling up the DagBag from /opt/airflow/dags/group_dag.py
[2024-04-17T12:18:40.927+0000] {logging_mixin.py:120} INFO - [2024-04-17T12:18:40.921+0000] {dagbag.py:342} ERROR - Failed to import: /opt/airflow/dags/group_dag.py
Traceback (most recent call last):
  File "/home/airflow/.local/lib/python3.7/site-packages/airflow/models/dagbag.py", line 338, in parse
    loader.exec_module(new_module)
  File "<frozen importlib._bootstrap_external>", line 728, in exec_module
  File "<frozen importlib._bootstrap>", line 219, in _call_with_frames_removed
  File "/opt/airflow/dags/group_dag.py", line 27, in <module>
    subdag=subdag_downloads(dag.dag_id, 'downloads', args)
  File "/opt/airflow/dags/subdags/subdags_downloads.py", line 9, in subdag_downloads
    catch = args['catchup']) as dag:
TypeError: __init__() got an unexpected keyword argument 'catch'
[2024-04-17T12:18:40.931+0000] {processor.py:768} WARNING - No viable dags retrieved from /opt/airflow/dags/group_dag.py
[2024-04-17T12:18:40.973+0000] {processor.py:176} INFO - Processing /opt/airflow/dags/group_dag.py took 0.131 seconds
[2024-04-17T12:19:11.096+0000] {processor.py:154} INFO - Started process (PID=7322) to work on /opt/airflow/dags/group_dag.py
[2024-04-17T12:19:11.102+0000] {processor.py:756} INFO - Processing file /opt/airflow/dags/group_dag.py for tasks to queue
[2024-04-17T12:19:11.108+0000] {logging_mixin.py:120} INFO - [2024-04-17T12:19:11.108+0000] {dagbag.py:537} INFO - Filling up the DagBag from /opt/airflow/dags/group_dag.py
[2024-04-17T12:19:11.186+0000] {logging_mixin.py:120} INFO - [2024-04-17T12:19:11.177+0000] {dagbag.py:342} ERROR - Failed to import: /opt/airflow/dags/group_dag.py
Traceback (most recent call last):
  File "/home/airflow/.local/lib/python3.7/site-packages/airflow/models/dagbag.py", line 338, in parse
    loader.exec_module(new_module)
  File "<frozen importlib._bootstrap_external>", line 728, in exec_module
  File "<frozen importlib._bootstrap>", line 219, in _call_with_frames_removed
  File "/opt/airflow/dags/group_dag.py", line 27, in <module>
    subdag=subdag_downloads(dag.dag_id, 'downloads', args)
  File "/opt/airflow/dags/subdags/subdags_downloads.py", line 9, in subdag_downloads
    catch = args['catchup']) as dag:
TypeError: __init__() got an unexpected keyword argument 'catch'
[2024-04-17T12:19:11.190+0000] {processor.py:768} WARNING - No viable dags retrieved from /opt/airflow/dags/group_dag.py
[2024-04-17T12:19:11.263+0000] {processor.py:176} INFO - Processing /opt/airflow/dags/group_dag.py took 0.183 seconds
[2024-04-17T12:19:42.093+0000] {processor.py:154} INFO - Started process (PID=7391) to work on /opt/airflow/dags/group_dag.py
[2024-04-17T12:19:42.099+0000] {processor.py:756} INFO - Processing file /opt/airflow/dags/group_dag.py for tasks to queue
[2024-04-17T12:19:42.103+0000] {logging_mixin.py:120} INFO - [2024-04-17T12:19:42.101+0000] {dagbag.py:537} INFO - Filling up the DagBag from /opt/airflow/dags/group_dag.py
[2024-04-17T12:19:42.232+0000] {logging_mixin.py:120} INFO - [2024-04-17T12:19:42.225+0000] {dagbag.py:342} ERROR - Failed to import: /opt/airflow/dags/group_dag.py
Traceback (most recent call last):
  File "/home/airflow/.local/lib/python3.7/site-packages/airflow/models/dagbag.py", line 338, in parse
    loader.exec_module(new_module)
  File "<frozen importlib._bootstrap_external>", line 728, in exec_module
  File "<frozen importlib._bootstrap>", line 219, in _call_with_frames_removed
  File "/opt/airflow/dags/group_dag.py", line 27, in <module>
    subdag=subdag_downloads(dag.dag_id, 'downloads', args)
  File "/opt/airflow/dags/subdags/subdags_downloads.py", line 9, in subdag_downloads
    catch = args['catchup']) as dag:
TypeError: __init__() got an unexpected keyword argument 'catch'
[2024-04-17T12:19:42.235+0000] {processor.py:768} WARNING - No viable dags retrieved from /opt/airflow/dags/group_dag.py
[2024-04-17T12:19:42.298+0000] {processor.py:176} INFO - Processing /opt/airflow/dags/group_dag.py took 0.232 seconds
[2024-04-17T12:20:12.950+0000] {processor.py:154} INFO - Started process (PID=7460) to work on /opt/airflow/dags/group_dag.py
[2024-04-17T12:20:12.955+0000] {processor.py:756} INFO - Processing file /opt/airflow/dags/group_dag.py for tasks to queue
[2024-04-17T12:20:12.958+0000] {logging_mixin.py:120} INFO - [2024-04-17T12:20:12.957+0000] {dagbag.py:537} INFO - Filling up the DagBag from /opt/airflow/dags/group_dag.py
[2024-04-17T12:20:13.013+0000] {logging_mixin.py:120} INFO - [2024-04-17T12:20:13.006+0000] {dagbag.py:342} ERROR - Failed to import: /opt/airflow/dags/group_dag.py
Traceback (most recent call last):
  File "/home/airflow/.local/lib/python3.7/site-packages/airflow/models/dagbag.py", line 338, in parse
    loader.exec_module(new_module)
  File "<frozen importlib._bootstrap_external>", line 728, in exec_module
  File "<frozen importlib._bootstrap>", line 219, in _call_with_frames_removed
  File "/opt/airflow/dags/group_dag.py", line 27, in <module>
    subdag=subdag_downloads(dag.dag_id, 'downloads', args)
  File "/opt/airflow/dags/subdags/subdags_downloads.py", line 9, in subdag_downloads
    catch = args['catchup']) as dag:
TypeError: __init__() got an unexpected keyword argument 'catch'
[2024-04-17T12:20:13.014+0000] {processor.py:768} WARNING - No viable dags retrieved from /opt/airflow/dags/group_dag.py
[2024-04-17T12:20:13.062+0000] {processor.py:176} INFO - Processing /opt/airflow/dags/group_dag.py took 0.118 seconds
[2024-04-17T12:20:43.133+0000] {processor.py:154} INFO - Started process (PID=7536) to work on /opt/airflow/dags/group_dag.py
[2024-04-17T12:20:43.135+0000] {processor.py:756} INFO - Processing file /opt/airflow/dags/group_dag.py for tasks to queue
[2024-04-17T12:20:43.137+0000] {logging_mixin.py:120} INFO - [2024-04-17T12:20:43.137+0000] {dagbag.py:537} INFO - Filling up the DagBag from /opt/airflow/dags/group_dag.py
[2024-04-17T12:20:43.218+0000] {logging_mixin.py:120} INFO - [2024-04-17T12:20:43.207+0000] {dagbag.py:342} ERROR - Failed to import: /opt/airflow/dags/group_dag.py
Traceback (most recent call last):
  File "/home/airflow/.local/lib/python3.7/site-packages/airflow/models/dagbag.py", line 338, in parse
    loader.exec_module(new_module)
  File "<frozen importlib._bootstrap_external>", line 728, in exec_module
  File "<frozen importlib._bootstrap>", line 219, in _call_with_frames_removed
  File "/opt/airflow/dags/group_dag.py", line 27, in <module>
    subdag=subdag_downloads(dag.dag_id, 'downloads', args)
  File "/opt/airflow/dags/subdags/subdags_downloads.py", line 9, in subdag_downloads
    catch = args['catchup']) as dag:
TypeError: __init__() got an unexpected keyword argument 'catch'
[2024-04-17T12:20:43.221+0000] {processor.py:768} WARNING - No viable dags retrieved from /opt/airflow/dags/group_dag.py
[2024-04-17T12:20:43.323+0000] {processor.py:176} INFO - Processing /opt/airflow/dags/group_dag.py took 0.204 seconds
[2024-04-17T12:21:14.147+0000] {processor.py:154} INFO - Started process (PID=7604) to work on /opt/airflow/dags/group_dag.py
[2024-04-17T12:21:14.156+0000] {processor.py:756} INFO - Processing file /opt/airflow/dags/group_dag.py for tasks to queue
[2024-04-17T12:21:14.159+0000] {logging_mixin.py:120} INFO - [2024-04-17T12:21:14.158+0000] {dagbag.py:537} INFO - Filling up the DagBag from /opt/airflow/dags/group_dag.py
[2024-04-17T12:21:14.238+0000] {logging_mixin.py:120} INFO - [2024-04-17T12:21:14.228+0000] {dagbag.py:342} ERROR - Failed to import: /opt/airflow/dags/group_dag.py
Traceback (most recent call last):
  File "/home/airflow/.local/lib/python3.7/site-packages/airflow/models/dagbag.py", line 338, in parse
    loader.exec_module(new_module)
  File "<frozen importlib._bootstrap_external>", line 728, in exec_module
  File "<frozen importlib._bootstrap>", line 219, in _call_with_frames_removed
  File "/opt/airflow/dags/group_dag.py", line 27, in <module>
    subdag=subdag_downloads(dag.dag_id, 'downloads', args)
  File "/opt/airflow/dags/subdags/subdags_downloads.py", line 9, in subdag_downloads
    catch = args['catchup']) as dag:
TypeError: __init__() got an unexpected keyword argument 'catch'
[2024-04-17T12:21:14.240+0000] {processor.py:768} WARNING - No viable dags retrieved from /opt/airflow/dags/group_dag.py
[2024-04-17T12:21:14.292+0000] {processor.py:176} INFO - Processing /opt/airflow/dags/group_dag.py took 0.156 seconds
[2024-04-17T12:21:45.067+0000] {processor.py:154} INFO - Started process (PID=7673) to work on /opt/airflow/dags/group_dag.py
[2024-04-17T12:21:45.078+0000] {processor.py:756} INFO - Processing file /opt/airflow/dags/group_dag.py for tasks to queue
[2024-04-17T12:21:45.081+0000] {logging_mixin.py:120} INFO - [2024-04-17T12:21:45.081+0000] {dagbag.py:537} INFO - Filling up the DagBag from /opt/airflow/dags/group_dag.py
[2024-04-17T12:21:45.185+0000] {logging_mixin.py:120} INFO - [2024-04-17T12:21:45.177+0000] {dagbag.py:342} ERROR - Failed to import: /opt/airflow/dags/group_dag.py
Traceback (most recent call last):
  File "/home/airflow/.local/lib/python3.7/site-packages/airflow/models/dagbag.py", line 338, in parse
    loader.exec_module(new_module)
  File "<frozen importlib._bootstrap_external>", line 728, in exec_module
  File "<frozen importlib._bootstrap>", line 219, in _call_with_frames_removed
  File "/opt/airflow/dags/group_dag.py", line 27, in <module>
    subdag=subdag_downloads(dag.dag_id, 'downloads', args)
  File "/opt/airflow/dags/subdags/subdags_downloads.py", line 9, in subdag_downloads
    catch = args['catchup']) as dag:
TypeError: __init__() got an unexpected keyword argument 'catch'
[2024-04-17T12:21:45.189+0000] {processor.py:768} WARNING - No viable dags retrieved from /opt/airflow/dags/group_dag.py
[2024-04-17T12:21:45.299+0000] {processor.py:176} INFO - Processing /opt/airflow/dags/group_dag.py took 0.256 seconds
[2024-04-17T12:22:15.428+0000] {processor.py:154} INFO - Started process (PID=7749) to work on /opt/airflow/dags/group_dag.py
[2024-04-17T12:22:15.431+0000] {processor.py:756} INFO - Processing file /opt/airflow/dags/group_dag.py for tasks to queue
[2024-04-17T12:22:15.434+0000] {logging_mixin.py:120} INFO - [2024-04-17T12:22:15.433+0000] {dagbag.py:537} INFO - Filling up the DagBag from /opt/airflow/dags/group_dag.py
[2024-04-17T12:22:15.517+0000] {logging_mixin.py:120} INFO - [2024-04-17T12:22:15.512+0000] {dagbag.py:342} ERROR - Failed to import: /opt/airflow/dags/group_dag.py
Traceback (most recent call last):
  File "/home/airflow/.local/lib/python3.7/site-packages/airflow/models/dagbag.py", line 338, in parse
    loader.exec_module(new_module)
  File "<frozen importlib._bootstrap_external>", line 728, in exec_module
  File "<frozen importlib._bootstrap>", line 219, in _call_with_frames_removed
  File "/opt/airflow/dags/group_dag.py", line 27, in <module>
    subdag=subdag_downloads(dag.dag_id, 'downloads', args)
  File "/opt/airflow/dags/subdags/subdags_downloads.py", line 9, in subdag_downloads
    catch = args['catchup']) as dag:
TypeError: __init__() got an unexpected keyword argument 'catch'
[2024-04-17T12:22:15.519+0000] {processor.py:768} WARNING - No viable dags retrieved from /opt/airflow/dags/group_dag.py
[2024-04-17T12:22:15.572+0000] {processor.py:176} INFO - Processing /opt/airflow/dags/group_dag.py took 0.156 seconds
[2024-04-17T12:22:45.748+0000] {processor.py:154} INFO - Started process (PID=7818) to work on /opt/airflow/dags/group_dag.py
[2024-04-17T12:22:45.751+0000] {processor.py:756} INFO - Processing file /opt/airflow/dags/group_dag.py for tasks to queue
[2024-04-17T12:22:45.753+0000] {logging_mixin.py:120} INFO - [2024-04-17T12:22:45.752+0000] {dagbag.py:537} INFO - Filling up the DagBag from /opt/airflow/dags/group_dag.py
[2024-04-17T12:22:45.831+0000] {logging_mixin.py:120} INFO - [2024-04-17T12:22:45.823+0000] {dagbag.py:342} ERROR - Failed to import: /opt/airflow/dags/group_dag.py
Traceback (most recent call last):
  File "/home/airflow/.local/lib/python3.7/site-packages/airflow/models/dagbag.py", line 338, in parse
    loader.exec_module(new_module)
  File "<frozen importlib._bootstrap_external>", line 728, in exec_module
  File "<frozen importlib._bootstrap>", line 219, in _call_with_frames_removed
  File "/opt/airflow/dags/group_dag.py", line 27, in <module>
    subdag=subdag_downloads(dag.dag_id, 'downloads', args)
  File "/opt/airflow/dags/subdags/subdags_downloads.py", line 9, in subdag_downloads
    catch = args['catchup']) as dag:
TypeError: __init__() got an unexpected keyword argument 'catch'
[2024-04-17T12:22:45.833+0000] {processor.py:768} WARNING - No viable dags retrieved from /opt/airflow/dags/group_dag.py
[2024-04-17T12:22:45.885+0000] {processor.py:176} INFO - Processing /opt/airflow/dags/group_dag.py took 0.149 seconds
[2024-04-17T12:23:16.421+0000] {processor.py:154} INFO - Started process (PID=7885) to work on /opt/airflow/dags/group_dag.py
[2024-04-17T12:23:16.424+0000] {processor.py:756} INFO - Processing file /opt/airflow/dags/group_dag.py for tasks to queue
[2024-04-17T12:23:16.432+0000] {logging_mixin.py:120} INFO - [2024-04-17T12:23:16.430+0000] {dagbag.py:537} INFO - Filling up the DagBag from /opt/airflow/dags/group_dag.py
[2024-04-17T12:23:16.493+0000] {logging_mixin.py:120} INFO - [2024-04-17T12:23:16.488+0000] {dagbag.py:342} ERROR - Failed to import: /opt/airflow/dags/group_dag.py
Traceback (most recent call last):
  File "/home/airflow/.local/lib/python3.7/site-packages/airflow/models/dagbag.py", line 338, in parse
    loader.exec_module(new_module)
  File "<frozen importlib._bootstrap_external>", line 728, in exec_module
  File "<frozen importlib._bootstrap>", line 219, in _call_with_frames_removed
  File "/opt/airflow/dags/group_dag.py", line 27, in <module>
    subdag=subdag_downloads(dag.dag_id, 'downloads', args)
  File "/opt/airflow/dags/subdags/subdags_downloads.py", line 9, in subdag_downloads
    catch = args['catchup']) as dag:
TypeError: __init__() got an unexpected keyword argument 'catch'
[2024-04-17T12:23:16.495+0000] {processor.py:768} WARNING - No viable dags retrieved from /opt/airflow/dags/group_dag.py
[2024-04-17T12:23:16.554+0000] {processor.py:176} INFO - Processing /opt/airflow/dags/group_dag.py took 0.144 seconds
[2024-04-17T12:23:47.406+0000] {processor.py:154} INFO - Started process (PID=7952) to work on /opt/airflow/dags/group_dag.py
[2024-04-17T12:23:47.409+0000] {processor.py:756} INFO - Processing file /opt/airflow/dags/group_dag.py for tasks to queue
[2024-04-17T12:23:47.415+0000] {logging_mixin.py:120} INFO - [2024-04-17T12:23:47.413+0000] {dagbag.py:537} INFO - Filling up the DagBag from /opt/airflow/dags/group_dag.py
[2024-04-17T12:23:47.495+0000] {logging_mixin.py:120} INFO - [2024-04-17T12:23:47.490+0000] {dagbag.py:342} ERROR - Failed to import: /opt/airflow/dags/group_dag.py
Traceback (most recent call last):
  File "/home/airflow/.local/lib/python3.7/site-packages/airflow/models/dagbag.py", line 338, in parse
    loader.exec_module(new_module)
  File "<frozen importlib._bootstrap_external>", line 728, in exec_module
  File "<frozen importlib._bootstrap>", line 219, in _call_with_frames_removed
  File "/opt/airflow/dags/group_dag.py", line 27, in <module>
    subdag=subdag_downloads(dag.dag_id, 'downloads', args)
  File "/opt/airflow/dags/subdags/subdags_downloads.py", line 9, in subdag_downloads
    catch = args['catchup']) as dag:
TypeError: __init__() got an unexpected keyword argument 'catch'
[2024-04-17T12:23:47.498+0000] {processor.py:768} WARNING - No viable dags retrieved from /opt/airflow/dags/group_dag.py
[2024-04-17T12:23:47.554+0000] {processor.py:176} INFO - Processing /opt/airflow/dags/group_dag.py took 0.167 seconds
[2024-04-17T12:24:17.774+0000] {processor.py:154} INFO - Started process (PID=8030) to work on /opt/airflow/dags/group_dag.py
[2024-04-17T12:24:17.776+0000] {processor.py:756} INFO - Processing file /opt/airflow/dags/group_dag.py for tasks to queue
[2024-04-17T12:24:17.779+0000] {logging_mixin.py:120} INFO - [2024-04-17T12:24:17.778+0000] {dagbag.py:537} INFO - Filling up the DagBag from /opt/airflow/dags/group_dag.py
[2024-04-17T12:24:17.846+0000] {logging_mixin.py:120} INFO - [2024-04-17T12:24:17.842+0000] {dagbag.py:342} ERROR - Failed to import: /opt/airflow/dags/group_dag.py
Traceback (most recent call last):
  File "/home/airflow/.local/lib/python3.7/site-packages/airflow/models/dagbag.py", line 338, in parse
    loader.exec_module(new_module)
  File "<frozen importlib._bootstrap_external>", line 728, in exec_module
  File "<frozen importlib._bootstrap>", line 219, in _call_with_frames_removed
  File "/opt/airflow/dags/group_dag.py", line 27, in <module>
    subdag=subdag_downloads(dag.dag_id, 'downloads', args)
  File "/opt/airflow/dags/subdags/subdags_downloads.py", line 9, in subdag_downloads
    catch = args['catchup']) as dag:
TypeError: __init__() got an unexpected keyword argument 'catch'
[2024-04-17T12:24:17.849+0000] {processor.py:768} WARNING - No viable dags retrieved from /opt/airflow/dags/group_dag.py
[2024-04-17T12:24:17.885+0000] {processor.py:176} INFO - Processing /opt/airflow/dags/group_dag.py took 0.120 seconds
[2024-04-17T12:24:48.026+0000] {processor.py:154} INFO - Started process (PID=8099) to work on /opt/airflow/dags/group_dag.py
[2024-04-17T12:24:48.028+0000] {processor.py:756} INFO - Processing file /opt/airflow/dags/group_dag.py for tasks to queue
[2024-04-17T12:24:48.030+0000] {logging_mixin.py:120} INFO - [2024-04-17T12:24:48.029+0000] {dagbag.py:537} INFO - Filling up the DagBag from /opt/airflow/dags/group_dag.py
[2024-04-17T12:24:48.075+0000] {logging_mixin.py:120} INFO - [2024-04-17T12:24:48.069+0000] {dagbag.py:342} ERROR - Failed to import: /opt/airflow/dags/group_dag.py
Traceback (most recent call last):
  File "/home/airflow/.local/lib/python3.7/site-packages/airflow/models/dagbag.py", line 338, in parse
    loader.exec_module(new_module)
  File "<frozen importlib._bootstrap_external>", line 728, in exec_module
  File "<frozen importlib._bootstrap>", line 219, in _call_with_frames_removed
  File "/opt/airflow/dags/group_dag.py", line 27, in <module>
    subdag=subdag_downloads(dag.dag_id, 'downloads', args)
  File "/opt/airflow/dags/subdags/subdags_downloads.py", line 9, in subdag_downloads
    catch = args['catchup']) as dag:
TypeError: __init__() got an unexpected keyword argument 'catch'
[2024-04-17T12:24:48.076+0000] {processor.py:768} WARNING - No viable dags retrieved from /opt/airflow/dags/group_dag.py
[2024-04-17T12:24:48.108+0000] {processor.py:176} INFO - Processing /opt/airflow/dags/group_dag.py took 0.090 seconds
[2024-04-17T12:25:18.920+0000] {processor.py:154} INFO - Started process (PID=8178) to work on /opt/airflow/dags/group_dag.py
[2024-04-17T12:25:18.923+0000] {processor.py:756} INFO - Processing file /opt/airflow/dags/group_dag.py for tasks to queue
[2024-04-17T12:25:18.929+0000] {logging_mixin.py:120} INFO - [2024-04-17T12:25:18.928+0000] {dagbag.py:537} INFO - Filling up the DagBag from /opt/airflow/dags/group_dag.py
[2024-04-17T12:25:18.988+0000] {logging_mixin.py:120} INFO - [2024-04-17T12:25:18.982+0000] {dagbag.py:342} ERROR - Failed to import: /opt/airflow/dags/group_dag.py
Traceback (most recent call last):
  File "/home/airflow/.local/lib/python3.7/site-packages/airflow/models/dagbag.py", line 338, in parse
    loader.exec_module(new_module)
  File "<frozen importlib._bootstrap_external>", line 728, in exec_module
  File "<frozen importlib._bootstrap>", line 219, in _call_with_frames_removed
  File "/opt/airflow/dags/group_dag.py", line 27, in <module>
    subdag=subdag_downloads(dag.dag_id, 'downloads', args)
  File "/opt/airflow/dags/subdags/subdags_downloads.py", line 9, in subdag_downloads
    catch = args['catchup']) as dag:
TypeError: __init__() got an unexpected keyword argument 'catch'
[2024-04-17T12:25:18.990+0000] {processor.py:768} WARNING - No viable dags retrieved from /opt/airflow/dags/group_dag.py
[2024-04-17T12:25:19.053+0000] {processor.py:176} INFO - Processing /opt/airflow/dags/group_dag.py took 0.146 seconds
[2024-04-17T12:25:49.362+0000] {processor.py:154} INFO - Started process (PID=8243) to work on /opt/airflow/dags/group_dag.py
[2024-04-17T12:25:49.368+0000] {processor.py:756} INFO - Processing file /opt/airflow/dags/group_dag.py for tasks to queue
[2024-04-17T12:25:49.372+0000] {logging_mixin.py:120} INFO - [2024-04-17T12:25:49.371+0000] {dagbag.py:537} INFO - Filling up the DagBag from /opt/airflow/dags/group_dag.py
[2024-04-17T12:25:49.454+0000] {logging_mixin.py:120} INFO - [2024-04-17T12:25:49.443+0000] {dagbag.py:342} ERROR - Failed to import: /opt/airflow/dags/group_dag.py
Traceback (most recent call last):
  File "/home/airflow/.local/lib/python3.7/site-packages/airflow/models/dagbag.py", line 338, in parse
    loader.exec_module(new_module)
  File "<frozen importlib._bootstrap_external>", line 728, in exec_module
  File "<frozen importlib._bootstrap>", line 219, in _call_with_frames_removed
  File "/opt/airflow/dags/group_dag.py", line 27, in <module>
    subdag=subdag_downloads(dag.dag_id, 'downloads', args)
  File "/opt/airflow/dags/subdags/subdags_downloads.py", line 9, in subdag_downloads
    catch = args['catchup']) as dag:
TypeError: __init__() got an unexpected keyword argument 'catch'
[2024-04-17T12:25:49.456+0000] {processor.py:768} WARNING - No viable dags retrieved from /opt/airflow/dags/group_dag.py
[2024-04-17T12:25:49.519+0000] {processor.py:176} INFO - Processing /opt/airflow/dags/group_dag.py took 0.168 seconds
[2024-04-17T12:26:19.747+0000] {processor.py:154} INFO - Started process (PID=8310) to work on /opt/airflow/dags/group_dag.py
[2024-04-17T12:26:19.753+0000] {processor.py:756} INFO - Processing file /opt/airflow/dags/group_dag.py for tasks to queue
[2024-04-17T12:26:19.758+0000] {logging_mixin.py:120} INFO - [2024-04-17T12:26:19.757+0000] {dagbag.py:537} INFO - Filling up the DagBag from /opt/airflow/dags/group_dag.py
[2024-04-17T12:26:19.865+0000] {logging_mixin.py:120} INFO - [2024-04-17T12:26:19.859+0000] {dagbag.py:342} ERROR - Failed to import: /opt/airflow/dags/group_dag.py
Traceback (most recent call last):
  File "/home/airflow/.local/lib/python3.7/site-packages/airflow/models/dagbag.py", line 338, in parse
    loader.exec_module(new_module)
  File "<frozen importlib._bootstrap_external>", line 728, in exec_module
  File "<frozen importlib._bootstrap>", line 219, in _call_with_frames_removed
  File "/opt/airflow/dags/group_dag.py", line 27, in <module>
    subdag=subdag_downloads(dag.dag_id, 'downloads', args)
  File "/opt/airflow/dags/subdags/subdags_downloads.py", line 9, in subdag_downloads
    catch = args['catchup']) as dag:
TypeError: __init__() got an unexpected keyword argument 'catch'
[2024-04-17T12:26:19.869+0000] {processor.py:768} WARNING - No viable dags retrieved from /opt/airflow/dags/group_dag.py
[2024-04-17T12:26:19.929+0000] {processor.py:176} INFO - Processing /opt/airflow/dags/group_dag.py took 0.197 seconds
[2024-04-17T12:26:50.260+0000] {processor.py:154} INFO - Started process (PID=8376) to work on /opt/airflow/dags/group_dag.py
[2024-04-17T12:26:50.264+0000] {processor.py:756} INFO - Processing file /opt/airflow/dags/group_dag.py for tasks to queue
[2024-04-17T12:26:50.267+0000] {logging_mixin.py:120} INFO - [2024-04-17T12:26:50.266+0000] {dagbag.py:537} INFO - Filling up the DagBag from /opt/airflow/dags/group_dag.py
[2024-04-17T12:26:50.333+0000] {logging_mixin.py:120} INFO - [2024-04-17T12:26:50.327+0000] {dagbag.py:342} ERROR - Failed to import: /opt/airflow/dags/group_dag.py
Traceback (most recent call last):
  File "/home/airflow/.local/lib/python3.7/site-packages/airflow/models/dagbag.py", line 338, in parse
    loader.exec_module(new_module)
  File "<frozen importlib._bootstrap_external>", line 728, in exec_module
  File "<frozen importlib._bootstrap>", line 219, in _call_with_frames_removed
  File "/opt/airflow/dags/group_dag.py", line 27, in <module>
    subdag=subdag_downloads(dag.dag_id, 'downloads', args)
  File "/opt/airflow/dags/subdags/subdags_downloads.py", line 9, in subdag_downloads
    catch = args['catchup']) as dag:
TypeError: __init__() got an unexpected keyword argument 'catch'
[2024-04-17T12:26:50.335+0000] {processor.py:768} WARNING - No viable dags retrieved from /opt/airflow/dags/group_dag.py
[2024-04-17T12:26:50.382+0000] {processor.py:176} INFO - Processing /opt/airflow/dags/group_dag.py took 0.132 seconds
[2024-04-17T12:27:20.800+0000] {processor.py:154} INFO - Started process (PID=8442) to work on /opt/airflow/dags/group_dag.py
[2024-04-17T12:27:20.809+0000] {processor.py:756} INFO - Processing file /opt/airflow/dags/group_dag.py for tasks to queue
[2024-04-17T12:27:20.814+0000] {logging_mixin.py:120} INFO - [2024-04-17T12:27:20.814+0000] {dagbag.py:537} INFO - Filling up the DagBag from /opt/airflow/dags/group_dag.py
[2024-04-17T12:27:20.914+0000] {logging_mixin.py:120} INFO - [2024-04-17T12:27:20.903+0000] {dagbag.py:342} ERROR - Failed to import: /opt/airflow/dags/group_dag.py
Traceback (most recent call last):
  File "/home/airflow/.local/lib/python3.7/site-packages/airflow/models/dagbag.py", line 338, in parse
    loader.exec_module(new_module)
  File "<frozen importlib._bootstrap_external>", line 728, in exec_module
  File "<frozen importlib._bootstrap>", line 219, in _call_with_frames_removed
  File "/opt/airflow/dags/group_dag.py", line 27, in <module>
    subdag=subdag_downloads(dag.dag_id, 'downloads', args)
  File "/opt/airflow/dags/subdags/subdags_downloads.py", line 9, in subdag_downloads
    catch = args['catchup']) as dag:
TypeError: __init__() got an unexpected keyword argument 'catch'
[2024-04-17T12:27:20.917+0000] {processor.py:768} WARNING - No viable dags retrieved from /opt/airflow/dags/group_dag.py
[2024-04-17T12:27:20.987+0000] {processor.py:176} INFO - Processing /opt/airflow/dags/group_dag.py took 0.201 seconds
[2024-04-17T12:27:51.754+0000] {processor.py:154} INFO - Started process (PID=8512) to work on /opt/airflow/dags/group_dag.py
[2024-04-17T12:27:51.762+0000] {processor.py:756} INFO - Processing file /opt/airflow/dags/group_dag.py for tasks to queue
[2024-04-17T12:27:51.768+0000] {logging_mixin.py:120} INFO - [2024-04-17T12:27:51.767+0000] {dagbag.py:537} INFO - Filling up the DagBag from /opt/airflow/dags/group_dag.py
[2024-04-17T12:27:51.874+0000] {logging_mixin.py:120} INFO - [2024-04-17T12:27:51.865+0000] {dagbag.py:342} ERROR - Failed to import: /opt/airflow/dags/group_dag.py
Traceback (most recent call last):
  File "/home/airflow/.local/lib/python3.7/site-packages/airflow/models/dagbag.py", line 338, in parse
    loader.exec_module(new_module)
  File "<frozen importlib._bootstrap_external>", line 728, in exec_module
  File "<frozen importlib._bootstrap>", line 219, in _call_with_frames_removed
  File "/opt/airflow/dags/group_dag.py", line 27, in <module>
    subdag=subdag_downloads(dag.dag_id, 'downloads', args)
  File "/opt/airflow/dags/subdags/subdags_downloads.py", line 9, in subdag_downloads
    catch = args['catchup']) as dag:
TypeError: __init__() got an unexpected keyword argument 'catch'
[2024-04-17T12:27:51.881+0000] {processor.py:768} WARNING - No viable dags retrieved from /opt/airflow/dags/group_dag.py
[2024-04-17T12:27:51.969+0000] {processor.py:176} INFO - Processing /opt/airflow/dags/group_dag.py took 0.229 seconds
[2024-04-17T12:28:22.370+0000] {processor.py:154} INFO - Started process (PID=8581) to work on /opt/airflow/dags/group_dag.py
[2024-04-17T12:28:22.372+0000] {processor.py:756} INFO - Processing file /opt/airflow/dags/group_dag.py for tasks to queue
[2024-04-17T12:28:22.374+0000] {logging_mixin.py:120} INFO - [2024-04-17T12:28:22.374+0000] {dagbag.py:537} INFO - Filling up the DagBag from /opt/airflow/dags/group_dag.py
[2024-04-17T12:28:22.441+0000] {logging_mixin.py:120} INFO - [2024-04-17T12:28:22.436+0000] {dagbag.py:342} ERROR - Failed to import: /opt/airflow/dags/group_dag.py
Traceback (most recent call last):
  File "/home/airflow/.local/lib/python3.7/site-packages/airflow/models/dagbag.py", line 338, in parse
    loader.exec_module(new_module)
  File "<frozen importlib._bootstrap_external>", line 728, in exec_module
  File "<frozen importlib._bootstrap>", line 219, in _call_with_frames_removed
  File "/opt/airflow/dags/group_dag.py", line 27, in <module>
    subdag=subdag_downloads(dag.dag_id, 'downloads', args)
  File "/opt/airflow/dags/subdags/subdags_downloads.py", line 9, in subdag_downloads
    catch = args['catchup']) as dag:
TypeError: __init__() got an unexpected keyword argument 'catch'
[2024-04-17T12:28:22.444+0000] {processor.py:768} WARNING - No viable dags retrieved from /opt/airflow/dags/group_dag.py
[2024-04-17T12:28:22.487+0000] {processor.py:176} INFO - Processing /opt/airflow/dags/group_dag.py took 0.132 seconds
[2024-04-17T12:28:52.614+0000] {processor.py:154} INFO - Started process (PID=8646) to work on /opt/airflow/dags/group_dag.py
[2024-04-17T12:28:52.629+0000] {processor.py:756} INFO - Processing file /opt/airflow/dags/group_dag.py for tasks to queue
[2024-04-17T12:28:52.635+0000] {logging_mixin.py:120} INFO - [2024-04-17T12:28:52.634+0000] {dagbag.py:537} INFO - Filling up the DagBag from /opt/airflow/dags/group_dag.py
[2024-04-17T12:28:52.706+0000] {logging_mixin.py:120} INFO - [2024-04-17T12:28:52.700+0000] {dagbag.py:342} ERROR - Failed to import: /opt/airflow/dags/group_dag.py
Traceback (most recent call last):
  File "/home/airflow/.local/lib/python3.7/site-packages/airflow/models/dagbag.py", line 338, in parse
    loader.exec_module(new_module)
  File "<frozen importlib._bootstrap_external>", line 728, in exec_module
  File "<frozen importlib._bootstrap>", line 219, in _call_with_frames_removed
  File "/opt/airflow/dags/group_dag.py", line 27, in <module>
    subdag=subdag_downloads(dag.dag_id, 'downloads', args)
  File "/opt/airflow/dags/subdags/subdags_downloads.py", line 9, in subdag_downloads
    catch = args['catchup']) as dag:
TypeError: __init__() got an unexpected keyword argument 'catch'
[2024-04-17T12:28:52.708+0000] {processor.py:768} WARNING - No viable dags retrieved from /opt/airflow/dags/group_dag.py
[2024-04-17T12:28:52.750+0000] {processor.py:176} INFO - Processing /opt/airflow/dags/group_dag.py took 0.146 seconds
[2024-04-17T12:29:23.266+0000] {processor.py:154} INFO - Started process (PID=8725) to work on /opt/airflow/dags/group_dag.py
[2024-04-17T12:29:23.270+0000] {processor.py:756} INFO - Processing file /opt/airflow/dags/group_dag.py for tasks to queue
[2024-04-17T12:29:23.275+0000] {logging_mixin.py:120} INFO - [2024-04-17T12:29:23.274+0000] {dagbag.py:537} INFO - Filling up the DagBag from /opt/airflow/dags/group_dag.py
[2024-04-17T12:29:23.359+0000] {logging_mixin.py:120} INFO - [2024-04-17T12:29:23.352+0000] {dagbag.py:342} ERROR - Failed to import: /opt/airflow/dags/group_dag.py
Traceback (most recent call last):
  File "/home/airflow/.local/lib/python3.7/site-packages/airflow/models/dagbag.py", line 338, in parse
    loader.exec_module(new_module)
  File "<frozen importlib._bootstrap_external>", line 728, in exec_module
  File "<frozen importlib._bootstrap>", line 219, in _call_with_frames_removed
  File "/opt/airflow/dags/group_dag.py", line 27, in <module>
    subdag=subdag_downloads(dag.dag_id, 'downloads', args)
  File "/opt/airflow/dags/subdags/subdags_downloads.py", line 9, in subdag_downloads
    catch = args['catchup']) as dag:
TypeError: __init__() got an unexpected keyword argument 'catch'
[2024-04-17T12:29:23.361+0000] {processor.py:768} WARNING - No viable dags retrieved from /opt/airflow/dags/group_dag.py
[2024-04-17T12:29:23.420+0000] {processor.py:176} INFO - Processing /opt/airflow/dags/group_dag.py took 0.167 seconds
[2024-04-17T12:29:53.684+0000] {processor.py:154} INFO - Started process (PID=8791) to work on /opt/airflow/dags/group_dag.py
[2024-04-17T12:29:53.691+0000] {processor.py:756} INFO - Processing file /opt/airflow/dags/group_dag.py for tasks to queue
[2024-04-17T12:29:53.695+0000] {logging_mixin.py:120} INFO - [2024-04-17T12:29:53.695+0000] {dagbag.py:537} INFO - Filling up the DagBag from /opt/airflow/dags/group_dag.py
[2024-04-17T12:29:53.792+0000] {logging_mixin.py:120} INFO - [2024-04-17T12:29:53.786+0000] {dagbag.py:342} ERROR - Failed to import: /opt/airflow/dags/group_dag.py
Traceback (most recent call last):
  File "/home/airflow/.local/lib/python3.7/site-packages/airflow/models/dagbag.py", line 338, in parse
    loader.exec_module(new_module)
  File "<frozen importlib._bootstrap_external>", line 728, in exec_module
  File "<frozen importlib._bootstrap>", line 219, in _call_with_frames_removed
  File "/opt/airflow/dags/group_dag.py", line 27, in <module>
    subdag=subdag_downloads(dag.dag_id, 'downloads', args)
  File "/opt/airflow/dags/subdags/subdags_downloads.py", line 9, in subdag_downloads
    catch = args['catchup']) as dag:
TypeError: __init__() got an unexpected keyword argument 'catch'
[2024-04-17T12:29:53.797+0000] {processor.py:768} WARNING - No viable dags retrieved from /opt/airflow/dags/group_dag.py
[2024-04-17T12:29:53.857+0000] {processor.py:176} INFO - Processing /opt/airflow/dags/group_dag.py took 0.183 seconds
[2024-04-17T12:30:24.383+0000] {processor.py:154} INFO - Started process (PID=8861) to work on /opt/airflow/dags/group_dag.py
[2024-04-17T12:30:24.387+0000] {processor.py:756} INFO - Processing file /opt/airflow/dags/group_dag.py for tasks to queue
[2024-04-17T12:30:24.390+0000] {logging_mixin.py:120} INFO - [2024-04-17T12:30:24.390+0000] {dagbag.py:537} INFO - Filling up the DagBag from /opt/airflow/dags/group_dag.py
[2024-04-17T12:30:24.477+0000] {logging_mixin.py:120} INFO - [2024-04-17T12:30:24.462+0000] {dagbag.py:342} ERROR - Failed to import: /opt/airflow/dags/group_dag.py
Traceback (most recent call last):
  File "/home/airflow/.local/lib/python3.7/site-packages/airflow/models/dagbag.py", line 338, in parse
    loader.exec_module(new_module)
  File "<frozen importlib._bootstrap_external>", line 728, in exec_module
  File "<frozen importlib._bootstrap>", line 219, in _call_with_frames_removed
  File "/opt/airflow/dags/group_dag.py", line 27, in <module>
    subdag=subdag_downloads(dag.dag_id, 'downloads', args)
  File "/opt/airflow/dags/subdags/subdags_downloads.py", line 9, in subdag_downloads
    catch = args['catchup']) as dag:
TypeError: __init__() got an unexpected keyword argument 'catch'
[2024-04-17T12:30:24.487+0000] {processor.py:768} WARNING - No viable dags retrieved from /opt/airflow/dags/group_dag.py
[2024-04-17T12:30:24.548+0000] {processor.py:176} INFO - Processing /opt/airflow/dags/group_dag.py took 0.176 seconds
[2024-04-17T12:30:54.929+0000] {processor.py:154} INFO - Started process (PID=8940) to work on /opt/airflow/dags/group_dag.py
[2024-04-17T12:30:54.935+0000] {processor.py:756} INFO - Processing file /opt/airflow/dags/group_dag.py for tasks to queue
[2024-04-17T12:30:54.946+0000] {logging_mixin.py:120} INFO - [2024-04-17T12:30:54.946+0000] {dagbag.py:537} INFO - Filling up the DagBag from /opt/airflow/dags/group_dag.py
[2024-04-17T12:30:55.045+0000] {logging_mixin.py:120} INFO - [2024-04-17T12:30:55.040+0000] {dagbag.py:342} ERROR - Failed to import: /opt/airflow/dags/group_dag.py
Traceback (most recent call last):
  File "/home/airflow/.local/lib/python3.7/site-packages/airflow/models/dagbag.py", line 338, in parse
    loader.exec_module(new_module)
  File "<frozen importlib._bootstrap_external>", line 728, in exec_module
  File "<frozen importlib._bootstrap>", line 219, in _call_with_frames_removed
  File "/opt/airflow/dags/group_dag.py", line 27, in <module>
    subdag=subdag_downloads(dag.dag_id, 'downloads', args)
  File "/opt/airflow/dags/subdags/subdags_downloads.py", line 9, in subdag_downloads
    catch = args['catchup']) as dag:
TypeError: __init__() got an unexpected keyword argument 'catch'
[2024-04-17T12:30:55.046+0000] {processor.py:768} WARNING - No viable dags retrieved from /opt/airflow/dags/group_dag.py
[2024-04-17T12:30:55.120+0000] {processor.py:176} INFO - Processing /opt/airflow/dags/group_dag.py took 0.205 seconds
[2024-04-17T12:31:25.327+0000] {processor.py:154} INFO - Started process (PID=9011) to work on /opt/airflow/dags/group_dag.py
[2024-04-17T12:31:25.331+0000] {processor.py:756} INFO - Processing file /opt/airflow/dags/group_dag.py for tasks to queue
[2024-04-17T12:31:25.334+0000] {logging_mixin.py:120} INFO - [2024-04-17T12:31:25.333+0000] {dagbag.py:537} INFO - Filling up the DagBag from /opt/airflow/dags/group_dag.py
[2024-04-17T12:31:25.436+0000] {logging_mixin.py:120} INFO - [2024-04-17T12:31:25.429+0000] {dagbag.py:342} ERROR - Failed to import: /opt/airflow/dags/group_dag.py
Traceback (most recent call last):
  File "/home/airflow/.local/lib/python3.7/site-packages/airflow/models/dagbag.py", line 338, in parse
    loader.exec_module(new_module)
  File "<frozen importlib._bootstrap_external>", line 728, in exec_module
  File "<frozen importlib._bootstrap>", line 219, in _call_with_frames_removed
  File "/opt/airflow/dags/group_dag.py", line 27, in <module>
    subdag=subdag_downloads(dag.dag_id, 'downloads', args)
  File "/opt/airflow/dags/subdags/subdags_downloads.py", line 9, in subdag_downloads
    catch = args['catchup']) as dag:
TypeError: __init__() got an unexpected keyword argument 'catch'
[2024-04-17T12:31:25.442+0000] {processor.py:768} WARNING - No viable dags retrieved from /opt/airflow/dags/group_dag.py
[2024-04-17T12:31:25.494+0000] {processor.py:176} INFO - Processing /opt/airflow/dags/group_dag.py took 0.181 seconds
[2024-04-17T12:31:55.912+0000] {processor.py:154} INFO - Started process (PID=9080) to work on /opt/airflow/dags/group_dag.py
[2024-04-17T12:31:55.915+0000] {processor.py:756} INFO - Processing file /opt/airflow/dags/group_dag.py for tasks to queue
[2024-04-17T12:31:55.919+0000] {logging_mixin.py:120} INFO - [2024-04-17T12:31:55.918+0000] {dagbag.py:537} INFO - Filling up the DagBag from /opt/airflow/dags/group_dag.py
[2024-04-17T12:31:56.052+0000] {logging_mixin.py:120} INFO - [2024-04-17T12:31:56.033+0000] {dagbag.py:342} ERROR - Failed to import: /opt/airflow/dags/group_dag.py
Traceback (most recent call last):
  File "/home/airflow/.local/lib/python3.7/site-packages/airflow/models/dagbag.py", line 338, in parse
    loader.exec_module(new_module)
  File "<frozen importlib._bootstrap_external>", line 728, in exec_module
  File "<frozen importlib._bootstrap>", line 219, in _call_with_frames_removed
  File "/opt/airflow/dags/group_dag.py", line 27, in <module>
    subdag=subdag_downloads(dag.dag_id, 'downloads', args)
  File "/opt/airflow/dags/subdags/subdags_downloads.py", line 9, in subdag_downloads
    catch = args['catchup']) as dag:
TypeError: __init__() got an unexpected keyword argument 'catch'
[2024-04-17T12:31:56.054+0000] {processor.py:768} WARNING - No viable dags retrieved from /opt/airflow/dags/group_dag.py
[2024-04-17T12:31:56.093+0000] {processor.py:176} INFO - Processing /opt/airflow/dags/group_dag.py took 0.194 seconds
[2024-04-17T12:32:26.336+0000] {processor.py:154} INFO - Started process (PID=9158) to work on /opt/airflow/dags/group_dag.py
[2024-04-17T12:32:26.339+0000] {processor.py:756} INFO - Processing file /opt/airflow/dags/group_dag.py for tasks to queue
[2024-04-17T12:32:26.342+0000] {logging_mixin.py:120} INFO - [2024-04-17T12:32:26.341+0000] {dagbag.py:537} INFO - Filling up the DagBag from /opt/airflow/dags/group_dag.py
[2024-04-17T12:32:26.398+0000] {logging_mixin.py:120} INFO - [2024-04-17T12:32:26.391+0000] {dagbag.py:342} ERROR - Failed to import: /opt/airflow/dags/group_dag.py
Traceback (most recent call last):
  File "/home/airflow/.local/lib/python3.7/site-packages/airflow/models/dagbag.py", line 338, in parse
    loader.exec_module(new_module)
  File "<frozen importlib._bootstrap_external>", line 728, in exec_module
  File "<frozen importlib._bootstrap>", line 219, in _call_with_frames_removed
  File "/opt/airflow/dags/group_dag.py", line 27, in <module>
    subdag=subdag_downloads(dag.dag_id, 'downloads', args)
  File "/opt/airflow/dags/subdags/subdags_downloads.py", line 9, in subdag_downloads
    catch = args['catchup']) as dag:
TypeError: __init__() got an unexpected keyword argument 'catch'
[2024-04-17T12:32:26.399+0000] {processor.py:768} WARNING - No viable dags retrieved from /opt/airflow/dags/group_dag.py
[2024-04-17T12:32:26.442+0000] {processor.py:176} INFO - Processing /opt/airflow/dags/group_dag.py took 0.118 seconds
[2024-04-17T12:32:57.128+0000] {processor.py:154} INFO - Started process (PID=9227) to work on /opt/airflow/dags/group_dag.py
[2024-04-17T12:32:57.137+0000] {processor.py:756} INFO - Processing file /opt/airflow/dags/group_dag.py for tasks to queue
[2024-04-17T12:32:57.140+0000] {logging_mixin.py:120} INFO - [2024-04-17T12:32:57.140+0000] {dagbag.py:537} INFO - Filling up the DagBag from /opt/airflow/dags/group_dag.py
[2024-04-17T12:32:57.265+0000] {logging_mixin.py:120} INFO - [2024-04-17T12:32:57.253+0000] {dagbag.py:342} ERROR - Failed to import: /opt/airflow/dags/group_dag.py
Traceback (most recent call last):
  File "/home/airflow/.local/lib/python3.7/site-packages/airflow/models/dagbag.py", line 338, in parse
    loader.exec_module(new_module)
  File "<frozen importlib._bootstrap_external>", line 728, in exec_module
  File "<frozen importlib._bootstrap>", line 219, in _call_with_frames_removed
  File "/opt/airflow/dags/group_dag.py", line 27, in <module>
    subdag=subdag_downloads(dag.dag_id, 'downloads', args)
  File "/opt/airflow/dags/subdags/subdags_downloads.py", line 9, in subdag_downloads
    catch = args['catchup']) as dag:
TypeError: __init__() got an unexpected keyword argument 'catch'
[2024-04-17T12:32:57.275+0000] {processor.py:768} WARNING - No viable dags retrieved from /opt/airflow/dags/group_dag.py
[2024-04-17T12:32:57.376+0000] {processor.py:176} INFO - Processing /opt/airflow/dags/group_dag.py took 0.262 seconds
[2024-04-17T12:33:27.521+0000] {processor.py:154} INFO - Started process (PID=9306) to work on /opt/airflow/dags/group_dag.py
[2024-04-17T12:33:27.524+0000] {processor.py:756} INFO - Processing file /opt/airflow/dags/group_dag.py for tasks to queue
[2024-04-17T12:33:27.525+0000] {logging_mixin.py:120} INFO - [2024-04-17T12:33:27.525+0000] {dagbag.py:537} INFO - Filling up the DagBag from /opt/airflow/dags/group_dag.py
[2024-04-17T12:33:27.605+0000] {logging_mixin.py:120} INFO - [2024-04-17T12:33:27.599+0000] {dagbag.py:342} ERROR - Failed to import: /opt/airflow/dags/group_dag.py
Traceback (most recent call last):
  File "/home/airflow/.local/lib/python3.7/site-packages/airflow/models/dagbag.py", line 338, in parse
    loader.exec_module(new_module)
  File "<frozen importlib._bootstrap_external>", line 728, in exec_module
  File "<frozen importlib._bootstrap>", line 219, in _call_with_frames_removed
  File "/opt/airflow/dags/group_dag.py", line 27, in <module>
    subdag=subdag_downloads(dag.dag_id, 'downloads', args)
  File "/opt/airflow/dags/subdags/subdags_downloads.py", line 9, in subdag_downloads
    catch = args['catchup']) as dag:
TypeError: __init__() got an unexpected keyword argument 'catch'
[2024-04-17T12:33:27.606+0000] {processor.py:768} WARNING - No viable dags retrieved from /opt/airflow/dags/group_dag.py
[2024-04-17T12:33:27.658+0000] {processor.py:176} INFO - Processing /opt/airflow/dags/group_dag.py took 0.148 seconds
[2024-04-17T12:33:58.480+0000] {processor.py:154} INFO - Started process (PID=9375) to work on /opt/airflow/dags/group_dag.py
[2024-04-17T12:33:58.487+0000] {processor.py:756} INFO - Processing file /opt/airflow/dags/group_dag.py for tasks to queue
[2024-04-17T12:33:58.492+0000] {logging_mixin.py:120} INFO - [2024-04-17T12:33:58.491+0000] {dagbag.py:537} INFO - Filling up the DagBag from /opt/airflow/dags/group_dag.py
[2024-04-17T12:33:58.553+0000] {logging_mixin.py:120} INFO - [2024-04-17T12:33:58.545+0000] {dagbag.py:342} ERROR - Failed to import: /opt/airflow/dags/group_dag.py
Traceback (most recent call last):
  File "/home/airflow/.local/lib/python3.7/site-packages/airflow/models/dagbag.py", line 338, in parse
    loader.exec_module(new_module)
  File "<frozen importlib._bootstrap_external>", line 728, in exec_module
  File "<frozen importlib._bootstrap>", line 219, in _call_with_frames_removed
  File "/opt/airflow/dags/group_dag.py", line 27, in <module>
    subdag=subdag_downloads(dag.dag_id, 'downloads', args)
  File "/opt/airflow/dags/subdags/subdags_downloads.py", line 9, in subdag_downloads
    catch = args['catchup']) as dag:
TypeError: __init__() got an unexpected keyword argument 'catch'
[2024-04-17T12:33:58.556+0000] {processor.py:768} WARNING - No viable dags retrieved from /opt/airflow/dags/group_dag.py
[2024-04-17T12:33:58.600+0000] {processor.py:176} INFO - Processing /opt/airflow/dags/group_dag.py took 0.141 seconds
[2024-04-17T12:34:29.426+0000] {processor.py:154} INFO - Started process (PID=9444) to work on /opt/airflow/dags/group_dag.py
[2024-04-17T12:34:29.431+0000] {processor.py:756} INFO - Processing file /opt/airflow/dags/group_dag.py for tasks to queue
[2024-04-17T12:34:29.440+0000] {logging_mixin.py:120} INFO - [2024-04-17T12:34:29.439+0000] {dagbag.py:537} INFO - Filling up the DagBag from /opt/airflow/dags/group_dag.py
[2024-04-17T12:34:29.536+0000] {logging_mixin.py:120} INFO - [2024-04-17T12:34:29.531+0000] {dagbag.py:342} ERROR - Failed to import: /opt/airflow/dags/group_dag.py
Traceback (most recent call last):
  File "/home/airflow/.local/lib/python3.7/site-packages/airflow/models/dagbag.py", line 338, in parse
    loader.exec_module(new_module)
  File "<frozen importlib._bootstrap_external>", line 728, in exec_module
  File "<frozen importlib._bootstrap>", line 219, in _call_with_frames_removed
  File "/opt/airflow/dags/group_dag.py", line 27, in <module>
    subdag=subdag_downloads(dag.dag_id, 'downloads', args)
  File "/opt/airflow/dags/subdags/subdags_downloads.py", line 9, in subdag_downloads
    catch = args['catchup']) as dag:
TypeError: __init__() got an unexpected keyword argument 'catch'
[2024-04-17T12:34:29.538+0000] {processor.py:768} WARNING - No viable dags retrieved from /opt/airflow/dags/group_dag.py
[2024-04-17T12:34:29.597+0000] {processor.py:176} INFO - Processing /opt/airflow/dags/group_dag.py took 0.181 seconds
[2024-04-17T12:35:00.019+0000] {processor.py:154} INFO - Started process (PID=9523) to work on /opt/airflow/dags/group_dag.py
[2024-04-17T12:35:00.031+0000] {processor.py:756} INFO - Processing file /opt/airflow/dags/group_dag.py for tasks to queue
[2024-04-17T12:35:00.038+0000] {logging_mixin.py:120} INFO - [2024-04-17T12:35:00.037+0000] {dagbag.py:537} INFO - Filling up the DagBag from /opt/airflow/dags/group_dag.py
[2024-04-17T12:35:00.170+0000] {logging_mixin.py:120} INFO - [2024-04-17T12:35:00.153+0000] {dagbag.py:342} ERROR - Failed to import: /opt/airflow/dags/group_dag.py
Traceback (most recent call last):
  File "/home/airflow/.local/lib/python3.7/site-packages/airflow/models/dagbag.py", line 338, in parse
    loader.exec_module(new_module)
  File "<frozen importlib._bootstrap_external>", line 728, in exec_module
  File "<frozen importlib._bootstrap>", line 219, in _call_with_frames_removed
  File "/opt/airflow/dags/group_dag.py", line 27, in <module>
    subdag=subdag_downloads(dag.dag_id, 'downloads', args)
  File "/opt/airflow/dags/subdags/subdags_downloads.py", line 9, in subdag_downloads
    catch = args['catchup']) as dag:
TypeError: __init__() got an unexpected keyword argument 'catch'
[2024-04-17T12:35:00.172+0000] {processor.py:768} WARNING - No viable dags retrieved from /opt/airflow/dags/group_dag.py
[2024-04-17T12:35:00.244+0000] {processor.py:176} INFO - Processing /opt/airflow/dags/group_dag.py took 0.237 seconds
[2024-04-17T12:35:31.092+0000] {processor.py:154} INFO - Started process (PID=9591) to work on /opt/airflow/dags/group_dag.py
[2024-04-17T12:35:31.095+0000] {processor.py:756} INFO - Processing file /opt/airflow/dags/group_dag.py for tasks to queue
[2024-04-17T12:35:31.098+0000] {logging_mixin.py:120} INFO - [2024-04-17T12:35:31.098+0000] {dagbag.py:537} INFO - Filling up the DagBag from /opt/airflow/dags/group_dag.py
[2024-04-17T12:35:31.202+0000] {logging_mixin.py:120} INFO - [2024-04-17T12:35:31.193+0000] {dagbag.py:342} ERROR - Failed to import: /opt/airflow/dags/group_dag.py
Traceback (most recent call last):
  File "/home/airflow/.local/lib/python3.7/site-packages/airflow/models/dagbag.py", line 338, in parse
    loader.exec_module(new_module)
  File "<frozen importlib._bootstrap_external>", line 728, in exec_module
  File "<frozen importlib._bootstrap>", line 219, in _call_with_frames_removed
  File "/opt/airflow/dags/group_dag.py", line 27, in <module>
    subdag=subdag_downloads(dag.dag_id, 'downloads', args)
  File "/opt/airflow/dags/subdags/subdags_downloads.py", line 9, in subdag_downloads
    catch = args['catchup']) as dag:
TypeError: __init__() got an unexpected keyword argument 'catch'
[2024-04-17T12:35:31.204+0000] {processor.py:768} WARNING - No viable dags retrieved from /opt/airflow/dags/group_dag.py
[2024-04-17T12:35:31.255+0000] {processor.py:176} INFO - Processing /opt/airflow/dags/group_dag.py took 0.174 seconds
[2024-04-17T12:36:02.024+0000] {processor.py:154} INFO - Started process (PID=9662) to work on /opt/airflow/dags/group_dag.py
[2024-04-17T12:36:02.027+0000] {processor.py:756} INFO - Processing file /opt/airflow/dags/group_dag.py for tasks to queue
[2024-04-17T12:36:02.030+0000] {logging_mixin.py:120} INFO - [2024-04-17T12:36:02.030+0000] {dagbag.py:537} INFO - Filling up the DagBag from /opt/airflow/dags/group_dag.py
[2024-04-17T12:36:02.102+0000] {logging_mixin.py:120} INFO - [2024-04-17T12:36:02.098+0000] {dagbag.py:342} ERROR - Failed to import: /opt/airflow/dags/group_dag.py
Traceback (most recent call last):
  File "/home/airflow/.local/lib/python3.7/site-packages/airflow/models/dagbag.py", line 338, in parse
    loader.exec_module(new_module)
  File "<frozen importlib._bootstrap_external>", line 728, in exec_module
  File "<frozen importlib._bootstrap>", line 219, in _call_with_frames_removed
  File "/opt/airflow/dags/group_dag.py", line 27, in <module>
    subdag=subdag_downloads(dag.dag_id, 'downloads', args)
  File "/opt/airflow/dags/subdags/subdags_downloads.py", line 9, in subdag_downloads
    catch = args['catchup']) as dag:
TypeError: __init__() got an unexpected keyword argument 'catch'
[2024-04-17T12:36:02.105+0000] {processor.py:768} WARNING - No viable dags retrieved from /opt/airflow/dags/group_dag.py
[2024-04-17T12:36:02.148+0000] {processor.py:176} INFO - Processing /opt/airflow/dags/group_dag.py took 0.139 seconds
[2024-04-17T12:36:32.621+0000] {processor.py:154} INFO - Started process (PID=9739) to work on /opt/airflow/dags/group_dag.py
[2024-04-17T12:36:32.623+0000] {processor.py:756} INFO - Processing file /opt/airflow/dags/group_dag.py for tasks to queue
[2024-04-17T12:36:32.626+0000] {logging_mixin.py:120} INFO - [2024-04-17T12:36:32.626+0000] {dagbag.py:537} INFO - Filling up the DagBag from /opt/airflow/dags/group_dag.py
[2024-04-17T12:36:32.696+0000] {logging_mixin.py:120} INFO - [2024-04-17T12:36:32.690+0000] {dagbag.py:342} ERROR - Failed to import: /opt/airflow/dags/group_dag.py
Traceback (most recent call last):
  File "/home/airflow/.local/lib/python3.7/site-packages/airflow/models/dagbag.py", line 338, in parse
    loader.exec_module(new_module)
  File "<frozen importlib._bootstrap_external>", line 728, in exec_module
  File "<frozen importlib._bootstrap>", line 219, in _call_with_frames_removed
  File "/opt/airflow/dags/group_dag.py", line 27, in <module>
    subdag=subdag_downloads(dag.dag_id, 'downloads', args)
  File "/opt/airflow/dags/subdags/subdags_downloads.py", line 9, in subdag_downloads
    catch = args['catchup']) as dag:
TypeError: __init__() got an unexpected keyword argument 'catch'
[2024-04-17T12:36:32.697+0000] {processor.py:768} WARNING - No viable dags retrieved from /opt/airflow/dags/group_dag.py
[2024-04-17T12:36:32.749+0000] {processor.py:176} INFO - Processing /opt/airflow/dags/group_dag.py took 0.140 seconds
[2024-04-17T12:37:03.371+0000] {processor.py:154} INFO - Started process (PID=9808) to work on /opt/airflow/dags/group_dag.py
[2024-04-17T12:37:03.374+0000] {processor.py:756} INFO - Processing file /opt/airflow/dags/group_dag.py for tasks to queue
[2024-04-17T12:37:03.376+0000] {logging_mixin.py:120} INFO - [2024-04-17T12:37:03.376+0000] {dagbag.py:537} INFO - Filling up the DagBag from /opt/airflow/dags/group_dag.py
[2024-04-17T12:37:03.434+0000] {logging_mixin.py:120} INFO - [2024-04-17T12:37:03.428+0000] {dagbag.py:342} ERROR - Failed to import: /opt/airflow/dags/group_dag.py
Traceback (most recent call last):
  File "/home/airflow/.local/lib/python3.7/site-packages/airflow/models/dagbag.py", line 338, in parse
    loader.exec_module(new_module)
  File "<frozen importlib._bootstrap_external>", line 728, in exec_module
  File "<frozen importlib._bootstrap>", line 219, in _call_with_frames_removed
  File "/opt/airflow/dags/group_dag.py", line 27, in <module>
    subdag=subdag_downloads(dag.dag_id, 'downloads', args)
  File "/opt/airflow/dags/subdags/subdags_downloads.py", line 9, in subdag_downloads
    catch = args['catchup']) as dag:
TypeError: __init__() got an unexpected keyword argument 'catch'
[2024-04-17T12:37:03.436+0000] {processor.py:768} WARNING - No viable dags retrieved from /opt/airflow/dags/group_dag.py
[2024-04-17T12:37:03.499+0000] {processor.py:176} INFO - Processing /opt/airflow/dags/group_dag.py took 0.164 seconds
[2024-04-17T12:37:33.614+0000] {processor.py:154} INFO - Started process (PID=9886) to work on /opt/airflow/dags/group_dag.py
[2024-04-17T12:37:33.618+0000] {processor.py:756} INFO - Processing file /opt/airflow/dags/group_dag.py for tasks to queue
[2024-04-17T12:37:33.624+0000] {logging_mixin.py:120} INFO - [2024-04-17T12:37:33.623+0000] {dagbag.py:537} INFO - Filling up the DagBag from /opt/airflow/dags/group_dag.py
[2024-04-17T12:37:33.695+0000] {logging_mixin.py:120} INFO - [2024-04-17T12:37:33.688+0000] {dagbag.py:342} ERROR - Failed to import: /opt/airflow/dags/group_dag.py
Traceback (most recent call last):
  File "/home/airflow/.local/lib/python3.7/site-packages/airflow/models/dagbag.py", line 338, in parse
    loader.exec_module(new_module)
  File "<frozen importlib._bootstrap_external>", line 728, in exec_module
  File "<frozen importlib._bootstrap>", line 219, in _call_with_frames_removed
  File "/opt/airflow/dags/group_dag.py", line 27, in <module>
    subdag=subdag_downloads(dag.dag_id, 'downloads', args)
  File "/opt/airflow/dags/subdags/subdags_downloads.py", line 9, in subdag_downloads
    catch = args['catchup']) as dag:
TypeError: __init__() got an unexpected keyword argument 'catch'
[2024-04-17T12:37:33.697+0000] {processor.py:768} WARNING - No viable dags retrieved from /opt/airflow/dags/group_dag.py
[2024-04-17T12:37:33.732+0000] {processor.py:176} INFO - Processing /opt/airflow/dags/group_dag.py took 0.130 seconds
[2024-04-17T12:38:04.092+0000] {processor.py:154} INFO - Started process (PID=9953) to work on /opt/airflow/dags/group_dag.py
[2024-04-17T12:38:04.098+0000] {processor.py:756} INFO - Processing file /opt/airflow/dags/group_dag.py for tasks to queue
[2024-04-17T12:38:04.104+0000] {logging_mixin.py:120} INFO - [2024-04-17T12:38:04.104+0000] {dagbag.py:537} INFO - Filling up the DagBag from /opt/airflow/dags/group_dag.py
[2024-04-17T12:38:04.184+0000] {logging_mixin.py:120} INFO - [2024-04-17T12:38:04.176+0000] {dagbag.py:342} ERROR - Failed to import: /opt/airflow/dags/group_dag.py
Traceback (most recent call last):
  File "/home/airflow/.local/lib/python3.7/site-packages/airflow/models/dagbag.py", line 338, in parse
    loader.exec_module(new_module)
  File "<frozen importlib._bootstrap_external>", line 728, in exec_module
  File "<frozen importlib._bootstrap>", line 219, in _call_with_frames_removed
  File "/opt/airflow/dags/group_dag.py", line 27, in <module>
    subdag=subdag_downloads(dag.dag_id, 'downloads', args)
  File "/opt/airflow/dags/subdags/subdags_downloads.py", line 9, in subdag_downloads
    catch = args['catchup']) as dag:
TypeError: __init__() got an unexpected keyword argument 'catch'
[2024-04-17T12:38:04.186+0000] {processor.py:768} WARNING - No viable dags retrieved from /opt/airflow/dags/group_dag.py
[2024-04-17T12:38:04.227+0000] {processor.py:176} INFO - Processing /opt/airflow/dags/group_dag.py took 0.143 seconds
[2024-04-17T12:38:34.436+0000] {processor.py:154} INFO - Started process (PID=10020) to work on /opt/airflow/dags/group_dag.py
[2024-04-17T12:38:34.443+0000] {processor.py:756} INFO - Processing file /opt/airflow/dags/group_dag.py for tasks to queue
[2024-04-17T12:38:34.448+0000] {logging_mixin.py:120} INFO - [2024-04-17T12:38:34.447+0000] {dagbag.py:537} INFO - Filling up the DagBag from /opt/airflow/dags/group_dag.py
[2024-04-17T12:38:34.540+0000] {logging_mixin.py:120} INFO - [2024-04-17T12:38:34.535+0000] {dagbag.py:342} ERROR - Failed to import: /opt/airflow/dags/group_dag.py
Traceback (most recent call last):
  File "/home/airflow/.local/lib/python3.7/site-packages/airflow/models/dagbag.py", line 338, in parse
    loader.exec_module(new_module)
  File "<frozen importlib._bootstrap_external>", line 728, in exec_module
  File "<frozen importlib._bootstrap>", line 219, in _call_with_frames_removed
  File "/opt/airflow/dags/group_dag.py", line 27, in <module>
    subdag=subdag_downloads(dag.dag_id, 'downloads', args)
  File "/opt/airflow/dags/subdags/subdags_downloads.py", line 9, in subdag_downloads
    catch = args['catchup']) as dag:
TypeError: __init__() got an unexpected keyword argument 'catch'
[2024-04-17T12:38:34.542+0000] {processor.py:768} WARNING - No viable dags retrieved from /opt/airflow/dags/group_dag.py
[2024-04-17T12:38:34.603+0000] {processor.py:176} INFO - Processing /opt/airflow/dags/group_dag.py took 0.186 seconds
[2024-04-17T12:39:04.875+0000] {processor.py:154} INFO - Started process (PID=10097) to work on /opt/airflow/dags/group_dag.py
[2024-04-17T12:39:04.878+0000] {processor.py:756} INFO - Processing file /opt/airflow/dags/group_dag.py for tasks to queue
[2024-04-17T12:39:04.881+0000] {logging_mixin.py:120} INFO - [2024-04-17T12:39:04.881+0000] {dagbag.py:537} INFO - Filling up the DagBag from /opt/airflow/dags/group_dag.py
[2024-04-17T12:39:04.933+0000] {logging_mixin.py:120} INFO - [2024-04-17T12:39:04.929+0000] {dagbag.py:342} ERROR - Failed to import: /opt/airflow/dags/group_dag.py
Traceback (most recent call last):
  File "/home/airflow/.local/lib/python3.7/site-packages/airflow/models/dagbag.py", line 338, in parse
    loader.exec_module(new_module)
  File "<frozen importlib._bootstrap_external>", line 728, in exec_module
  File "<frozen importlib._bootstrap>", line 219, in _call_with_frames_removed
  File "/opt/airflow/dags/group_dag.py", line 27, in <module>
    subdag=subdag_downloads(dag.dag_id, 'downloads', args)
  File "/opt/airflow/dags/subdags/subdags_downloads.py", line 9, in subdag_downloads
    catch = args['catchup']) as dag:
TypeError: __init__() got an unexpected keyword argument 'catch'
[2024-04-17T12:39:04.935+0000] {processor.py:768} WARNING - No viable dags retrieved from /opt/airflow/dags/group_dag.py
[2024-04-17T12:39:04.979+0000] {processor.py:176} INFO - Processing /opt/airflow/dags/group_dag.py took 0.113 seconds
[2024-04-17T12:39:35.587+0000] {processor.py:154} INFO - Started process (PID=10164) to work on /opt/airflow/dags/group_dag.py
[2024-04-17T12:39:35.589+0000] {processor.py:756} INFO - Processing file /opt/airflow/dags/group_dag.py for tasks to queue
[2024-04-17T12:39:35.593+0000] {logging_mixin.py:120} INFO - [2024-04-17T12:39:35.593+0000] {dagbag.py:537} INFO - Filling up the DagBag from /opt/airflow/dags/group_dag.py
[2024-04-17T12:39:35.654+0000] {logging_mixin.py:120} INFO - [2024-04-17T12:39:35.649+0000] {dagbag.py:342} ERROR - Failed to import: /opt/airflow/dags/group_dag.py
Traceback (most recent call last):
  File "/home/airflow/.local/lib/python3.7/site-packages/airflow/models/dagbag.py", line 338, in parse
    loader.exec_module(new_module)
  File "<frozen importlib._bootstrap_external>", line 728, in exec_module
  File "<frozen importlib._bootstrap>", line 219, in _call_with_frames_removed
  File "/opt/airflow/dags/group_dag.py", line 27, in <module>
    subdag=subdag_downloads(dag.dag_id, 'downloads', args)
  File "/opt/airflow/dags/subdags/subdags_downloads.py", line 9, in subdag_downloads
    catch = args['catchup']) as dag:
TypeError: __init__() got an unexpected keyword argument 'catch'
[2024-04-17T12:39:35.656+0000] {processor.py:768} WARNING - No viable dags retrieved from /opt/airflow/dags/group_dag.py
[2024-04-17T12:39:35.748+0000] {processor.py:176} INFO - Processing /opt/airflow/dags/group_dag.py took 0.169 seconds
[2024-04-17T12:40:06.047+0000] {processor.py:154} INFO - Started process (PID=10231) to work on /opt/airflow/dags/group_dag.py
[2024-04-17T12:40:06.051+0000] {processor.py:756} INFO - Processing file /opt/airflow/dags/group_dag.py for tasks to queue
[2024-04-17T12:40:06.053+0000] {logging_mixin.py:120} INFO - [2024-04-17T12:40:06.053+0000] {dagbag.py:537} INFO - Filling up the DagBag from /opt/airflow/dags/group_dag.py
[2024-04-17T12:40:06.118+0000] {logging_mixin.py:120} INFO - [2024-04-17T12:40:06.108+0000] {dagbag.py:342} ERROR - Failed to import: /opt/airflow/dags/group_dag.py
Traceback (most recent call last):
  File "/home/airflow/.local/lib/python3.7/site-packages/airflow/models/dagbag.py", line 338, in parse
    loader.exec_module(new_module)
  File "<frozen importlib._bootstrap_external>", line 728, in exec_module
  File "<frozen importlib._bootstrap>", line 219, in _call_with_frames_removed
  File "/opt/airflow/dags/group_dag.py", line 27, in <module>
    subdag=subdag_downloads(dag.dag_id, 'downloads', args)
  File "/opt/airflow/dags/subdags/subdags_downloads.py", line 9, in subdag_downloads
    catch = args['catchup']) as dag:
TypeError: __init__() got an unexpected keyword argument 'catch'
[2024-04-17T12:40:06.120+0000] {processor.py:768} WARNING - No viable dags retrieved from /opt/airflow/dags/group_dag.py
[2024-04-17T12:40:06.179+0000] {processor.py:176} INFO - Processing /opt/airflow/dags/group_dag.py took 0.143 seconds
[2024-04-17T12:40:36.612+0000] {processor.py:154} INFO - Started process (PID=10308) to work on /opt/airflow/dags/group_dag.py
[2024-04-17T12:40:36.621+0000] {processor.py:756} INFO - Processing file /opt/airflow/dags/group_dag.py for tasks to queue
[2024-04-17T12:40:36.624+0000] {logging_mixin.py:120} INFO - [2024-04-17T12:40:36.624+0000] {dagbag.py:537} INFO - Filling up the DagBag from /opt/airflow/dags/group_dag.py
[2024-04-17T12:40:36.746+0000] {logging_mixin.py:120} INFO - [2024-04-17T12:40:36.739+0000] {dagbag.py:342} ERROR - Failed to import: /opt/airflow/dags/group_dag.py
Traceback (most recent call last):
  File "/home/airflow/.local/lib/python3.7/site-packages/airflow/models/dagbag.py", line 338, in parse
    loader.exec_module(new_module)
  File "<frozen importlib._bootstrap_external>", line 728, in exec_module
  File "<frozen importlib._bootstrap>", line 219, in _call_with_frames_removed
  File "/opt/airflow/dags/group_dag.py", line 27, in <module>
    subdag=subdag_downloads(dag.dag_id, 'downloads', args)
  File "/opt/airflow/dags/subdags/subdags_downloads.py", line 9, in subdag_downloads
    catch = args['catchup']) as dag:
TypeError: __init__() got an unexpected keyword argument 'catch'
[2024-04-17T12:40:36.754+0000] {processor.py:768} WARNING - No viable dags retrieved from /opt/airflow/dags/group_dag.py
[2024-04-17T12:40:36.841+0000] {processor.py:176} INFO - Processing /opt/airflow/dags/group_dag.py took 0.237 seconds
[2024-04-17T12:41:06.997+0000] {processor.py:154} INFO - Started process (PID=10376) to work on /opt/airflow/dags/group_dag.py
[2024-04-17T12:41:07.001+0000] {processor.py:756} INFO - Processing file /opt/airflow/dags/group_dag.py for tasks to queue
[2024-04-17T12:41:07.004+0000] {logging_mixin.py:120} INFO - [2024-04-17T12:41:07.004+0000] {dagbag.py:537} INFO - Filling up the DagBag from /opt/airflow/dags/group_dag.py
[2024-04-17T12:41:07.060+0000] {logging_mixin.py:120} INFO - [2024-04-17T12:41:07.055+0000] {dagbag.py:342} ERROR - Failed to import: /opt/airflow/dags/group_dag.py
Traceback (most recent call last):
  File "/home/airflow/.local/lib/python3.7/site-packages/airflow/models/dagbag.py", line 338, in parse
    loader.exec_module(new_module)
  File "<frozen importlib._bootstrap_external>", line 728, in exec_module
  File "<frozen importlib._bootstrap>", line 219, in _call_with_frames_removed
  File "/opt/airflow/dags/group_dag.py", line 27, in <module>
    subdag=subdag_downloads(dag.dag_id, 'downloads', args)
  File "/opt/airflow/dags/subdags/subdags_downloads.py", line 9, in subdag_downloads
    catch = args['catchup']) as dag:
TypeError: __init__() got an unexpected keyword argument 'catch'
[2024-04-17T12:41:07.062+0000] {processor.py:768} WARNING - No viable dags retrieved from /opt/airflow/dags/group_dag.py
[2024-04-17T12:41:07.118+0000] {processor.py:176} INFO - Processing /opt/airflow/dags/group_dag.py took 0.128 seconds
[2024-04-17T12:41:37.391+0000] {processor.py:154} INFO - Started process (PID=10444) to work on /opt/airflow/dags/group_dag.py
[2024-04-17T12:41:37.394+0000] {processor.py:756} INFO - Processing file /opt/airflow/dags/group_dag.py for tasks to queue
[2024-04-17T12:41:37.397+0000] {logging_mixin.py:120} INFO - [2024-04-17T12:41:37.396+0000] {dagbag.py:537} INFO - Filling up the DagBag from /opt/airflow/dags/group_dag.py
[2024-04-17T12:41:37.465+0000] {logging_mixin.py:120} INFO - [2024-04-17T12:41:37.461+0000] {dagbag.py:342} ERROR - Failed to import: /opt/airflow/dags/group_dag.py
Traceback (most recent call last):
  File "/home/airflow/.local/lib/python3.7/site-packages/airflow/models/dagbag.py", line 338, in parse
    loader.exec_module(new_module)
  File "<frozen importlib._bootstrap_external>", line 728, in exec_module
  File "<frozen importlib._bootstrap>", line 219, in _call_with_frames_removed
  File "/opt/airflow/dags/group_dag.py", line 27, in <module>
    subdag=subdag_downloads(dag.dag_id, 'downloads', args)
  File "/opt/airflow/dags/subdags/subdags_downloads.py", line 9, in subdag_downloads
    catch = args['catchup']) as dag:
TypeError: __init__() got an unexpected keyword argument 'catch'
[2024-04-17T12:41:37.468+0000] {processor.py:768} WARNING - No viable dags retrieved from /opt/airflow/dags/group_dag.py
[2024-04-17T12:41:37.517+0000] {processor.py:176} INFO - Processing /opt/airflow/dags/group_dag.py took 0.138 seconds
[2024-04-17T12:42:07.936+0000] {processor.py:154} INFO - Started process (PID=10522) to work on /opt/airflow/dags/group_dag.py
[2024-04-17T12:42:07.940+0000] {processor.py:756} INFO - Processing file /opt/airflow/dags/group_dag.py for tasks to queue
[2024-04-17T12:42:07.948+0000] {logging_mixin.py:120} INFO - [2024-04-17T12:42:07.948+0000] {dagbag.py:537} INFO - Filling up the DagBag from /opt/airflow/dags/group_dag.py
[2024-04-17T12:42:08.056+0000] {logging_mixin.py:120} INFO - [2024-04-17T12:42:08.051+0000] {dagbag.py:342} ERROR - Failed to import: /opt/airflow/dags/group_dag.py
Traceback (most recent call last):
  File "/home/airflow/.local/lib/python3.7/site-packages/airflow/models/dagbag.py", line 338, in parse
    loader.exec_module(new_module)
  File "<frozen importlib._bootstrap_external>", line 728, in exec_module
  File "<frozen importlib._bootstrap>", line 219, in _call_with_frames_removed
  File "/opt/airflow/dags/group_dag.py", line 27, in <module>
    subdag=subdag_downloads(dag.dag_id, 'downloads', args)
  File "/opt/airflow/dags/subdags/subdags_downloads.py", line 9, in subdag_downloads
    catch = args['catchup']) as dag:
TypeError: __init__() got an unexpected keyword argument 'catch'
[2024-04-17T12:42:08.064+0000] {processor.py:768} WARNING - No viable dags retrieved from /opt/airflow/dags/group_dag.py
[2024-04-17T12:42:08.129+0000] {processor.py:176} INFO - Processing /opt/airflow/dags/group_dag.py took 0.207 seconds
[2024-04-17T12:42:38.820+0000] {processor.py:154} INFO - Started process (PID=10592) to work on /opt/airflow/dags/group_dag.py
[2024-04-17T12:42:38.827+0000] {processor.py:756} INFO - Processing file /opt/airflow/dags/group_dag.py for tasks to queue
[2024-04-17T12:42:38.840+0000] {logging_mixin.py:120} INFO - [2024-04-17T12:42:38.840+0000] {dagbag.py:537} INFO - Filling up the DagBag from /opt/airflow/dags/group_dag.py
[2024-04-17T12:42:39.057+0000] {logging_mixin.py:120} INFO - [2024-04-17T12:42:39.040+0000] {dagbag.py:342} ERROR - Failed to import: /opt/airflow/dags/group_dag.py
Traceback (most recent call last):
  File "/home/airflow/.local/lib/python3.7/site-packages/airflow/models/dagbag.py", line 338, in parse
    loader.exec_module(new_module)
  File "<frozen importlib._bootstrap_external>", line 728, in exec_module
  File "<frozen importlib._bootstrap>", line 219, in _call_with_frames_removed
  File "/opt/airflow/dags/group_dag.py", line 27, in <module>
    subdag=subdag_downloads(dag.dag_id, 'downloads', args)
  File "/opt/airflow/dags/subdags/subdags_downloads.py", line 9, in subdag_downloads
    catch = args['catchup']) as dag:
TypeError: __init__() got an unexpected keyword argument 'catch'
[2024-04-17T12:42:39.058+0000] {processor.py:768} WARNING - No viable dags retrieved from /opt/airflow/dags/group_dag.py
[2024-04-17T12:42:39.124+0000] {processor.py:176} INFO - Processing /opt/airflow/dags/group_dag.py took 0.335 seconds
[2024-04-17T12:43:09.604+0000] {processor.py:154} INFO - Started process (PID=10661) to work on /opt/airflow/dags/group_dag.py
[2024-04-17T12:43:09.606+0000] {processor.py:756} INFO - Processing file /opt/airflow/dags/group_dag.py for tasks to queue
[2024-04-17T12:43:09.609+0000] {logging_mixin.py:120} INFO - [2024-04-17T12:43:09.609+0000] {dagbag.py:537} INFO - Filling up the DagBag from /opt/airflow/dags/group_dag.py
[2024-04-17T12:43:09.656+0000] {logging_mixin.py:120} INFO - [2024-04-17T12:43:09.653+0000] {dagbag.py:342} ERROR - Failed to import: /opt/airflow/dags/group_dag.py
Traceback (most recent call last):
  File "/home/airflow/.local/lib/python3.7/site-packages/airflow/models/dagbag.py", line 338, in parse
    loader.exec_module(new_module)
  File "<frozen importlib._bootstrap_external>", line 728, in exec_module
  File "<frozen importlib._bootstrap>", line 219, in _call_with_frames_removed
  File "/opt/airflow/dags/group_dag.py", line 27, in <module>
    subdag=subdag_downloads(dag.dag_id, 'downloads', args)
  File "/opt/airflow/dags/subdags/subdags_downloads.py", line 9, in subdag_downloads
    catch = args['catchup']) as dag:
TypeError: __init__() got an unexpected keyword argument 'catch'
[2024-04-17T12:43:09.657+0000] {processor.py:768} WARNING - No viable dags retrieved from /opt/airflow/dags/group_dag.py
[2024-04-17T12:43:09.716+0000] {processor.py:176} INFO - Processing /opt/airflow/dags/group_dag.py took 0.119 seconds
[2024-04-17T12:43:39.857+0000] {processor.py:154} INFO - Started process (PID=10739) to work on /opt/airflow/dags/group_dag.py
[2024-04-17T12:43:39.859+0000] {processor.py:756} INFO - Processing file /opt/airflow/dags/group_dag.py for tasks to queue
[2024-04-17T12:43:39.861+0000] {logging_mixin.py:120} INFO - [2024-04-17T12:43:39.861+0000] {dagbag.py:537} INFO - Filling up the DagBag from /opt/airflow/dags/group_dag.py
[2024-04-17T12:43:39.900+0000] {logging_mixin.py:120} INFO - [2024-04-17T12:43:39.896+0000] {dagbag.py:342} ERROR - Failed to import: /opt/airflow/dags/group_dag.py
Traceback (most recent call last):
  File "/home/airflow/.local/lib/python3.7/site-packages/airflow/models/dagbag.py", line 338, in parse
    loader.exec_module(new_module)
  File "<frozen importlib._bootstrap_external>", line 728, in exec_module
  File "<frozen importlib._bootstrap>", line 219, in _call_with_frames_removed
  File "/opt/airflow/dags/group_dag.py", line 27, in <module>
    subdag=subdag_downloads(dag.dag_id, 'downloads', args)
  File "/opt/airflow/dags/subdags/subdags_downloads.py", line 9, in subdag_downloads
    catch = args['catchup']) as dag:
TypeError: __init__() got an unexpected keyword argument 'catch'
[2024-04-17T12:43:39.901+0000] {processor.py:768} WARNING - No viable dags retrieved from /opt/airflow/dags/group_dag.py
[2024-04-17T12:43:39.933+0000] {processor.py:176} INFO - Processing /opt/airflow/dags/group_dag.py took 0.081 seconds
[2024-04-17T12:44:10.546+0000] {processor.py:154} INFO - Started process (PID=10805) to work on /opt/airflow/dags/group_dag.py
[2024-04-17T12:44:10.547+0000] {processor.py:756} INFO - Processing file /opt/airflow/dags/group_dag.py for tasks to queue
[2024-04-17T12:44:10.551+0000] {logging_mixin.py:120} INFO - [2024-04-17T12:44:10.550+0000] {dagbag.py:537} INFO - Filling up the DagBag from /opt/airflow/dags/group_dag.py
[2024-04-17T12:44:10.603+0000] {logging_mixin.py:120} INFO - [2024-04-17T12:44:10.596+0000] {dagbag.py:342} ERROR - Failed to import: /opt/airflow/dags/group_dag.py
Traceback (most recent call last):
  File "/home/airflow/.local/lib/python3.7/site-packages/airflow/models/dagbag.py", line 338, in parse
    loader.exec_module(new_module)
  File "<frozen importlib._bootstrap_external>", line 728, in exec_module
  File "<frozen importlib._bootstrap>", line 219, in _call_with_frames_removed
  File "/opt/airflow/dags/group_dag.py", line 27, in <module>
    subdag=subdag_downloads(dag.dag_id, 'downloads', args)
  File "/opt/airflow/dags/subdags/subdags_downloads.py", line 9, in subdag_downloads
    catch = args['catchup']) as dag:
TypeError: __init__() got an unexpected keyword argument 'catch'
[2024-04-17T12:44:10.607+0000] {processor.py:768} WARNING - No viable dags retrieved from /opt/airflow/dags/group_dag.py
[2024-04-17T12:44:10.663+0000] {processor.py:176} INFO - Processing /opt/airflow/dags/group_dag.py took 0.133 seconds
[2024-04-17T12:44:41.072+0000] {processor.py:154} INFO - Started process (PID=10884) to work on /opt/airflow/dags/group_dag.py
[2024-04-17T12:44:41.081+0000] {processor.py:756} INFO - Processing file /opt/airflow/dags/group_dag.py for tasks to queue
[2024-04-17T12:44:41.086+0000] {logging_mixin.py:120} INFO - [2024-04-17T12:44:41.085+0000] {dagbag.py:537} INFO - Filling up the DagBag from /opt/airflow/dags/group_dag.py
[2024-04-17T12:44:41.201+0000] {logging_mixin.py:120} INFO - [2024-04-17T12:44:41.188+0000] {dagbag.py:342} ERROR - Failed to import: /opt/airflow/dags/group_dag.py
Traceback (most recent call last):
  File "/home/airflow/.local/lib/python3.7/site-packages/airflow/models/dagbag.py", line 338, in parse
    loader.exec_module(new_module)
  File "<frozen importlib._bootstrap_external>", line 728, in exec_module
  File "<frozen importlib._bootstrap>", line 219, in _call_with_frames_removed
  File "/opt/airflow/dags/group_dag.py", line 27, in <module>
    subdag=subdag_downloads(dag.dag_id, 'downloads', args)
  File "/opt/airflow/dags/subdags/subdags_downloads.py", line 9, in subdag_downloads
    catch = args['catchup']) as dag:
TypeError: __init__() got an unexpected keyword argument 'catch'
[2024-04-17T12:44:41.204+0000] {processor.py:768} WARNING - No viable dags retrieved from /opt/airflow/dags/group_dag.py
[2024-04-17T12:44:41.267+0000] {processor.py:176} INFO - Processing /opt/airflow/dags/group_dag.py took 0.241 seconds
[2024-04-17T12:45:11.403+0000] {processor.py:154} INFO - Started process (PID=10953) to work on /opt/airflow/dags/group_dag.py
[2024-04-17T12:45:11.406+0000] {processor.py:756} INFO - Processing file /opt/airflow/dags/group_dag.py for tasks to queue
[2024-04-17T12:45:11.408+0000] {logging_mixin.py:120} INFO - [2024-04-17T12:45:11.408+0000] {dagbag.py:537} INFO - Filling up the DagBag from /opt/airflow/dags/group_dag.py
[2024-04-17T12:45:11.458+0000] {logging_mixin.py:120} INFO - [2024-04-17T12:45:11.454+0000] {dagbag.py:342} ERROR - Failed to import: /opt/airflow/dags/group_dag.py
Traceback (most recent call last):
  File "/home/airflow/.local/lib/python3.7/site-packages/airflow/models/dagbag.py", line 338, in parse
    loader.exec_module(new_module)
  File "<frozen importlib._bootstrap_external>", line 728, in exec_module
  File "<frozen importlib._bootstrap>", line 219, in _call_with_frames_removed
  File "/opt/airflow/dags/group_dag.py", line 27, in <module>
    subdag=subdag_downloads(dag.dag_id, 'downloads', args)
  File "/opt/airflow/dags/subdags/subdags_downloads.py", line 9, in subdag_downloads
    catch = args['catchup']) as dag:
TypeError: __init__() got an unexpected keyword argument 'catch'
[2024-04-17T12:45:11.460+0000] {processor.py:768} WARNING - No viable dags retrieved from /opt/airflow/dags/group_dag.py
[2024-04-17T12:45:11.520+0000] {processor.py:176} INFO - Processing /opt/airflow/dags/group_dag.py took 0.127 seconds
[2024-04-17T12:45:41.939+0000] {processor.py:154} INFO - Started process (PID=11021) to work on /opt/airflow/dags/group_dag.py
[2024-04-17T12:45:41.942+0000] {processor.py:756} INFO - Processing file /opt/airflow/dags/group_dag.py for tasks to queue
[2024-04-17T12:45:41.945+0000] {logging_mixin.py:120} INFO - [2024-04-17T12:45:41.944+0000] {dagbag.py:537} INFO - Filling up the DagBag from /opt/airflow/dags/group_dag.py
[2024-04-17T12:45:42.022+0000] {logging_mixin.py:120} INFO - [2024-04-17T12:45:42.016+0000] {dagbag.py:342} ERROR - Failed to import: /opt/airflow/dags/group_dag.py
Traceback (most recent call last):
  File "/home/airflow/.local/lib/python3.7/site-packages/airflow/models/dagbag.py", line 338, in parse
    loader.exec_module(new_module)
  File "<frozen importlib._bootstrap_external>", line 728, in exec_module
  File "<frozen importlib._bootstrap>", line 219, in _call_with_frames_removed
  File "/opt/airflow/dags/group_dag.py", line 27, in <module>
    subdag=subdag_downloads(dag.dag_id, 'downloads', args)
  File "/opt/airflow/dags/subdags/subdags_downloads.py", line 9, in subdag_downloads
    catch = args['catchup']) as dag:
TypeError: __init__() got an unexpected keyword argument 'catch'
[2024-04-17T12:45:42.026+0000] {processor.py:768} WARNING - No viable dags retrieved from /opt/airflow/dags/group_dag.py
[2024-04-17T12:45:42.077+0000] {processor.py:176} INFO - Processing /opt/airflow/dags/group_dag.py took 0.149 seconds
[2024-04-17T12:46:12.179+0000] {processor.py:154} INFO - Started process (PID=11096) to work on /opt/airflow/dags/group_dag.py
[2024-04-17T12:46:12.185+0000] {processor.py:756} INFO - Processing file /opt/airflow/dags/group_dag.py for tasks to queue
[2024-04-17T12:46:12.196+0000] {logging_mixin.py:120} INFO - [2024-04-17T12:46:12.195+0000] {dagbag.py:537} INFO - Filling up the DagBag from /opt/airflow/dags/group_dag.py
[2024-04-17T12:46:12.311+0000] {logging_mixin.py:120} INFO - [2024-04-17T12:46:12.302+0000] {dagbag.py:342} ERROR - Failed to import: /opt/airflow/dags/group_dag.py
Traceback (most recent call last):
  File "/home/airflow/.local/lib/python3.7/site-packages/airflow/models/dagbag.py", line 338, in parse
    loader.exec_module(new_module)
  File "<frozen importlib._bootstrap_external>", line 728, in exec_module
  File "<frozen importlib._bootstrap>", line 219, in _call_with_frames_removed
  File "/opt/airflow/dags/group_dag.py", line 27, in <module>
    subdag=subdag_downloads(dag.dag_id, 'downloads', args)
  File "/opt/airflow/dags/subdags/subdags_downloads.py", line 9, in subdag_downloads
    catch = args['catchup']) as dag:
TypeError: __init__() got an unexpected keyword argument 'catch'
[2024-04-17T12:46:12.314+0000] {processor.py:768} WARNING - No viable dags retrieved from /opt/airflow/dags/group_dag.py
[2024-04-17T12:46:12.416+0000] {processor.py:176} INFO - Processing /opt/airflow/dags/group_dag.py took 0.258 seconds
[2024-04-17T12:46:42.973+0000] {processor.py:154} INFO - Started process (PID=11166) to work on /opt/airflow/dags/group_dag.py
[2024-04-17T12:46:42.976+0000] {processor.py:756} INFO - Processing file /opt/airflow/dags/group_dag.py for tasks to queue
[2024-04-17T12:46:42.978+0000] {logging_mixin.py:120} INFO - [2024-04-17T12:46:42.978+0000] {dagbag.py:537} INFO - Filling up the DagBag from /opt/airflow/dags/group_dag.py
[2024-04-17T12:46:43.021+0000] {logging_mixin.py:120} INFO - [2024-04-17T12:46:43.018+0000] {dagbag.py:342} ERROR - Failed to import: /opt/airflow/dags/group_dag.py
Traceback (most recent call last):
  File "/home/airflow/.local/lib/python3.7/site-packages/airflow/models/dagbag.py", line 338, in parse
    loader.exec_module(new_module)
  File "<frozen importlib._bootstrap_external>", line 728, in exec_module
  File "<frozen importlib._bootstrap>", line 219, in _call_with_frames_removed
  File "/opt/airflow/dags/group_dag.py", line 27, in <module>
    subdag=subdag_downloads(dag.dag_id, 'downloads', args)
  File "/opt/airflow/dags/subdags/subdags_downloads.py", line 9, in subdag_downloads
    catch = args['catchup']) as dag:
TypeError: __init__() got an unexpected keyword argument 'catch'
[2024-04-17T12:46:43.022+0000] {processor.py:768} WARNING - No viable dags retrieved from /opt/airflow/dags/group_dag.py
[2024-04-17T12:46:43.056+0000] {processor.py:176} INFO - Processing /opt/airflow/dags/group_dag.py took 0.092 seconds
[2024-04-17T12:47:13.858+0000] {processor.py:154} INFO - Started process (PID=11245) to work on /opt/airflow/dags/group_dag.py
[2024-04-17T12:47:13.861+0000] {processor.py:756} INFO - Processing file /opt/airflow/dags/group_dag.py for tasks to queue
[2024-04-17T12:47:13.863+0000] {logging_mixin.py:120} INFO - [2024-04-17T12:47:13.862+0000] {dagbag.py:537} INFO - Filling up the DagBag from /opt/airflow/dags/group_dag.py
[2024-04-17T12:47:13.919+0000] {logging_mixin.py:120} INFO - [2024-04-17T12:47:13.914+0000] {dagbag.py:342} ERROR - Failed to import: /opt/airflow/dags/group_dag.py
Traceback (most recent call last):
  File "/home/airflow/.local/lib/python3.7/site-packages/airflow/models/dagbag.py", line 338, in parse
    loader.exec_module(new_module)
  File "<frozen importlib._bootstrap_external>", line 728, in exec_module
  File "<frozen importlib._bootstrap>", line 219, in _call_with_frames_removed
  File "/opt/airflow/dags/group_dag.py", line 27, in <module>
    subdag=subdag_downloads(dag.dag_id, 'downloads', args)
  File "/opt/airflow/dags/subdags/subdags_downloads.py", line 9, in subdag_downloads
    catch = args['catchup']) as dag:
TypeError: __init__() got an unexpected keyword argument 'catch'
[2024-04-17T12:47:13.922+0000] {processor.py:768} WARNING - No viable dags retrieved from /opt/airflow/dags/group_dag.py
[2024-04-17T12:47:13.960+0000] {processor.py:176} INFO - Processing /opt/airflow/dags/group_dag.py took 0.110 seconds
[2024-04-17T12:47:44.088+0000] {processor.py:154} INFO - Started process (PID=11312) to work on /opt/airflow/dags/group_dag.py
[2024-04-17T12:47:44.091+0000] {processor.py:756} INFO - Processing file /opt/airflow/dags/group_dag.py for tasks to queue
[2024-04-17T12:47:44.092+0000] {logging_mixin.py:120} INFO - [2024-04-17T12:47:44.092+0000] {dagbag.py:537} INFO - Filling up the DagBag from /opt/airflow/dags/group_dag.py
[2024-04-17T12:47:44.137+0000] {logging_mixin.py:120} INFO - [2024-04-17T12:47:44.133+0000] {dagbag.py:342} ERROR - Failed to import: /opt/airflow/dags/group_dag.py
Traceback (most recent call last):
  File "/home/airflow/.local/lib/python3.7/site-packages/airflow/models/dagbag.py", line 338, in parse
    loader.exec_module(new_module)
  File "<frozen importlib._bootstrap_external>", line 728, in exec_module
  File "<frozen importlib._bootstrap>", line 219, in _call_with_frames_removed
  File "/opt/airflow/dags/group_dag.py", line 27, in <module>
    subdag=subdag_downloads(dag.dag_id, 'downloads', args)
  File "/opt/airflow/dags/subdags/subdags_downloads.py", line 9, in subdag_downloads
    catch = args['catchup']) as dag:
TypeError: __init__() got an unexpected keyword argument 'catch'
[2024-04-17T12:47:44.139+0000] {processor.py:768} WARNING - No viable dags retrieved from /opt/airflow/dags/group_dag.py
[2024-04-17T12:47:44.175+0000] {processor.py:176} INFO - Processing /opt/airflow/dags/group_dag.py took 0.095 seconds
[2024-04-17T12:48:15.095+0000] {processor.py:154} INFO - Started process (PID=11392) to work on /opt/airflow/dags/group_dag.py
[2024-04-17T12:48:15.098+0000] {processor.py:756} INFO - Processing file /opt/airflow/dags/group_dag.py for tasks to queue
[2024-04-17T12:48:15.101+0000] {logging_mixin.py:120} INFO - [2024-04-17T12:48:15.100+0000] {dagbag.py:537} INFO - Filling up the DagBag from /opt/airflow/dags/group_dag.py
[2024-04-17T12:48:15.187+0000] {logging_mixin.py:120} INFO - [2024-04-17T12:48:15.181+0000] {dagbag.py:342} ERROR - Failed to import: /opt/airflow/dags/group_dag.py
Traceback (most recent call last):
  File "/home/airflow/.local/lib/python3.7/site-packages/airflow/models/dagbag.py", line 338, in parse
    loader.exec_module(new_module)
  File "<frozen importlib._bootstrap_external>", line 728, in exec_module
  File "<frozen importlib._bootstrap>", line 219, in _call_with_frames_removed
  File "/opt/airflow/dags/group_dag.py", line 27, in <module>
    subdag=subdag_downloads(dag.dag_id, 'downloads', args)
  File "/opt/airflow/dags/subdags/subdags_downloads.py", line 9, in subdag_downloads
    catch = args['catchup']) as dag:
TypeError: __init__() got an unexpected keyword argument 'catch'
[2024-04-17T12:48:15.191+0000] {processor.py:768} WARNING - No viable dags retrieved from /opt/airflow/dags/group_dag.py
[2024-04-17T12:48:15.248+0000] {processor.py:176} INFO - Processing /opt/airflow/dags/group_dag.py took 0.162 seconds
[2024-04-17T12:48:45.935+0000] {processor.py:154} INFO - Started process (PID=11461) to work on /opt/airflow/dags/group_dag.py
[2024-04-17T12:48:45.939+0000] {processor.py:756} INFO - Processing file /opt/airflow/dags/group_dag.py for tasks to queue
[2024-04-17T12:48:45.948+0000] {logging_mixin.py:120} INFO - [2024-04-17T12:48:45.946+0000] {dagbag.py:537} INFO - Filling up the DagBag from /opt/airflow/dags/group_dag.py
[2024-04-17T12:48:46.053+0000] {logging_mixin.py:120} INFO - [2024-04-17T12:48:46.047+0000] {dagbag.py:342} ERROR - Failed to import: /opt/airflow/dags/group_dag.py
Traceback (most recent call last):
  File "/home/airflow/.local/lib/python3.7/site-packages/airflow/models/dagbag.py", line 338, in parse
    loader.exec_module(new_module)
  File "<frozen importlib._bootstrap_external>", line 728, in exec_module
  File "<frozen importlib._bootstrap>", line 219, in _call_with_frames_removed
  File "/opt/airflow/dags/group_dag.py", line 27, in <module>
    subdag=subdag_downloads(dag.dag_id, 'downloads', args)
  File "/opt/airflow/dags/subdags/subdags_downloads.py", line 9, in subdag_downloads
    catch = args['catchup']) as dag:
TypeError: __init__() got an unexpected keyword argument 'catch'
[2024-04-17T12:48:46.056+0000] {processor.py:768} WARNING - No viable dags retrieved from /opt/airflow/dags/group_dag.py
[2024-04-17T12:48:46.115+0000] {processor.py:176} INFO - Processing /opt/airflow/dags/group_dag.py took 0.209 seconds
[2024-04-17T12:49:16.385+0000] {processor.py:154} INFO - Started process (PID=11530) to work on /opt/airflow/dags/group_dag.py
[2024-04-17T12:49:16.388+0000] {processor.py:756} INFO - Processing file /opt/airflow/dags/group_dag.py for tasks to queue
[2024-04-17T12:49:16.391+0000] {logging_mixin.py:120} INFO - [2024-04-17T12:49:16.390+0000] {dagbag.py:537} INFO - Filling up the DagBag from /opt/airflow/dags/group_dag.py
[2024-04-17T12:49:16.465+0000] {logging_mixin.py:120} INFO - [2024-04-17T12:49:16.457+0000] {dagbag.py:342} ERROR - Failed to import: /opt/airflow/dags/group_dag.py
Traceback (most recent call last):
  File "/home/airflow/.local/lib/python3.7/site-packages/airflow/models/dagbag.py", line 338, in parse
    loader.exec_module(new_module)
  File "<frozen importlib._bootstrap_external>", line 728, in exec_module
  File "<frozen importlib._bootstrap>", line 219, in _call_with_frames_removed
  File "/opt/airflow/dags/group_dag.py", line 27, in <module>
    subdag=subdag_downloads(dag.dag_id, 'downloads', args)
  File "/opt/airflow/dags/subdags/subdags_downloads.py", line 9, in subdag_downloads
    catch = args['catchup']) as dag:
TypeError: __init__() got an unexpected keyword argument 'catch'
[2024-04-17T12:49:16.466+0000] {processor.py:768} WARNING - No viable dags retrieved from /opt/airflow/dags/group_dag.py
[2024-04-17T12:49:16.525+0000] {processor.py:176} INFO - Processing /opt/airflow/dags/group_dag.py took 0.150 seconds
[2024-04-17T12:49:47.359+0000] {processor.py:154} INFO - Started process (PID=11608) to work on /opt/airflow/dags/group_dag.py
[2024-04-17T12:49:47.362+0000] {processor.py:756} INFO - Processing file /opt/airflow/dags/group_dag.py for tasks to queue
[2024-04-17T12:49:47.364+0000] {logging_mixin.py:120} INFO - [2024-04-17T12:49:47.364+0000] {dagbag.py:537} INFO - Filling up the DagBag from /opt/airflow/dags/group_dag.py
[2024-04-17T12:49:47.424+0000] {logging_mixin.py:120} INFO - [2024-04-17T12:49:47.420+0000] {dagbag.py:342} ERROR - Failed to import: /opt/airflow/dags/group_dag.py
Traceback (most recent call last):
  File "/home/airflow/.local/lib/python3.7/site-packages/airflow/models/dagbag.py", line 338, in parse
    loader.exec_module(new_module)
  File "<frozen importlib._bootstrap_external>", line 728, in exec_module
  File "<frozen importlib._bootstrap>", line 219, in _call_with_frames_removed
  File "/opt/airflow/dags/group_dag.py", line 27, in <module>
    subdag=subdag_downloads(dag.dag_id, 'downloads', args)
  File "/opt/airflow/dags/subdags/subdags_downloads.py", line 9, in subdag_downloads
    catch = args['catchup']) as dag:
TypeError: __init__() got an unexpected keyword argument 'catch'
[2024-04-17T12:49:47.425+0000] {processor.py:768} WARNING - No viable dags retrieved from /opt/airflow/dags/group_dag.py
[2024-04-17T12:49:47.491+0000] {processor.py:176} INFO - Processing /opt/airflow/dags/group_dag.py took 0.138 seconds
[2024-04-17T12:50:17.765+0000] {processor.py:154} INFO - Started process (PID=11677) to work on /opt/airflow/dags/group_dag.py
[2024-04-17T12:50:17.775+0000] {processor.py:756} INFO - Processing file /opt/airflow/dags/group_dag.py for tasks to queue
[2024-04-17T12:50:17.795+0000] {logging_mixin.py:120} INFO - [2024-04-17T12:50:17.794+0000] {dagbag.py:537} INFO - Filling up the DagBag from /opt/airflow/dags/group_dag.py
[2024-04-17T12:50:17.979+0000] {logging_mixin.py:120} INFO - [2024-04-17T12:50:17.945+0000] {dagbag.py:342} ERROR - Failed to import: /opt/airflow/dags/group_dag.py
Traceback (most recent call last):
  File "/home/airflow/.local/lib/python3.7/site-packages/airflow/models/dagbag.py", line 338, in parse
    loader.exec_module(new_module)
  File "<frozen importlib._bootstrap_external>", line 728, in exec_module
  File "<frozen importlib._bootstrap>", line 219, in _call_with_frames_removed
  File "/opt/airflow/dags/group_dag.py", line 27, in <module>
    subdag=subdag_downloads(dag.dag_id, 'downloads', args)
  File "/opt/airflow/dags/subdags/subdags_downloads.py", line 9, in subdag_downloads
    catch = args['catchup']) as dag:
TypeError: __init__() got an unexpected keyword argument 'catch'
[2024-04-17T12:50:17.984+0000] {processor.py:768} WARNING - No viable dags retrieved from /opt/airflow/dags/group_dag.py
[2024-04-17T12:50:18.110+0000] {processor.py:176} INFO - Processing /opt/airflow/dags/group_dag.py took 0.372 seconds
[2024-04-17T12:50:48.494+0000] {processor.py:154} INFO - Started process (PID=11746) to work on /opt/airflow/dags/group_dag.py
[2024-04-17T12:50:48.500+0000] {processor.py:756} INFO - Processing file /opt/airflow/dags/group_dag.py for tasks to queue
[2024-04-17T12:50:48.504+0000] {logging_mixin.py:120} INFO - [2024-04-17T12:50:48.503+0000] {dagbag.py:537} INFO - Filling up the DagBag from /opt/airflow/dags/group_dag.py
[2024-04-17T12:50:48.636+0000] {logging_mixin.py:120} INFO - [2024-04-17T12:50:48.622+0000] {dagbag.py:342} ERROR - Failed to import: /opt/airflow/dags/group_dag.py
Traceback (most recent call last):
  File "/home/airflow/.local/lib/python3.7/site-packages/airflow/models/dagbag.py", line 338, in parse
    loader.exec_module(new_module)
  File "<frozen importlib._bootstrap_external>", line 728, in exec_module
  File "<frozen importlib._bootstrap>", line 219, in _call_with_frames_removed
  File "/opt/airflow/dags/group_dag.py", line 27, in <module>
    subdag=subdag_downloads(dag.dag_id, 'downloads', args)
  File "/opt/airflow/dags/subdags/subdags_downloads.py", line 9, in subdag_downloads
    catch = args['catchup']) as dag:
TypeError: __init__() got an unexpected keyword argument 'catch'
[2024-04-17T12:50:48.646+0000] {processor.py:768} WARNING - No viable dags retrieved from /opt/airflow/dags/group_dag.py
[2024-04-17T12:50:48.752+0000] {processor.py:176} INFO - Processing /opt/airflow/dags/group_dag.py took 0.274 seconds
[2024-04-17T12:51:19.008+0000] {processor.py:154} INFO - Started process (PID=11815) to work on /opt/airflow/dags/group_dag.py
[2024-04-17T12:51:19.014+0000] {processor.py:756} INFO - Processing file /opt/airflow/dags/group_dag.py for tasks to queue
[2024-04-17T12:51:19.018+0000] {logging_mixin.py:120} INFO - [2024-04-17T12:51:19.017+0000] {dagbag.py:537} INFO - Filling up the DagBag from /opt/airflow/dags/group_dag.py
[2024-04-17T12:51:19.157+0000] {logging_mixin.py:120} INFO - [2024-04-17T12:51:19.152+0000] {dagbag.py:342} ERROR - Failed to import: /opt/airflow/dags/group_dag.py
Traceback (most recent call last):
  File "/home/airflow/.local/lib/python3.7/site-packages/airflow/models/dagbag.py", line 338, in parse
    loader.exec_module(new_module)
  File "<frozen importlib._bootstrap_external>", line 728, in exec_module
  File "<frozen importlib._bootstrap>", line 219, in _call_with_frames_removed
  File "/opt/airflow/dags/group_dag.py", line 27, in <module>
    subdag=subdag_downloads(dag.dag_id, 'downloads', args)
  File "/opt/airflow/dags/subdags/subdags_downloads.py", line 9, in subdag_downloads
    catch = args['catchup']) as dag:
TypeError: __init__() got an unexpected keyword argument 'catch'
[2024-04-17T12:51:19.162+0000] {processor.py:768} WARNING - No viable dags retrieved from /opt/airflow/dags/group_dag.py
[2024-04-17T12:51:19.224+0000] {processor.py:176} INFO - Processing /opt/airflow/dags/group_dag.py took 0.233 seconds
[2024-04-17T12:51:49.322+0000] {processor.py:154} INFO - Started process (PID=11893) to work on /opt/airflow/dags/group_dag.py
[2024-04-17T12:51:49.325+0000] {processor.py:756} INFO - Processing file /opt/airflow/dags/group_dag.py for tasks to queue
[2024-04-17T12:51:49.328+0000] {logging_mixin.py:120} INFO - [2024-04-17T12:51:49.327+0000] {dagbag.py:537} INFO - Filling up the DagBag from /opt/airflow/dags/group_dag.py
[2024-04-17T12:51:49.400+0000] {logging_mixin.py:120} INFO - [2024-04-17T12:51:49.391+0000] {dagbag.py:342} ERROR - Failed to import: /opt/airflow/dags/group_dag.py
Traceback (most recent call last):
  File "/home/airflow/.local/lib/python3.7/site-packages/airflow/models/dagbag.py", line 338, in parse
    loader.exec_module(new_module)
  File "<frozen importlib._bootstrap_external>", line 728, in exec_module
  File "<frozen importlib._bootstrap>", line 219, in _call_with_frames_removed
  File "/opt/airflow/dags/group_dag.py", line 27, in <module>
    subdag=subdag_downloads(dag.dag_id, 'downloads', args)
  File "/opt/airflow/dags/subdags/subdags_downloads.py", line 9, in subdag_downloads
    catch = args['catchup']) as dag:
TypeError: __init__() got an unexpected keyword argument 'catch'
[2024-04-17T12:51:49.403+0000] {processor.py:768} WARNING - No viable dags retrieved from /opt/airflow/dags/group_dag.py
[2024-04-17T12:51:49.475+0000] {processor.py:176} INFO - Processing /opt/airflow/dags/group_dag.py took 0.167 seconds
[2024-04-17T12:52:19.615+0000] {processor.py:154} INFO - Started process (PID=11961) to work on /opt/airflow/dags/group_dag.py
[2024-04-17T12:52:19.623+0000] {processor.py:756} INFO - Processing file /opt/airflow/dags/group_dag.py for tasks to queue
[2024-04-17T12:52:19.626+0000] {logging_mixin.py:120} INFO - [2024-04-17T12:52:19.626+0000] {dagbag.py:537} INFO - Filling up the DagBag from /opt/airflow/dags/group_dag.py
[2024-04-17T12:52:19.692+0000] {logging_mixin.py:120} INFO - [2024-04-17T12:52:19.686+0000] {dagbag.py:342} ERROR - Failed to import: /opt/airflow/dags/group_dag.py
Traceback (most recent call last):
  File "/home/airflow/.local/lib/python3.7/site-packages/airflow/models/dagbag.py", line 338, in parse
    loader.exec_module(new_module)
  File "<frozen importlib._bootstrap_external>", line 728, in exec_module
  File "<frozen importlib._bootstrap>", line 219, in _call_with_frames_removed
  File "/opt/airflow/dags/group_dag.py", line 27, in <module>
    subdag=subdag_downloads(dag.dag_id, 'downloads', args)
  File "/opt/airflow/dags/subdags/subdags_downloads.py", line 9, in subdag_downloads
    catch = args['catchup']) as dag:
TypeError: __init__() got an unexpected keyword argument 'catch'
[2024-04-17T12:52:19.694+0000] {processor.py:768} WARNING - No viable dags retrieved from /opt/airflow/dags/group_dag.py
[2024-04-17T12:52:19.753+0000] {processor.py:176} INFO - Processing /opt/airflow/dags/group_dag.py took 0.145 seconds
[2024-04-17T12:52:49.811+0000] {processor.py:154} INFO - Started process (PID=12030) to work on /opt/airflow/dags/group_dag.py
[2024-04-17T12:52:49.813+0000] {processor.py:756} INFO - Processing file /opt/airflow/dags/group_dag.py for tasks to queue
[2024-04-17T12:52:49.815+0000] {logging_mixin.py:120} INFO - [2024-04-17T12:52:49.815+0000] {dagbag.py:537} INFO - Filling up the DagBag from /opt/airflow/dags/group_dag.py
[2024-04-17T12:52:49.867+0000] {logging_mixin.py:120} INFO - [2024-04-17T12:52:49.863+0000] {dagbag.py:342} ERROR - Failed to import: /opt/airflow/dags/group_dag.py
Traceback (most recent call last):
  File "/home/airflow/.local/lib/python3.7/site-packages/airflow/models/dagbag.py", line 338, in parse
    loader.exec_module(new_module)
  File "<frozen importlib._bootstrap_external>", line 728, in exec_module
  File "<frozen importlib._bootstrap>", line 219, in _call_with_frames_removed
  File "/opt/airflow/dags/group_dag.py", line 27, in <module>
    subdag=subdag_downloads(dag.dag_id, 'downloads', args)
  File "/opt/airflow/dags/subdags/subdags_downloads.py", line 9, in subdag_downloads
    catch = args['catchup']) as dag:
TypeError: __init__() got an unexpected keyword argument 'catch'
[2024-04-17T12:52:49.875+0000] {processor.py:768} WARNING - No viable dags retrieved from /opt/airflow/dags/group_dag.py
[2024-04-17T12:52:49.915+0000] {processor.py:176} INFO - Processing /opt/airflow/dags/group_dag.py took 0.109 seconds
[2024-04-17T12:53:20.383+0000] {processor.py:154} INFO - Started process (PID=12098) to work on /opt/airflow/dags/group_dag.py
[2024-04-17T12:53:20.386+0000] {processor.py:756} INFO - Processing file /opt/airflow/dags/group_dag.py for tasks to queue
[2024-04-17T12:53:20.388+0000] {logging_mixin.py:120} INFO - [2024-04-17T12:53:20.388+0000] {dagbag.py:537} INFO - Filling up the DagBag from /opt/airflow/dags/group_dag.py
[2024-04-17T12:53:20.467+0000] {logging_mixin.py:120} INFO - [2024-04-17T12:53:20.463+0000] {dagbag.py:342} ERROR - Failed to import: /opt/airflow/dags/group_dag.py
Traceback (most recent call last):
  File "/home/airflow/.local/lib/python3.7/site-packages/airflow/models/dagbag.py", line 338, in parse
    loader.exec_module(new_module)
  File "<frozen importlib._bootstrap_external>", line 728, in exec_module
  File "<frozen importlib._bootstrap>", line 219, in _call_with_frames_removed
  File "/opt/airflow/dags/group_dag.py", line 27, in <module>
    subdag=subdag_downloads(dag.dag_id, 'downloads', args)
  File "/opt/airflow/dags/subdags/subdags_downloads.py", line 9, in subdag_downloads
    catch = args['catchup']) as dag:
TypeError: __init__() got an unexpected keyword argument 'catch'
[2024-04-17T12:53:20.468+0000] {processor.py:768} WARNING - No viable dags retrieved from /opt/airflow/dags/group_dag.py
[2024-04-17T12:53:20.536+0000] {processor.py:176} INFO - Processing /opt/airflow/dags/group_dag.py took 0.167 seconds
[2024-04-17T12:53:51.030+0000] {processor.py:154} INFO - Started process (PID=12165) to work on /opt/airflow/dags/group_dag.py
[2024-04-17T12:53:51.036+0000] {processor.py:756} INFO - Processing file /opt/airflow/dags/group_dag.py for tasks to queue
[2024-04-17T12:53:51.039+0000] {logging_mixin.py:120} INFO - [2024-04-17T12:53:51.039+0000] {dagbag.py:537} INFO - Filling up the DagBag from /opt/airflow/dags/group_dag.py
[2024-04-17T12:53:51.115+0000] {logging_mixin.py:120} INFO - [2024-04-17T12:53:51.107+0000] {dagbag.py:342} ERROR - Failed to import: /opt/airflow/dags/group_dag.py
Traceback (most recent call last):
  File "/home/airflow/.local/lib/python3.7/site-packages/airflow/models/dagbag.py", line 338, in parse
    loader.exec_module(new_module)
  File "<frozen importlib._bootstrap_external>", line 728, in exec_module
  File "<frozen importlib._bootstrap>", line 219, in _call_with_frames_removed
  File "/opt/airflow/dags/group_dag.py", line 27, in <module>
    subdag=subdag_downloads(dag.dag_id, 'downloads', args)
  File "/opt/airflow/dags/subdags/subdags_downloads.py", line 9, in subdag_downloads
    catch = args['catchup']) as dag:
TypeError: __init__() got an unexpected keyword argument 'catch'
[2024-04-17T12:53:51.117+0000] {processor.py:768} WARNING - No viable dags retrieved from /opt/airflow/dags/group_dag.py
[2024-04-17T12:53:51.176+0000] {processor.py:176} INFO - Processing /opt/airflow/dags/group_dag.py took 0.166 seconds
[2024-04-17T12:54:21.318+0000] {processor.py:154} INFO - Started process (PID=12236) to work on /opt/airflow/dags/group_dag.py
[2024-04-17T12:54:21.322+0000] {processor.py:756} INFO - Processing file /opt/airflow/dags/group_dag.py for tasks to queue
[2024-04-17T12:54:21.327+0000] {logging_mixin.py:120} INFO - [2024-04-17T12:54:21.326+0000] {dagbag.py:537} INFO - Filling up the DagBag from /opt/airflow/dags/group_dag.py
[2024-04-17T12:54:21.481+0000] {logging_mixin.py:120} INFO - [2024-04-17T12:54:21.471+0000] {dagbag.py:342} ERROR - Failed to import: /opt/airflow/dags/group_dag.py
Traceback (most recent call last):
  File "/home/airflow/.local/lib/python3.7/site-packages/airflow/models/dagbag.py", line 338, in parse
    loader.exec_module(new_module)
  File "<frozen importlib._bootstrap_external>", line 728, in exec_module
  File "<frozen importlib._bootstrap>", line 219, in _call_with_frames_removed
  File "/opt/airflow/dags/group_dag.py", line 27, in <module>
    subdag=subdag_downloads(dag.dag_id, 'downloads', args)
  File "/opt/airflow/dags/subdags/subdags_downloads.py", line 9, in subdag_downloads
    catch = args['catchup']) as dag:
TypeError: __init__() got an unexpected keyword argument 'catch'
[2024-04-17T12:54:21.486+0000] {processor.py:768} WARNING - No viable dags retrieved from /opt/airflow/dags/group_dag.py
[2024-04-17T12:54:21.551+0000] {processor.py:176} INFO - Processing /opt/airflow/dags/group_dag.py took 0.253 seconds
[2024-04-17T12:54:52.189+0000] {processor.py:154} INFO - Started process (PID=12305) to work on /opt/airflow/dags/group_dag.py
[2024-04-17T12:54:52.195+0000] {processor.py:756} INFO - Processing file /opt/airflow/dags/group_dag.py for tasks to queue
[2024-04-17T12:54:52.200+0000] {logging_mixin.py:120} INFO - [2024-04-17T12:54:52.199+0000] {dagbag.py:537} INFO - Filling up the DagBag from /opt/airflow/dags/group_dag.py
[2024-04-17T12:54:52.315+0000] {logging_mixin.py:120} INFO - [2024-04-17T12:54:52.309+0000] {dagbag.py:342} ERROR - Failed to import: /opt/airflow/dags/group_dag.py
Traceback (most recent call last):
  File "/home/airflow/.local/lib/python3.7/site-packages/airflow/models/dagbag.py", line 338, in parse
    loader.exec_module(new_module)
  File "<frozen importlib._bootstrap_external>", line 728, in exec_module
  File "<frozen importlib._bootstrap>", line 219, in _call_with_frames_removed
  File "/opt/airflow/dags/group_dag.py", line 27, in <module>
    subdag=subdag_downloads(dag.dag_id, 'downloads', args)
  File "/opt/airflow/dags/subdags/subdags_downloads.py", line 9, in subdag_downloads
    catch = args['catchup']) as dag:
TypeError: __init__() got an unexpected keyword argument 'catch'
[2024-04-17T12:54:52.323+0000] {processor.py:768} WARNING - No viable dags retrieved from /opt/airflow/dags/group_dag.py
[2024-04-17T12:54:52.410+0000] {processor.py:176} INFO - Processing /opt/airflow/dags/group_dag.py took 0.300 seconds
[2024-04-17T12:55:22.704+0000] {processor.py:154} INFO - Started process (PID=12373) to work on /opt/airflow/dags/group_dag.py
[2024-04-17T12:55:22.710+0000] {processor.py:756} INFO - Processing file /opt/airflow/dags/group_dag.py for tasks to queue
[2024-04-17T12:55:22.713+0000] {logging_mixin.py:120} INFO - [2024-04-17T12:55:22.712+0000] {dagbag.py:537} INFO - Filling up the DagBag from /opt/airflow/dags/group_dag.py
[2024-04-17T12:55:22.840+0000] {logging_mixin.py:120} INFO - [2024-04-17T12:55:22.833+0000] {dagbag.py:342} ERROR - Failed to import: /opt/airflow/dags/group_dag.py
Traceback (most recent call last):
  File "/home/airflow/.local/lib/python3.7/site-packages/airflow/models/dagbag.py", line 338, in parse
    loader.exec_module(new_module)
  File "<frozen importlib._bootstrap_external>", line 728, in exec_module
  File "<frozen importlib._bootstrap>", line 219, in _call_with_frames_removed
  File "/opt/airflow/dags/group_dag.py", line 27, in <module>
    subdag=subdag_downloads(dag.dag_id, 'downloads', args)
  File "/opt/airflow/dags/subdags/subdags_downloads.py", line 9, in subdag_downloads
    catch = args['catchup']) as dag:
TypeError: __init__() got an unexpected keyword argument 'catch'
[2024-04-17T12:55:22.843+0000] {processor.py:768} WARNING - No viable dags retrieved from /opt/airflow/dags/group_dag.py
[2024-04-17T12:55:22.912+0000] {processor.py:176} INFO - Processing /opt/airflow/dags/group_dag.py took 0.219 seconds
[2024-04-17T12:55:53.086+0000] {processor.py:154} INFO - Started process (PID=12441) to work on /opt/airflow/dags/group_dag.py
[2024-04-17T12:55:53.092+0000] {processor.py:756} INFO - Processing file /opt/airflow/dags/group_dag.py for tasks to queue
[2024-04-17T12:55:53.097+0000] {logging_mixin.py:120} INFO - [2024-04-17T12:55:53.096+0000] {dagbag.py:537} INFO - Filling up the DagBag from /opt/airflow/dags/group_dag.py
[2024-04-17T12:55:53.212+0000] {logging_mixin.py:120} INFO - [2024-04-17T12:55:53.201+0000] {dagbag.py:342} ERROR - Failed to import: /opt/airflow/dags/group_dag.py
Traceback (most recent call last):
  File "/home/airflow/.local/lib/python3.7/site-packages/airflow/models/dagbag.py", line 338, in parse
    loader.exec_module(new_module)
  File "<frozen importlib._bootstrap_external>", line 728, in exec_module
  File "<frozen importlib._bootstrap>", line 219, in _call_with_frames_removed
  File "/opt/airflow/dags/group_dag.py", line 27, in <module>
    subdag=subdag_downloads(dag.dag_id, 'downloads', args)
  File "/opt/airflow/dags/subdags/subdags_downloads.py", line 9, in subdag_downloads
    catch = args['catchup']) as dag:
TypeError: __init__() got an unexpected keyword argument 'catch'
[2024-04-17T12:55:53.217+0000] {processor.py:768} WARNING - No viable dags retrieved from /opt/airflow/dags/group_dag.py
[2024-04-17T12:55:53.285+0000] {processor.py:176} INFO - Processing /opt/airflow/dags/group_dag.py took 0.217 seconds
[2024-04-17T12:56:23.592+0000] {processor.py:154} INFO - Started process (PID=12508) to work on /opt/airflow/dags/group_dag.py
[2024-04-17T12:56:23.598+0000] {processor.py:756} INFO - Processing file /opt/airflow/dags/group_dag.py for tasks to queue
[2024-04-17T12:56:23.603+0000] {logging_mixin.py:120} INFO - [2024-04-17T12:56:23.603+0000] {dagbag.py:537} INFO - Filling up the DagBag from /opt/airflow/dags/group_dag.py
[2024-04-17T12:56:23.704+0000] {logging_mixin.py:120} INFO - [2024-04-17T12:56:23.690+0000] {dagbag.py:342} ERROR - Failed to import: /opt/airflow/dags/group_dag.py
Traceback (most recent call last):
  File "/home/airflow/.local/lib/python3.7/site-packages/airflow/models/dagbag.py", line 338, in parse
    loader.exec_module(new_module)
  File "<frozen importlib._bootstrap_external>", line 728, in exec_module
  File "<frozen importlib._bootstrap>", line 219, in _call_with_frames_removed
  File "/opt/airflow/dags/group_dag.py", line 27, in <module>
    subdag=subdag_downloads(dag.dag_id, 'downloads', args)
  File "/opt/airflow/dags/subdags/subdags_downloads.py", line 9, in subdag_downloads
    catch = args['catchup']) as dag:
TypeError: __init__() got an unexpected keyword argument 'catch'
[2024-04-17T12:56:23.707+0000] {processor.py:768} WARNING - No viable dags retrieved from /opt/airflow/dags/group_dag.py
[2024-04-17T12:56:23.785+0000] {processor.py:176} INFO - Processing /opt/airflow/dags/group_dag.py took 0.216 seconds
[2024-04-17T12:56:54.786+0000] {processor.py:154} INFO - Started process (PID=12578) to work on /opt/airflow/dags/group_dag.py
[2024-04-17T12:56:54.791+0000] {processor.py:756} INFO - Processing file /opt/airflow/dags/group_dag.py for tasks to queue
[2024-04-17T12:56:54.796+0000] {logging_mixin.py:120} INFO - [2024-04-17T12:56:54.795+0000] {dagbag.py:537} INFO - Filling up the DagBag from /opt/airflow/dags/group_dag.py
[2024-04-17T12:56:54.908+0000] {logging_mixin.py:120} INFO - [2024-04-17T12:56:54.897+0000] {dagbag.py:342} ERROR - Failed to import: /opt/airflow/dags/group_dag.py
Traceback (most recent call last):
  File "/home/airflow/.local/lib/python3.7/site-packages/airflow/models/dagbag.py", line 338, in parse
    loader.exec_module(new_module)
  File "<frozen importlib._bootstrap_external>", line 728, in exec_module
  File "<frozen importlib._bootstrap>", line 219, in _call_with_frames_removed
  File "/opt/airflow/dags/group_dag.py", line 27, in <module>
    subdag=subdag_downloads(dag.dag_id, 'downloads', args)
  File "/opt/airflow/dags/subdags/subdags_downloads.py", line 9, in subdag_downloads
    catch = args['catchup']) as dag:
TypeError: __init__() got an unexpected keyword argument 'catch'
[2024-04-17T12:56:54.922+0000] {processor.py:768} WARNING - No viable dags retrieved from /opt/airflow/dags/group_dag.py
[2024-04-17T12:56:55.022+0000] {processor.py:176} INFO - Processing /opt/airflow/dags/group_dag.py took 0.254 seconds
[2024-04-17T12:57:25.824+0000] {processor.py:154} INFO - Started process (PID=12646) to work on /opt/airflow/dags/group_dag.py
[2024-04-17T12:57:25.828+0000] {processor.py:756} INFO - Processing file /opt/airflow/dags/group_dag.py for tasks to queue
[2024-04-17T12:57:25.830+0000] {logging_mixin.py:120} INFO - [2024-04-17T12:57:25.830+0000] {dagbag.py:537} INFO - Filling up the DagBag from /opt/airflow/dags/group_dag.py
[2024-04-17T12:57:25.906+0000] {logging_mixin.py:120} INFO - [2024-04-17T12:57:25.894+0000] {dagbag.py:342} ERROR - Failed to import: /opt/airflow/dags/group_dag.py
Traceback (most recent call last):
  File "/home/airflow/.local/lib/python3.7/site-packages/airflow/models/dagbag.py", line 338, in parse
    loader.exec_module(new_module)
  File "<frozen importlib._bootstrap_external>", line 728, in exec_module
  File "<frozen importlib._bootstrap>", line 219, in _call_with_frames_removed
  File "/opt/airflow/dags/group_dag.py", line 27, in <module>
    subdag=subdag_downloads(dag.dag_id, 'downloads', args)
  File "/opt/airflow/dags/subdags/subdags_downloads.py", line 9, in subdag_downloads
    catch = args['catchup']) as dag:
TypeError: __init__() got an unexpected keyword argument 'catch'
[2024-04-17T12:57:25.907+0000] {processor.py:768} WARNING - No viable dags retrieved from /opt/airflow/dags/group_dag.py
[2024-04-17T12:57:25.964+0000] {processor.py:176} INFO - Processing /opt/airflow/dags/group_dag.py took 0.158 seconds
[2024-04-17T12:57:56.630+0000] {processor.py:154} INFO - Started process (PID=12723) to work on /opt/airflow/dags/group_dag.py
[2024-04-17T12:57:56.639+0000] {processor.py:756} INFO - Processing file /opt/airflow/dags/group_dag.py for tasks to queue
[2024-04-17T12:57:56.643+0000] {logging_mixin.py:120} INFO - [2024-04-17T12:57:56.642+0000] {dagbag.py:537} INFO - Filling up the DagBag from /opt/airflow/dags/group_dag.py
[2024-04-17T12:57:56.733+0000] {logging_mixin.py:120} INFO - [2024-04-17T12:57:56.728+0000] {dagbag.py:342} ERROR - Failed to import: /opt/airflow/dags/group_dag.py
Traceback (most recent call last):
  File "/home/airflow/.local/lib/python3.7/site-packages/airflow/models/dagbag.py", line 338, in parse
    loader.exec_module(new_module)
  File "<frozen importlib._bootstrap_external>", line 728, in exec_module
  File "<frozen importlib._bootstrap>", line 219, in _call_with_frames_removed
  File "/opt/airflow/dags/group_dag.py", line 27, in <module>
    subdag=subdag_downloads(dag.dag_id, 'downloads', args)
  File "/opt/airflow/dags/subdags/subdags_downloads.py", line 9, in subdag_downloads
    catch = args['catchup']) as dag:
TypeError: __init__() got an unexpected keyword argument 'catch'
[2024-04-17T12:57:56.734+0000] {processor.py:768} WARNING - No viable dags retrieved from /opt/airflow/dags/group_dag.py
[2024-04-17T12:57:56.781+0000] {processor.py:176} INFO - Processing /opt/airflow/dags/group_dag.py took 0.159 seconds
[2024-04-17T12:58:27.069+0000] {processor.py:154} INFO - Started process (PID=12789) to work on /opt/airflow/dags/group_dag.py
[2024-04-17T12:58:27.074+0000] {processor.py:756} INFO - Processing file /opt/airflow/dags/group_dag.py for tasks to queue
[2024-04-17T12:58:27.080+0000] {logging_mixin.py:120} INFO - [2024-04-17T12:58:27.080+0000] {dagbag.py:537} INFO - Filling up the DagBag from /opt/airflow/dags/group_dag.py
[2024-04-17T12:58:27.180+0000] {logging_mixin.py:120} INFO - [2024-04-17T12:58:27.171+0000] {dagbag.py:342} ERROR - Failed to import: /opt/airflow/dags/group_dag.py
Traceback (most recent call last):
  File "/home/airflow/.local/lib/python3.7/site-packages/airflow/models/dagbag.py", line 338, in parse
    loader.exec_module(new_module)
  File "<frozen importlib._bootstrap_external>", line 728, in exec_module
  File "<frozen importlib._bootstrap>", line 219, in _call_with_frames_removed
  File "/opt/airflow/dags/group_dag.py", line 27, in <module>
    subdag=subdag_downloads(dag.dag_id, 'downloads', args)
  File "/opt/airflow/dags/subdags/subdags_downloads.py", line 9, in subdag_downloads
    catch = args['catchup']) as dag:
TypeError: __init__() got an unexpected keyword argument 'catch'
[2024-04-17T12:58:27.182+0000] {processor.py:768} WARNING - No viable dags retrieved from /opt/airflow/dags/group_dag.py
[2024-04-17T12:58:27.239+0000] {processor.py:176} INFO - Processing /opt/airflow/dags/group_dag.py took 0.186 seconds
[2024-04-17T12:58:57.958+0000] {processor.py:154} INFO - Started process (PID=12864) to work on /opt/airflow/dags/group_dag.py
[2024-04-17T12:58:57.972+0000] {processor.py:756} INFO - Processing file /opt/airflow/dags/group_dag.py for tasks to queue
[2024-04-17T12:58:57.976+0000] {logging_mixin.py:120} INFO - [2024-04-17T12:58:57.975+0000] {dagbag.py:537} INFO - Filling up the DagBag from /opt/airflow/dags/group_dag.py
[2024-04-17T12:58:58.089+0000] {logging_mixin.py:120} INFO - [2024-04-17T12:58:58.082+0000] {dagbag.py:342} ERROR - Failed to import: /opt/airflow/dags/group_dag.py
Traceback (most recent call last):
  File "/home/airflow/.local/lib/python3.7/site-packages/airflow/models/dagbag.py", line 338, in parse
    loader.exec_module(new_module)
  File "<frozen importlib._bootstrap_external>", line 728, in exec_module
  File "<frozen importlib._bootstrap>", line 219, in _call_with_frames_removed
  File "/opt/airflow/dags/group_dag.py", line 27, in <module>
    subdag=subdag_downloads(dag.dag_id, 'downloads', args)
  File "/opt/airflow/dags/subdags/subdags_downloads.py", line 9, in subdag_downloads
    catch = args['catchup']) as dag:
TypeError: __init__() got an unexpected keyword argument 'catch'
[2024-04-17T12:58:58.092+0000] {processor.py:768} WARNING - No viable dags retrieved from /opt/airflow/dags/group_dag.py
[2024-04-17T12:58:58.174+0000] {processor.py:176} INFO - Processing /opt/airflow/dags/group_dag.py took 0.244 seconds
[2024-04-17T12:59:28.611+0000] {processor.py:154} INFO - Started process (PID=12935) to work on /opt/airflow/dags/group_dag.py
[2024-04-17T12:59:28.619+0000] {processor.py:756} INFO - Processing file /opt/airflow/dags/group_dag.py for tasks to queue
[2024-04-17T12:59:28.637+0000] {logging_mixin.py:120} INFO - [2024-04-17T12:59:28.637+0000] {dagbag.py:537} INFO - Filling up the DagBag from /opt/airflow/dags/group_dag.py
[2024-04-17T12:59:28.880+0000] {logging_mixin.py:120} INFO - [2024-04-17T12:59:28.873+0000] {dagbag.py:342} ERROR - Failed to import: /opt/airflow/dags/group_dag.py
Traceback (most recent call last):
  File "/home/airflow/.local/lib/python3.7/site-packages/airflow/models/dagbag.py", line 338, in parse
    loader.exec_module(new_module)
  File "<frozen importlib._bootstrap_external>", line 728, in exec_module
  File "<frozen importlib._bootstrap>", line 219, in _call_with_frames_removed
  File "/opt/airflow/dags/group_dag.py", line 27, in <module>
    subdag=subdag_downloads(dag.dag_id, 'downloads', args)
  File "/opt/airflow/dags/subdags/subdags_downloads.py", line 9, in subdag_downloads
    catch = args['catchup']) as dag:
TypeError: __init__() got an unexpected keyword argument 'catch'
[2024-04-17T12:59:28.887+0000] {processor.py:768} WARNING - No viable dags retrieved from /opt/airflow/dags/group_dag.py
[2024-04-17T12:59:28.961+0000] {processor.py:176} INFO - Processing /opt/airflow/dags/group_dag.py took 0.368 seconds
[2024-04-17T12:59:59.304+0000] {processor.py:154} INFO - Started process (PID=13005) to work on /opt/airflow/dags/group_dag.py
[2024-04-17T12:59:59.310+0000] {processor.py:756} INFO - Processing file /opt/airflow/dags/group_dag.py for tasks to queue
[2024-04-17T12:59:59.313+0000] {logging_mixin.py:120} INFO - [2024-04-17T12:59:59.313+0000] {dagbag.py:537} INFO - Filling up the DagBag from /opt/airflow/dags/group_dag.py
[2024-04-17T12:59:59.379+0000] {logging_mixin.py:120} INFO - [2024-04-17T12:59:59.371+0000] {dagbag.py:342} ERROR - Failed to import: /opt/airflow/dags/group_dag.py
Traceback (most recent call last):
  File "/home/airflow/.local/lib/python3.7/site-packages/airflow/models/dagbag.py", line 338, in parse
    loader.exec_module(new_module)
  File "<frozen importlib._bootstrap_external>", line 728, in exec_module
  File "<frozen importlib._bootstrap>", line 219, in _call_with_frames_removed
  File "/opt/airflow/dags/group_dag.py", line 27, in <module>
    subdag=subdag_downloads(dag.dag_id, 'downloads', args)
  File "/opt/airflow/dags/subdags/subdags_downloads.py", line 9, in subdag_downloads
    catch = args['catchup']) as dag:
TypeError: __init__() got an unexpected keyword argument 'catch'
[2024-04-17T12:59:59.382+0000] {processor.py:768} WARNING - No viable dags retrieved from /opt/airflow/dags/group_dag.py
[2024-04-17T12:59:59.444+0000] {processor.py:176} INFO - Processing /opt/airflow/dags/group_dag.py took 0.156 seconds
[2024-04-17T13:00:29.600+0000] {processor.py:154} INFO - Started process (PID=13072) to work on /opt/airflow/dags/group_dag.py
[2024-04-17T13:00:29.614+0000] {processor.py:756} INFO - Processing file /opt/airflow/dags/group_dag.py for tasks to queue
[2024-04-17T13:00:29.618+0000] {logging_mixin.py:120} INFO - [2024-04-17T13:00:29.617+0000] {dagbag.py:537} INFO - Filling up the DagBag from /opt/airflow/dags/group_dag.py
[2024-04-17T13:00:29.861+0000] {logging_mixin.py:120} INFO - [2024-04-17T13:00:29.849+0000] {dagbag.py:342} ERROR - Failed to import: /opt/airflow/dags/group_dag.py
Traceback (most recent call last):
  File "/home/airflow/.local/lib/python3.7/site-packages/airflow/models/dagbag.py", line 338, in parse
    loader.exec_module(new_module)
  File "<frozen importlib._bootstrap_external>", line 728, in exec_module
  File "<frozen importlib._bootstrap>", line 219, in _call_with_frames_removed
  File "/opt/airflow/dags/group_dag.py", line 27, in <module>
    subdag=subdag_downloads(dag.dag_id, 'downloads', args)
  File "/opt/airflow/dags/subdags/subdags_downloads.py", line 9, in subdag_downloads
    catch = args['catchup']) as dag:
TypeError: __init__() got an unexpected keyword argument 'catch'
[2024-04-17T13:00:29.867+0000] {processor.py:768} WARNING - No viable dags retrieved from /opt/airflow/dags/group_dag.py
[2024-04-17T13:00:29.971+0000] {processor.py:176} INFO - Processing /opt/airflow/dags/group_dag.py took 0.400 seconds
[2024-04-17T13:01:00.266+0000] {processor.py:154} INFO - Started process (PID=13142) to work on /opt/airflow/dags/group_dag.py
[2024-04-17T13:01:00.270+0000] {processor.py:756} INFO - Processing file /opt/airflow/dags/group_dag.py for tasks to queue
[2024-04-17T13:01:00.281+0000] {logging_mixin.py:120} INFO - [2024-04-17T13:01:00.277+0000] {dagbag.py:537} INFO - Filling up the DagBag from /opt/airflow/dags/group_dag.py
[2024-04-17T13:01:00.427+0000] {logging_mixin.py:120} INFO - [2024-04-17T13:01:00.418+0000] {dagbag.py:342} ERROR - Failed to import: /opt/airflow/dags/group_dag.py
Traceback (most recent call last):
  File "/home/airflow/.local/lib/python3.7/site-packages/airflow/models/dagbag.py", line 338, in parse
    loader.exec_module(new_module)
  File "<frozen importlib._bootstrap_external>", line 728, in exec_module
  File "<frozen importlib._bootstrap>", line 219, in _call_with_frames_removed
  File "/opt/airflow/dags/group_dag.py", line 27, in <module>
    subdag=subdag_downloads(dag.dag_id, 'downloads', args)
  File "/opt/airflow/dags/subdags/subdags_downloads.py", line 9, in subdag_downloads
    catch = args['catchup']) as dag:
TypeError: __init__() got an unexpected keyword argument 'catch'
[2024-04-17T13:01:00.433+0000] {processor.py:768} WARNING - No viable dags retrieved from /opt/airflow/dags/group_dag.py
[2024-04-17T13:01:00.496+0000] {processor.py:176} INFO - Processing /opt/airflow/dags/group_dag.py took 0.257 seconds
[2024-04-17T13:01:30.721+0000] {processor.py:154} INFO - Started process (PID=13211) to work on /opt/airflow/dags/group_dag.py
[2024-04-17T13:01:30.725+0000] {processor.py:756} INFO - Processing file /opt/airflow/dags/group_dag.py for tasks to queue
[2024-04-17T13:01:30.730+0000] {logging_mixin.py:120} INFO - [2024-04-17T13:01:30.729+0000] {dagbag.py:537} INFO - Filling up the DagBag from /opt/airflow/dags/group_dag.py
[2024-04-17T13:01:30.813+0000] {logging_mixin.py:120} INFO - [2024-04-17T13:01:30.806+0000] {dagbag.py:342} ERROR - Failed to import: /opt/airflow/dags/group_dag.py
Traceback (most recent call last):
  File "/home/airflow/.local/lib/python3.7/site-packages/airflow/models/dagbag.py", line 338, in parse
    loader.exec_module(new_module)
  File "<frozen importlib._bootstrap_external>", line 728, in exec_module
  File "<frozen importlib._bootstrap>", line 219, in _call_with_frames_removed
  File "/opt/airflow/dags/group_dag.py", line 27, in <module>
    subdag=subdag_downloads(dag.dag_id, 'downloads', args)
  File "/opt/airflow/dags/subdags/subdags_downloads.py", line 9, in subdag_downloads
    catch = args['catchup']) as dag:
TypeError: __init__() got an unexpected keyword argument 'catch'
[2024-04-17T13:01:30.819+0000] {processor.py:768} WARNING - No viable dags retrieved from /opt/airflow/dags/group_dag.py
[2024-04-17T13:01:30.875+0000] {processor.py:176} INFO - Processing /opt/airflow/dags/group_dag.py took 0.170 seconds
[2024-04-17T13:02:01.489+0000] {processor.py:154} INFO - Started process (PID=13287) to work on /opt/airflow/dags/group_dag.py
[2024-04-17T13:02:01.509+0000] {processor.py:756} INFO - Processing file /opt/airflow/dags/group_dag.py for tasks to queue
[2024-04-17T13:02:01.514+0000] {logging_mixin.py:120} INFO - [2024-04-17T13:02:01.514+0000] {dagbag.py:537} INFO - Filling up the DagBag from /opt/airflow/dags/group_dag.py
[2024-04-17T13:02:01.662+0000] {logging_mixin.py:120} INFO - [2024-04-17T13:02:01.647+0000] {dagbag.py:342} ERROR - Failed to import: /opt/airflow/dags/group_dag.py
Traceback (most recent call last):
  File "/home/airflow/.local/lib/python3.7/site-packages/airflow/models/dagbag.py", line 338, in parse
    loader.exec_module(new_module)
  File "<frozen importlib._bootstrap_external>", line 728, in exec_module
  File "<frozen importlib._bootstrap>", line 219, in _call_with_frames_removed
  File "/opt/airflow/dags/group_dag.py", line 27, in <module>
    subdag=subdag_downloads(dag.dag_id, 'downloads', args)
  File "/opt/airflow/dags/subdags/subdags_downloads.py", line 9, in subdag_downloads
    catch = args['catchup']) as dag:
TypeError: __init__() got an unexpected keyword argument 'catch'
[2024-04-17T13:02:01.664+0000] {processor.py:768} WARNING - No viable dags retrieved from /opt/airflow/dags/group_dag.py
[2024-04-17T13:02:01.800+0000] {processor.py:176} INFO - Processing /opt/airflow/dags/group_dag.py took 0.334 seconds
[2024-04-17T13:02:32.054+0000] {processor.py:154} INFO - Started process (PID=13356) to work on /opt/airflow/dags/group_dag.py
[2024-04-17T13:02:32.062+0000] {processor.py:756} INFO - Processing file /opt/airflow/dags/group_dag.py for tasks to queue
[2024-04-17T13:02:32.065+0000] {logging_mixin.py:120} INFO - [2024-04-17T13:02:32.065+0000] {dagbag.py:537} INFO - Filling up the DagBag from /opt/airflow/dags/group_dag.py
[2024-04-17T13:02:32.145+0000] {logging_mixin.py:120} INFO - [2024-04-17T13:02:32.137+0000] {dagbag.py:342} ERROR - Failed to import: /opt/airflow/dags/group_dag.py
Traceback (most recent call last):
  File "/home/airflow/.local/lib/python3.7/site-packages/airflow/models/dagbag.py", line 338, in parse
    loader.exec_module(new_module)
  File "<frozen importlib._bootstrap_external>", line 728, in exec_module
  File "<frozen importlib._bootstrap>", line 219, in _call_with_frames_removed
  File "/opt/airflow/dags/group_dag.py", line 27, in <module>
    subdag=subdag_downloads(dag.dag_id, 'downloads', args)
  File "/opt/airflow/dags/subdags/subdags_downloads.py", line 9, in subdag_downloads
    catch = args['catchup']) as dag:
TypeError: __init__() got an unexpected keyword argument 'catch'
[2024-04-17T13:02:32.147+0000] {processor.py:768} WARNING - No viable dags retrieved from /opt/airflow/dags/group_dag.py
[2024-04-17T13:02:32.214+0000] {processor.py:176} INFO - Processing /opt/airflow/dags/group_dag.py took 0.175 seconds
[2024-04-17T13:03:02.349+0000] {processor.py:154} INFO - Started process (PID=13421) to work on /opt/airflow/dags/group_dag.py
[2024-04-17T13:03:02.351+0000] {processor.py:756} INFO - Processing file /opt/airflow/dags/group_dag.py for tasks to queue
[2024-04-17T13:03:02.353+0000] {logging_mixin.py:120} INFO - [2024-04-17T13:03:02.353+0000] {dagbag.py:537} INFO - Filling up the DagBag from /opt/airflow/dags/group_dag.py
[2024-04-17T13:03:02.515+0000] {logging_mixin.py:120} INFO - [2024-04-17T13:03:02.507+0000] {dagbag.py:342} ERROR - Failed to import: /opt/airflow/dags/group_dag.py
Traceback (most recent call last):
  File "/home/airflow/.local/lib/python3.7/site-packages/airflow/models/dagbag.py", line 338, in parse
    loader.exec_module(new_module)
  File "<frozen importlib._bootstrap_external>", line 728, in exec_module
  File "<frozen importlib._bootstrap>", line 219, in _call_with_frames_removed
  File "/opt/airflow/dags/group_dag.py", line 27, in <module>
    subdag=subdag_downloads(dag.dag_id, 'downloads', args)
  File "/opt/airflow/dags/subdags/subdags_downloads.py", line 9, in subdag_downloads
    catch = args['catchup']) as dag:
TypeError: __init__() got an unexpected keyword argument 'catch'
[2024-04-17T13:03:02.520+0000] {processor.py:768} WARNING - No viable dags retrieved from /opt/airflow/dags/group_dag.py
[2024-04-17T13:03:02.648+0000] {processor.py:176} INFO - Processing /opt/airflow/dags/group_dag.py took 0.335 seconds
[2024-04-17T13:03:33.184+0000] {processor.py:154} INFO - Started process (PID=13491) to work on /opt/airflow/dags/group_dag.py
[2024-04-17T13:03:33.187+0000] {processor.py:756} INFO - Processing file /opt/airflow/dags/group_dag.py for tasks to queue
[2024-04-17T13:03:33.192+0000] {logging_mixin.py:120} INFO - [2024-04-17T13:03:33.191+0000] {dagbag.py:537} INFO - Filling up the DagBag from /opt/airflow/dags/group_dag.py
[2024-04-17T13:03:33.268+0000] {logging_mixin.py:120} INFO - [2024-04-17T13:03:33.259+0000] {dagbag.py:342} ERROR - Failed to import: /opt/airflow/dags/group_dag.py
Traceback (most recent call last):
  File "/home/airflow/.local/lib/python3.7/site-packages/airflow/models/dagbag.py", line 338, in parse
    loader.exec_module(new_module)
  File "<frozen importlib._bootstrap_external>", line 728, in exec_module
  File "<frozen importlib._bootstrap>", line 219, in _call_with_frames_removed
  File "/opt/airflow/dags/group_dag.py", line 27, in <module>
    subdag=subdag_downloads(dag.dag_id, 'downloads', args)
  File "/opt/airflow/dags/subdags/subdags_downloads.py", line 9, in subdag_downloads
    catch = args['catchup']) as dag:
TypeError: __init__() got an unexpected keyword argument 'catch'
[2024-04-17T13:03:33.272+0000] {processor.py:768} WARNING - No viable dags retrieved from /opt/airflow/dags/group_dag.py
[2024-04-17T13:03:33.361+0000] {processor.py:176} INFO - Processing /opt/airflow/dags/group_dag.py took 0.184 seconds
[2024-04-17T13:04:03.517+0000] {processor.py:154} INFO - Started process (PID=13557) to work on /opt/airflow/dags/group_dag.py
[2024-04-17T13:04:03.521+0000] {processor.py:756} INFO - Processing file /opt/airflow/dags/group_dag.py for tasks to queue
[2024-04-17T13:04:03.523+0000] {logging_mixin.py:120} INFO - [2024-04-17T13:04:03.523+0000] {dagbag.py:537} INFO - Filling up the DagBag from /opt/airflow/dags/group_dag.py
[2024-04-17T13:04:03.598+0000] {logging_mixin.py:120} INFO - [2024-04-17T13:04:03.590+0000] {dagbag.py:342} ERROR - Failed to import: /opt/airflow/dags/group_dag.py
Traceback (most recent call last):
  File "/home/airflow/.local/lib/python3.7/site-packages/airflow/models/dagbag.py", line 338, in parse
    loader.exec_module(new_module)
  File "<frozen importlib._bootstrap_external>", line 728, in exec_module
  File "<frozen importlib._bootstrap>", line 219, in _call_with_frames_removed
  File "/opt/airflow/dags/group_dag.py", line 27, in <module>
    subdag=subdag_downloads(dag.dag_id, 'downloads', args)
  File "/opt/airflow/dags/subdags/subdags_downloads.py", line 9, in subdag_downloads
    catch = args['catchup']) as dag:
TypeError: __init__() got an unexpected keyword argument 'catch'
[2024-04-17T13:04:03.601+0000] {processor.py:768} WARNING - No viable dags retrieved from /opt/airflow/dags/group_dag.py
[2024-04-17T13:04:03.655+0000] {processor.py:176} INFO - Processing /opt/airflow/dags/group_dag.py took 0.148 seconds
[2024-04-17T13:04:34.308+0000] {processor.py:154} INFO - Started process (PID=13635) to work on /opt/airflow/dags/group_dag.py
[2024-04-17T13:04:34.311+0000] {processor.py:756} INFO - Processing file /opt/airflow/dags/group_dag.py for tasks to queue
[2024-04-17T13:04:34.315+0000] {logging_mixin.py:120} INFO - [2024-04-17T13:04:34.315+0000] {dagbag.py:537} INFO - Filling up the DagBag from /opt/airflow/dags/group_dag.py
[2024-04-17T13:04:34.404+0000] {logging_mixin.py:120} INFO - [2024-04-17T13:04:34.391+0000] {dagbag.py:342} ERROR - Failed to import: /opt/airflow/dags/group_dag.py
Traceback (most recent call last):
  File "/home/airflow/.local/lib/python3.7/site-packages/airflow/models/dagbag.py", line 338, in parse
    loader.exec_module(new_module)
  File "<frozen importlib._bootstrap_external>", line 728, in exec_module
  File "<frozen importlib._bootstrap>", line 219, in _call_with_frames_removed
  File "/opt/airflow/dags/group_dag.py", line 27, in <module>
    subdag=subdag_downloads(dag.dag_id, 'downloads', args)
  File "/opt/airflow/dags/subdags/subdags_downloads.py", line 9, in subdag_downloads
    catch = args['catchup']) as dag:
TypeError: __init__() got an unexpected keyword argument 'catch'
[2024-04-17T13:04:34.406+0000] {processor.py:768} WARNING - No viable dags retrieved from /opt/airflow/dags/group_dag.py
[2024-04-17T13:04:34.479+0000] {processor.py:176} INFO - Processing /opt/airflow/dags/group_dag.py took 0.182 seconds
[2024-04-17T13:05:04.650+0000] {processor.py:154} INFO - Started process (PID=13704) to work on /opt/airflow/dags/group_dag.py
[2024-04-17T13:05:04.661+0000] {processor.py:756} INFO - Processing file /opt/airflow/dags/group_dag.py for tasks to queue
[2024-04-17T13:05:04.666+0000] {logging_mixin.py:120} INFO - [2024-04-17T13:05:04.665+0000] {dagbag.py:537} INFO - Filling up the DagBag from /opt/airflow/dags/group_dag.py
[2024-04-17T13:05:04.785+0000] {logging_mixin.py:120} INFO - [2024-04-17T13:05:04.763+0000] {dagbag.py:342} ERROR - Failed to import: /opt/airflow/dags/group_dag.py
Traceback (most recent call last):
  File "/home/airflow/.local/lib/python3.7/site-packages/airflow/models/dagbag.py", line 338, in parse
    loader.exec_module(new_module)
  File "<frozen importlib._bootstrap_external>", line 728, in exec_module
  File "<frozen importlib._bootstrap>", line 219, in _call_with_frames_removed
  File "/opt/airflow/dags/group_dag.py", line 27, in <module>
    subdag=subdag_downloads(dag.dag_id, 'downloads', args)
  File "/opt/airflow/dags/subdags/subdags_downloads.py", line 9, in subdag_downloads
    catch = args['catchup']) as dag:
TypeError: __init__() got an unexpected keyword argument 'catch'
[2024-04-17T13:05:04.791+0000] {processor.py:768} WARNING - No viable dags retrieved from /opt/airflow/dags/group_dag.py
[2024-04-17T13:05:04.921+0000] {processor.py:176} INFO - Processing /opt/airflow/dags/group_dag.py took 0.282 seconds
