[2024-03-29T05:22:27.366+0000] {taskinstance.py:1165} INFO - Dependencies all met for <TaskInstance: user_processing.create_table manual__2024-03-29T05:22:25.415445+00:00 [queued]>
[2024-03-29T05:22:27.389+0000] {taskinstance.py:1165} INFO - Dependencies all met for <TaskInstance: user_processing.create_table manual__2024-03-29T05:22:25.415445+00:00 [queued]>
[2024-03-29T05:22:27.390+0000] {taskinstance.py:1362} INFO - 
--------------------------------------------------------------------------------
[2024-03-29T05:22:27.391+0000] {taskinstance.py:1363} INFO - Starting attempt 1 of 1
[2024-03-29T05:22:27.392+0000] {taskinstance.py:1364} INFO - 
--------------------------------------------------------------------------------
[2024-03-29T05:22:27.415+0000] {taskinstance.py:1383} INFO - Executing <Task(PostgresOperator): create_table> on 2024-03-29 05:22:25.415445+00:00
[2024-03-29T05:22:27.423+0000] {standard_task_runner.py:55} INFO - Started process 6154 to run task
[2024-03-29T05:22:27.431+0000] {standard_task_runner.py:82} INFO - Running: ['***', 'tasks', 'run', 'user_processing', 'create_table', 'manual__2024-03-29T05:22:25.415445+00:00', '--job-id', '42', '--raw', '--subdir', 'DAGS_FOLDER/user_processing.py', '--cfg-path', '/tmp/tmppcx2yzly']
[2024-03-29T05:22:27.432+0000] {standard_task_runner.py:83} INFO - Job 42: Subtask create_table
[2024-03-29T05:22:27.550+0000] {task_command.py:376} INFO - Running <TaskInstance: user_processing.create_table manual__2024-03-29T05:22:25.415445+00:00 [running]> on host 0245ea477832
[2024-03-29T05:22:27.669+0000] {taskinstance.py:1592} INFO - Exporting the following env vars:
AIRFLOW_CTX_DAG_OWNER=***
AIRFLOW_CTX_DAG_ID=user_processing
AIRFLOW_CTX_TASK_ID=create_table
AIRFLOW_CTX_EXECUTION_DATE=2024-03-29T05:22:25.415445+00:00
AIRFLOW_CTX_TRY_NUMBER=1
AIRFLOW_CTX_DAG_RUN_ID=manual__2024-03-29T05:22:25.415445+00:00
[2024-03-29T05:22:27.713+0000] {taskinstance.py:1851} ERROR - Task failed with exception
Traceback (most recent call last):
  File "/home/airflow/.local/lib/python3.7/site-packages/airflow/providers/postgres/operators/postgres.py", line 94, in execute
    self.hook.run(self.sql, self.autocommit, parameters=self.parameters)
  File "/home/airflow/.local/lib/python3.7/site-packages/airflow/providers/common/sql/hooks/sql.py", line 288, in run
    with closing(self.get_conn()) as conn:
  File "/home/airflow/.local/lib/python3.7/site-packages/airflow/providers/postgres/hooks/postgres.py", line 88, in get_conn
    conn = deepcopy(self.connection or self.get_connection(conn_id))
  File "/home/airflow/.local/lib/python3.7/site-packages/airflow/hooks/base.py", line 70, in get_connection
    conn = Connection.get_connection_from_secrets(conn_id)
  File "/home/airflow/.local/lib/python3.7/site-packages/airflow/models/connection.py", line 432, in get_connection_from_secrets
    raise AirflowNotFoundException(f"The conn_id `{conn_id}` isn't defined")
airflow.exceptions.AirflowNotFoundException: The conn_id `postgres` isn't defined
[2024-03-29T05:22:27.727+0000] {taskinstance.py:1406} INFO - Marking task as FAILED. dag_id=user_processing, task_id=create_table, execution_date=20240329T052225, start_date=20240329T052227, end_date=20240329T052227
[2024-03-29T05:22:27.754+0000] {standard_task_runner.py:105} ERROR - Failed to execute job 42 for task create_table (The conn_id `postgres` isn't defined; 6154)
[2024-03-29T05:22:27.802+0000] {local_task_job.py:164} INFO - Task exited with return code 1
[2024-03-29T05:22:27.840+0000] {local_task_job.py:273} INFO - 0 downstream tasks scheduled from follow-on schedule check
