[2024-04-15T15:40:38.736+0000] {taskinstance.py:1165} INFO - Dependencies all met for <TaskInstance: user_processing.is_api_available scheduled__2024-04-14T00:00:00+00:00 [queued]>
[2024-04-15T15:40:38.779+0000] {taskinstance.py:1165} INFO - Dependencies all met for <TaskInstance: user_processing.is_api_available scheduled__2024-04-14T00:00:00+00:00 [queued]>
[2024-04-15T15:40:38.787+0000] {taskinstance.py:1362} INFO - 
--------------------------------------------------------------------------------
[2024-04-15T15:40:38.789+0000] {taskinstance.py:1363} INFO - Starting attempt 1 of 1
[2024-04-15T15:40:38.790+0000] {taskinstance.py:1364} INFO - 
--------------------------------------------------------------------------------
[2024-04-15T15:40:38.877+0000] {taskinstance.py:1383} INFO - Executing <Task(HttpSensor): is_api_available> on 2024-04-14 00:00:00+00:00
[2024-04-15T15:40:38.932+0000] {standard_task_runner.py:55} INFO - Started process 41648 to run task
[2024-04-15T15:40:39.022+0000] {standard_task_runner.py:82} INFO - Running: ['***', 'tasks', 'run', 'user_processing', 'is_api_available', 'scheduled__2024-04-14T00:00:00+00:00', '--job-id', '268', '--raw', '--subdir', 'DAGS_FOLDER/user_processing.py', '--cfg-path', '/tmp/tmpypze63qz']
[2024-04-15T15:40:39.057+0000] {standard_task_runner.py:83} INFO - Job 268: Subtask is_api_available
[2024-04-15T15:40:39.412+0000] {task_command.py:376} INFO - Running <TaskInstance: user_processing.is_api_available scheduled__2024-04-14T00:00:00+00:00 [running]> on host a868c0c748e3
[2024-04-15T15:40:39.819+0000] {taskinstance.py:1592} INFO - Exporting the following env vars:
AIRFLOW_CTX_DAG_OWNER=***
AIRFLOW_CTX_DAG_ID=user_processing
AIRFLOW_CTX_TASK_ID=is_api_available
AIRFLOW_CTX_EXECUTION_DATE=2024-04-14T00:00:00+00:00
AIRFLOW_CTX_TRY_NUMBER=1
AIRFLOW_CTX_DAG_RUN_ID=scheduled__2024-04-14T00:00:00+00:00
[2024-04-15T15:40:39.824+0000] {http.py:120} INFO - Poking: api/
[2024-04-15T15:40:39.943+0000] {taskinstance.py:1851} ERROR - Task failed with exception
Traceback (most recent call last):
  File "/home/airflow/.local/lib/python3.7/site-packages/airflow/sensors/base.py", line 189, in execute
    poke_return = self.poke(context)
  File "/home/airflow/.local/lib/python3.7/site-packages/airflow/providers/http/sensors/http.py", line 135, in poke
    raise exc
  File "/home/airflow/.local/lib/python3.7/site-packages/airflow/providers/http/sensors/http.py", line 126, in poke
    extra_options=self.extra_options,
  File "/home/airflow/.local/lib/python3.7/site-packages/airflow/providers/http/hooks/http.py", line 128, in run
    session = self.get_conn(headers)
  File "/home/airflow/.local/lib/python3.7/site-packages/airflow/providers/http/hooks/http.py", line 82, in get_conn
    conn = self.get_connection(self.http_conn_id)
  File "/home/airflow/.local/lib/python3.7/site-packages/airflow/hooks/base.py", line 70, in get_connection
    conn = Connection.get_connection_from_secrets(conn_id)
  File "/home/airflow/.local/lib/python3.7/site-packages/airflow/models/connection.py", line 432, in get_connection_from_secrets
    raise AirflowNotFoundException(f"The conn_id `{conn_id}` isn't defined")
airflow.exceptions.AirflowNotFoundException: The conn_id `user_api` isn't defined
[2024-04-15T15:40:39.956+0000] {taskinstance.py:1406} INFO - Marking task as FAILED. dag_id=user_processing, task_id=is_api_available, execution_date=20240414T000000, start_date=20240415T154038, end_date=20240415T154039
[2024-04-15T15:40:39.976+0000] {standard_task_runner.py:105} ERROR - Failed to execute job 268 for task is_api_available (The conn_id `user_api` isn't defined; 41648)
[2024-04-15T15:40:40.007+0000] {local_task_job.py:164} INFO - Task exited with return code 1
[2024-04-15T15:40:40.066+0000] {local_task_job.py:273} INFO - 0 downstream tasks scheduled from follow-on schedule check
