[2024-04-15T15:40:33.083+0000] {processor.py:154} INFO - Started process (PID=18878) to work on /opt/airflow/dags/group_dag.py
[2024-04-15T15:40:33.094+0000] {processor.py:756} INFO - Processing file /opt/airflow/dags/group_dag.py for tasks to queue
[2024-04-15T15:40:33.097+0000] {logging_mixin.py:120} INFO - [2024-04-15T15:40:33.097+0000] {dagbag.py:537} INFO - Filling up the DagBag from /opt/airflow/dags/group_dag.py
[2024-04-15T15:40:33.315+0000] {logging_mixin.py:120} INFO - [2024-04-15T15:40:33.303+0000] {dagbag.py:342} ERROR - Failed to import: /opt/airflow/dags/group_dag.py
Traceback (most recent call last):
  File "/home/airflow/.local/lib/python3.7/site-packages/airflow/models/dagbag.py", line 338, in parse
    loader.exec_module(new_module)
  File "<frozen importlib._bootstrap_external>", line 728, in exec_module
  File "<frozen importlib._bootstrap>", line 219, in _call_with_frames_removed
  File "/opt/airflow/dags/group_dag.py", line 27, in <module>
    subdag=subdag_downloads(dag.dag_id, 'downloads', args)
  File "/opt/airflow/dags/subdags/subdags_downloads.py", line 9, in subdag_downloads
    catch = args['catchup']) as dag:
TypeError: __init__() got an unexpected keyword argument 'catch'
[2024-04-15T15:40:33.328+0000] {processor.py:768} WARNING - No viable dags retrieved from /opt/airflow/dags/group_dag.py
[2024-04-15T15:40:33.707+0000] {processor.py:176} INFO - Processing /opt/airflow/dags/group_dag.py took 0.644 seconds
[2024-04-15T15:41:04.687+0000] {processor.py:154} INFO - Started process (PID=18946) to work on /opt/airflow/dags/group_dag.py
[2024-04-15T15:41:04.690+0000] {processor.py:756} INFO - Processing file /opt/airflow/dags/group_dag.py for tasks to queue
[2024-04-15T15:41:04.692+0000] {logging_mixin.py:120} INFO - [2024-04-15T15:41:04.692+0000] {dagbag.py:537} INFO - Filling up the DagBag from /opt/airflow/dags/group_dag.py
[2024-04-15T15:41:04.757+0000] {logging_mixin.py:120} INFO - [2024-04-15T15:41:04.750+0000] {dagbag.py:342} ERROR - Failed to import: /opt/airflow/dags/group_dag.py
Traceback (most recent call last):
  File "/home/airflow/.local/lib/python3.7/site-packages/airflow/models/dagbag.py", line 338, in parse
    loader.exec_module(new_module)
  File "<frozen importlib._bootstrap_external>", line 728, in exec_module
  File "<frozen importlib._bootstrap>", line 219, in _call_with_frames_removed
  File "/opt/airflow/dags/group_dag.py", line 27, in <module>
    subdag=subdag_downloads(dag.dag_id, 'downloads', args)
  File "/opt/airflow/dags/subdags/subdags_downloads.py", line 9, in subdag_downloads
    catch = args['catchup']) as dag:
TypeError: __init__() got an unexpected keyword argument 'catch'
[2024-04-15T15:41:04.764+0000] {processor.py:768} WARNING - No viable dags retrieved from /opt/airflow/dags/group_dag.py
[2024-04-15T15:41:04.817+0000] {processor.py:176} INFO - Processing /opt/airflow/dags/group_dag.py took 0.136 seconds
[2024-04-15T15:41:35.465+0000] {processor.py:154} INFO - Started process (PID=19016) to work on /opt/airflow/dags/group_dag.py
[2024-04-15T15:41:35.468+0000] {processor.py:756} INFO - Processing file /opt/airflow/dags/group_dag.py for tasks to queue
[2024-04-15T15:41:35.470+0000] {logging_mixin.py:120} INFO - [2024-04-15T15:41:35.470+0000] {dagbag.py:537} INFO - Filling up the DagBag from /opt/airflow/dags/group_dag.py
[2024-04-15T15:41:35.518+0000] {logging_mixin.py:120} INFO - [2024-04-15T15:41:35.514+0000] {dagbag.py:342} ERROR - Failed to import: /opt/airflow/dags/group_dag.py
Traceback (most recent call last):
  File "/home/airflow/.local/lib/python3.7/site-packages/airflow/models/dagbag.py", line 338, in parse
    loader.exec_module(new_module)
  File "<frozen importlib._bootstrap_external>", line 728, in exec_module
  File "<frozen importlib._bootstrap>", line 219, in _call_with_frames_removed
  File "/opt/airflow/dags/group_dag.py", line 27, in <module>
    subdag=subdag_downloads(dag.dag_id, 'downloads', args)
  File "/opt/airflow/dags/subdags/subdags_downloads.py", line 9, in subdag_downloads
    catch = args['catchup']) as dag:
TypeError: __init__() got an unexpected keyword argument 'catch'
[2024-04-15T15:41:35.520+0000] {processor.py:768} WARNING - No viable dags retrieved from /opt/airflow/dags/group_dag.py
[2024-04-15T15:41:35.573+0000] {processor.py:176} INFO - Processing /opt/airflow/dags/group_dag.py took 0.115 seconds
[2024-04-15T15:42:05.719+0000] {processor.py:154} INFO - Started process (PID=19092) to work on /opt/airflow/dags/group_dag.py
[2024-04-15T15:42:05.722+0000] {processor.py:756} INFO - Processing file /opt/airflow/dags/group_dag.py for tasks to queue
[2024-04-15T15:42:05.725+0000] {logging_mixin.py:120} INFO - [2024-04-15T15:42:05.725+0000] {dagbag.py:537} INFO - Filling up the DagBag from /opt/airflow/dags/group_dag.py
[2024-04-15T15:42:05.788+0000] {logging_mixin.py:120} INFO - [2024-04-15T15:42:05.783+0000] {dagbag.py:342} ERROR - Failed to import: /opt/airflow/dags/group_dag.py
Traceback (most recent call last):
  File "/home/airflow/.local/lib/python3.7/site-packages/airflow/models/dagbag.py", line 338, in parse
    loader.exec_module(new_module)
  File "<frozen importlib._bootstrap_external>", line 728, in exec_module
  File "<frozen importlib._bootstrap>", line 219, in _call_with_frames_removed
  File "/opt/airflow/dags/group_dag.py", line 27, in <module>
    subdag=subdag_downloads(dag.dag_id, 'downloads', args)
  File "/opt/airflow/dags/subdags/subdags_downloads.py", line 9, in subdag_downloads
    catch = args['catchup']) as dag:
TypeError: __init__() got an unexpected keyword argument 'catch'
[2024-04-15T15:42:05.796+0000] {processor.py:768} WARNING - No viable dags retrieved from /opt/airflow/dags/group_dag.py
[2024-04-15T15:42:05.840+0000] {processor.py:176} INFO - Processing /opt/airflow/dags/group_dag.py took 0.136 seconds
[2024-04-15T15:42:36.729+0000] {processor.py:154} INFO - Started process (PID=19163) to work on /opt/airflow/dags/group_dag.py
[2024-04-15T15:42:36.731+0000] {processor.py:756} INFO - Processing file /opt/airflow/dags/group_dag.py for tasks to queue
[2024-04-15T15:42:36.733+0000] {logging_mixin.py:120} INFO - [2024-04-15T15:42:36.732+0000] {dagbag.py:537} INFO - Filling up the DagBag from /opt/airflow/dags/group_dag.py
[2024-04-15T15:42:36.777+0000] {logging_mixin.py:120} INFO - [2024-04-15T15:42:36.771+0000] {dagbag.py:342} ERROR - Failed to import: /opt/airflow/dags/group_dag.py
Traceback (most recent call last):
  File "/home/airflow/.local/lib/python3.7/site-packages/airflow/models/dagbag.py", line 338, in parse
    loader.exec_module(new_module)
  File "<frozen importlib._bootstrap_external>", line 728, in exec_module
  File "<frozen importlib._bootstrap>", line 219, in _call_with_frames_removed
  File "/opt/airflow/dags/group_dag.py", line 27, in <module>
    subdag=subdag_downloads(dag.dag_id, 'downloads', args)
  File "/opt/airflow/dags/subdags/subdags_downloads.py", line 9, in subdag_downloads
    catch = args['catchup']) as dag:
TypeError: __init__() got an unexpected keyword argument 'catch'
[2024-04-15T15:42:36.779+0000] {processor.py:768} WARNING - No viable dags retrieved from /opt/airflow/dags/group_dag.py
[2024-04-15T15:42:36.812+0000] {processor.py:176} INFO - Processing /opt/airflow/dags/group_dag.py took 0.088 seconds
[2024-04-15T15:43:07.602+0000] {processor.py:154} INFO - Started process (PID=19236) to work on /opt/airflow/dags/group_dag.py
[2024-04-15T15:43:07.606+0000] {processor.py:756} INFO - Processing file /opt/airflow/dags/group_dag.py for tasks to queue
[2024-04-15T15:43:07.609+0000] {logging_mixin.py:120} INFO - [2024-04-15T15:43:07.609+0000] {dagbag.py:537} INFO - Filling up the DagBag from /opt/airflow/dags/group_dag.py
[2024-04-15T15:43:07.757+0000] {logging_mixin.py:120} INFO - [2024-04-15T15:43:07.736+0000] {dagbag.py:342} ERROR - Failed to import: /opt/airflow/dags/group_dag.py
Traceback (most recent call last):
  File "/home/airflow/.local/lib/python3.7/site-packages/airflow/models/dagbag.py", line 338, in parse
    loader.exec_module(new_module)
  File "<frozen importlib._bootstrap_external>", line 728, in exec_module
  File "<frozen importlib._bootstrap>", line 219, in _call_with_frames_removed
  File "/opt/airflow/dags/group_dag.py", line 27, in <module>
    subdag=subdag_downloads(dag.dag_id, 'downloads', args)
  File "/opt/airflow/dags/subdags/subdags_downloads.py", line 9, in subdag_downloads
    catch = args['catchup']) as dag:
TypeError: __init__() got an unexpected keyword argument 'catch'
[2024-04-15T15:43:07.763+0000] {processor.py:768} WARNING - No viable dags retrieved from /opt/airflow/dags/group_dag.py
[2024-04-15T15:43:07.872+0000] {processor.py:176} INFO - Processing /opt/airflow/dags/group_dag.py took 0.293 seconds
[2024-04-15T15:43:37.967+0000] {processor.py:154} INFO - Started process (PID=19303) to work on /opt/airflow/dags/group_dag.py
[2024-04-15T15:43:37.970+0000] {processor.py:756} INFO - Processing file /opt/airflow/dags/group_dag.py for tasks to queue
[2024-04-15T15:43:37.973+0000] {logging_mixin.py:120} INFO - [2024-04-15T15:43:37.972+0000] {dagbag.py:537} INFO - Filling up the DagBag from /opt/airflow/dags/group_dag.py
[2024-04-15T15:43:38.026+0000] {logging_mixin.py:120} INFO - [2024-04-15T15:43:38.022+0000] {dagbag.py:342} ERROR - Failed to import: /opt/airflow/dags/group_dag.py
Traceback (most recent call last):
  File "/home/airflow/.local/lib/python3.7/site-packages/airflow/models/dagbag.py", line 338, in parse
    loader.exec_module(new_module)
  File "<frozen importlib._bootstrap_external>", line 728, in exec_module
  File "<frozen importlib._bootstrap>", line 219, in _call_with_frames_removed
  File "/opt/airflow/dags/group_dag.py", line 27, in <module>
    subdag=subdag_downloads(dag.dag_id, 'downloads', args)
  File "/opt/airflow/dags/subdags/subdags_downloads.py", line 9, in subdag_downloads
    catch = args['catchup']) as dag:
TypeError: __init__() got an unexpected keyword argument 'catch'
[2024-04-15T15:43:38.028+0000] {processor.py:768} WARNING - No viable dags retrieved from /opt/airflow/dags/group_dag.py
[2024-04-15T15:43:38.060+0000] {processor.py:176} INFO - Processing /opt/airflow/dags/group_dag.py took 0.100 seconds
[2024-04-15T15:44:08.352+0000] {processor.py:154} INFO - Started process (PID=19381) to work on /opt/airflow/dags/group_dag.py
[2024-04-15T15:44:08.354+0000] {processor.py:756} INFO - Processing file /opt/airflow/dags/group_dag.py for tasks to queue
[2024-04-15T15:44:08.356+0000] {logging_mixin.py:120} INFO - [2024-04-15T15:44:08.356+0000] {dagbag.py:537} INFO - Filling up the DagBag from /opt/airflow/dags/group_dag.py
[2024-04-15T15:44:08.391+0000] {logging_mixin.py:120} INFO - [2024-04-15T15:44:08.388+0000] {dagbag.py:342} ERROR - Failed to import: /opt/airflow/dags/group_dag.py
Traceback (most recent call last):
  File "/home/airflow/.local/lib/python3.7/site-packages/airflow/models/dagbag.py", line 338, in parse
    loader.exec_module(new_module)
  File "<frozen importlib._bootstrap_external>", line 728, in exec_module
  File "<frozen importlib._bootstrap>", line 219, in _call_with_frames_removed
  File "/opt/airflow/dags/group_dag.py", line 27, in <module>
    subdag=subdag_downloads(dag.dag_id, 'downloads', args)
  File "/opt/airflow/dags/subdags/subdags_downloads.py", line 9, in subdag_downloads
    catch = args['catchup']) as dag:
TypeError: __init__() got an unexpected keyword argument 'catch'
[2024-04-15T15:44:08.393+0000] {processor.py:768} WARNING - No viable dags retrieved from /opt/airflow/dags/group_dag.py
[2024-04-15T15:44:08.427+0000] {processor.py:176} INFO - Processing /opt/airflow/dags/group_dag.py took 0.083 seconds
[2024-04-15T15:44:38.920+0000] {processor.py:154} INFO - Started process (PID=19458) to work on /opt/airflow/dags/group_dag.py
[2024-04-15T15:44:38.922+0000] {processor.py:756} INFO - Processing file /opt/airflow/dags/group_dag.py for tasks to queue
[2024-04-15T15:44:38.924+0000] {logging_mixin.py:120} INFO - [2024-04-15T15:44:38.924+0000] {dagbag.py:537} INFO - Filling up the DagBag from /opt/airflow/dags/group_dag.py
[2024-04-15T15:44:38.970+0000] {logging_mixin.py:120} INFO - [2024-04-15T15:44:38.966+0000] {dagbag.py:342} ERROR - Failed to import: /opt/airflow/dags/group_dag.py
Traceback (most recent call last):
  File "/home/airflow/.local/lib/python3.7/site-packages/airflow/models/dagbag.py", line 338, in parse
    loader.exec_module(new_module)
  File "<frozen importlib._bootstrap_external>", line 728, in exec_module
  File "<frozen importlib._bootstrap>", line 219, in _call_with_frames_removed
  File "/opt/airflow/dags/group_dag.py", line 27, in <module>
    subdag=subdag_downloads(dag.dag_id, 'downloads', args)
  File "/opt/airflow/dags/subdags/subdags_downloads.py", line 9, in subdag_downloads
    catch = args['catchup']) as dag:
TypeError: __init__() got an unexpected keyword argument 'catch'
[2024-04-15T15:44:38.972+0000] {processor.py:768} WARNING - No viable dags retrieved from /opt/airflow/dags/group_dag.py
[2024-04-15T15:44:39.018+0000] {processor.py:176} INFO - Processing /opt/airflow/dags/group_dag.py took 0.107 seconds
[2024-04-15T15:45:09.561+0000] {processor.py:154} INFO - Started process (PID=19528) to work on /opt/airflow/dags/group_dag.py
[2024-04-15T15:45:09.564+0000] {processor.py:756} INFO - Processing file /opt/airflow/dags/group_dag.py for tasks to queue
[2024-04-15T15:45:09.567+0000] {logging_mixin.py:120} INFO - [2024-04-15T15:45:09.567+0000] {dagbag.py:537} INFO - Filling up the DagBag from /opt/airflow/dags/group_dag.py
[2024-04-15T15:45:09.629+0000] {logging_mixin.py:120} INFO - [2024-04-15T15:45:09.623+0000] {dagbag.py:342} ERROR - Failed to import: /opt/airflow/dags/group_dag.py
Traceback (most recent call last):
  File "/home/airflow/.local/lib/python3.7/site-packages/airflow/models/dagbag.py", line 338, in parse
    loader.exec_module(new_module)
  File "<frozen importlib._bootstrap_external>", line 728, in exec_module
  File "<frozen importlib._bootstrap>", line 219, in _call_with_frames_removed
  File "/opt/airflow/dags/group_dag.py", line 27, in <module>
    subdag=subdag_downloads(dag.dag_id, 'downloads', args)
  File "/opt/airflow/dags/subdags/subdags_downloads.py", line 9, in subdag_downloads
    catch = args['catchup']) as dag:
TypeError: __init__() got an unexpected keyword argument 'catch'
[2024-04-15T15:45:09.631+0000] {processor.py:768} WARNING - No viable dags retrieved from /opt/airflow/dags/group_dag.py
[2024-04-15T15:45:09.665+0000] {processor.py:176} INFO - Processing /opt/airflow/dags/group_dag.py took 0.115 seconds
[2024-04-15T15:45:39.726+0000] {processor.py:154} INFO - Started process (PID=19605) to work on /opt/airflow/dags/group_dag.py
[2024-04-15T15:45:39.730+0000] {processor.py:756} INFO - Processing file /opt/airflow/dags/group_dag.py for tasks to queue
[2024-04-15T15:45:39.732+0000] {logging_mixin.py:120} INFO - [2024-04-15T15:45:39.732+0000] {dagbag.py:537} INFO - Filling up the DagBag from /opt/airflow/dags/group_dag.py
[2024-04-15T15:45:39.774+0000] {logging_mixin.py:120} INFO - [2024-04-15T15:45:39.769+0000] {dagbag.py:342} ERROR - Failed to import: /opt/airflow/dags/group_dag.py
Traceback (most recent call last):
  File "/home/airflow/.local/lib/python3.7/site-packages/airflow/models/dagbag.py", line 338, in parse
    loader.exec_module(new_module)
  File "<frozen importlib._bootstrap_external>", line 728, in exec_module
  File "<frozen importlib._bootstrap>", line 219, in _call_with_frames_removed
  File "/opt/airflow/dags/group_dag.py", line 27, in <module>
    subdag=subdag_downloads(dag.dag_id, 'downloads', args)
  File "/opt/airflow/dags/subdags/subdags_downloads.py", line 9, in subdag_downloads
    catch = args['catchup']) as dag:
TypeError: __init__() got an unexpected keyword argument 'catch'
[2024-04-15T15:45:39.775+0000] {processor.py:768} WARNING - No viable dags retrieved from /opt/airflow/dags/group_dag.py
[2024-04-15T15:45:39.807+0000] {processor.py:176} INFO - Processing /opt/airflow/dags/group_dag.py took 0.093 seconds
[2024-04-15T15:46:09.910+0000] {processor.py:154} INFO - Started process (PID=19672) to work on /opt/airflow/dags/group_dag.py
[2024-04-15T15:46:09.912+0000] {processor.py:756} INFO - Processing file /opt/airflow/dags/group_dag.py for tasks to queue
[2024-04-15T15:46:09.914+0000] {logging_mixin.py:120} INFO - [2024-04-15T15:46:09.914+0000] {dagbag.py:537} INFO - Filling up the DagBag from /opt/airflow/dags/group_dag.py
[2024-04-15T15:46:09.962+0000] {logging_mixin.py:120} INFO - [2024-04-15T15:46:09.958+0000] {dagbag.py:342} ERROR - Failed to import: /opt/airflow/dags/group_dag.py
Traceback (most recent call last):
  File "/home/airflow/.local/lib/python3.7/site-packages/airflow/models/dagbag.py", line 338, in parse
    loader.exec_module(new_module)
  File "<frozen importlib._bootstrap_external>", line 728, in exec_module
  File "<frozen importlib._bootstrap>", line 219, in _call_with_frames_removed
  File "/opt/airflow/dags/group_dag.py", line 27, in <module>
    subdag=subdag_downloads(dag.dag_id, 'downloads', args)
  File "/opt/airflow/dags/subdags/subdags_downloads.py", line 9, in subdag_downloads
    catch = args['catchup']) as dag:
TypeError: __init__() got an unexpected keyword argument 'catch'
[2024-04-15T15:46:09.963+0000] {processor.py:768} WARNING - No viable dags retrieved from /opt/airflow/dags/group_dag.py
[2024-04-15T15:46:09.999+0000] {processor.py:176} INFO - Processing /opt/airflow/dags/group_dag.py took 0.097 seconds
[2024-04-15T15:46:40.300+0000] {processor.py:154} INFO - Started process (PID=19750) to work on /opt/airflow/dags/group_dag.py
[2024-04-15T15:46:40.302+0000] {processor.py:756} INFO - Processing file /opt/airflow/dags/group_dag.py for tasks to queue
[2024-04-15T15:46:40.304+0000] {logging_mixin.py:120} INFO - [2024-04-15T15:46:40.303+0000] {dagbag.py:537} INFO - Filling up the DagBag from /opt/airflow/dags/group_dag.py
[2024-04-15T15:46:40.346+0000] {logging_mixin.py:120} INFO - [2024-04-15T15:46:40.339+0000] {dagbag.py:342} ERROR - Failed to import: /opt/airflow/dags/group_dag.py
Traceback (most recent call last):
  File "/home/airflow/.local/lib/python3.7/site-packages/airflow/models/dagbag.py", line 338, in parse
    loader.exec_module(new_module)
  File "<frozen importlib._bootstrap_external>", line 728, in exec_module
  File "<frozen importlib._bootstrap>", line 219, in _call_with_frames_removed
  File "/opt/airflow/dags/group_dag.py", line 27, in <module>
    subdag=subdag_downloads(dag.dag_id, 'downloads', args)
  File "/opt/airflow/dags/subdags/subdags_downloads.py", line 9, in subdag_downloads
    catch = args['catchup']) as dag:
TypeError: __init__() got an unexpected keyword argument 'catch'
[2024-04-15T15:46:40.348+0000] {processor.py:768} WARNING - No viable dags retrieved from /opt/airflow/dags/group_dag.py
[2024-04-15T15:46:40.386+0000] {processor.py:176} INFO - Processing /opt/airflow/dags/group_dag.py took 0.091 seconds
[2024-04-15T15:47:10.546+0000] {processor.py:154} INFO - Started process (PID=19820) to work on /opt/airflow/dags/group_dag.py
[2024-04-15T15:47:10.550+0000] {processor.py:756} INFO - Processing file /opt/airflow/dags/group_dag.py for tasks to queue
[2024-04-15T15:47:10.553+0000] {logging_mixin.py:120} INFO - [2024-04-15T15:47:10.553+0000] {dagbag.py:537} INFO - Filling up the DagBag from /opt/airflow/dags/group_dag.py
[2024-04-15T15:47:10.593+0000] {logging_mixin.py:120} INFO - [2024-04-15T15:47:10.589+0000] {dagbag.py:342} ERROR - Failed to import: /opt/airflow/dags/group_dag.py
Traceback (most recent call last):
  File "/home/airflow/.local/lib/python3.7/site-packages/airflow/models/dagbag.py", line 338, in parse
    loader.exec_module(new_module)
  File "<frozen importlib._bootstrap_external>", line 728, in exec_module
  File "<frozen importlib._bootstrap>", line 219, in _call_with_frames_removed
  File "/opt/airflow/dags/group_dag.py", line 27, in <module>
    subdag=subdag_downloads(dag.dag_id, 'downloads', args)
  File "/opt/airflow/dags/subdags/subdags_downloads.py", line 9, in subdag_downloads
    catch = args['catchup']) as dag:
TypeError: __init__() got an unexpected keyword argument 'catch'
[2024-04-15T15:47:10.594+0000] {processor.py:768} WARNING - No viable dags retrieved from /opt/airflow/dags/group_dag.py
[2024-04-15T15:47:10.628+0000] {processor.py:176} INFO - Processing /opt/airflow/dags/group_dag.py took 0.090 seconds
[2024-04-15T15:47:40.781+0000] {processor.py:154} INFO - Started process (PID=19899) to work on /opt/airflow/dags/group_dag.py
[2024-04-15T15:47:40.785+0000] {processor.py:756} INFO - Processing file /opt/airflow/dags/group_dag.py for tasks to queue
[2024-04-15T15:47:40.787+0000] {logging_mixin.py:120} INFO - [2024-04-15T15:47:40.787+0000] {dagbag.py:537} INFO - Filling up the DagBag from /opt/airflow/dags/group_dag.py
[2024-04-15T15:47:40.826+0000] {logging_mixin.py:120} INFO - [2024-04-15T15:47:40.822+0000] {dagbag.py:342} ERROR - Failed to import: /opt/airflow/dags/group_dag.py
Traceback (most recent call last):
  File "/home/airflow/.local/lib/python3.7/site-packages/airflow/models/dagbag.py", line 338, in parse
    loader.exec_module(new_module)
  File "<frozen importlib._bootstrap_external>", line 728, in exec_module
  File "<frozen importlib._bootstrap>", line 219, in _call_with_frames_removed
  File "/opt/airflow/dags/group_dag.py", line 27, in <module>
    subdag=subdag_downloads(dag.dag_id, 'downloads', args)
  File "/opt/airflow/dags/subdags/subdags_downloads.py", line 9, in subdag_downloads
    catch = args['catchup']) as dag:
TypeError: __init__() got an unexpected keyword argument 'catch'
[2024-04-15T15:47:40.828+0000] {processor.py:768} WARNING - No viable dags retrieved from /opt/airflow/dags/group_dag.py
[2024-04-15T15:47:40.861+0000] {processor.py:176} INFO - Processing /opt/airflow/dags/group_dag.py took 0.085 seconds
[2024-04-15T15:48:11.042+0000] {processor.py:154} INFO - Started process (PID=19968) to work on /opt/airflow/dags/group_dag.py
[2024-04-15T15:48:11.044+0000] {processor.py:756} INFO - Processing file /opt/airflow/dags/group_dag.py for tasks to queue
[2024-04-15T15:48:11.045+0000] {logging_mixin.py:120} INFO - [2024-04-15T15:48:11.045+0000] {dagbag.py:537} INFO - Filling up the DagBag from /opt/airflow/dags/group_dag.py
[2024-04-15T15:48:11.084+0000] {logging_mixin.py:120} INFO - [2024-04-15T15:48:11.080+0000] {dagbag.py:342} ERROR - Failed to import: /opt/airflow/dags/group_dag.py
Traceback (most recent call last):
  File "/home/airflow/.local/lib/python3.7/site-packages/airflow/models/dagbag.py", line 338, in parse
    loader.exec_module(new_module)
  File "<frozen importlib._bootstrap_external>", line 728, in exec_module
  File "<frozen importlib._bootstrap>", line 219, in _call_with_frames_removed
  File "/opt/airflow/dags/group_dag.py", line 27, in <module>
    subdag=subdag_downloads(dag.dag_id, 'downloads', args)
  File "/opt/airflow/dags/subdags/subdags_downloads.py", line 9, in subdag_downloads
    catch = args['catchup']) as dag:
TypeError: __init__() got an unexpected keyword argument 'catch'
[2024-04-15T15:48:11.085+0000] {processor.py:768} WARNING - No viable dags retrieved from /opt/airflow/dags/group_dag.py
[2024-04-15T15:48:11.117+0000] {processor.py:176} INFO - Processing /opt/airflow/dags/group_dag.py took 0.080 seconds
[2024-04-15T15:48:42.037+0000] {processor.py:154} INFO - Started process (PID=20045) to work on /opt/airflow/dags/group_dag.py
[2024-04-15T15:48:42.041+0000] {processor.py:756} INFO - Processing file /opt/airflow/dags/group_dag.py for tasks to queue
[2024-04-15T15:48:42.043+0000] {logging_mixin.py:120} INFO - [2024-04-15T15:48:42.043+0000] {dagbag.py:537} INFO - Filling up the DagBag from /opt/airflow/dags/group_dag.py
[2024-04-15T15:48:42.087+0000] {logging_mixin.py:120} INFO - [2024-04-15T15:48:42.083+0000] {dagbag.py:342} ERROR - Failed to import: /opt/airflow/dags/group_dag.py
Traceback (most recent call last):
  File "/home/airflow/.local/lib/python3.7/site-packages/airflow/models/dagbag.py", line 338, in parse
    loader.exec_module(new_module)
  File "<frozen importlib._bootstrap_external>", line 728, in exec_module
  File "<frozen importlib._bootstrap>", line 219, in _call_with_frames_removed
  File "/opt/airflow/dags/group_dag.py", line 27, in <module>
    subdag=subdag_downloads(dag.dag_id, 'downloads', args)
  File "/opt/airflow/dags/subdags/subdags_downloads.py", line 9, in subdag_downloads
    catch = args['catchup']) as dag:
TypeError: __init__() got an unexpected keyword argument 'catch'
[2024-04-15T15:48:42.089+0000] {processor.py:768} WARNING - No viable dags retrieved from /opt/airflow/dags/group_dag.py
[2024-04-15T15:48:42.123+0000] {processor.py:176} INFO - Processing /opt/airflow/dags/group_dag.py took 0.092 seconds
[2024-04-15T15:49:12.251+0000] {processor.py:154} INFO - Started process (PID=20114) to work on /opt/airflow/dags/group_dag.py
[2024-04-15T15:49:12.254+0000] {processor.py:756} INFO - Processing file /opt/airflow/dags/group_dag.py for tasks to queue
[2024-04-15T15:49:12.256+0000] {logging_mixin.py:120} INFO - [2024-04-15T15:49:12.256+0000] {dagbag.py:537} INFO - Filling up the DagBag from /opt/airflow/dags/group_dag.py
[2024-04-15T15:49:12.293+0000] {logging_mixin.py:120} INFO - [2024-04-15T15:49:12.290+0000] {dagbag.py:342} ERROR - Failed to import: /opt/airflow/dags/group_dag.py
Traceback (most recent call last):
  File "/home/airflow/.local/lib/python3.7/site-packages/airflow/models/dagbag.py", line 338, in parse
    loader.exec_module(new_module)
  File "<frozen importlib._bootstrap_external>", line 728, in exec_module
  File "<frozen importlib._bootstrap>", line 219, in _call_with_frames_removed
  File "/opt/airflow/dags/group_dag.py", line 27, in <module>
    subdag=subdag_downloads(dag.dag_id, 'downloads', args)
  File "/opt/airflow/dags/subdags/subdags_downloads.py", line 9, in subdag_downloads
    catch = args['catchup']) as dag:
TypeError: __init__() got an unexpected keyword argument 'catch'
[2024-04-15T15:49:12.294+0000] {processor.py:768} WARNING - No viable dags retrieved from /opt/airflow/dags/group_dag.py
[2024-04-15T15:49:12.320+0000] {processor.py:176} INFO - Processing /opt/airflow/dags/group_dag.py took 0.074 seconds
[2024-04-15T15:49:42.756+0000] {processor.py:154} INFO - Started process (PID=20192) to work on /opt/airflow/dags/group_dag.py
[2024-04-15T15:49:42.758+0000] {processor.py:756} INFO - Processing file /opt/airflow/dags/group_dag.py for tasks to queue
[2024-04-15T15:49:42.762+0000] {logging_mixin.py:120} INFO - [2024-04-15T15:49:42.762+0000] {dagbag.py:537} INFO - Filling up the DagBag from /opt/airflow/dags/group_dag.py
[2024-04-15T15:49:42.806+0000] {logging_mixin.py:120} INFO - [2024-04-15T15:49:42.803+0000] {dagbag.py:342} ERROR - Failed to import: /opt/airflow/dags/group_dag.py
Traceback (most recent call last):
  File "/home/airflow/.local/lib/python3.7/site-packages/airflow/models/dagbag.py", line 338, in parse
    loader.exec_module(new_module)
  File "<frozen importlib._bootstrap_external>", line 728, in exec_module
  File "<frozen importlib._bootstrap>", line 219, in _call_with_frames_removed
  File "/opt/airflow/dags/group_dag.py", line 27, in <module>
    subdag=subdag_downloads(dag.dag_id, 'downloads', args)
  File "/opt/airflow/dags/subdags/subdags_downloads.py", line 9, in subdag_downloads
    catch = args['catchup']) as dag:
TypeError: __init__() got an unexpected keyword argument 'catch'
[2024-04-15T15:49:42.808+0000] {processor.py:768} WARNING - No viable dags retrieved from /opt/airflow/dags/group_dag.py
[2024-04-15T15:49:42.844+0000] {processor.py:176} INFO - Processing /opt/airflow/dags/group_dag.py took 0.096 seconds
[2024-04-15T15:50:13.614+0000] {processor.py:154} INFO - Started process (PID=20271) to work on /opt/airflow/dags/group_dag.py
[2024-04-15T15:50:13.617+0000] {processor.py:756} INFO - Processing file /opt/airflow/dags/group_dag.py for tasks to queue
[2024-04-15T15:50:13.619+0000] {logging_mixin.py:120} INFO - [2024-04-15T15:50:13.619+0000] {dagbag.py:537} INFO - Filling up the DagBag from /opt/airflow/dags/group_dag.py
[2024-04-15T15:50:13.664+0000] {logging_mixin.py:120} INFO - [2024-04-15T15:50:13.661+0000] {dagbag.py:342} ERROR - Failed to import: /opt/airflow/dags/group_dag.py
Traceback (most recent call last):
  File "/home/airflow/.local/lib/python3.7/site-packages/airflow/models/dagbag.py", line 338, in parse
    loader.exec_module(new_module)
  File "<frozen importlib._bootstrap_external>", line 728, in exec_module
  File "<frozen importlib._bootstrap>", line 219, in _call_with_frames_removed
  File "/opt/airflow/dags/group_dag.py", line 27, in <module>
    subdag=subdag_downloads(dag.dag_id, 'downloads', args)
  File "/opt/airflow/dags/subdags/subdags_downloads.py", line 9, in subdag_downloads
    catch = args['catchup']) as dag:
TypeError: __init__() got an unexpected keyword argument 'catch'
[2024-04-15T15:50:13.666+0000] {processor.py:768} WARNING - No viable dags retrieved from /opt/airflow/dags/group_dag.py
[2024-04-15T15:50:13.703+0000] {processor.py:176} INFO - Processing /opt/airflow/dags/group_dag.py took 0.093 seconds
[2024-04-15T15:50:44.229+0000] {processor.py:154} INFO - Started process (PID=20340) to work on /opt/airflow/dags/group_dag.py
[2024-04-15T15:50:44.230+0000] {processor.py:756} INFO - Processing file /opt/airflow/dags/group_dag.py for tasks to queue
[2024-04-15T15:50:44.233+0000] {logging_mixin.py:120} INFO - [2024-04-15T15:50:44.233+0000] {dagbag.py:537} INFO - Filling up the DagBag from /opt/airflow/dags/group_dag.py
[2024-04-15T15:50:44.279+0000] {logging_mixin.py:120} INFO - [2024-04-15T15:50:44.275+0000] {dagbag.py:342} ERROR - Failed to import: /opt/airflow/dags/group_dag.py
Traceback (most recent call last):
  File "/home/airflow/.local/lib/python3.7/site-packages/airflow/models/dagbag.py", line 338, in parse
    loader.exec_module(new_module)
  File "<frozen importlib._bootstrap_external>", line 728, in exec_module
  File "<frozen importlib._bootstrap>", line 219, in _call_with_frames_removed
  File "/opt/airflow/dags/group_dag.py", line 27, in <module>
    subdag=subdag_downloads(dag.dag_id, 'downloads', args)
  File "/opt/airflow/dags/subdags/subdags_downloads.py", line 9, in subdag_downloads
    catch = args['catchup']) as dag:
TypeError: __init__() got an unexpected keyword argument 'catch'
[2024-04-15T15:50:44.280+0000] {processor.py:768} WARNING - No viable dags retrieved from /opt/airflow/dags/group_dag.py
[2024-04-15T15:50:44.313+0000] {processor.py:176} INFO - Processing /opt/airflow/dags/group_dag.py took 0.094 seconds
[2024-04-15T15:51:15.065+0000] {processor.py:154} INFO - Started process (PID=20418) to work on /opt/airflow/dags/group_dag.py
[2024-04-15T15:51:15.068+0000] {processor.py:756} INFO - Processing file /opt/airflow/dags/group_dag.py for tasks to queue
[2024-04-15T15:51:15.070+0000] {logging_mixin.py:120} INFO - [2024-04-15T15:51:15.070+0000] {dagbag.py:537} INFO - Filling up the DagBag from /opt/airflow/dags/group_dag.py
[2024-04-15T15:51:15.137+0000] {logging_mixin.py:120} INFO - [2024-04-15T15:51:15.133+0000] {dagbag.py:342} ERROR - Failed to import: /opt/airflow/dags/group_dag.py
Traceback (most recent call last):
  File "/home/airflow/.local/lib/python3.7/site-packages/airflow/models/dagbag.py", line 338, in parse
    loader.exec_module(new_module)
  File "<frozen importlib._bootstrap_external>", line 728, in exec_module
  File "<frozen importlib._bootstrap>", line 219, in _call_with_frames_removed
  File "/opt/airflow/dags/group_dag.py", line 27, in <module>
    subdag=subdag_downloads(dag.dag_id, 'downloads', args)
  File "/opt/airflow/dags/subdags/subdags_downloads.py", line 9, in subdag_downloads
    catch = args['catchup']) as dag:
TypeError: __init__() got an unexpected keyword argument 'catch'
[2024-04-15T15:51:15.139+0000] {processor.py:768} WARNING - No viable dags retrieved from /opt/airflow/dags/group_dag.py
[2024-04-15T15:51:15.176+0000] {processor.py:176} INFO - Processing /opt/airflow/dags/group_dag.py took 0.124 seconds
[2024-04-15T15:51:45.857+0000] {processor.py:154} INFO - Started process (PID=20489) to work on /opt/airflow/dags/group_dag.py
[2024-04-15T15:51:45.860+0000] {processor.py:756} INFO - Processing file /opt/airflow/dags/group_dag.py for tasks to queue
[2024-04-15T15:51:45.862+0000] {logging_mixin.py:120} INFO - [2024-04-15T15:51:45.861+0000] {dagbag.py:537} INFO - Filling up the DagBag from /opt/airflow/dags/group_dag.py
[2024-04-15T15:51:45.900+0000] {logging_mixin.py:120} INFO - [2024-04-15T15:51:45.897+0000] {dagbag.py:342} ERROR - Failed to import: /opt/airflow/dags/group_dag.py
Traceback (most recent call last):
  File "/home/airflow/.local/lib/python3.7/site-packages/airflow/models/dagbag.py", line 338, in parse
    loader.exec_module(new_module)
  File "<frozen importlib._bootstrap_external>", line 728, in exec_module
  File "<frozen importlib._bootstrap>", line 219, in _call_with_frames_removed
  File "/opt/airflow/dags/group_dag.py", line 27, in <module>
    subdag=subdag_downloads(dag.dag_id, 'downloads', args)
  File "/opt/airflow/dags/subdags/subdags_downloads.py", line 9, in subdag_downloads
    catch = args['catchup']) as dag:
TypeError: __init__() got an unexpected keyword argument 'catch'
[2024-04-15T15:51:45.902+0000] {processor.py:768} WARNING - No viable dags retrieved from /opt/airflow/dags/group_dag.py
[2024-04-15T15:51:45.908+0000] {processor.py:176} INFO - Processing /opt/airflow/dags/group_dag.py took 0.085 seconds
[2024-04-15T15:52:16.170+0000] {processor.py:154} INFO - Started process (PID=20568) to work on /opt/airflow/dags/group_dag.py
[2024-04-15T15:52:16.172+0000] {processor.py:756} INFO - Processing file /opt/airflow/dags/group_dag.py for tasks to queue
[2024-04-15T15:52:16.175+0000] {logging_mixin.py:120} INFO - [2024-04-15T15:52:16.174+0000] {dagbag.py:537} INFO - Filling up the DagBag from /opt/airflow/dags/group_dag.py
[2024-04-15T15:52:16.220+0000] {logging_mixin.py:120} INFO - [2024-04-15T15:52:16.217+0000] {dagbag.py:342} ERROR - Failed to import: /opt/airflow/dags/group_dag.py
Traceback (most recent call last):
  File "/home/airflow/.local/lib/python3.7/site-packages/airflow/models/dagbag.py", line 338, in parse
    loader.exec_module(new_module)
  File "<frozen importlib._bootstrap_external>", line 728, in exec_module
  File "<frozen importlib._bootstrap>", line 219, in _call_with_frames_removed
  File "/opt/airflow/dags/group_dag.py", line 27, in <module>
    subdag=subdag_downloads(dag.dag_id, 'downloads', args)
  File "/opt/airflow/dags/subdags/subdags_downloads.py", line 9, in subdag_downloads
    catch = args['catchup']) as dag:
TypeError: __init__() got an unexpected keyword argument 'catch'
[2024-04-15T15:52:16.222+0000] {processor.py:768} WARNING - No viable dags retrieved from /opt/airflow/dags/group_dag.py
[2024-04-15T15:52:16.254+0000] {processor.py:176} INFO - Processing /opt/airflow/dags/group_dag.py took 0.092 seconds
[2024-04-15T15:52:46.848+0000] {processor.py:154} INFO - Started process (PID=20637) to work on /opt/airflow/dags/group_dag.py
[2024-04-15T15:52:46.850+0000] {processor.py:756} INFO - Processing file /opt/airflow/dags/group_dag.py for tasks to queue
[2024-04-15T15:52:46.851+0000] {logging_mixin.py:120} INFO - [2024-04-15T15:52:46.851+0000] {dagbag.py:537} INFO - Filling up the DagBag from /opt/airflow/dags/group_dag.py
[2024-04-15T15:52:46.901+0000] {logging_mixin.py:120} INFO - [2024-04-15T15:52:46.895+0000] {dagbag.py:342} ERROR - Failed to import: /opt/airflow/dags/group_dag.py
Traceback (most recent call last):
  File "/home/airflow/.local/lib/python3.7/site-packages/airflow/models/dagbag.py", line 338, in parse
    loader.exec_module(new_module)
  File "<frozen importlib._bootstrap_external>", line 728, in exec_module
  File "<frozen importlib._bootstrap>", line 219, in _call_with_frames_removed
  File "/opt/airflow/dags/group_dag.py", line 27, in <module>
    subdag=subdag_downloads(dag.dag_id, 'downloads', args)
  File "/opt/airflow/dags/subdags/subdags_downloads.py", line 9, in subdag_downloads
    catch = args['catchup']) as dag:
TypeError: __init__() got an unexpected keyword argument 'catch'
[2024-04-15T15:52:46.902+0000] {processor.py:768} WARNING - No viable dags retrieved from /opt/airflow/dags/group_dag.py
[2024-04-15T15:52:46.930+0000] {processor.py:176} INFO - Processing /opt/airflow/dags/group_dag.py took 0.087 seconds
[2024-04-15T15:53:17.061+0000] {processor.py:154} INFO - Started process (PID=20715) to work on /opt/airflow/dags/group_dag.py
[2024-04-15T15:53:17.065+0000] {processor.py:756} INFO - Processing file /opt/airflow/dags/group_dag.py for tasks to queue
[2024-04-15T15:53:17.067+0000] {logging_mixin.py:120} INFO - [2024-04-15T15:53:17.066+0000] {dagbag.py:537} INFO - Filling up the DagBag from /opt/airflow/dags/group_dag.py
[2024-04-15T15:53:17.105+0000] {logging_mixin.py:120} INFO - [2024-04-15T15:53:17.102+0000] {dagbag.py:342} ERROR - Failed to import: /opt/airflow/dags/group_dag.py
Traceback (most recent call last):
  File "/home/airflow/.local/lib/python3.7/site-packages/airflow/models/dagbag.py", line 338, in parse
    loader.exec_module(new_module)
  File "<frozen importlib._bootstrap_external>", line 728, in exec_module
  File "<frozen importlib._bootstrap>", line 219, in _call_with_frames_removed
  File "/opt/airflow/dags/group_dag.py", line 27, in <module>
    subdag=subdag_downloads(dag.dag_id, 'downloads', args)
  File "/opt/airflow/dags/subdags/subdags_downloads.py", line 9, in subdag_downloads
    catch = args['catchup']) as dag:
TypeError: __init__() got an unexpected keyword argument 'catch'
[2024-04-15T15:53:17.106+0000] {processor.py:768} WARNING - No viable dags retrieved from /opt/airflow/dags/group_dag.py
[2024-04-15T15:53:17.136+0000] {processor.py:176} INFO - Processing /opt/airflow/dags/group_dag.py took 0.080 seconds
[2024-04-15T15:53:47.365+0000] {processor.py:154} INFO - Started process (PID=20785) to work on /opt/airflow/dags/group_dag.py
[2024-04-15T15:53:47.368+0000] {processor.py:756} INFO - Processing file /opt/airflow/dags/group_dag.py for tasks to queue
[2024-04-15T15:53:47.370+0000] {logging_mixin.py:120} INFO - [2024-04-15T15:53:47.370+0000] {dagbag.py:537} INFO - Filling up the DagBag from /opt/airflow/dags/group_dag.py
[2024-04-15T15:53:47.408+0000] {logging_mixin.py:120} INFO - [2024-04-15T15:53:47.405+0000] {dagbag.py:342} ERROR - Failed to import: /opt/airflow/dags/group_dag.py
Traceback (most recent call last):
  File "/home/airflow/.local/lib/python3.7/site-packages/airflow/models/dagbag.py", line 338, in parse
    loader.exec_module(new_module)
  File "<frozen importlib._bootstrap_external>", line 728, in exec_module
  File "<frozen importlib._bootstrap>", line 219, in _call_with_frames_removed
  File "/opt/airflow/dags/group_dag.py", line 27, in <module>
    subdag=subdag_downloads(dag.dag_id, 'downloads', args)
  File "/opt/airflow/dags/subdags/subdags_downloads.py", line 9, in subdag_downloads
    catch = args['catchup']) as dag:
TypeError: __init__() got an unexpected keyword argument 'catch'
[2024-04-15T15:53:47.409+0000] {processor.py:768} WARNING - No viable dags retrieved from /opt/airflow/dags/group_dag.py
[2024-04-15T15:53:47.436+0000] {processor.py:176} INFO - Processing /opt/airflow/dags/group_dag.py took 0.075 seconds
[2024-04-15T15:54:18.175+0000] {processor.py:154} INFO - Started process (PID=20863) to work on /opt/airflow/dags/group_dag.py
[2024-04-15T15:54:18.178+0000] {processor.py:756} INFO - Processing file /opt/airflow/dags/group_dag.py for tasks to queue
[2024-04-15T15:54:18.180+0000] {logging_mixin.py:120} INFO - [2024-04-15T15:54:18.180+0000] {dagbag.py:537} INFO - Filling up the DagBag from /opt/airflow/dags/group_dag.py
[2024-04-15T15:54:18.222+0000] {logging_mixin.py:120} INFO - [2024-04-15T15:54:18.218+0000] {dagbag.py:342} ERROR - Failed to import: /opt/airflow/dags/group_dag.py
Traceback (most recent call last):
  File "/home/airflow/.local/lib/python3.7/site-packages/airflow/models/dagbag.py", line 338, in parse
    loader.exec_module(new_module)
  File "<frozen importlib._bootstrap_external>", line 728, in exec_module
  File "<frozen importlib._bootstrap>", line 219, in _call_with_frames_removed
  File "/opt/airflow/dags/group_dag.py", line 27, in <module>
    subdag=subdag_downloads(dag.dag_id, 'downloads', args)
  File "/opt/airflow/dags/subdags/subdags_downloads.py", line 9, in subdag_downloads
    catch = args['catchup']) as dag:
TypeError: __init__() got an unexpected keyword argument 'catch'
[2024-04-15T15:54:18.223+0000] {processor.py:768} WARNING - No viable dags retrieved from /opt/airflow/dags/group_dag.py
[2024-04-15T15:54:18.251+0000] {processor.py:176} INFO - Processing /opt/airflow/dags/group_dag.py took 0.082 seconds
[2024-04-15T15:54:49.003+0000] {processor.py:154} INFO - Started process (PID=20941) to work on /opt/airflow/dags/group_dag.py
[2024-04-15T15:54:49.006+0000] {processor.py:756} INFO - Processing file /opt/airflow/dags/group_dag.py for tasks to queue
[2024-04-15T15:54:49.007+0000] {logging_mixin.py:120} INFO - [2024-04-15T15:54:49.007+0000] {dagbag.py:537} INFO - Filling up the DagBag from /opt/airflow/dags/group_dag.py
[2024-04-15T15:54:49.052+0000] {logging_mixin.py:120} INFO - [2024-04-15T15:54:49.046+0000] {dagbag.py:342} ERROR - Failed to import: /opt/airflow/dags/group_dag.py
Traceback (most recent call last):
  File "/home/airflow/.local/lib/python3.7/site-packages/airflow/models/dagbag.py", line 338, in parse
    loader.exec_module(new_module)
  File "<frozen importlib._bootstrap_external>", line 728, in exec_module
  File "<frozen importlib._bootstrap>", line 219, in _call_with_frames_removed
  File "/opt/airflow/dags/group_dag.py", line 27, in <module>
    subdag=subdag_downloads(dag.dag_id, 'downloads', args)
  File "/opt/airflow/dags/subdags/subdags_downloads.py", line 9, in subdag_downloads
    catch = args['catchup']) as dag:
TypeError: __init__() got an unexpected keyword argument 'catch'
[2024-04-15T15:54:49.055+0000] {processor.py:768} WARNING - No viable dags retrieved from /opt/airflow/dags/group_dag.py
[2024-04-15T15:54:49.087+0000] {processor.py:176} INFO - Processing /opt/airflow/dags/group_dag.py took 0.090 seconds
[2024-04-15T15:55:19.336+0000] {processor.py:154} INFO - Started process (PID=21010) to work on /opt/airflow/dags/group_dag.py
[2024-04-15T15:55:19.339+0000] {processor.py:756} INFO - Processing file /opt/airflow/dags/group_dag.py for tasks to queue
[2024-04-15T15:55:19.341+0000] {logging_mixin.py:120} INFO - [2024-04-15T15:55:19.341+0000] {dagbag.py:537} INFO - Filling up the DagBag from /opt/airflow/dags/group_dag.py
[2024-04-15T15:55:19.394+0000] {logging_mixin.py:120} INFO - [2024-04-15T15:55:19.389+0000] {dagbag.py:342} ERROR - Failed to import: /opt/airflow/dags/group_dag.py
Traceback (most recent call last):
  File "/home/airflow/.local/lib/python3.7/site-packages/airflow/models/dagbag.py", line 338, in parse
    loader.exec_module(new_module)
  File "<frozen importlib._bootstrap_external>", line 728, in exec_module
  File "<frozen importlib._bootstrap>", line 219, in _call_with_frames_removed
  File "/opt/airflow/dags/group_dag.py", line 27, in <module>
    subdag=subdag_downloads(dag.dag_id, 'downloads', args)
  File "/opt/airflow/dags/subdags/subdags_downloads.py", line 9, in subdag_downloads
    catch = args['catchup']) as dag:
TypeError: __init__() got an unexpected keyword argument 'catch'
[2024-04-15T15:55:19.396+0000] {processor.py:768} WARNING - No viable dags retrieved from /opt/airflow/dags/group_dag.py
[2024-04-15T15:55:19.437+0000] {processor.py:176} INFO - Processing /opt/airflow/dags/group_dag.py took 0.112 seconds
[2024-04-15T15:55:50.043+0000] {processor.py:154} INFO - Started process (PID=21087) to work on /opt/airflow/dags/group_dag.py
[2024-04-15T15:55:50.046+0000] {processor.py:756} INFO - Processing file /opt/airflow/dags/group_dag.py for tasks to queue
[2024-04-15T15:55:50.048+0000] {logging_mixin.py:120} INFO - [2024-04-15T15:55:50.048+0000] {dagbag.py:537} INFO - Filling up the DagBag from /opt/airflow/dags/group_dag.py
[2024-04-15T15:55:50.090+0000] {logging_mixin.py:120} INFO - [2024-04-15T15:55:50.087+0000] {dagbag.py:342} ERROR - Failed to import: /opt/airflow/dags/group_dag.py
Traceback (most recent call last):
  File "/home/airflow/.local/lib/python3.7/site-packages/airflow/models/dagbag.py", line 338, in parse
    loader.exec_module(new_module)
  File "<frozen importlib._bootstrap_external>", line 728, in exec_module
  File "<frozen importlib._bootstrap>", line 219, in _call_with_frames_removed
  File "/opt/airflow/dags/group_dag.py", line 27, in <module>
    subdag=subdag_downloads(dag.dag_id, 'downloads', args)
  File "/opt/airflow/dags/subdags/subdags_downloads.py", line 9, in subdag_downloads
    catch = args['catchup']) as dag:
TypeError: __init__() got an unexpected keyword argument 'catch'
[2024-04-15T15:55:50.091+0000] {processor.py:768} WARNING - No viable dags retrieved from /opt/airflow/dags/group_dag.py
[2024-04-15T15:55:50.124+0000] {processor.py:176} INFO - Processing /opt/airflow/dags/group_dag.py took 0.086 seconds
[2024-04-15T15:56:20.345+0000] {processor.py:154} INFO - Started process (PID=21155) to work on /opt/airflow/dags/group_dag.py
[2024-04-15T15:56:20.347+0000] {processor.py:756} INFO - Processing file /opt/airflow/dags/group_dag.py for tasks to queue
[2024-04-15T15:56:20.348+0000] {logging_mixin.py:120} INFO - [2024-04-15T15:56:20.348+0000] {dagbag.py:537} INFO - Filling up the DagBag from /opt/airflow/dags/group_dag.py
[2024-04-15T15:56:20.385+0000] {logging_mixin.py:120} INFO - [2024-04-15T15:56:20.382+0000] {dagbag.py:342} ERROR - Failed to import: /opt/airflow/dags/group_dag.py
Traceback (most recent call last):
  File "/home/airflow/.local/lib/python3.7/site-packages/airflow/models/dagbag.py", line 338, in parse
    loader.exec_module(new_module)
  File "<frozen importlib._bootstrap_external>", line 728, in exec_module
  File "<frozen importlib._bootstrap>", line 219, in _call_with_frames_removed
  File "/opt/airflow/dags/group_dag.py", line 27, in <module>
    subdag=subdag_downloads(dag.dag_id, 'downloads', args)
  File "/opt/airflow/dags/subdags/subdags_downloads.py", line 9, in subdag_downloads
    catch = args['catchup']) as dag:
TypeError: __init__() got an unexpected keyword argument 'catch'
[2024-04-15T15:56:20.387+0000] {processor.py:768} WARNING - No viable dags retrieved from /opt/airflow/dags/group_dag.py
[2024-04-15T15:56:20.425+0000] {processor.py:176} INFO - Processing /opt/airflow/dags/group_dag.py took 0.087 seconds
[2024-04-15T15:56:51.093+0000] {processor.py:154} INFO - Started process (PID=21234) to work on /opt/airflow/dags/group_dag.py
[2024-04-15T15:56:51.095+0000] {processor.py:756} INFO - Processing file /opt/airflow/dags/group_dag.py for tasks to queue
[2024-04-15T15:56:51.097+0000] {logging_mixin.py:120} INFO - [2024-04-15T15:56:51.096+0000] {dagbag.py:537} INFO - Filling up the DagBag from /opt/airflow/dags/group_dag.py
[2024-04-15T15:56:51.135+0000] {logging_mixin.py:120} INFO - [2024-04-15T15:56:51.132+0000] {dagbag.py:342} ERROR - Failed to import: /opt/airflow/dags/group_dag.py
Traceback (most recent call last):
  File "/home/airflow/.local/lib/python3.7/site-packages/airflow/models/dagbag.py", line 338, in parse
    loader.exec_module(new_module)
  File "<frozen importlib._bootstrap_external>", line 728, in exec_module
  File "<frozen importlib._bootstrap>", line 219, in _call_with_frames_removed
  File "/opt/airflow/dags/group_dag.py", line 27, in <module>
    subdag=subdag_downloads(dag.dag_id, 'downloads', args)
  File "/opt/airflow/dags/subdags/subdags_downloads.py", line 9, in subdag_downloads
    catch = args['catchup']) as dag:
TypeError: __init__() got an unexpected keyword argument 'catch'
[2024-04-15T15:56:51.136+0000] {processor.py:768} WARNING - No viable dags retrieved from /opt/airflow/dags/group_dag.py
[2024-04-15T15:56:51.167+0000] {processor.py:176} INFO - Processing /opt/airflow/dags/group_dag.py took 0.079 seconds
[2024-04-15T15:57:21.324+0000] {processor.py:154} INFO - Started process (PID=21304) to work on /opt/airflow/dags/group_dag.py
[2024-04-15T15:57:21.326+0000] {processor.py:756} INFO - Processing file /opt/airflow/dags/group_dag.py for tasks to queue
[2024-04-15T15:57:21.327+0000] {logging_mixin.py:120} INFO - [2024-04-15T15:57:21.327+0000] {dagbag.py:537} INFO - Filling up the DagBag from /opt/airflow/dags/group_dag.py
[2024-04-15T15:57:21.364+0000] {logging_mixin.py:120} INFO - [2024-04-15T15:57:21.360+0000] {dagbag.py:342} ERROR - Failed to import: /opt/airflow/dags/group_dag.py
Traceback (most recent call last):
  File "/home/airflow/.local/lib/python3.7/site-packages/airflow/models/dagbag.py", line 338, in parse
    loader.exec_module(new_module)
  File "<frozen importlib._bootstrap_external>", line 728, in exec_module
  File "<frozen importlib._bootstrap>", line 219, in _call_with_frames_removed
  File "/opt/airflow/dags/group_dag.py", line 27, in <module>
    subdag=subdag_downloads(dag.dag_id, 'downloads', args)
  File "/opt/airflow/dags/subdags/subdags_downloads.py", line 9, in subdag_downloads
    catch = args['catchup']) as dag:
TypeError: __init__() got an unexpected keyword argument 'catch'
[2024-04-15T15:57:21.365+0000] {processor.py:768} WARNING - No viable dags retrieved from /opt/airflow/dags/group_dag.py
[2024-04-15T15:57:21.402+0000] {processor.py:176} INFO - Processing /opt/airflow/dags/group_dag.py took 0.082 seconds
[2024-04-15T15:57:51.479+0000] {processor.py:154} INFO - Started process (PID=21383) to work on /opt/airflow/dags/group_dag.py
[2024-04-15T15:57:51.482+0000] {processor.py:756} INFO - Processing file /opt/airflow/dags/group_dag.py for tasks to queue
[2024-04-15T15:57:51.484+0000] {logging_mixin.py:120} INFO - [2024-04-15T15:57:51.484+0000] {dagbag.py:537} INFO - Filling up the DagBag from /opt/airflow/dags/group_dag.py
[2024-04-15T15:57:51.543+0000] {logging_mixin.py:120} INFO - [2024-04-15T15:57:51.535+0000] {dagbag.py:342} ERROR - Failed to import: /opt/airflow/dags/group_dag.py
Traceback (most recent call last):
  File "/home/airflow/.local/lib/python3.7/site-packages/airflow/models/dagbag.py", line 338, in parse
    loader.exec_module(new_module)
  File "<frozen importlib._bootstrap_external>", line 728, in exec_module
  File "<frozen importlib._bootstrap>", line 219, in _call_with_frames_removed
  File "/opt/airflow/dags/group_dag.py", line 27, in <module>
    subdag=subdag_downloads(dag.dag_id, 'downloads', args)
  File "/opt/airflow/dags/subdags/subdags_downloads.py", line 9, in subdag_downloads
    catch = args['catchup']) as dag:
TypeError: __init__() got an unexpected keyword argument 'catch'
[2024-04-15T15:57:51.545+0000] {processor.py:768} WARNING - No viable dags retrieved from /opt/airflow/dags/group_dag.py
[2024-04-15T15:57:51.595+0000] {processor.py:176} INFO - Processing /opt/airflow/dags/group_dag.py took 0.122 seconds
[2024-04-15T15:58:22.319+0000] {processor.py:154} INFO - Started process (PID=21461) to work on /opt/airflow/dags/group_dag.py
[2024-04-15T15:58:22.321+0000] {processor.py:756} INFO - Processing file /opt/airflow/dags/group_dag.py for tasks to queue
[2024-04-15T15:58:22.322+0000] {logging_mixin.py:120} INFO - [2024-04-15T15:58:22.322+0000] {dagbag.py:537} INFO - Filling up the DagBag from /opt/airflow/dags/group_dag.py
[2024-04-15T15:58:22.361+0000] {logging_mixin.py:120} INFO - [2024-04-15T15:58:22.358+0000] {dagbag.py:342} ERROR - Failed to import: /opt/airflow/dags/group_dag.py
Traceback (most recent call last):
  File "/home/airflow/.local/lib/python3.7/site-packages/airflow/models/dagbag.py", line 338, in parse
    loader.exec_module(new_module)
  File "<frozen importlib._bootstrap_external>", line 728, in exec_module
  File "<frozen importlib._bootstrap>", line 219, in _call_with_frames_removed
  File "/opt/airflow/dags/group_dag.py", line 27, in <module>
    subdag=subdag_downloads(dag.dag_id, 'downloads', args)
  File "/opt/airflow/dags/subdags/subdags_downloads.py", line 9, in subdag_downloads
    catch = args['catchup']) as dag:
TypeError: __init__() got an unexpected keyword argument 'catch'
[2024-04-15T15:58:22.362+0000] {processor.py:768} WARNING - No viable dags retrieved from /opt/airflow/dags/group_dag.py
[2024-04-15T15:58:22.398+0000] {processor.py:176} INFO - Processing /opt/airflow/dags/group_dag.py took 0.084 seconds
[2024-04-15T15:58:53.289+0000] {processor.py:154} INFO - Started process (PID=21530) to work on /opt/airflow/dags/group_dag.py
[2024-04-15T15:58:53.291+0000] {processor.py:756} INFO - Processing file /opt/airflow/dags/group_dag.py for tasks to queue
[2024-04-15T15:58:53.292+0000] {logging_mixin.py:120} INFO - [2024-04-15T15:58:53.292+0000] {dagbag.py:537} INFO - Filling up the DagBag from /opt/airflow/dags/group_dag.py
[2024-04-15T15:58:53.329+0000] {logging_mixin.py:120} INFO - [2024-04-15T15:58:53.325+0000] {dagbag.py:342} ERROR - Failed to import: /opt/airflow/dags/group_dag.py
Traceback (most recent call last):
  File "/home/airflow/.local/lib/python3.7/site-packages/airflow/models/dagbag.py", line 338, in parse
    loader.exec_module(new_module)
  File "<frozen importlib._bootstrap_external>", line 728, in exec_module
  File "<frozen importlib._bootstrap>", line 219, in _call_with_frames_removed
  File "/opt/airflow/dags/group_dag.py", line 27, in <module>
    subdag=subdag_downloads(dag.dag_id, 'downloads', args)
  File "/opt/airflow/dags/subdags/subdags_downloads.py", line 9, in subdag_downloads
    catch = args['catchup']) as dag:
TypeError: __init__() got an unexpected keyword argument 'catch'
[2024-04-15T15:58:53.331+0000] {processor.py:768} WARNING - No viable dags retrieved from /opt/airflow/dags/group_dag.py
[2024-04-15T15:58:53.361+0000] {processor.py:176} INFO - Processing /opt/airflow/dags/group_dag.py took 0.080 seconds
[2024-04-15T15:59:23.579+0000] {processor.py:154} INFO - Started process (PID=21609) to work on /opt/airflow/dags/group_dag.py
[2024-04-15T15:59:23.583+0000] {processor.py:756} INFO - Processing file /opt/airflow/dags/group_dag.py for tasks to queue
[2024-04-15T15:59:23.584+0000] {logging_mixin.py:120} INFO - [2024-04-15T15:59:23.584+0000] {dagbag.py:537} INFO - Filling up the DagBag from /opt/airflow/dags/group_dag.py
[2024-04-15T15:59:23.620+0000] {logging_mixin.py:120} INFO - [2024-04-15T15:59:23.617+0000] {dagbag.py:342} ERROR - Failed to import: /opt/airflow/dags/group_dag.py
Traceback (most recent call last):
  File "/home/airflow/.local/lib/python3.7/site-packages/airflow/models/dagbag.py", line 338, in parse
    loader.exec_module(new_module)
  File "<frozen importlib._bootstrap_external>", line 728, in exec_module
  File "<frozen importlib._bootstrap>", line 219, in _call_with_frames_removed
  File "/opt/airflow/dags/group_dag.py", line 27, in <module>
    subdag=subdag_downloads(dag.dag_id, 'downloads', args)
  File "/opt/airflow/dags/subdags/subdags_downloads.py", line 9, in subdag_downloads
    catch = args['catchup']) as dag:
TypeError: __init__() got an unexpected keyword argument 'catch'
[2024-04-15T15:59:23.621+0000] {processor.py:768} WARNING - No viable dags retrieved from /opt/airflow/dags/group_dag.py
[2024-04-15T15:59:23.653+0000] {processor.py:176} INFO - Processing /opt/airflow/dags/group_dag.py took 0.081 seconds
[2024-04-15T15:59:54.300+0000] {processor.py:154} INFO - Started process (PID=21678) to work on /opt/airflow/dags/group_dag.py
[2024-04-15T15:59:54.302+0000] {processor.py:756} INFO - Processing file /opt/airflow/dags/group_dag.py for tasks to queue
[2024-04-15T15:59:54.304+0000] {logging_mixin.py:120} INFO - [2024-04-15T15:59:54.303+0000] {dagbag.py:537} INFO - Filling up the DagBag from /opt/airflow/dags/group_dag.py
[2024-04-15T15:59:54.353+0000] {logging_mixin.py:120} INFO - [2024-04-15T15:59:54.349+0000] {dagbag.py:342} ERROR - Failed to import: /opt/airflow/dags/group_dag.py
Traceback (most recent call last):
  File "/home/airflow/.local/lib/python3.7/site-packages/airflow/models/dagbag.py", line 338, in parse
    loader.exec_module(new_module)
  File "<frozen importlib._bootstrap_external>", line 728, in exec_module
  File "<frozen importlib._bootstrap>", line 219, in _call_with_frames_removed
  File "/opt/airflow/dags/group_dag.py", line 27, in <module>
    subdag=subdag_downloads(dag.dag_id, 'downloads', args)
  File "/opt/airflow/dags/subdags/subdags_downloads.py", line 9, in subdag_downloads
    catch = args['catchup']) as dag:
TypeError: __init__() got an unexpected keyword argument 'catch'
[2024-04-15T15:59:54.355+0000] {processor.py:768} WARNING - No viable dags retrieved from /opt/airflow/dags/group_dag.py
[2024-04-15T15:59:54.385+0000] {processor.py:176} INFO - Processing /opt/airflow/dags/group_dag.py took 0.092 seconds
[2024-04-15T16:00:24.629+0000] {processor.py:154} INFO - Started process (PID=21754) to work on /opt/airflow/dags/group_dag.py
[2024-04-15T16:00:24.633+0000] {processor.py:756} INFO - Processing file /opt/airflow/dags/group_dag.py for tasks to queue
[2024-04-15T16:00:24.635+0000] {logging_mixin.py:120} INFO - [2024-04-15T16:00:24.635+0000] {dagbag.py:537} INFO - Filling up the DagBag from /opt/airflow/dags/group_dag.py
[2024-04-15T16:00:24.681+0000] {logging_mixin.py:120} INFO - [2024-04-15T16:00:24.678+0000] {dagbag.py:342} ERROR - Failed to import: /opt/airflow/dags/group_dag.py
Traceback (most recent call last):
  File "/home/airflow/.local/lib/python3.7/site-packages/airflow/models/dagbag.py", line 338, in parse
    loader.exec_module(new_module)
  File "<frozen importlib._bootstrap_external>", line 728, in exec_module
  File "<frozen importlib._bootstrap>", line 219, in _call_with_frames_removed
  File "/opt/airflow/dags/group_dag.py", line 27, in <module>
    subdag=subdag_downloads(dag.dag_id, 'downloads', args)
  File "/opt/airflow/dags/subdags/subdags_downloads.py", line 9, in subdag_downloads
    catch = args['catchup']) as dag:
TypeError: __init__() got an unexpected keyword argument 'catch'
[2024-04-15T16:00:24.682+0000] {processor.py:768} WARNING - No viable dags retrieved from /opt/airflow/dags/group_dag.py
[2024-04-15T16:00:24.714+0000] {processor.py:176} INFO - Processing /opt/airflow/dags/group_dag.py took 0.111 seconds
[2024-04-15T16:00:55.119+0000] {processor.py:154} INFO - Started process (PID=21821) to work on /opt/airflow/dags/group_dag.py
[2024-04-15T16:00:55.122+0000] {processor.py:756} INFO - Processing file /opt/airflow/dags/group_dag.py for tasks to queue
[2024-04-15T16:00:55.124+0000] {logging_mixin.py:120} INFO - [2024-04-15T16:00:55.124+0000] {dagbag.py:537} INFO - Filling up the DagBag from /opt/airflow/dags/group_dag.py
[2024-04-15T16:00:55.160+0000] {logging_mixin.py:120} INFO - [2024-04-15T16:00:55.157+0000] {dagbag.py:342} ERROR - Failed to import: /opt/airflow/dags/group_dag.py
Traceback (most recent call last):
  File "/home/airflow/.local/lib/python3.7/site-packages/airflow/models/dagbag.py", line 338, in parse
    loader.exec_module(new_module)
  File "<frozen importlib._bootstrap_external>", line 728, in exec_module
  File "<frozen importlib._bootstrap>", line 219, in _call_with_frames_removed
  File "/opt/airflow/dags/group_dag.py", line 27, in <module>
    subdag=subdag_downloads(dag.dag_id, 'downloads', args)
  File "/opt/airflow/dags/subdags/subdags_downloads.py", line 9, in subdag_downloads
    catch = args['catchup']) as dag:
TypeError: __init__() got an unexpected keyword argument 'catch'
[2024-04-15T16:00:55.161+0000] {processor.py:768} WARNING - No viable dags retrieved from /opt/airflow/dags/group_dag.py
[2024-04-15T16:00:55.194+0000] {processor.py:176} INFO - Processing /opt/airflow/dags/group_dag.py took 0.081 seconds
[2024-04-15T16:01:25.541+0000] {processor.py:154} INFO - Started process (PID=21899) to work on /opt/airflow/dags/group_dag.py
[2024-04-15T16:01:25.543+0000] {processor.py:756} INFO - Processing file /opt/airflow/dags/group_dag.py for tasks to queue
[2024-04-15T16:01:25.544+0000] {logging_mixin.py:120} INFO - [2024-04-15T16:01:25.544+0000] {dagbag.py:537} INFO - Filling up the DagBag from /opt/airflow/dags/group_dag.py
[2024-04-15T16:01:25.581+0000] {logging_mixin.py:120} INFO - [2024-04-15T16:01:25.578+0000] {dagbag.py:342} ERROR - Failed to import: /opt/airflow/dags/group_dag.py
Traceback (most recent call last):
  File "/home/airflow/.local/lib/python3.7/site-packages/airflow/models/dagbag.py", line 338, in parse
    loader.exec_module(new_module)
  File "<frozen importlib._bootstrap_external>", line 728, in exec_module
  File "<frozen importlib._bootstrap>", line 219, in _call_with_frames_removed
  File "/opt/airflow/dags/group_dag.py", line 27, in <module>
    subdag=subdag_downloads(dag.dag_id, 'downloads', args)
  File "/opt/airflow/dags/subdags/subdags_downloads.py", line 9, in subdag_downloads
    catch = args['catchup']) as dag:
TypeError: __init__() got an unexpected keyword argument 'catch'
[2024-04-15T16:01:25.582+0000] {processor.py:768} WARNING - No viable dags retrieved from /opt/airflow/dags/group_dag.py
[2024-04-15T16:01:25.611+0000] {processor.py:176} INFO - Processing /opt/airflow/dags/group_dag.py took 0.076 seconds
[2024-04-15T16:01:56.011+0000] {processor.py:154} INFO - Started process (PID=21976) to work on /opt/airflow/dags/group_dag.py
[2024-04-15T16:01:56.014+0000] {processor.py:756} INFO - Processing file /opt/airflow/dags/group_dag.py for tasks to queue
[2024-04-15T16:01:56.017+0000] {logging_mixin.py:120} INFO - [2024-04-15T16:01:56.016+0000] {dagbag.py:537} INFO - Filling up the DagBag from /opt/airflow/dags/group_dag.py
[2024-04-15T16:01:56.078+0000] {logging_mixin.py:120} INFO - [2024-04-15T16:01:56.074+0000] {dagbag.py:342} ERROR - Failed to import: /opt/airflow/dags/group_dag.py
Traceback (most recent call last):
  File "/home/airflow/.local/lib/python3.7/site-packages/airflow/models/dagbag.py", line 338, in parse
    loader.exec_module(new_module)
  File "<frozen importlib._bootstrap_external>", line 728, in exec_module
  File "<frozen importlib._bootstrap>", line 219, in _call_with_frames_removed
  File "/opt/airflow/dags/group_dag.py", line 27, in <module>
    subdag=subdag_downloads(dag.dag_id, 'downloads', args)
  File "/opt/airflow/dags/subdags/subdags_downloads.py", line 9, in subdag_downloads
    catch = args['catchup']) as dag:
TypeError: __init__() got an unexpected keyword argument 'catch'
[2024-04-15T16:01:56.080+0000] {processor.py:768} WARNING - No viable dags retrieved from /opt/airflow/dags/group_dag.py
[2024-04-15T16:01:56.113+0000] {processor.py:176} INFO - Processing /opt/airflow/dags/group_dag.py took 0.113 seconds
[2024-04-15T16:02:26.564+0000] {processor.py:154} INFO - Started process (PID=22045) to work on /opt/airflow/dags/group_dag.py
[2024-04-15T16:02:26.568+0000] {processor.py:756} INFO - Processing file /opt/airflow/dags/group_dag.py for tasks to queue
[2024-04-15T16:02:26.571+0000] {logging_mixin.py:120} INFO - [2024-04-15T16:02:26.571+0000] {dagbag.py:537} INFO - Filling up the DagBag from /opt/airflow/dags/group_dag.py
[2024-04-15T16:02:26.616+0000] {logging_mixin.py:120} INFO - [2024-04-15T16:02:26.610+0000] {dagbag.py:342} ERROR - Failed to import: /opt/airflow/dags/group_dag.py
Traceback (most recent call last):
  File "/home/airflow/.local/lib/python3.7/site-packages/airflow/models/dagbag.py", line 338, in parse
    loader.exec_module(new_module)
  File "<frozen importlib._bootstrap_external>", line 728, in exec_module
  File "<frozen importlib._bootstrap>", line 219, in _call_with_frames_removed
  File "/opt/airflow/dags/group_dag.py", line 27, in <module>
    subdag=subdag_downloads(dag.dag_id, 'downloads', args)
  File "/opt/airflow/dags/subdags/subdags_downloads.py", line 9, in subdag_downloads
    catch = args['catchup']) as dag:
TypeError: __init__() got an unexpected keyword argument 'catch'
[2024-04-15T16:02:26.618+0000] {processor.py:768} WARNING - No viable dags retrieved from /opt/airflow/dags/group_dag.py
[2024-04-15T16:02:26.658+0000] {processor.py:176} INFO - Processing /opt/airflow/dags/group_dag.py took 0.100 seconds
[2024-04-15T16:02:57.530+0000] {processor.py:154} INFO - Started process (PID=22124) to work on /opt/airflow/dags/group_dag.py
[2024-04-15T16:02:57.532+0000] {processor.py:756} INFO - Processing file /opt/airflow/dags/group_dag.py for tasks to queue
[2024-04-15T16:02:57.534+0000] {logging_mixin.py:120} INFO - [2024-04-15T16:02:57.534+0000] {dagbag.py:537} INFO - Filling up the DagBag from /opt/airflow/dags/group_dag.py
[2024-04-15T16:02:57.574+0000] {logging_mixin.py:120} INFO - [2024-04-15T16:02:57.571+0000] {dagbag.py:342} ERROR - Failed to import: /opt/airflow/dags/group_dag.py
Traceback (most recent call last):
  File "/home/airflow/.local/lib/python3.7/site-packages/airflow/models/dagbag.py", line 338, in parse
    loader.exec_module(new_module)
  File "<frozen importlib._bootstrap_external>", line 728, in exec_module
  File "<frozen importlib._bootstrap>", line 219, in _call_with_frames_removed
  File "/opt/airflow/dags/group_dag.py", line 27, in <module>
    subdag=subdag_downloads(dag.dag_id, 'downloads', args)
  File "/opt/airflow/dags/subdags/subdags_downloads.py", line 9, in subdag_downloads
    catch = args['catchup']) as dag:
TypeError: __init__() got an unexpected keyword argument 'catch'
[2024-04-15T16:02:57.575+0000] {processor.py:768} WARNING - No viable dags retrieved from /opt/airflow/dags/group_dag.py
[2024-04-15T16:02:57.605+0000] {processor.py:176} INFO - Processing /opt/airflow/dags/group_dag.py took 0.081 seconds
[2024-04-15T16:03:28.303+0000] {processor.py:154} INFO - Started process (PID=22194) to work on /opt/airflow/dags/group_dag.py
[2024-04-15T16:03:28.305+0000] {processor.py:756} INFO - Processing file /opt/airflow/dags/group_dag.py for tasks to queue
[2024-04-15T16:03:28.308+0000] {logging_mixin.py:120} INFO - [2024-04-15T16:03:28.307+0000] {dagbag.py:537} INFO - Filling up the DagBag from /opt/airflow/dags/group_dag.py
[2024-04-15T16:03:28.353+0000] {logging_mixin.py:120} INFO - [2024-04-15T16:03:28.349+0000] {dagbag.py:342} ERROR - Failed to import: /opt/airflow/dags/group_dag.py
Traceback (most recent call last):
  File "/home/airflow/.local/lib/python3.7/site-packages/airflow/models/dagbag.py", line 338, in parse
    loader.exec_module(new_module)
  File "<frozen importlib._bootstrap_external>", line 728, in exec_module
  File "<frozen importlib._bootstrap>", line 219, in _call_with_frames_removed
  File "/opt/airflow/dags/group_dag.py", line 27, in <module>
    subdag=subdag_downloads(dag.dag_id, 'downloads', args)
  File "/opt/airflow/dags/subdags/subdags_downloads.py", line 9, in subdag_downloads
    catch = args['catchup']) as dag:
TypeError: __init__() got an unexpected keyword argument 'catch'
[2024-04-15T16:03:28.354+0000] {processor.py:768} WARNING - No viable dags retrieved from /opt/airflow/dags/group_dag.py
[2024-04-15T16:03:28.388+0000] {processor.py:176} INFO - Processing /opt/airflow/dags/group_dag.py took 0.091 seconds
[2024-04-15T16:03:58.673+0000] {processor.py:154} INFO - Started process (PID=22272) to work on /opt/airflow/dags/group_dag.py
[2024-04-15T16:03:58.675+0000] {processor.py:756} INFO - Processing file /opt/airflow/dags/group_dag.py for tasks to queue
[2024-04-15T16:03:58.677+0000] {logging_mixin.py:120} INFO - [2024-04-15T16:03:58.677+0000] {dagbag.py:537} INFO - Filling up the DagBag from /opt/airflow/dags/group_dag.py
[2024-04-15T16:03:58.733+0000] {logging_mixin.py:120} INFO - [2024-04-15T16:03:58.728+0000] {dagbag.py:342} ERROR - Failed to import: /opt/airflow/dags/group_dag.py
Traceback (most recent call last):
  File "/home/airflow/.local/lib/python3.7/site-packages/airflow/models/dagbag.py", line 338, in parse
    loader.exec_module(new_module)
  File "<frozen importlib._bootstrap_external>", line 728, in exec_module
  File "<frozen importlib._bootstrap>", line 219, in _call_with_frames_removed
  File "/opt/airflow/dags/group_dag.py", line 27, in <module>
    subdag=subdag_downloads(dag.dag_id, 'downloads', args)
  File "/opt/airflow/dags/subdags/subdags_downloads.py", line 9, in subdag_downloads
    catch = args['catchup']) as dag:
TypeError: __init__() got an unexpected keyword argument 'catch'
[2024-04-15T16:03:58.734+0000] {processor.py:768} WARNING - No viable dags retrieved from /opt/airflow/dags/group_dag.py
[2024-04-15T16:03:58.841+0000] {processor.py:176} INFO - Processing /opt/airflow/dags/group_dag.py took 0.173 seconds
[2024-04-15T16:04:29.600+0000] {processor.py:154} INFO - Started process (PID=22340) to work on /opt/airflow/dags/group_dag.py
[2024-04-15T16:04:29.602+0000] {processor.py:756} INFO - Processing file /opt/airflow/dags/group_dag.py for tasks to queue
[2024-04-15T16:04:29.603+0000] {logging_mixin.py:120} INFO - [2024-04-15T16:04:29.603+0000] {dagbag.py:537} INFO - Filling up the DagBag from /opt/airflow/dags/group_dag.py
[2024-04-15T16:04:29.646+0000] {logging_mixin.py:120} INFO - [2024-04-15T16:04:29.643+0000] {dagbag.py:342} ERROR - Failed to import: /opt/airflow/dags/group_dag.py
Traceback (most recent call last):
  File "/home/airflow/.local/lib/python3.7/site-packages/airflow/models/dagbag.py", line 338, in parse
    loader.exec_module(new_module)
  File "<frozen importlib._bootstrap_external>", line 728, in exec_module
  File "<frozen importlib._bootstrap>", line 219, in _call_with_frames_removed
  File "/opt/airflow/dags/group_dag.py", line 27, in <module>
    subdag=subdag_downloads(dag.dag_id, 'downloads', args)
  File "/opt/airflow/dags/subdags/subdags_downloads.py", line 9, in subdag_downloads
    catch = args['catchup']) as dag:
TypeError: __init__() got an unexpected keyword argument 'catch'
[2024-04-15T16:04:29.648+0000] {processor.py:768} WARNING - No viable dags retrieved from /opt/airflow/dags/group_dag.py
[2024-04-15T16:04:29.682+0000] {processor.py:176} INFO - Processing /opt/airflow/dags/group_dag.py took 0.088 seconds
[2024-04-15T16:05:00.332+0000] {processor.py:154} INFO - Started process (PID=22419) to work on /opt/airflow/dags/group_dag.py
[2024-04-15T16:05:00.336+0000] {processor.py:756} INFO - Processing file /opt/airflow/dags/group_dag.py for tasks to queue
[2024-04-15T16:05:00.338+0000] {logging_mixin.py:120} INFO - [2024-04-15T16:05:00.338+0000] {dagbag.py:537} INFO - Filling up the DagBag from /opt/airflow/dags/group_dag.py
[2024-04-15T16:05:00.376+0000] {logging_mixin.py:120} INFO - [2024-04-15T16:05:00.373+0000] {dagbag.py:342} ERROR - Failed to import: /opt/airflow/dags/group_dag.py
Traceback (most recent call last):
  File "/home/airflow/.local/lib/python3.7/site-packages/airflow/models/dagbag.py", line 338, in parse
    loader.exec_module(new_module)
  File "<frozen importlib._bootstrap_external>", line 728, in exec_module
  File "<frozen importlib._bootstrap>", line 219, in _call_with_frames_removed
  File "/opt/airflow/dags/group_dag.py", line 27, in <module>
    subdag=subdag_downloads(dag.dag_id, 'downloads', args)
  File "/opt/airflow/dags/subdags/subdags_downloads.py", line 9, in subdag_downloads
    catch = args['catchup']) as dag:
TypeError: __init__() got an unexpected keyword argument 'catch'
[2024-04-15T16:05:00.378+0000] {processor.py:768} WARNING - No viable dags retrieved from /opt/airflow/dags/group_dag.py
[2024-04-15T16:05:00.406+0000] {processor.py:176} INFO - Processing /opt/airflow/dags/group_dag.py took 0.080 seconds
[2024-04-15T16:05:30.454+0000] {processor.py:154} INFO - Started process (PID=22489) to work on /opt/airflow/dags/group_dag.py
[2024-04-15T16:05:30.456+0000] {processor.py:756} INFO - Processing file /opt/airflow/dags/group_dag.py for tasks to queue
[2024-04-15T16:05:30.457+0000] {logging_mixin.py:120} INFO - [2024-04-15T16:05:30.457+0000] {dagbag.py:537} INFO - Filling up the DagBag from /opt/airflow/dags/group_dag.py
[2024-04-15T16:05:30.501+0000] {logging_mixin.py:120} INFO - [2024-04-15T16:05:30.497+0000] {dagbag.py:342} ERROR - Failed to import: /opt/airflow/dags/group_dag.py
Traceback (most recent call last):
  File "/home/airflow/.local/lib/python3.7/site-packages/airflow/models/dagbag.py", line 338, in parse
    loader.exec_module(new_module)
  File "<frozen importlib._bootstrap_external>", line 728, in exec_module
  File "<frozen importlib._bootstrap>", line 219, in _call_with_frames_removed
  File "/opt/airflow/dags/group_dag.py", line 27, in <module>
    subdag=subdag_downloads(dag.dag_id, 'downloads', args)
  File "/opt/airflow/dags/subdags/subdags_downloads.py", line 9, in subdag_downloads
    catch = args['catchup']) as dag:
TypeError: __init__() got an unexpected keyword argument 'catch'
[2024-04-15T16:05:30.502+0000] {processor.py:768} WARNING - No viable dags retrieved from /opt/airflow/dags/group_dag.py
[2024-04-15T16:05:30.538+0000] {processor.py:176} INFO - Processing /opt/airflow/dags/group_dag.py took 0.090 seconds
[2024-04-15T16:06:00.794+0000] {processor.py:154} INFO - Started process (PID=22566) to work on /opt/airflow/dags/group_dag.py
[2024-04-15T16:06:00.796+0000] {processor.py:756} INFO - Processing file /opt/airflow/dags/group_dag.py for tasks to queue
[2024-04-15T16:06:00.797+0000] {logging_mixin.py:120} INFO - [2024-04-15T16:06:00.797+0000] {dagbag.py:537} INFO - Filling up the DagBag from /opt/airflow/dags/group_dag.py
[2024-04-15T16:06:00.841+0000] {logging_mixin.py:120} INFO - [2024-04-15T16:06:00.837+0000] {dagbag.py:342} ERROR - Failed to import: /opt/airflow/dags/group_dag.py
Traceback (most recent call last):
  File "/home/airflow/.local/lib/python3.7/site-packages/airflow/models/dagbag.py", line 338, in parse
    loader.exec_module(new_module)
  File "<frozen importlib._bootstrap_external>", line 728, in exec_module
  File "<frozen importlib._bootstrap>", line 219, in _call_with_frames_removed
  File "/opt/airflow/dags/group_dag.py", line 27, in <module>
    subdag=subdag_downloads(dag.dag_id, 'downloads', args)
  File "/opt/airflow/dags/subdags/subdags_downloads.py", line 9, in subdag_downloads
    catch = args['catchup']) as dag:
TypeError: __init__() got an unexpected keyword argument 'catch'
[2024-04-15T16:06:00.844+0000] {processor.py:768} WARNING - No viable dags retrieved from /opt/airflow/dags/group_dag.py
[2024-04-15T16:06:00.876+0000] {processor.py:176} INFO - Processing /opt/airflow/dags/group_dag.py took 0.087 seconds
[2024-04-15T16:06:31.002+0000] {processor.py:154} INFO - Started process (PID=22635) to work on /opt/airflow/dags/group_dag.py
[2024-04-15T16:06:31.005+0000] {processor.py:756} INFO - Processing file /opt/airflow/dags/group_dag.py for tasks to queue
[2024-04-15T16:06:31.007+0000] {logging_mixin.py:120} INFO - [2024-04-15T16:06:31.007+0000] {dagbag.py:537} INFO - Filling up the DagBag from /opt/airflow/dags/group_dag.py
[2024-04-15T16:06:31.048+0000] {logging_mixin.py:120} INFO - [2024-04-15T16:06:31.044+0000] {dagbag.py:342} ERROR - Failed to import: /opt/airflow/dags/group_dag.py
Traceback (most recent call last):
  File "/home/airflow/.local/lib/python3.7/site-packages/airflow/models/dagbag.py", line 338, in parse
    loader.exec_module(new_module)
  File "<frozen importlib._bootstrap_external>", line 728, in exec_module
  File "<frozen importlib._bootstrap>", line 219, in _call_with_frames_removed
  File "/opt/airflow/dags/group_dag.py", line 27, in <module>
    subdag=subdag_downloads(dag.dag_id, 'downloads', args)
  File "/opt/airflow/dags/subdags/subdags_downloads.py", line 9, in subdag_downloads
    catch = args['catchup']) as dag:
TypeError: __init__() got an unexpected keyword argument 'catch'
[2024-04-15T16:06:31.050+0000] {processor.py:768} WARNING - No viable dags retrieved from /opt/airflow/dags/group_dag.py
[2024-04-15T16:06:31.086+0000] {processor.py:176} INFO - Processing /opt/airflow/dags/group_dag.py took 0.093 seconds
[2024-04-15T16:07:01.159+0000] {processor.py:154} INFO - Started process (PID=22714) to work on /opt/airflow/dags/group_dag.py
[2024-04-15T16:07:01.163+0000] {processor.py:756} INFO - Processing file /opt/airflow/dags/group_dag.py for tasks to queue
[2024-04-15T16:07:01.164+0000] {logging_mixin.py:120} INFO - [2024-04-15T16:07:01.164+0000] {dagbag.py:537} INFO - Filling up the DagBag from /opt/airflow/dags/group_dag.py
[2024-04-15T16:07:01.200+0000] {logging_mixin.py:120} INFO - [2024-04-15T16:07:01.197+0000] {dagbag.py:342} ERROR - Failed to import: /opt/airflow/dags/group_dag.py
Traceback (most recent call last):
  File "/home/airflow/.local/lib/python3.7/site-packages/airflow/models/dagbag.py", line 338, in parse
    loader.exec_module(new_module)
  File "<frozen importlib._bootstrap_external>", line 728, in exec_module
  File "<frozen importlib._bootstrap>", line 219, in _call_with_frames_removed
  File "/opt/airflow/dags/group_dag.py", line 27, in <module>
    subdag=subdag_downloads(dag.dag_id, 'downloads', args)
  File "/opt/airflow/dags/subdags/subdags_downloads.py", line 9, in subdag_downloads
    catch = args['catchup']) as dag:
TypeError: __init__() got an unexpected keyword argument 'catch'
[2024-04-15T16:07:01.201+0000] {processor.py:768} WARNING - No viable dags retrieved from /opt/airflow/dags/group_dag.py
[2024-04-15T16:07:01.231+0000] {processor.py:176} INFO - Processing /opt/airflow/dags/group_dag.py took 0.078 seconds
[2024-04-15T16:07:31.581+0000] {processor.py:154} INFO - Started process (PID=22782) to work on /opt/airflow/dags/group_dag.py
[2024-04-15T16:07:31.583+0000] {processor.py:756} INFO - Processing file /opt/airflow/dags/group_dag.py for tasks to queue
[2024-04-15T16:07:31.585+0000] {logging_mixin.py:120} INFO - [2024-04-15T16:07:31.585+0000] {dagbag.py:537} INFO - Filling up the DagBag from /opt/airflow/dags/group_dag.py
[2024-04-15T16:07:31.635+0000] {logging_mixin.py:120} INFO - [2024-04-15T16:07:31.629+0000] {dagbag.py:342} ERROR - Failed to import: /opt/airflow/dags/group_dag.py
Traceback (most recent call last):
  File "/home/airflow/.local/lib/python3.7/site-packages/airflow/models/dagbag.py", line 338, in parse
    loader.exec_module(new_module)
  File "<frozen importlib._bootstrap_external>", line 728, in exec_module
  File "<frozen importlib._bootstrap>", line 219, in _call_with_frames_removed
  File "/opt/airflow/dags/group_dag.py", line 27, in <module>
    subdag=subdag_downloads(dag.dag_id, 'downloads', args)
  File "/opt/airflow/dags/subdags/subdags_downloads.py", line 9, in subdag_downloads
    catch = args['catchup']) as dag:
TypeError: __init__() got an unexpected keyword argument 'catch'
[2024-04-15T16:07:31.637+0000] {processor.py:768} WARNING - No viable dags retrieved from /opt/airflow/dags/group_dag.py
[2024-04-15T16:07:31.677+0000] {processor.py:176} INFO - Processing /opt/airflow/dags/group_dag.py took 0.105 seconds
[2024-04-15T16:08:01.984+0000] {processor.py:154} INFO - Started process (PID=22857) to work on /opt/airflow/dags/group_dag.py
[2024-04-15T16:08:01.986+0000] {processor.py:756} INFO - Processing file /opt/airflow/dags/group_dag.py for tasks to queue
[2024-04-15T16:08:01.989+0000] {logging_mixin.py:120} INFO - [2024-04-15T16:08:01.988+0000] {dagbag.py:537} INFO - Filling up the DagBag from /opt/airflow/dags/group_dag.py
[2024-04-15T16:08:02.039+0000] {logging_mixin.py:120} INFO - [2024-04-15T16:08:02.036+0000] {dagbag.py:342} ERROR - Failed to import: /opt/airflow/dags/group_dag.py
Traceback (most recent call last):
  File "/home/airflow/.local/lib/python3.7/site-packages/airflow/models/dagbag.py", line 338, in parse
    loader.exec_module(new_module)
  File "<frozen importlib._bootstrap_external>", line 728, in exec_module
  File "<frozen importlib._bootstrap>", line 219, in _call_with_frames_removed
  File "/opt/airflow/dags/group_dag.py", line 27, in <module>
    subdag=subdag_downloads(dag.dag_id, 'downloads', args)
  File "/opt/airflow/dags/subdags/subdags_downloads.py", line 9, in subdag_downloads
    catch = args['catchup']) as dag:
TypeError: __init__() got an unexpected keyword argument 'catch'
[2024-04-15T16:08:02.041+0000] {processor.py:768} WARNING - No viable dags retrieved from /opt/airflow/dags/group_dag.py
[2024-04-15T16:08:02.078+0000] {processor.py:176} INFO - Processing /opt/airflow/dags/group_dag.py took 0.099 seconds
[2024-04-15T16:08:32.773+0000] {processor.py:154} INFO - Started process (PID=22936) to work on /opt/airflow/dags/group_dag.py
[2024-04-15T16:08:32.776+0000] {processor.py:756} INFO - Processing file /opt/airflow/dags/group_dag.py for tasks to queue
[2024-04-15T16:08:32.779+0000] {logging_mixin.py:120} INFO - [2024-04-15T16:08:32.779+0000] {dagbag.py:537} INFO - Filling up the DagBag from /opt/airflow/dags/group_dag.py
[2024-04-15T16:08:32.862+0000] {logging_mixin.py:120} INFO - [2024-04-15T16:08:32.855+0000] {dagbag.py:342} ERROR - Failed to import: /opt/airflow/dags/group_dag.py
Traceback (most recent call last):
  File "/home/airflow/.local/lib/python3.7/site-packages/airflow/models/dagbag.py", line 338, in parse
    loader.exec_module(new_module)
  File "<frozen importlib._bootstrap_external>", line 728, in exec_module
  File "<frozen importlib._bootstrap>", line 219, in _call_with_frames_removed
  File "/opt/airflow/dags/group_dag.py", line 27, in <module>
    subdag=subdag_downloads(dag.dag_id, 'downloads', args)
  File "/opt/airflow/dags/subdags/subdags_downloads.py", line 9, in subdag_downloads
    catch = args['catchup']) as dag:
TypeError: __init__() got an unexpected keyword argument 'catch'
[2024-04-15T16:08:32.865+0000] {processor.py:768} WARNING - No viable dags retrieved from /opt/airflow/dags/group_dag.py
[2024-04-15T16:08:32.924+0000] {processor.py:176} INFO - Processing /opt/airflow/dags/group_dag.py took 0.163 seconds
[2024-04-15T16:09:03.821+0000] {processor.py:154} INFO - Started process (PID=23004) to work on /opt/airflow/dags/group_dag.py
[2024-04-15T16:09:03.823+0000] {processor.py:756} INFO - Processing file /opt/airflow/dags/group_dag.py for tasks to queue
[2024-04-15T16:09:03.826+0000] {logging_mixin.py:120} INFO - [2024-04-15T16:09:03.826+0000] {dagbag.py:537} INFO - Filling up the DagBag from /opt/airflow/dags/group_dag.py
[2024-04-15T16:09:03.869+0000] {logging_mixin.py:120} INFO - [2024-04-15T16:09:03.866+0000] {dagbag.py:342} ERROR - Failed to import: /opt/airflow/dags/group_dag.py
Traceback (most recent call last):
  File "/home/airflow/.local/lib/python3.7/site-packages/airflow/models/dagbag.py", line 338, in parse
    loader.exec_module(new_module)
  File "<frozen importlib._bootstrap_external>", line 728, in exec_module
  File "<frozen importlib._bootstrap>", line 219, in _call_with_frames_removed
  File "/opt/airflow/dags/group_dag.py", line 27, in <module>
    subdag=subdag_downloads(dag.dag_id, 'downloads', args)
  File "/opt/airflow/dags/subdags/subdags_downloads.py", line 9, in subdag_downloads
    catch = args['catchup']) as dag:
TypeError: __init__() got an unexpected keyword argument 'catch'
[2024-04-15T16:09:03.870+0000] {processor.py:768} WARNING - No viable dags retrieved from /opt/airflow/dags/group_dag.py
[2024-04-15T16:09:03.907+0000] {processor.py:176} INFO - Processing /opt/airflow/dags/group_dag.py took 0.093 seconds
[2024-04-15T16:09:34.623+0000] {processor.py:154} INFO - Started process (PID=23082) to work on /opt/airflow/dags/group_dag.py
[2024-04-15T16:09:34.624+0000] {processor.py:756} INFO - Processing file /opt/airflow/dags/group_dag.py for tasks to queue
[2024-04-15T16:09:34.626+0000] {logging_mixin.py:120} INFO - [2024-04-15T16:09:34.626+0000] {dagbag.py:537} INFO - Filling up the DagBag from /opt/airflow/dags/group_dag.py
[2024-04-15T16:09:34.663+0000] {logging_mixin.py:120} INFO - [2024-04-15T16:09:34.659+0000] {dagbag.py:342} ERROR - Failed to import: /opt/airflow/dags/group_dag.py
Traceback (most recent call last):
  File "/home/airflow/.local/lib/python3.7/site-packages/airflow/models/dagbag.py", line 338, in parse
    loader.exec_module(new_module)
  File "<frozen importlib._bootstrap_external>", line 728, in exec_module
  File "<frozen importlib._bootstrap>", line 219, in _call_with_frames_removed
  File "/opt/airflow/dags/group_dag.py", line 27, in <module>
    subdag=subdag_downloads(dag.dag_id, 'downloads', args)
  File "/opt/airflow/dags/subdags/subdags_downloads.py", line 9, in subdag_downloads
    catch = args['catchup']) as dag:
TypeError: __init__() got an unexpected keyword argument 'catch'
[2024-04-15T16:09:34.664+0000] {processor.py:768} WARNING - No viable dags retrieved from /opt/airflow/dags/group_dag.py
[2024-04-15T16:09:34.709+0000] {processor.py:176} INFO - Processing /opt/airflow/dags/group_dag.py took 0.091 seconds
[2024-04-15T16:10:04.768+0000] {processor.py:154} INFO - Started process (PID=23151) to work on /opt/airflow/dags/group_dag.py
[2024-04-15T16:10:04.770+0000] {processor.py:756} INFO - Processing file /opt/airflow/dags/group_dag.py for tasks to queue
[2024-04-15T16:10:04.779+0000] {logging_mixin.py:120} INFO - [2024-04-15T16:10:04.779+0000] {dagbag.py:537} INFO - Filling up the DagBag from /opt/airflow/dags/group_dag.py
[2024-04-15T16:10:04.822+0000] {logging_mixin.py:120} INFO - [2024-04-15T16:10:04.818+0000] {dagbag.py:342} ERROR - Failed to import: /opt/airflow/dags/group_dag.py
Traceback (most recent call last):
  File "/home/airflow/.local/lib/python3.7/site-packages/airflow/models/dagbag.py", line 338, in parse
    loader.exec_module(new_module)
  File "<frozen importlib._bootstrap_external>", line 728, in exec_module
  File "<frozen importlib._bootstrap>", line 219, in _call_with_frames_removed
  File "/opt/airflow/dags/group_dag.py", line 27, in <module>
    subdag=subdag_downloads(dag.dag_id, 'downloads', args)
  File "/opt/airflow/dags/subdags/subdags_downloads.py", line 9, in subdag_downloads
    catch = args['catchup']) as dag:
TypeError: __init__() got an unexpected keyword argument 'catch'
[2024-04-15T16:10:04.830+0000] {processor.py:768} WARNING - No viable dags retrieved from /opt/airflow/dags/group_dag.py
[2024-04-15T16:10:04.864+0000] {processor.py:176} INFO - Processing /opt/airflow/dags/group_dag.py took 0.101 seconds
[2024-04-15T16:10:35.529+0000] {processor.py:154} INFO - Started process (PID=23230) to work on /opt/airflow/dags/group_dag.py
[2024-04-15T16:10:35.531+0000] {processor.py:756} INFO - Processing file /opt/airflow/dags/group_dag.py for tasks to queue
[2024-04-15T16:10:35.534+0000] {logging_mixin.py:120} INFO - [2024-04-15T16:10:35.534+0000] {dagbag.py:537} INFO - Filling up the DagBag from /opt/airflow/dags/group_dag.py
[2024-04-15T16:10:35.586+0000] {logging_mixin.py:120} INFO - [2024-04-15T16:10:35.581+0000] {dagbag.py:342} ERROR - Failed to import: /opt/airflow/dags/group_dag.py
Traceback (most recent call last):
  File "/home/airflow/.local/lib/python3.7/site-packages/airflow/models/dagbag.py", line 338, in parse
    loader.exec_module(new_module)
  File "<frozen importlib._bootstrap_external>", line 728, in exec_module
  File "<frozen importlib._bootstrap>", line 219, in _call_with_frames_removed
  File "/opt/airflow/dags/group_dag.py", line 27, in <module>
    subdag=subdag_downloads(dag.dag_id, 'downloads', args)
  File "/opt/airflow/dags/subdags/subdags_downloads.py", line 9, in subdag_downloads
    catch = args['catchup']) as dag:
TypeError: __init__() got an unexpected keyword argument 'catch'
[2024-04-15T16:10:35.587+0000] {processor.py:768} WARNING - No viable dags retrieved from /opt/airflow/dags/group_dag.py
[2024-04-15T16:10:35.622+0000] {processor.py:176} INFO - Processing /opt/airflow/dags/group_dag.py took 0.109 seconds
[2024-04-15T16:11:06.366+0000] {processor.py:154} INFO - Started process (PID=23306) to work on /opt/airflow/dags/group_dag.py
[2024-04-15T16:11:06.368+0000] {processor.py:756} INFO - Processing file /opt/airflow/dags/group_dag.py for tasks to queue
[2024-04-15T16:11:06.380+0000] {logging_mixin.py:120} INFO - [2024-04-15T16:11:06.379+0000] {dagbag.py:537} INFO - Filling up the DagBag from /opt/airflow/dags/group_dag.py
[2024-04-15T16:11:06.420+0000] {logging_mixin.py:120} INFO - [2024-04-15T16:11:06.417+0000] {dagbag.py:342} ERROR - Failed to import: /opt/airflow/dags/group_dag.py
Traceback (most recent call last):
  File "/home/airflow/.local/lib/python3.7/site-packages/airflow/models/dagbag.py", line 338, in parse
    loader.exec_module(new_module)
  File "<frozen importlib._bootstrap_external>", line 728, in exec_module
  File "<frozen importlib._bootstrap>", line 219, in _call_with_frames_removed
  File "/opt/airflow/dags/group_dag.py", line 27, in <module>
    subdag=subdag_downloads(dag.dag_id, 'downloads', args)
  File "/opt/airflow/dags/subdags/subdags_downloads.py", line 9, in subdag_downloads
    catch = args['catchup']) as dag:
TypeError: __init__() got an unexpected keyword argument 'catch'
[2024-04-15T16:11:06.421+0000] {processor.py:768} WARNING - No viable dags retrieved from /opt/airflow/dags/group_dag.py
[2024-04-15T16:11:06.449+0000] {processor.py:176} INFO - Processing /opt/airflow/dags/group_dag.py took 0.089 seconds
[2024-04-15T16:11:36.651+0000] {processor.py:154} INFO - Started process (PID=23377) to work on /opt/airflow/dags/group_dag.py
[2024-04-15T16:11:36.653+0000] {processor.py:756} INFO - Processing file /opt/airflow/dags/group_dag.py for tasks to queue
[2024-04-15T16:11:36.655+0000] {logging_mixin.py:120} INFO - [2024-04-15T16:11:36.655+0000] {dagbag.py:537} INFO - Filling up the DagBag from /opt/airflow/dags/group_dag.py
[2024-04-15T16:11:36.703+0000] {logging_mixin.py:120} INFO - [2024-04-15T16:11:36.698+0000] {dagbag.py:342} ERROR - Failed to import: /opt/airflow/dags/group_dag.py
Traceback (most recent call last):
  File "/home/airflow/.local/lib/python3.7/site-packages/airflow/models/dagbag.py", line 338, in parse
    loader.exec_module(new_module)
  File "<frozen importlib._bootstrap_external>", line 728, in exec_module
  File "<frozen importlib._bootstrap>", line 219, in _call_with_frames_removed
  File "/opt/airflow/dags/group_dag.py", line 27, in <module>
    subdag=subdag_downloads(dag.dag_id, 'downloads', args)
  File "/opt/airflow/dags/subdags/subdags_downloads.py", line 9, in subdag_downloads
    catch = args['catchup']) as dag:
TypeError: __init__() got an unexpected keyword argument 'catch'
[2024-04-15T16:11:36.705+0000] {processor.py:768} WARNING - No viable dags retrieved from /opt/airflow/dags/group_dag.py
[2024-04-15T16:11:36.738+0000] {processor.py:176} INFO - Processing /opt/airflow/dags/group_dag.py took 0.093 seconds
[2024-04-15T16:12:06.919+0000] {processor.py:154} INFO - Started process (PID=23454) to work on /opt/airflow/dags/group_dag.py
[2024-04-15T16:12:06.924+0000] {processor.py:756} INFO - Processing file /opt/airflow/dags/group_dag.py for tasks to queue
[2024-04-15T16:12:06.927+0000] {logging_mixin.py:120} INFO - [2024-04-15T16:12:06.926+0000] {dagbag.py:537} INFO - Filling up the DagBag from /opt/airflow/dags/group_dag.py
[2024-04-15T16:12:06.971+0000] {logging_mixin.py:120} INFO - [2024-04-15T16:12:06.966+0000] {dagbag.py:342} ERROR - Failed to import: /opt/airflow/dags/group_dag.py
Traceback (most recent call last):
  File "/home/airflow/.local/lib/python3.7/site-packages/airflow/models/dagbag.py", line 338, in parse
    loader.exec_module(new_module)
  File "<frozen importlib._bootstrap_external>", line 728, in exec_module
  File "<frozen importlib._bootstrap>", line 219, in _call_with_frames_removed
  File "/opt/airflow/dags/group_dag.py", line 27, in <module>
    subdag=subdag_downloads(dag.dag_id, 'downloads', args)
  File "/opt/airflow/dags/subdags/subdags_downloads.py", line 9, in subdag_downloads
    catch = args['catchup']) as dag:
TypeError: __init__() got an unexpected keyword argument 'catch'
[2024-04-15T16:12:06.972+0000] {processor.py:768} WARNING - No viable dags retrieved from /opt/airflow/dags/group_dag.py
[2024-04-15T16:12:07.021+0000] {processor.py:176} INFO - Processing /opt/airflow/dags/group_dag.py took 0.110 seconds
[2024-04-15T16:12:37.409+0000] {processor.py:154} INFO - Started process (PID=23520) to work on /opt/airflow/dags/group_dag.py
[2024-04-15T16:12:37.412+0000] {processor.py:756} INFO - Processing file /opt/airflow/dags/group_dag.py for tasks to queue
[2024-04-15T16:12:37.414+0000] {logging_mixin.py:120} INFO - [2024-04-15T16:12:37.414+0000] {dagbag.py:537} INFO - Filling up the DagBag from /opt/airflow/dags/group_dag.py
[2024-04-15T16:12:37.466+0000] {logging_mixin.py:120} INFO - [2024-04-15T16:12:37.461+0000] {dagbag.py:342} ERROR - Failed to import: /opt/airflow/dags/group_dag.py
Traceback (most recent call last):
  File "/home/airflow/.local/lib/python3.7/site-packages/airflow/models/dagbag.py", line 338, in parse
    loader.exec_module(new_module)
  File "<frozen importlib._bootstrap_external>", line 728, in exec_module
  File "<frozen importlib._bootstrap>", line 219, in _call_with_frames_removed
  File "/opt/airflow/dags/group_dag.py", line 27, in <module>
    subdag=subdag_downloads(dag.dag_id, 'downloads', args)
  File "/opt/airflow/dags/subdags/subdags_downloads.py", line 9, in subdag_downloads
    catch = args['catchup']) as dag:
TypeError: __init__() got an unexpected keyword argument 'catch'
[2024-04-15T16:12:37.467+0000] {processor.py:768} WARNING - No viable dags retrieved from /opt/airflow/dags/group_dag.py
[2024-04-15T16:12:37.501+0000] {processor.py:176} INFO - Processing /opt/airflow/dags/group_dag.py took 0.101 seconds
[2024-04-15T16:13:07.575+0000] {processor.py:154} INFO - Started process (PID=23599) to work on /opt/airflow/dags/group_dag.py
[2024-04-15T16:13:07.578+0000] {processor.py:756} INFO - Processing file /opt/airflow/dags/group_dag.py for tasks to queue
[2024-04-15T16:13:07.581+0000] {logging_mixin.py:120} INFO - [2024-04-15T16:13:07.580+0000] {dagbag.py:537} INFO - Filling up the DagBag from /opt/airflow/dags/group_dag.py
[2024-04-15T16:13:07.631+0000] {logging_mixin.py:120} INFO - [2024-04-15T16:13:07.627+0000] {dagbag.py:342} ERROR - Failed to import: /opt/airflow/dags/group_dag.py
Traceback (most recent call last):
  File "/home/airflow/.local/lib/python3.7/site-packages/airflow/models/dagbag.py", line 338, in parse
    loader.exec_module(new_module)
  File "<frozen importlib._bootstrap_external>", line 728, in exec_module
  File "<frozen importlib._bootstrap>", line 219, in _call_with_frames_removed
  File "/opt/airflow/dags/group_dag.py", line 27, in <module>
    subdag=subdag_downloads(dag.dag_id, 'downloads', args)
  File "/opt/airflow/dags/subdags/subdags_downloads.py", line 9, in subdag_downloads
    catch = args['catchup']) as dag:
TypeError: __init__() got an unexpected keyword argument 'catch'
[2024-04-15T16:13:07.634+0000] {processor.py:768} WARNING - No viable dags retrieved from /opt/airflow/dags/group_dag.py
[2024-04-15T16:13:07.677+0000] {processor.py:176} INFO - Processing /opt/airflow/dags/group_dag.py took 0.110 seconds
[2024-04-15T16:13:37.932+0000] {processor.py:154} INFO - Started process (PID=23668) to work on /opt/airflow/dags/group_dag.py
[2024-04-15T16:13:37.942+0000] {processor.py:756} INFO - Processing file /opt/airflow/dags/group_dag.py for tasks to queue
[2024-04-15T16:13:37.960+0000] {logging_mixin.py:120} INFO - [2024-04-15T16:13:37.959+0000] {dagbag.py:537} INFO - Filling up the DagBag from /opt/airflow/dags/group_dag.py
[2024-04-15T16:13:38.135+0000] {logging_mixin.py:120} INFO - [2024-04-15T16:13:38.115+0000] {dagbag.py:342} ERROR - Failed to import: /opt/airflow/dags/group_dag.py
Traceback (most recent call last):
  File "/home/airflow/.local/lib/python3.7/site-packages/airflow/models/dagbag.py", line 338, in parse
    loader.exec_module(new_module)
  File "<frozen importlib._bootstrap_external>", line 728, in exec_module
  File "<frozen importlib._bootstrap>", line 219, in _call_with_frames_removed
  File "/opt/airflow/dags/group_dag.py", line 27, in <module>
    subdag=subdag_downloads(dag.dag_id, 'downloads', args)
  File "/opt/airflow/dags/subdags/subdags_downloads.py", line 9, in subdag_downloads
    catch = args['catchup']) as dag:
TypeError: __init__() got an unexpected keyword argument 'catch'
[2024-04-15T16:13:38.142+0000] {processor.py:768} WARNING - No viable dags retrieved from /opt/airflow/dags/group_dag.py
[2024-04-15T16:13:38.297+0000] {processor.py:176} INFO - Processing /opt/airflow/dags/group_dag.py took 0.395 seconds
[2024-04-15T16:20:18.015+0000] {processor.py:154} INFO - Started process (PID=23684) to work on /opt/airflow/dags/group_dag.py
[2024-04-15T16:20:18.028+0000] {processor.py:756} INFO - Processing file /opt/airflow/dags/group_dag.py for tasks to queue
[2024-04-15T16:20:18.041+0000] {logging_mixin.py:120} INFO - [2024-04-15T16:20:18.041+0000] {dagbag.py:537} INFO - Filling up the DagBag from /opt/airflow/dags/group_dag.py
[2024-04-15T16:20:18.208+0000] {logging_mixin.py:120} INFO - [2024-04-15T16:20:18.194+0000] {dagbag.py:342} ERROR - Failed to import: /opt/airflow/dags/group_dag.py
Traceback (most recent call last):
  File "/home/airflow/.local/lib/python3.7/site-packages/airflow/models/dagbag.py", line 338, in parse
    loader.exec_module(new_module)
  File "<frozen importlib._bootstrap_external>", line 728, in exec_module
  File "<frozen importlib._bootstrap>", line 219, in _call_with_frames_removed
  File "/opt/airflow/dags/group_dag.py", line 27, in <module>
    subdag=subdag_downloads(dag.dag_id, 'downloads', args)
  File "/opt/airflow/dags/subdags/subdags_downloads.py", line 9, in subdag_downloads
    catch = args['catchup']) as dag:
TypeError: __init__() got an unexpected keyword argument 'catch'
[2024-04-15T16:20:18.209+0000] {processor.py:768} WARNING - No viable dags retrieved from /opt/airflow/dags/group_dag.py
[2024-04-15T16:20:18.289+0000] {processor.py:176} INFO - Processing /opt/airflow/dags/group_dag.py took 0.294 seconds
